Workbook

Sheet Read Me
A1: Cable tray structural check
A2: Strength, shear and deflection of ladder, perforated and trough trays, trapeze channels and cantilever arms. Standalone, formula-driven.
A4: Purpose | B4: Check whether a cable tray, a trapeze channel or a cantilever arm carries a given cable load over a given support spacing, and find the safe working load (SWL) and the longest span that still carries the load.
A5: How to use | B5: Enter one tray per row on Inputs (yellow cells): type, width, depth, steel thickness, the cable load in kg/m, the support span in m, the support condition and the concentrated load. Calc does the work row by row. Summary shows one row in detail (change the row number in its yellow cell), the verdict for every row, and a chart of SWL against span.
A6: Method | B6: 1) Section: thin-wall rectangular parts give area, neutral axis, second moment I and section moduli (perforation holes reduce the base plate of perforated and trough trays). 2) Straight tray or channel as a beam: bending M = kw·w·L² + kp·P·L, shear V = kv·(w·L + P), deflection d = dw·w·L⁴/EI + dp·P·L³/EI, with coefficients for a simple or a continuous span; the moment capacity is allowable stress × the smaller section modulus × a splice efficiency for the coupler joint. 3) Ladder rungs are checked separately as simply supported beams across the width. 4) Cantilever arm: the cable and tray load of one support spacing acts at mid-length of the arm plus an installer load at the tip, checked for bending, shear and tip deflection (limit = arm length / 100). 5) SWL is the cable load at which the first of bending, shear or deflection governs, after deducting the tray self-weight.
A7: Verdict | B7: PASS when every utilisation (applied ÷ capacity) is at most 100%. The governing check is the one with the smallest SWL.
A8: Self-weight | B8: Type the tray weight in kg/m if you know it (for example from the cost model or a catalogue). Leave it blank to use the estimate computed from the section area and, for ladders, the rungs.
A9: Conventions | B9: Yellow fill = input. Blue font = a typed assumption (Parameters). Black = formula. Green fill = key output. Units: mm, N and MPa inside the calculation; kg, kg/m and m on the sheets that you read.
A10: Origin | B10: This workbook mirrors the structural check in the Should-Cost dashboards (cable-trays.html, tab Structural check) and reproduces its results; the dashboard model is an own calculation, not taken from a vendor or code workbook. The sample rows on Inputs are the cases used to verify the workbook against the dashboard.
A11: Limits | B11: Elastic design with a single factor of safety on yield; no web-crippling, lateral-torsional or local-buckling design (slenderness flags only); no seismic or wind load; fittings (bends, tees, crosses) are not checked here: check the straight tray they connect to and keep their support spacing to about half the straight-run span. This is a screening check, not a certified design: confirm against the manufacturer's load-span table or NEMA VE 1 / IEC 61537 type test data before relying on it.

Sheet Inputs
A1: Inputs: one tray per row
A2: Yellow cells are inputs. Kinds: ladder, perf (perforated), trough, channel, arm (cantilever arm). Clear a row's Kind to leave it out.
A4: Tag | B4: Kind | C4: Width | D4: Depth | E4: Thickness | F4: Arm length | G4: Self-weight (blank = estimate) | H4: Cable load | I4: Support span / arm spacing | J4: Support | K4: Point load | L4: Deflection limit | M4: Channel span | N4: Supported tray weight
C5: mm | D5: mm | E5: mm | F5: mm (arm) | G5: kg/m | H5: kg/m | I5: m | J5: simple / continuous | K5: kg | L5: L / x | M5: mm (channel) | N5: kg/m (arm, channel)
A6: Ladder 600 x 100 x 2.0, simple span | B6: ladder | C6: 600 | D6: 100 | E6: 2 | G6: 8.56 | H6: 40 | I6: 2.5 | J6: simple | K6: 90 | L6: 200
A7: Ladder 300 x 75 x 2.0, continuous | B7: ladder | C7: 300 | D7: 75 | E7: 2 | G7: 6.079 | H7: 30 | I7: 3 | J7: continuous | K7: 90 | L7: 200
A8: Ladder 600 x 100 x 2.0, overloaded | B8: ladder | C8: 600 | D8: 100 | E8: 2 | G8: 8.56 | H8: 400 | I8: 2.5 | J8: simple | K8: 90 | L8: 200
A9: Perforated 300 x 100 x 2.0 | B9: perf | C9: 300 | D9: 100 | E9: 2 | G9: 9.028 | H9: 25 | I9: 2 | J9: simple | K9: 90 | L9: 200
A10: Trough 150 x 50 x 2.5 | B10: trough | C10: 150 | D10: 50 | E10: 2.5 | G10: 5.403 | H10: 10 | I10: 1.5 | J10: simple | K10: 60 | L10: 200
A11: Cantilever arm 620 mm, 41 x 41 x 2.5 | B11: arm | C11: 41 | D11: 41 | E11: 2.5 | F11: 620 | G11: 2.796 | H11: 20 | I11: 2 | J11: simple | K11: 90 | L11: 200 | N11: 8
A12: Cantilever arm 320 mm, 41 x 41 x 2.5 | B12: arm | C12: 41 | D12: 41 | E12: 2.5 | F12: 320 | G12: 2.8 | H12: 20 | I12: 2 | J12: simple | K12: 90 | L12: 200 | N12: 8
A13: Channel 41 x 41 x 2.5, trapeze 600 mm | B13: channel | C13: 41 | D13: 41 | E13: 2.5 | G13: 2.791 | H13: 20 | I13: 2 | J13: simple | K13: 90 | L13: 200 | M13: 600 | N13: 8
A27: Arm: enter the arm length in "Arm length", the arm spacing along the run in "Support span / arm spacing", and the weight of tray supported per metre in the last column.
A28: Channel: the channel span is the trapeze length between its two hangers; the cable and tray load of one support spacing acts on it as a uniform load.
A29: Straight tray (ladder, perf, trough): "Support span" is the distance between supports; support condition simple or continuous over several spans.

Sheet Summary
A1: Summary
A2: Pick a row to see it in detail. The table below lists every row.
A3: Row to show (1-20) | B3: 1
A5: Tray
A6: Tag | B6: =INDEX(Inputs!$A$6:$A$25,$B$3) -> Ladder 600 x 100 x 2.0, simple span
A7: Kind | B7: =INDEX(Inputs!$B$6:$B$25,$B$3) -> ladder
A8: Width x depth x thickness (mm) | B8: =INDEX(Inputs!$C$6:$C$25,$B$3)&" x "&INDEX(Inputs!$D$6:$D$25,$B$3)&" x "&INDEX(Inputs!$E$6:$E$25,$B$3) -> 600 x 100 x 2
A9: Cable load | B9: =INDEX(Inputs!$H$6:$H$25,$B$3) -> 40 | C9: kg/m
A10: Support span / arm spacing | B10: =INDEX(Inputs!$I$6:$I$25,$B$3) -> 2.5 | C10: m
A12: Result
A13: VERDICT | B13: =INDEX(Calc!$BW$6:$BW$25,$B$3) -> PASS
A14: Safe working load | B14: =INDEX(Calc!$BU$6:$BU$25,$B$3) -> 94.250745 | C14: kg/m
A15: Governing check | B15: =INDEX(Calc!$BV$6:$BV$25,$B$3) -> bending
A16: Governing utilisation | B16: =INDEX(Calc!$BT$6:$BT$25,$B$3) -> 0.819135
A17: Load margin (SWL / load - 1) | B17: =INDEX(Calc!$BX$6:$BX$25,$B$3) -> 1.3562686
A18: Safe working load per arm | B18: =IF(B7="arm",INDEX(Calc!$BI$6:$BI$25,$B$3),"n/a") -> n/a | C18: kg
A20: Utilisation (applied / capacity)
A21: Bending | B21: =INDEX(Calc!$BQ$6:$BQ$25,$B$3) -> 0.68966012
A22: Shear in the webs | B22: =INDEX(Calc!$BR$6:$BR$25,$B$3) -> 0.025922925
A23: Deflection | B23: =INDEX(Calc!$BS$6:$BS$25,$B$3) -> 0.26042207
A24: Rung bending (ladder) | B24: =IF(B7="ladder",INDEX(Calc!$AW$6:$AW$25,$B$3),"n/a") -> 0.819135
A26: Section
A27: Section area | B27: =INDEX(Calc!$N$6:$N$25,$B$3) -> 600 | C27: mm²
A28: Neutral axis from base | B28: =INDEX(Calc!$O$6:$O$25,$B$3) -> 50 | C28: mm
A29: Second moment I | B29: =INDEX(Calc!$P$6:$P$25,$B$3) -> 813600 | C29: mm⁴
A30: Section modulus, base | B30: =INDEX(Calc!$Q$6:$Q$25,$B$3) -> 16272 | C30: mm³
A31: Section modulus, top | B31: =INDEX(Calc!$R$6:$R$25,$B$3) -> 16272 | C31: mm³
A32: Self-weight used | B32: =INDEX(Calc!$U$6:$U$25,$B$3) -> 8.56 | C32: kg/m
A33: Slenderness flags | B33: =INDEX(Calc!$Y$6:$Y$25,$B$3)
A35: Longest span that carries the load | B35: ='Span curve'!B7 -> 3.2404385 | C35: m | D35: ='Span curve'!B8
A36: Resolution 0.1 m with linear interpolation between grid points. Channels have no span curve (the channel span is fixed).
A38: Row / tag | B38: Kind | C38: SWL kg/m | D38: Load kg/m | E38: Utilisation | F38: Governing | G38: Verdict
A39: =IF(Inputs!B6="","",1&" "&Inputs!A6) -> 1 Ladder 600 x 100 x 2.0, simple span | B39: =IF(Inputs!B6="","",Inputs!B6) -> ladder | C39: =IF(Inputs!B6="","",Calc!BU6) -> 94.250745 | D39: =IF(Inputs!B6="","",Inputs!H6) -> 40 | E39: =IF(Inputs!B6="","",Calc!BT6) -> 0.819135 | F39: =IF(Inputs!B6="","",Calc!BV6) -> bending | G39: =IF(Inputs!B6="","",Calc!BW6) -> PASS
A40: =IF(Inputs!B7="","",2&" "&Inputs!A7) -> 2 Ladder 300 x 75 x 2.0, continuous | B40: =IF(Inputs!B7="","",Inputs!B7) -> ladder | C40: =IF(Inputs!B7="","",Calc!BU7) -> 35.169592 | D40: =IF(Inputs!B7="","",Inputs!H7) -> 30 | E40: =IF(Inputs!B7="","",Calc!BT7) -> 0.94894159 | F40: =IF(Inputs!B7="","",Calc!BV7) -> bending | G40: =IF(Inputs!B7="","",Calc!BW7) -> PASS
A41: =IF(Inputs!B8="","",3&" "&Inputs!A8) -> 3 Ladder 600 x 100 x 2.0, overloaded | B41: =IF(Inputs!B8="","",Inputs!B8) -> ladder | C41: =IF(Inputs!B8="","",Calc!BU8) -> 94.250745 | D41: =IF(Inputs!B8="","",Inputs!H8) -> 400 | E41: =IF(Inputs!B8="","",Calc!BT8) -> 2.7490301 | F41: =IF(Inputs!B8="","",Calc!BV8) -> bending | G41: =IF(Inputs!B8="","",Calc!BW8) -> FAIL
A42: =IF(Inputs!B9="","",4&" "&Inputs!A9) -> 4 Perforated 300 x 100 x 2.0 | B42: =IF(Inputs!B9="","",Inputs!B9) -> perf | C42: =IF(Inputs!B9="","",Calc!BU9) -> 181.06278 | D42: =IF(Inputs!B9="","",Inputs!H9) -> 25 | E42: =IF(Inputs!B9="","",Calc!BT9) -> 0.44281357 | F42: =IF(Inputs!B9="","",Calc!BV9) -> bending | G42: =IF(Inputs!B9="","",Calc!BW9) -> PASS
A43: =IF(Inputs!B10="","",5&" "&Inputs!A10) -> 5 Trough 150 x 50 x 2.5 | B43: =IF(Inputs!B10="","",Inputs!B10) -> trough | C43: =IF(Inputs!B10="","",Calc!BU10) -> 18.065729 | D43: =IF(Inputs!B10="","",Inputs!H10) -> 10 | E43: =IF(Inputs!B10="","",Calc!BT10) -> 0.9220467 | F43: =IF(Inputs!B10="","",Calc!BV10) -> bending | G43: =IF(Inputs!B10="","",Calc!BW10) -> PASS
A44: =IF(Inputs!B11="","",6&" "&Inputs!A11) -> 6 Cantilever arm 620 mm, 41 x 41 x 2.5 | B44: =IF(Inputs!B11="","",Inputs!B11) -> arm | C44: =IF(Inputs!B11="","",Calc!BU11) -> 45.267376 | D44: =IF(Inputs!B11="","",Inputs!H11) -> 20 | E44: =IF(Inputs!B11="","",Calc!BT11) -> 0.69655131 | F44: =IF(Inputs!B11="","",Calc!BV11) -> bending | G44: =IF(Inputs!B11="","",Calc!BW11) -> PASS
A45: =IF(Inputs!B12="","",7&" "&Inputs!A12) -> 7 Cantilever arm 320 mm, 41 x 41 x 2.5 | B45: =IF(Inputs!B12="","",Inputs!B12) -> arm | C45: =IF(Inputs!B12="","",Calc!BU12) -> 123.33054 | D45: =IF(Inputs!B12="","",Inputs!H12) -> 20 | E45: =IF(Inputs!B12="","",Calc!BT12) -> 0.35951035 | F45: =IF(Inputs!B12="","",Calc!BV12) -> bending | G45: =IF(Inputs!B12="","",Calc!BW12) -> PASS
A46: =IF(Inputs!B13="","",8&" "&Inputs!A13) -> 8 Channel 41 x 41 x 2.5, trapeze 600 mm | B46: =IF(Inputs!B13="","",Inputs!B13) -> channel | C46: =IF(Inputs!B13="","",Calc!BU13) -> 328.19067 | D46: =IF(Inputs!B13="","",Inputs!H13) -> 20 | E46: =IF(Inputs!B13="","",Calc!BT13) -> 0.62779055 | F46: =IF(Inputs!B13="","",Calc!BV13) -> bending | G46: =IF(Inputs!B13="","",Calc!BW13) -> PASS
...

Sheet Calc
A1: Calculation: one row per tray
A2: Same row numbers as Inputs. Section (1), beam check (2), arm check (3), result (4).
A4: Tag | B4: Kind | C4: Perforation ratio | D4: Return width | E4: Part 1 area | F4: Part 1 centroid | G4: Part 1 own I | H4: Part 2 area | I4: Part 2 centroid | J4: Part 2 own I | K4: Part 3 area | L4: Part 3 centroid | M4: Part 3 own I | N4: Section area | O4: Neutral axis from base | P4: Second moment I | Q4: Z, base | R4: Z, top | S4: Web area | T4: Self-weight estimate | U4: Self-weight used | V4: Web depth / t | W4: Return / t | X4: Base width / t | Y4: Slenderness flags | Z4: kw | AA4: kp | AB4: dw | AC4: dp | AD4: kv | AE4: Allowable stress | AF4: Point load | AG4: EI | AH4: Shear capacity | AI4: Beam span L | AJ4: Cable line load | AK4: Moment capacity (beam) | AL4: Deflection limit | AM4: Self load | AN4: Cable load | AO4: Applied moment | AP4: Applied shear | AQ4: Deflection | AR4: SWL, bending | AS4: SWL, shear | AT4: SWL, deflection | AU4: SWL (beam) | AV4: Governing (beam) | AW4: Rung utilisation | AX4: Moment capacity (arm) | AY4: Tip deflection limit | AZ4: Cable load on one arm | BA4: Cable + tray on one arm | BB4: Tip load | BC4: Applied moment | BD4: Applied shear | BE4: Tip deflection | BF4: Arm capacity, bending | BG4: Arm capacity, shear | BH4: Arm capacity, deflection | BI4: SWL per arm | BJ4: SWL (arm) | BK4: Governing (arm) | BL4: Moment capacity | BM4: Applied moment | BN4: Applied shear | BO4: Deflection | BP4: Deflection limit | BQ4: Bending utilisation | BR4: Shear utilisation | BS4: Deflection utilisation | BT4: Governing utilisation | BU4: SAFE WORKING LOAD | BV4: Governing check | BW4: VERDICT | BX4: Load margin
D5: mm | E5: mm² | F5: mm | G5: mm⁴ | H5: mm² | I5: mm | J5: mm⁴ | K5: mm² | L5: mm | M5: mm⁴ | N5: mm² | O5: mm | P5: mm⁴ | Q5: mm³ | R5: mm³ | S5: mm² | T5: kg/m | U5: kg/m | AE5: MPa | AF5: N | AG5: N·mm² | AH5: N | AI5: mm | AJ5: kg/m | AK5: N·mm | AL5: mm | AM5: N/mm | AN5: N/mm | AO5: N·mm | AP5: N | AQ5: mm | AR5: kg/m | AS5: kg/m | AT5: kg/m | AU5: kg/m | AX5: N·mm | AY5: mm | AZ5: N | BA5: N | BB5: N | BC5: N·mm | BD5: N | BE5: mm | BF5: kg | BG5: kg | BH5: kg | BI5: kg | BJ5: kg/m | BL5: N·mm | BM5: N·mm | BN5: N | BO5: mm | BP5: mm | BU5: kg/m | BX5: %
A6: =IF(Inputs!A6="","",Inputs!A6) -> Ladder 600 x 100 x 2.0, simple span | B6: =IF(Inputs!$B6="","",Inputs!$B6) -> ladder | C6: =IF(Inputs!$B6="","",IF(OR(Inputs!$B6="perf",Inputs!$B6="trough"),MIN(0.5,IF(Inputs!$B6="perf",p_perfN*p_perfL*p_perfW/(p_perfSp*Inputs!$C6),p_trN*p_trL*p_trW/(p_trSp*Inputs!$C6))),0)) -> 0 | D6: =IF(Inputs!$B6="","",IF(Inputs!$B6="ladder",p_collar,IF(Inputs!$B6="perf",IF(AND(Inputs!$C6>=300,Inputs!$D6>=100),15,0),IF(Inputs!$B6="trough",0,p_lip)))) -> 25 | E6: =IF(Inputs!$B6="","",IF(Inputs!$B6="ladder",2*Inputs!$E6*Inputs!$D6,IF(OR(Inputs!$B6="perf",Inputs!$B6="trough"),(Inputs!$C6+4)*Inputs!$E6*(1-C6),Inputs!$C6*Inputs!$E6))) -> 400 | F6: =IF(Inputs!$B6="","",IF(Inputs!$B6="ladder",Inputs!$D6/2,Inputs!$E6/2)) -> 50 | G6: =IF(Inputs!$B6="","",IF(Inputs!$B6="ladder",2*Inputs!$E6*Inputs!$D6^3/12,IF(OR(Inputs!$B6="perf",Inputs!$B6="trough"),0,Inputs!$C6*Inputs!$E6^3/12))) -> 333333.33 | H6: =IF(Inputs!$B6="","",IF(Inputs!$B6="ladder",2*D6*Inputs!$E6,2*Inputs!$E6*Inputs!$D6)) -> 100 | I6: =IF(Inputs!$B6="","",IF(Inputs!$B6="ladder",Inputs!$E6/2,Inputs!$D6/2)) -> 1 | J6: =IF(Inputs!$B6="","",IF(Inputs!$B6="ladder",2*D6*Inputs!$E6^3/12,2*Inputs!$E6*Inputs!$D6^3/12)) -> 33.333333 | K6: =IF(Inputs!$B6="","",2*D6*Inputs!$E6) -> 100 | L6: =IF(Inputs!$B6="","",Inputs!$D6-Inputs!$E6/2) -> 99 | M6: =IF(Inputs!$B6="","",2*D6*Inputs!$E6^3/12) -> 33.333333 | N6: =IF(Inputs!$B6="","",E6+H6+K6) -> 600 | O6: =IF(Inputs!$B6="","",(E6*F6+H6*I6+K6*L6)/N6) -> 50 | P6: =IF(Inputs!$B6="","",(G6+E6*(F6-O6)^2)+(J6+H6*(I6-O6)^2)+(M6+K6*(L6-O6)^2)) -> 813600 | Q6: =IF(Inputs!$B6="","",P6/O6) -> 16272 | R6: =IF(Inputs!$B6="","",P6/(Inputs!$D6-O6)) -> 16272 | S6: =IF(Inputs!$B6="","",2*Inputs!$D6*Inputs!$E6) -> 400 | T6: =IF(Inputs!$B6="","",N6*0.00785+IF(Inputs!$B6="ladder",p_rungN/2.5*(p_rungW*p_rungT+2*p_rungT*p_rungH)*Inputs!$C6*0.00000785,0)) -> 8.1012 | U6: =IF(Inputs!$B6="","",IF(Inputs!$G6="",T6,Inputs!$G6)) -> 8.56 | V6: =IF(Inputs!$B6="","",Inputs!$D6/Inputs!$E6) -> 50 | W6: =IF(Inputs!$B6="","",IF(D6>0,D6/Inputs!$E6,0)) -> 12.5 | X6: =IF(Inputs!$B6="","",IF(OR(Inputs!$B6="perf",Inputs!$B6="trough"),(Inputs!$C6+4)/Inputs!$E6,IF(OR(Inputs!$B6="channel",Inputs!$B6="arm"),Inputs!$C6/Inputs!$E6,0))) -> 0 | Y6: =IF(Inputs!$B6="","",IF(V6>p_webS,"web; ","")&IF(W6>p_flS,"flange; ","")&IF(X6>p_plS,"base plate; ","")) | Z6: =IF(Inputs!$B6="","",IFERROR(INDEX(sup_kw,MATCH(Inputs!$J6,sup_names,0)),INDEX(sup_kw,1))) -> 0.125 | AA6: =IF(Inputs!$B6="","",IFERROR(INDEX(sup_kp,MATCH(Inputs!$J6,sup_names,0)),INDEX(sup_kp,1))) -> 0.25 | AB6: =IF(Inputs!$B6="","",IFERROR(INDEX(sup_dw,MATCH(Inputs!$J6,sup_names,0)),INDEX(sup_dw,1))) -> 0.013020833 | AC6: =IF(Inputs!$B6="","",IFERROR(INDEX(sup_dp,MATCH(Inputs!$J6,sup_names,0)),INDEX(sup_dp,1))) -> 0.020833333 | AD6: =IF(Inputs!$B6="","",IFERROR(INDEX(sup_kv,MATCH(Inputs!$J6,sup_names,0)),INDEX(sup_kv,1))) -> 0.5 | AE6: =IF(Inputs!$B6="","",p_fy/p_fs) -> 149.7006 | AF6: =IF(Inputs!$B6="","",Inputs!$K6*p_g) -> 882.9 | AG6: =IF(Inputs!$B6="","",p_E*P6) -> 162720000000 | AH6: =IF(Inputs!$B6="","",p_shear*p_fy*S6) -> 40000 | AI6: =IF(Inputs!$B6="","",IF(Inputs!$B6="channel",Inputs!$M6,Inputs!$I6*1000)) -> 2500 | AJ6: =IF(Inputs!$B6="","",IF(Inputs!$B6="channel",(Inputs!$H6+Inputs!$N6)*Inputs!$I6/(AI6/1000),Inputs!$H6)) -> 40 | AK6: =IF(Inputs!$B6="","",AE6*MIN(Q6,R6)*p_splice) -> 1339760.5 | AL6: =IF(Inputs!$B6="","",AI6/Inputs!$L6) -> 12.5 | AM6: =IF(Inputs!$B6="","",U6*p_g/1000) -> 0.0839736 | AN6: =IF(Inputs!$B6="","",AJ6*p_g/1000) -> 0.3924 | AO6: =IF(Inputs!$B6="","",Z6*(AM6+AN6)*AI6^2+AA6*AF6*AI6) -> 923979.38 | AP6: =IF(Inputs!$B6="","",AD6*((AM6+AN6)*AI6+AF6)) -> 1036.917 | AQ6: =IF(Inputs!$B6="","",AB6*(AM6+AN6)*AI6^4/AG6+AC6*AF6*AI6^3/AG6) -> 3.2552759 | AR6: =IF(Inputs!$B6="","",MAX(0,(AK6-AA6*AF6*AI6)/(Z6*AI6^2)-AM6)*1000/p_g) -> 94.250745 | AS6: =IF(Inputs!$B6="","",MAX(0,(AH6-AD6*AF6)/(AD6*AI6)-AM6)*1000/p_g) -> 3217.4176 | AT6: =IF(Inputs!$B6="","",MAX(0,(AL6-AC6*AF6*AI6^3/AG6)/(AB6*AI6^4/AG6)-AM6)*1000/p_g) -> 341.48594 | AU6: =IF(Inputs!$B6="","",MIN(AR6,AS6,AT6)) -> 94.250745 | AV6: =IF(Inputs!$B6="","",IF(AU6=AR6,"bending",IF(AU6=AT6,"deflection","shear"))) -> bending | AW6: =IF(Inputs!$B6="","",IF(Inputs!$B6="ladder",((Inputs!$H6*2500/p_rungN/1000*p_g)*Inputs!$C6/8+(AF6/3)*Inputs!$C6/4)/(p_fy/p_fs*p_rungZ),"")) -> 0.819135 | AX6: =IF(Inputs!$B6="","",IF(Inputs!$B6="arm",AE6*MIN(Q6,R6),"")) | AY6: =IF(Inputs!$B6="","",IF(Inputs!$B6="arm",Inputs!$F6/p_cant,"")) | AZ6: =IF(Inputs!$B6="","",IF(Inputs!$B6="arm",Inputs!$H6*Inputs!$I6*p_g,"")) | BA6: =IF(Inputs!$B6="","",IF(Inputs!$B6="arm",AZ6+Inputs!$N6*Inputs!$I6*p_g,"")) | BB6: =IF(Inputs!$B6="","",IF(Inputs!$B6="arm",AF6/3,"")) | BC6: =IF(Inputs!$B6="","",IF(Inputs!$B6="arm",BA6*Inputs!$F6/2+BB6*Inputs!$F6,"")) | BD6: =IF(Inputs!$B6="","",IF(Inputs!$B6="arm",BA6+BB6,"")) | BE6: =IF(Inputs!$B6="","",IF(Inputs!$B6="arm",BA6*Inputs!$F6^3/(8*AG6)+BB6*Inputs!$F6^3/(3*AG6),"")) | BF6: =IF(Inputs!$B6="","",IF(Inputs!$B6="arm",(AX6-BB6*Inputs!$F6)/(Inputs!$F6/2)/p_g-Inputs!$N6*Inputs!$I6,"")) | BG6: =IF(Inputs!$B6="","",IF(Inputs!$B6="arm",(AH6-BB6)/p_g-Inputs!$N6*Inputs!$I6,"")) | BH6: =IF(Inputs!$B6="","",IF(Inputs!$B6="arm",(AY6-BB6*Inputs!$F6^3/(3*AG6))/(Inputs!$F6^3/(8*AG6))/p_g-Inputs!$N6*Inputs!$I6,"")) | BI6: =IF(Inputs!$B6="","",IF(Inputs!$B6="arm",MAX(0,MIN(BF6,BG6,BH6)),"")) | BJ6: =IF(Inputs!$B6="","",IF(Inputs!$B6="arm",BI6/Inputs!$I6,"")) | BK6: =IF(Inputs!$B6="","",IF(Inputs!$B6="arm",IF(BI6=MAX(0,BF6),"bending",IF(BI6=MAX(0,BH6),"deflection","shear")),"")) | BL6: =IF(Inputs!$B6="","",IF(Inputs!$B6="arm",AX6,AK6)) -> 1339760.5 | BM6: =IF(Inputs!$B6="","",IF(Inputs!$B6="arm",BC6,AO6)) -> 923979.38 | BN6: =IF(Inputs!$B6="","",IF(Inputs!$B6="arm",BD6,AP6)) -> 1036.917 | BO6: =IF(Inputs!$B6="","",IF(Inputs!$B6="arm",BE6,AQ6)) -> 3.2552759 | BP6: =IF(Inputs!$B6="","",IF(Inputs!$B6="arm",AY6,AL6)) -> 12.5 | BQ6: =IF(Inputs!$B6="","",BM6/BL6) -> 0.68966012 | BR6: =IF(Inputs!$B6="","",BN6/AH6) -> 0.025922925 | BS6: =IF(Inputs!$B6="","",BO6/BP6) -> 0.26042207 | BT6: =IF(Inputs!$B6="","",MAX(BQ6,BR6,BS6,IF(Inputs!$B6="ladder",AW6,0))) -> 0.819135 | BU6: =IF(Inputs!$B6="","",IF(Inputs!$B6="arm",BJ6,AU6)) -> 94.250745 | BV6: =IF(Inputs!$B6="","",IF(Inputs!$B6="arm",BK6,AV6)) -> bending | BW6: =IF(Inputs!$B6="","",IF(BT6<=1,"PASS","FAIL")) -> PASS | BX6: =IF(Inputs!$B6="","",IF(Inputs!$H6>0,BU6/Inputs!$H6-1,"")) -> 1.3562686
A7: =IF(Inputs!A7="","",Inputs!A7) -> Ladder 300 x 75 x 2.0, continuous | B7: =IF(Inputs!$B7="","",Inputs!$B7) -> ladder | C7: =IF(Inputs!$B7="","",IF(OR(Inputs!$B7="perf",Inputs!$B7="trough"),MIN(0.5,IF(Inputs!$B7="perf",p_perfN*p_perfL*p_perfW/(p_perfSp*Inputs!$C7),p_trN*p_trL*p_trW/(p_trSp*Inputs!$C7))),0)) -> 0 | D7: =IF(Inputs!$B7="","",IF(Inputs!$B7="ladder",p_collar,IF(Inputs!$B7="perf",IF(AND(Inputs!$C7>=300,Inputs!$D7>=100),15,0),IF(Inputs!$B7="trough",0,p_lip)))) -> 25 | E7: =IF(Inputs!$B7="","",IF(Inputs!$B7="ladder",2*Inputs!$E7*Inputs!$D7,IF(OR(Inputs!$B7="perf",Inputs!$B7="trough"),(Inputs!$C7+4)*Inputs!$E7*(1-C7),Inputs!$C7*Inputs!$E7))) -> 300 | F7: =IF(Inputs!$B7="","",IF(Inputs!$B7="ladder",Inputs!$D7/2,Inputs!$E7/2)) -> 37.5 | G7: =IF(Inputs!$B7="","",IF(Inputs!$B7="ladder",2*Inputs!$E7*Inputs!$D7^3/12,IF(OR(Inputs!$B7="perf",Inputs!$B7="trough"),0,Inputs!$C7*Inputs!$E7^3/12))) -> 140625 | H7: =IF(Inputs!$B7="","",IF(Inputs!$B7="ladder",2*D7*Inputs!$E7,2*Inputs!$E7*Inputs!$D7)) -> 100 | I7: =IF(Inputs!$B7="","",IF(Inputs!$B7="ladder",Inputs!$E7/2,Inputs!$D7/2)) -> 1 | J7: =IF(Inputs!$B7="","",IF(Inputs!$B7="ladder",2*D7*Inputs!$E7^3/12,2*Inputs!$E7*Inputs!$D7^3/12)) -> 33.333333 | K7: =IF(Inputs!$B7="","",2*D7*Inputs!$E7) -> 100 | L7: =IF(Inputs!$B7="","",Inputs!$D7-Inputs!$E7/2) -> 74 | M7: =IF(Inputs!$B7="","",2*D7*Inputs!$E7^3/12) -> 33.333333 | N7: =IF(Inputs!$B7="","",E7+H7+K7) -> 500 | O7: =IF(Inputs!$B7="","",(E7*F7+H7*I7+K7*L7)/N7) -> 37.5 | P7: =IF(Inputs!$B7="","",(G7+E7*(F7-O7)^2)+(J7+H7*(I7-O7)^2)+(M7+K7*(L7-O7)^2)) -> 407141.67 | Q7: =IF(Inputs!$B7="","",P7/O7) -> 10857.111 | R7: =IF(Inputs!$B7="","",P7/(Inputs!$D7-O7)) -> 10857.111 | S7: =IF(Inputs!$B7="","",2*Inputs!$D7*Inputs!$E7) -> 300 | T7: =IF(Inputs!$B7="","",N7*0.00785+IF(Inputs!$B7="ladder",p_rungN/2.5*(p_rungW*p_rungT+2*p_rungT*p_rungH)*Inputs!$C7*0.00000785,0)) -> 5.6206 | U7: =IF(Inputs!$B7="","",IF(Inputs!$G7="",T7,Inputs!$G7)) -> 6.079 | V7: =IF(Inputs!$B7="","",Inputs!$D7/Inputs!$E7) -> 37.5 | W7: =IF(Inputs!$B7="","",IF(D7>0,D7/Inputs!$E7,0)) -> 12.5 | X7: =IF(Inputs!$B7="","",IF(OR(Inputs!$B7="perf",Inputs!$B7="trough"),(Inputs!$C7+4)/Inputs!$E7,IF(OR(Inputs!$B7="channel",Inputs!$B7="arm"),Inputs!$C7/Inputs!$E7,0))) -> 0 | Y7: =IF(Inputs!$B7="","",IF(V7>p_webS,"web; ","")&IF(W7>p_flS,"flange; ","")&IF(X7>p_plS,"base plate; ","")) | Z7: =IF(Inputs!$B7="","",IFERROR(INDEX(sup_kw,MATCH(Inputs!$J7,sup_names,0)),INDEX(sup_kw,1))) -> 0.1 | AA7: =IF(Inputs!$B7="","",IFERROR(INDEX(sup_kp,MATCH(Inputs!$J7,sup_names,0)),INDEX(sup_kp,1))) -> 0.2 | AB7: =IF(Inputs!$B7="","",IFERROR(INDEX(sup_dw,MATCH(Inputs!$J7,sup_names,0)),INDEX(sup_dw,1))) -> 0.0068965517 | AC7: =IF(Inputs!$B7="","",IFERROR(INDEX(sup_dp,MATCH(Inputs!$J7,sup_names,0)),INDEX(sup_dp,1))) -> 0.0094339623 | AD7: =IF(Inputs!$B7="","",IFERROR(INDEX(sup_kv,MATCH(Inputs!$J7,sup_names,0)),INDEX(sup_kv,1))) -> 0.6 | AE7: =IF(Inputs!$B7="","",p_fy/p_fs) -> 149.7006 | AF7: =IF(Inputs!$B7="","",Inputs!$K7*p_g) -> 882.9 | AG7: =IF(Inputs!$B7="","",p_E*P7) -> 8.1428333e+10 | AH7: =IF(Inputs!$B7="","",p_shear*p_fy*S7) -> 30000 | AI7: =IF(Inputs!$B7="","",IF(Inputs!$B7="channel",Inputs!$M7,Inputs!$I7*1000)) -> 3000 | AJ7: =IF(Inputs!$B7="","",IF(Inputs!$B7="channel",(Inputs!$H7+Inputs!$N7)*Inputs!$I7/(AI7/1000),Inputs!$H7)) -> 30 | AK7: =IF(Inputs!$B7="","",AE7*MIN(Q7,R7)*p_splice) -> 893923.82 | AL7: =IF(Inputs!$B7="","",AI7/Inputs!$L7) -> 15 | AM7: =IF(Inputs!$B7="","",U7*p_g/1000) -> 0.05963499 | AN7: =IF(Inputs!$B7="","",AJ7*p_g/1000) -> 0.2943 | AO7: =IF(Inputs!$B7="","",Z7*(AM7+AN7)*AI7^2+AA7*AF7*AI7) -> 848281.49 | AP7: =IF(Inputs!$B7="","",AD7*((AM7+AN7)*AI7+AF7)) -> 1166.823 | AQ7: =IF(Inputs!$B7="","",AB7*(AM7+AN7)*AI7^4/AG7+AC7*AF7*AI7^3/AG7) -> 5.1899015 | AR7: =IF(Inputs!$B7="","",MAX(0,(AK7-AA7*AF7*AI7)/(Z7*AI7^2)-AM7)*1000/p_g) -> 35.169592 | AS7: =IF(Inputs!$B7="","",MAX(0,(AH7-AD7*AF7)/(AD7*AI7)-AM7)*1000/p_g) -> 1662.8677 | AT7: =IF(Inputs!$B7="","",MAX(0,(AL7-AC7*AF7*AI7^3/AG7)/(AB7*AI7^4/AG7)-AM7)*1000/p_g) -> 175.76823 | AU7: =IF(Inputs!$B7="","",MIN(AR7,AS7,AT7)) -> 35.169592 | AV7: =IF(Inputs!$B7="","",IF(AU7=AR7,"bending",IF(AU7=AT7,"deflection","shear"))) -> bending | AW7: =IF(Inputs!$B7="","",IF(Inputs!$B7="ladder",((Inputs!$H7*2500/p_rungN/1000*p_g)*Inputs!$C7/8+(AF7/3)*Inputs!$C7/4)/(p_fy/p_fs*p_rungZ),"")) -> 0.39494009 | AX7: =IF(Inputs!$B7="","",IF(Inputs!$B7="arm",AE7*MIN(Q7,R7),"")) | AY7: =IF(Inputs!$B7="","",IF(Inputs!$B7="arm",Inputs!$F7/p_cant,"")) | AZ7: =IF(Inputs!$B7="","",IF(Inputs!$B7="arm",Inputs!$H7*Inputs!$I7*p_g,"")) | BA7: =IF(Inputs!$B7="","",IF(Inputs!$B7="arm",AZ7+Inputs!$N7*Inputs!$I7*p_g,"")) | BB7: =IF(Inputs!$B7="","",IF(Inputs!$B7="arm",AF7/3,"")) | BC7: =IF(Inputs!$B7="","",IF(Inputs!$B7="arm",BA7*Inputs!$F7/2+BB7*Inputs!$F7,"")) | BD7: =IF(Inputs!$B7="","",IF(Inputs!$B7="arm",BA7+BB7,"")) | BE7: =IF(Inputs!$B7="","",IF(Inputs!$B7="arm",BA7*Inputs!$F7^3/(8*AG7)+BB7*Inputs!$F7^3/(3*AG7),"")) | BF7: =IF(Inputs!$B7="","",IF(Inputs!$B7="arm",(AX7-BB7*Inputs!$F7)/(Inputs!$F7/2)/p_g-Inputs!$N7*Inputs!$I7,"")) | BG7: =IF(Inputs!$B7="","",IF(Inputs!$B7="arm",(AH7-BB7)/p_g-Inputs!$N7*Inputs!$I7,"")) | BH7: =IF(Inputs!$B7="","",IF(Inputs!$B7="arm",(AY7-BB7*Inputs!$F7^3/(3*AG7))/(Inputs!$F7^3/(8*AG7))/p_g-Inputs!$N7*Inputs!$I7,"")) | BI7: =IF(Inputs!$B7="","",IF(Inputs!$B7="arm",MAX(0,MIN(BF7,BG7,BH7)),"")) | BJ7: =IF(Inputs!$B7="","",IF(Inputs!$B7="arm",BI7/Inputs!$I7,"")) | BK7: =IF(Inputs!$B7="","",IF(Inputs!$B7="arm",IF(BI7=MAX(0,BF7),"bending",IF(BI7=MAX(0,BH7),"deflection","shear")),"")) | BL7: =IF(Inputs!$B7="","",IF(Inputs!$B7="arm",AX7,AK7)) -> 893923.82 | BM7: =IF(Inputs!$B7="","",IF(Inputs!$B7="arm",BC7,AO7)) -> 848281.49 | BN7: =IF(Inputs!$B7="","",IF(Inputs!$B7="arm",BD7,AP7)) -> 1166.823 | BO7: =IF(Inputs!$B7="","",IF(Inputs!$B7="arm",BE7,AQ7)) -> 5.1899015 | BP7: =IF(Inputs!$B7="","",IF(Inputs!$B7="arm",AY7,AL7)) -> 15 | BQ7: =IF(Inputs!$B7="","",BM7/BL7) -> 0.94894159 | BR7: =IF(Inputs!$B7="","",BN7/AH7) -> 0.038894099 | BS7: =IF(Inputs!$B7="","",BO7/BP7) -> 0.34599343 | BT7: =IF(Inputs!$B7="","",MAX(BQ7,BR7,BS7,IF(Inputs!$B7="ladder",AW7,0))) -> 0.94894159 | BU7: =IF(Inputs!$B7="","",IF(Inputs!$B7="arm",BJ7,AU7)) -> 35.169592 | BV7: =IF(Inputs!$B7="","",IF(Inputs!$B7="arm",BK7,AV7)) -> bending | BW7: =IF(Inputs!$B7="","",IF(BT7<=1,"PASS","FAIL")) -> PASS | BX7: =IF(Inputs!$B7="","",IF(Inputs!$H7>0,BU7/Inputs!$H7-1,"")) -> 0.17231973
A8: =IF(Inputs!A8="","",Inputs!A8) -> Ladder 600 x 100 x 2.0, overloaded | B8: =IF(Inputs!$B8="","",Inputs!$B8) -> ladder | C8: =IF(Inputs!$B8="","",IF(OR(Inputs!$B8="perf",Inputs!$B8="trough"),MIN(0.5,IF(Inputs!$B8="perf",p_perfN*p_perfL*p_perfW/(p_perfSp*Inputs!$C8),p_trN*p_trL*p_trW/(p_trSp*Inputs!$C8))),0)) -> 0 | D8: =IF(Inputs!$B8="","",IF(Inputs!$B8="ladder",p_collar,IF(Inputs!$B8="perf",IF(AND(Inputs!$C8>=300,Inputs!$D8>=100),15,0),IF(Inputs!$B8="trough",0,p_lip)))) -> 25 | E8: =IF(Inputs!$B8="","",IF(Inputs!$B8="ladder",2*Inputs!$E8*Inputs!$D8,IF(OR(Inputs!$B8="perf",Inputs!$B8="trough"),(Inputs!$C8+4)*Inputs!$E8*(1-C8),Inputs!$C8*Inputs!$E8))) -> 400 | F8: =IF(Inputs!$B8="","",IF(Inputs!$B8="ladder",Inputs!$D8/2,Inputs!$E8/2)) -> 50 | G8: =IF(Inputs!$B8="","",IF(Inputs!$B8="ladder",2*Inputs!$E8*Inputs!$D8^3/12,IF(OR(Inputs!$B8="perf",Inputs!$B8="trough"),0,Inputs!$C8*Inputs!$E8^3/12))) -> 333333.33 | H8: =IF(Inputs!$B8="","",IF(Inputs!$B8="ladder",2*D8*Inputs!$E8,2*Inputs!$E8*Inputs!$D8)) -> 100 | I8: =IF(Inputs!$B8="","",IF(Inputs!$B8="ladder",Inputs!$E8/2,Inputs!$D8/2)) -> 1 | J8: =IF(Inputs!$B8="","",IF(Inputs!$B8="ladder",2*D8*Inputs!$E8^3/12,2*Inputs!$E8*Inputs!$D8^3/12)) -> 33.333333 | K8: =IF(Inputs!$B8="","",2*D8*Inputs!$E8) -> 100 | L8: =IF(Inputs!$B8="","",Inputs!$D8-Inputs!$E8/2) -> 99 | M8: =IF(Inputs!$B8="","",2*D8*Inputs!$E8^3/12) -> 33.333333 | N8: =IF(Inputs!$B8="","",E8+H8+K8) -> 600 | O8: =IF(Inputs!$B8="","",(E8*F8+H8*I8+K8*L8)/N8) -> 50 | P8: =IF(Inputs!$B8="","",(G8+E8*(F8-O8)^2)+(J8+H8*(I8-O8)^2)+(M8+K8*(L8-O8)^2)) -> 813600 | Q8: =IF(Inputs!$B8="","",P8/O8) -> 16272 | R8: =IF(Inputs!$B8="","",P8/(Inputs!$D8-O8)) -> 16272 | S8: =IF(Inputs!$B8="","",2*Inputs!$D8*Inputs!$E8) -> 400 | T8: =IF(Inputs!$B8="","",N8*0.00785+IF(Inputs!$B8="ladder",p_rungN/2.5*(p_rungW*p_rungT+2*p_rungT*p_rungH)*Inputs!$C8*0.00000785,0)) -> 8.1012 | U8: =IF(Inputs!$B8="","",IF(Inputs!$G8="",T8,Inputs!$G8)) -> 8.56 | V8: =IF(Inputs!$B8="","",Inputs!$D8/Inputs!$E8) -> 50 | W8: =IF(Inputs!$B8="","",IF(D8>0,D8/Inputs!$E8,0)) -> 12.5 | X8: =IF(Inputs!$B8="","",IF(OR(Inputs!$B8="perf",Inputs!$B8="trough"),(Inputs!$C8+4)/Inputs!$E8,IF(OR(Inputs!$B8="channel",Inputs!$B8="arm"),Inputs!$C8/Inputs!$E8,0))) -> 0 | Y8: =IF(Inputs!$B8="","",IF(V8>p_webS,"web; ","")&IF(W8>p_flS,"flange; ","")&IF(X8>p_plS,"base plate; ","")) | Z8: =IF(Inputs!$B8="","",IFERROR(INDEX(sup_kw,MATCH(Inputs!$J8,sup_names,0)),INDEX(sup_kw,1))) -> 0.125 | AA8: =IF(Inputs!$B8="","",IFERROR(INDEX(sup_kp,MATCH(Inputs!$J8,sup_names,0)),INDEX(sup_kp,1))) -> 0.25 | AB8: =IF(Inputs!$B8="","",IFERROR(INDEX(sup_dw,MATCH(Inputs!$J8,sup_names,0)),INDEX(sup_dw,1))) -> 0.013020833 | AC8: =IF(Inputs!$B8="","",IFERROR(INDEX(sup_dp,MATCH(Inputs!$J8,sup_names,0)),INDEX(sup_dp,1))) -> 0.020833333 | AD8: =IF(Inputs!$B8="","",IFERROR(INDEX(sup_kv,MATCH(Inputs!$J8,sup_names,0)),INDEX(sup_kv,1))) -> 0.5 | AE8: =IF(Inputs!$B8="","",p_fy/p_fs) -> 149.7006 | AF8: =IF(Inputs!$B8="","",Inputs!$K8*p_g) -> 882.9 | AG8: =IF(Inputs!$B8="","",p_E*P8) -> 162720000000 | AH8: =IF(Inputs!$B8="","",p_shear*p_fy*S8) -> 40000 | AI8: =IF(Inputs!$B8="","",IF(Inputs!$B8="channel",Inputs!$M8,Inputs!$I8*1000)) -> 2500 | AJ8: =IF(Inputs!$B8="","",IF(Inputs!$B8="channel",(Inputs!$H8+Inputs!$N8)*Inputs!$I8/(AI8/1000),Inputs!$H8)) -> 400 | AK8: =IF(Inputs!$B8="","",AE8*MIN(Q8,R8)*p_splice) -> 1339760.5 | AL8: =IF(Inputs!$B8="","",AI8/Inputs!$L8) -> 12.5 | AM8: =IF(Inputs!$B8="","",U8*p_g/1000) -> 0.0839736 | AN8: =IF(Inputs!$B8="","",AJ8*p_g/1000) -> 3.924 | AO8: =IF(Inputs!$B8="","",Z8*(AM8+AN8)*AI8^2+AA8*AF8*AI8) -> 3683041.9 | AP8: =IF(Inputs!$B8="","",AD8*((AM8+AN8)*AI8+AF8)) -> 5451.417 | AQ8: =IF(Inputs!$B8="","",AB8*(AM8+AN8)*AI8^4/AG8+AC8*AF8*AI8^3/AG8) -> 14.294267 | AR8: =IF(Inputs!$B8="","",MAX(0,(AK8-AA8*AF8*AI8)/(Z8*AI8^2)-AM8)*1000/p_g) -> 94.250745 | AS8: =IF(Inputs!$B8="","",MAX(0,(AH8-AD8*AF8)/(AD8*AI8)-AM8)*1000/p_g) -> 3217.4176 | AT8: =IF(Inputs!$B8="","",MAX(0,(AL8-AC8*AF8*AI8^3/AG8)/(AB8*AI8^4/AG8)-AM8)*1000/p_g) -> 341.48594 | AU8: =IF(Inputs!$B8="","",MIN(AR8,AS8,AT8)) -> 94.250745 | AV8: =IF(Inputs!$B8="","",IF(AU8=AR8,"bending",IF(AU8=AT8,"deflection","shear"))) -> bending | AW8: =IF(Inputs!$B8="","",IF(Inputs!$B8="ladder",((Inputs!$H8*2500/p_rungN/1000*p_g)*Inputs!$C8/8+(AF8/3)*Inputs!$C8/4)/(p_fy/p_fs*p_rungZ),"")) -> 1.8723086 | AX8: =IF(Inputs!$B8="","",IF(Inputs!$B8="arm",AE8*MIN(Q8,R8),"")) | AY8: =IF(Inputs!$B8="","",IF(Inputs!$B8="arm",Inputs!$F8/p_cant,"")) | AZ8: =IF(Inputs!$B8="","",IF(Inputs!$B8="arm",Inputs!$H8*Inputs!$I8*p_g,"")) | BA8: =IF(Inputs!$B8="","",IF(Inputs!$B8="arm",AZ8+Inputs!$N8*Inputs!$I8*p_g,"")) | BB8: =IF(Inputs!$B8="","",IF(Inputs!$B8="arm",AF8/3,"")) | BC8: =IF(Inputs!$B8="","",IF(Inputs!$B8="arm",BA8*Inputs!$F8/2+BB8*Inputs!$F8,"")) | BD8: =IF(Inputs!$B8="","",IF(Inputs!$B8="arm",BA8+BB8,"")) | BE8: =IF(Inputs!$B8="","",IF(Inputs!$B8="arm",BA8*Inputs!$F8^3/(8*AG8)+BB8*Inputs!$F8^3/(3*AG8),"")) | BF8: =IF(Inputs!$B8="","",IF(Inputs!$B8="arm",(AX8-BB8*Inputs!$F8)/(Inputs!$F8/2)/p_g-Inputs!$N8*Inputs!$I8,"")) | BG8: =IF(Inputs!$B8="","",IF(Inputs!$B8="arm",(AH8-BB8)/p_g-Inputs!$N8*Inputs!$I8,"")) | BH8: =IF(Inputs!$B8="","",IF(Inputs!$B8="arm",(AY8-BB8*Inputs!$F8^3/(3*AG8))/(Inputs!$F8^3/(8*AG8))/p_g-Inputs!$N8*Inputs!$I8,"")) | BI8: =IF(Inputs!$B8="","",IF(Inputs!$B8="arm",MAX(0,MIN(BF8,BG8,BH8)),"")) | BJ8: =IF(Inputs!$B8="","",IF(Inputs!$B8="arm",BI8/Inputs!$I8,"")) | BK8: =IF(Inputs!$B8="","",IF(Inputs!$B8="arm",IF(BI8=MAX(0,BF8),"bending",IF(BI8=MAX(0,BH8),"deflection","shear")),"")) | BL8: =IF(Inputs!$B8="","",IF(Inputs!$B8="arm",AX8,AK8)) -> 1339760.5 | BM8: =IF(Inputs!$B8="","",IF(Inputs!$B8="arm",BC8,AO8)) -> 3683041.9 | BN8: =IF(Inputs!$B8="","",IF(Inputs!$B8="arm",BD8,AP8)) -> 5451.417 | BO8: =IF(Inputs!$B8="","",IF(Inputs!$B8="arm",BE8,AQ8)) -> 14.294267 | BP8: =IF(Inputs!$B8="","",IF(Inputs!$B8="arm",AY8,AL8)) -> 12.5 | BQ8: =IF(Inputs!$B8="","",BM8/BL8) -> 2.7490301 | BR8: =IF(Inputs!$B8="","",BN8/AH8) -> 0.13628542 | BS8: =IF(Inputs!$B8="","",BO8/BP8) -> 1.1435414 | BT8: =IF(Inputs!$B8="","",MAX(BQ8,BR8,BS8,IF(Inputs!$B8="ladder",AW8,0))) -> 2.7490301 | BU8: =IF(Inputs!$B8="","",IF(Inputs!$B8="arm",BJ8,AU8)) -> 94.250745 | BV8: =IF(Inputs!$B8="","",IF(Inputs!$B8="arm",BK8,AV8)) -> bending | BW8: =IF(Inputs!$B8="","",IF(BT8<=1,"PASS","FAIL")) -> FAIL | BX8: =IF(Inputs!$B8="","",IF(Inputs!$H8>0,BU8/Inputs!$H8-1,"")) -> -0.76437314
A9: =IF(Inputs!A9="","",Inputs!A9) -> Perforated 300 x 100 x 2.0 | B9: =IF(Inputs!$B9="","",Inputs!$B9) -> perf | C9: =IF(Inputs!$B9="","",IF(OR(Inputs!$B9="perf",Inputs!$B9="trough"),MIN(0.5,IF(Inputs!$B9="perf",p_perfN*p_perfL*p_perfW/(p_perfSp*Inputs!$C9),p_trN*p_trL*p_trW/(p_trSp*Inputs!$C9))),0)) -> 0.066666667 | D9: =IF(Inputs!$B9="","",IF(Inputs!$B9="ladder",p_collar,IF(Inputs!$B9="perf",IF(AND(Inputs!$C9>=300,Inputs!$D9>=100),15,0),IF(Inputs!$B9="trough",0,p_lip)))) -> 15 | E9: =IF(Inputs!$B9="","",IF(Inputs!$B9="ladder",2*Inputs!$E9*Inputs!$D9,IF(OR(Inputs!$B9="perf",Inputs!$B9="trough"),(Inputs!$C9+4)*Inputs!$E9*(1-C9),Inputs!$C9*Inputs!$E9))) -> 567.46667 | F9: =IF(Inputs!$B9="","",IF(Inputs!$B9="ladder",Inputs!$D9/2,Inputs!$E9/2)) -> 1 | G9: =IF(Inputs!$B9="","",IF(Inputs!$B9="ladder",2*Inputs!$E9*Inputs!$D9^3/12,IF(OR(Inputs!$B9="perf",Inputs!$B9="trough"),0,Inputs!$C9*Inputs!$E9^3/12))) -> 0 | H9: =IF(Inputs!$B9="","",IF(Inputs!$B9="ladder",2*D9*Inputs!$E9,2*Inputs!$E9*Inputs!$D9)) -> 400 | I9: =IF(Inputs!$B9="","",IF(Inputs!$B9="ladder",Inputs!$E9/2,Inputs!$D9/2)) -> 50 | J9: =IF(Inputs!$B9="","",IF(Inputs!$B9="ladder",2*D9*Inputs!$E9^3/12,2*Inputs!$E9*Inputs!$D9^3/12)) -> 333333.33 | K9: =IF(Inputs!$B9="","",2*D9*Inputs!$E9) -> 60 | L9: =IF(Inputs!$B9="","",Inputs!$D9-Inputs!$E9/2) -> 99 | M9: =IF(Inputs!$B9="","",2*D9*Inputs!$E9^3/12) -> 20 | N9: =IF(Inputs!$B9="","",E9+H9+K9) -> 1027.4667 | O9: =IF(Inputs!$B9="","",(E9*F9+H9*I9+K9*L9)/N9) -> 25.798858 | P9: =IF(Inputs!$B9="","",(G9+E9*(F9-O9)^2)+(J9+H9*(I9-O9)^2)+(M9+K9*(L9-O9)^2)) -> 1238118.4 | Q9: =IF(Inputs!$B9="","",P9/O9) -> 47991.211 | R9: =IF(Inputs!$B9="","",P9/(Inputs!$D9-O9)) -> 16685.975 | S9: =IF(Inputs!$B9="","",2*Inputs!$D9*Inputs!$E9) -> 400 | T9: =IF(Inputs!$B9="","",N9*0.00785+IF(Inputs!$B9="ladder",p_rungN/2.5*(p_rungW*p_rungT+2*p_rungT*p_rungH)*Inputs!$C9*0.00000785,0)) -> 8.0656133 | U9: =IF(Inputs!$B9="","",IF(Inputs!$G9="",T9,Inputs!$G9)) -> 9.028 | V9: =IF(Inputs!$B9="","",Inputs!$D9/Inputs!$E9) -> 50 | W9: =IF(Inputs!$B9="","",IF(D9>0,D9/Inputs!$E9,0)) -> 7.5 | X9: =IF(Inputs!$B9="","",IF(OR(Inputs!$B9="perf",Inputs!$B9="trough"),(Inputs!$C9+4)/Inputs!$E9,IF(OR(Inputs!$B9="channel",Inputs!$B9="arm"),Inputs!$C9/Inputs!$E9,0))) -> 152 | Y9: =IF(Inputs!$B9="","",IF(V9>p_webS,"web; ","")&IF(W9>p_flS,"flange; ","")&IF(X9>p_plS,"base plate; ","")) | Z9: =IF(Inputs!$B9="","",IFERROR(INDEX(sup_kw,MATCH(Inputs!$J9,sup_names,0)),INDEX(sup_kw,1))) -> 0.125 | AA9: =IF(Inputs!$B9="","",IFERROR(INDEX(sup_kp,MATCH(Inputs!$J9,sup_names,0)),INDEX(sup_kp,1))) -> 0.25 | AB9: =IF(Inputs!$B9="","",IFERROR(INDEX(sup_dw,MATCH(Inputs!$J9,sup_names,0)),INDEX(sup_dw,1))) -> 0.013020833 | AC9: =IF(Inputs!$B9="","",IFERROR(INDEX(sup_dp,MATCH(Inputs!$J9,sup_names,0)),INDEX(sup_dp,1))) -> 0.020833333 | AD9: =IF(Inputs!$B9="","",IFERROR(INDEX(sup_kv,MATCH(Inputs!$J9,sup_names,0)),INDEX(sup_kv,1))) -> 0.5 | AE9: =IF(Inputs!$B9="","",p_fy/p_fs) -> 149.7006 | AF9: =IF(Inputs!$B9="","",Inputs!$K9*p_g) -> 882.9 | AG9: =IF(Inputs!$B9="","",p_E*P9) -> 2.4762369e+11 | AH9: =IF(Inputs!$B9="","",p_shear*p_fy*S9) -> 40000 | AI9: =IF(Inputs!$B9="","",IF(Inputs!$B9="channel",Inputs!$M9,Inputs!$I9*1000)) -> 2000 | AJ9: =IF(Inputs!$B9="","",IF(Inputs!$B9="channel",(Inputs!$H9+Inputs!$N9)*Inputs!$I9/(AI9/1000),Inputs!$H9)) -> 25 | AK9: =IF(Inputs!$B9="","",AE9*MIN(Q9,R9)*p_splice) -> 1373845.3 | AL9: =IF(Inputs!$B9="","",AI9/Inputs!$L9) -> 10 | AM9: =IF(Inputs!$B9="","",U9*p_g/1000) -> 0.08856468 | AN9: =IF(Inputs!$B9="","",AJ9*p_g/1000) -> 0.24525 | AO9: =IF(Inputs!$B9="","",Z9*(AM9+AN9)*AI9^2+AA9*AF9*AI9) -> 608357.34 | AP9: =IF(Inputs!$B9="","",AD9*((AM9+AN9)*AI9+AF9)) -> 775.26468 | AQ9: =IF(Inputs!$B9="","",AB9*(AM9+AN9)*AI9^4/AG9+AC9*AF9*AI9^3/AG9) -> 0.87509692 | AR9: =IF(Inputs!$B9="","",MAX(0,(AK9-AA9*AF9*AI9)/(Z9*AI9^2)-AM9)*1000/p_g) -> 181.06278 | AS9: =IF(Inputs!$B9="","",MAX(0,(AH9-AD9*AF9)/(AD9*AI9)-AM9)*1000/p_g) -> 4023.444 | AT9: =IF(Inputs!$B9="","",MAX(0,(AL9-AC9*AF9*AI9^3/AG9)/(AB9*AI9^4/AG9)-AM9)*1000/p_g) -> 1130.5864 | AU9: =IF(Inputs!$B9="","",MIN(AR9,AS9,AT9)) -> 181.06278 | AV9: =IF(Inputs!$B9="","",IF(AU9=AR9,"bending",IF(AU9=AT9,"deflection","shear"))) -> bending | AW9: =IF(Inputs!$B9="","",IF(Inputs!$B9="ladder",((Inputs!$H9*2500/p_rungN/1000*p_g)*Inputs!$C9/8+(AF9/3)*Inputs!$C9/4)/(p_fy/p_fs*p_rungZ),"")) | AX9: =IF(Inputs!$B9="","",IF(Inputs!$B9="arm",AE9*MIN(Q9,R9),"")) | AY9: =IF(Inputs!$B9="","",IF(Inputs!$B9="arm",Inputs!$F9/p_cant,"")) | AZ9: =IF(Inputs!$B9="","",IF(Inputs!$B9="arm",Inputs!$H9*Inputs!$I9*p_g,"")) | BA9: =IF(Inputs!$B9="","",IF(Inputs!$B9="arm",AZ9+Inputs!$N9*Inputs!$I9*p_g,"")) | BB9: =IF(Inputs!$B9="","",IF(Inputs!$B9="arm",AF9/3,"")) | BC9: =IF(Inputs!$B9="","",IF(Inputs!$B9="arm",BA9*Inputs!$F9/2+BB9*Inputs!$F9,"")) | BD9: =IF(Inputs!$B9="","",IF(Inputs!$B9="arm",BA9+BB9,"")) | BE9: =IF(Inputs!$B9="","",IF(Inputs!$B9="arm",BA9*Inputs!$F9^3/(8*AG9)+BB9*Inputs!$F9^3/(3*AG9),"")) | BF9: =IF(Inputs!$B9="","",IF(Inputs!$B9="arm",(AX9-BB9*Inputs!$F9)/(Inputs!$F9/2)/p_g-Inputs!$N9*Inputs!$I9,"")) | BG9: =IF(Inputs!$B9="","",IF(Inputs!$B9="arm",(AH9-BB9)/p_g-Inputs!$N9*Inputs!$I9,"")) | BH9: =IF(Inputs!$B9="","",IF(Inputs!$B9="arm",(AY9-BB9*Inputs!$F9^3/(3*AG9))/(Inputs!$F9^3/(8*AG9))/p_g-Inputs!$N9*Inputs!$I9,"")) | BI9: =IF(Inputs!$B9="","",IF(Inputs!$B9="arm",MAX(0,MIN(BF9,BG9,BH9)),"")) | BJ9: =IF(Inputs!$B9="","",IF(Inputs!$B9="arm",BI9/Inputs!$I9,"")) | BK9: =IF(Inputs!$B9="","",IF(Inputs!$B9="arm",IF(BI9=MAX(0,BF9),"bending",IF(BI9=MAX(0,BH9),"deflection","shear")),"")) | BL9: =IF(Inputs!$B9="","",IF(Inputs!$B9="arm",AX9,AK9)) -> 1373845.3 | BM9: =IF(Inputs!$B9="","",IF(Inputs!$B9="arm",BC9,AO9)) -> 608357.34 | BN9: =IF(Inputs!$B9="","",IF(Inputs!$B9="arm",BD9,AP9)) -> 775.26468 | BO9: =IF(Inputs!$B9="","",IF(Inputs!$B9="arm",BE9,AQ9)) -> 0.87509692 | BP9: =IF(Inputs!$B9="","",IF(Inputs!$B9="arm",AY9,AL9)) -> 10 | BQ9: =IF(Inputs!$B9="","",BM9/BL9) -> 0.44281357 | BR9: =IF(Inputs!$B9="","",BN9/AH9) -> 0.019381617 | BS9: =IF(Inputs!$B9="","",BO9/BP9) -> 0.087509692 | BT9: =IF(Inputs!$B9="","",MAX(BQ9,BR9,BS9,IF(Inputs!$B9="ladder",AW9,0))) -> 0.44281357 | BU9: =IF(Inputs!$B9="","",IF(Inputs!$B9="arm",BJ9,AU9)) -> 181.06278 | BV9: =IF(Inputs!$B9="","",IF(Inputs!$B9="arm",BK9,AV9)) -> bending | BW9: =IF(Inputs!$B9="","",IF(BT9<=1,"PASS","FAIL")) -> PASS | BX9: =IF(Inputs!$B9="","",IF(Inputs!$H9>0,BU9/Inputs!$H9-1,"")) -> 6.2425112
A10: =IF(Inputs!A10="","",Inputs!A10) -> Trough 150 x 50 x 2.5 | B10: =IF(Inputs!$B10="","",Inputs!$B10) -> trough | C10: =IF(Inputs!$B10="","",IF(OR(Inputs!$B10="perf",Inputs!$B10="trough"),MIN(0.5,IF(Inputs!$B10="perf",p_perfN*p_perfL*p_perfW/(p_perfSp*Inputs!$C10),p_trN*p_trL*p_trW/(p_trSp*Inputs!$C10))),0)) -> 0.066666667 | D10: =IF(Inputs!$B10="","",IF(Inputs!$B10="ladder",p_collar,IF(Inputs!$B10="perf",IF(AND(Inputs!$C10>=300,Inputs!$D10>=100),15,0),IF(Inputs!$B10="trough",0,p_lip)))) -> 0 | E10: =IF(Inputs!$B10="","",IF(Inputs!$B10="ladder",2*Inputs!$E10*Inputs!$D10,IF(OR(Inputs!$B10="perf",Inputs!$B10="trough"),(Inputs!$C10+4)*Inputs!$E10*(1-C10),Inputs!$C10*Inputs!$E10))) -> 359.33333 | F10: =IF(Inputs!$B10="","",IF(Inputs!$B10="ladder",Inputs!$D10/2,Inputs!$E10/2)) -> 1.25 | G10: =IF(Inputs!$B10="","",IF(Inputs!$B10="ladder",2*Inputs!$E10*Inputs!$D10^3/12,IF(OR(Inputs!$B10="perf",Inputs!$B10="trough"),0,Inputs!$C10*Inputs!$E10^3/12))) -> 0 | H10: =IF(Inputs!$B10="","",IF(Inputs!$B10="ladder",2*D10*Inputs!$E10,2*Inputs!$E10*Inputs!$D10)) -> 250 | I10: =IF(Inputs!$B10="","",IF(Inputs!$B10="ladder",Inputs!$E10/2,Inputs!$D10/2)) -> 25 | J10: =IF(Inputs!$B10="","",IF(Inputs!$B10="ladder",2*D10*Inputs!$E10^3/12,2*Inputs!$E10*Inputs!$D10^3/12)) -> 52083.333 | K10: =IF(Inputs!$B10="","",2*D10*Inputs!$E10) -> 0 | L10: =IF(Inputs!$B10="","",Inputs!$D10-Inputs!$E10/2) -> 48.75 | M10: =IF(Inputs!$B10="","",2*D10*Inputs!$E10^3/12) -> 0 | N10: =IF(Inputs!$B10="","",E10+H10+K10) -> 609.33333 | O10: =IF(Inputs!$B10="","",(E10*F10+H10*I10+K10*L10)/N10) -> 10.994256 | P10: =IF(Inputs!$B10="","",(G10+E10*(F10-O10)^2)+(J10+H10*(I10-O10)^2)+(M10+K10*(L10-O10)^2)) -> 135242.44 | Q10: =IF(Inputs!$B10="","",P10/O10) -> 12301.191 | R10: =IF(Inputs!$B10="","",P10/(Inputs!$D10-O10)) -> 3467.2442 | S10: =IF(Inputs!$B10="","",2*Inputs!$D10*Inputs!$E10) -> 250 | T10: =IF(Inputs!$B10="","",N10*0.00785+IF(Inputs!$B10="ladder",p_rungN/2.5*(p_rungW*p_rungT+2*p_rungT*p_rungH)*Inputs!$C10*0.00000785,0)) -> 4.7832667 | U10: =IF(Inputs!$B10="","",IF(Inputs!$G10="",T10,Inputs!$G10)) -> 5.403 | V10: =IF(Inputs!$B10="","",Inputs!$D10/Inputs!$E10) -> 20 | W10: =IF(Inputs!$B10="","",IF(D10>0,D10/Inputs!$E10,0)) -> 0 | X10: =IF(Inputs!$B10="","",IF(OR(Inputs!$B10="perf",Inputs!$B10="trough"),(Inputs!$C10+4)/Inputs!$E10,IF(OR(Inputs!$B10="channel",Inputs!$B10="arm"),Inputs!$C10/Inputs!$E10,0))) -> 61.6 | Y10: =IF(Inputs!$B10="","",IF(V10>p_webS,"web; ","")&IF(W10>p_flS,"flange; ","")&IF(X10>p_plS,"base plate; ","")) | Z10: =IF(Inputs!$B10="","",IFERROR(INDEX(sup_kw,MATCH(Inputs!$J10,sup_names,0)),INDEX(sup_kw,1))) -> 0.125 | AA10: =IF(Inputs!$B10="","",IFERROR(INDEX(sup_kp,MATCH(Inputs!$J10,sup_names,0)),INDEX(sup_kp,1))) -> 0.25 | AB10: =IF(Inputs!$B10="","",IFERROR(INDEX(sup_dw,MATCH(Inputs!$J10,sup_names,0)),INDEX(sup_dw,1))) -> 0.013020833 | AC10: =IF(Inputs!$B10="","",IFERROR(INDEX(sup_dp,MATCH(Inputs!$J10,sup_names,0)),INDEX(sup_dp,1))) -> 0.020833333 | AD10: =IF(Inputs!$B10="","",IFERROR(INDEX(sup_kv,MATCH(Inputs!$J10,sup_names,0)),INDEX(sup_kv,1))) -> 0.5 | AE10: =IF(Inputs!$B10="","",p_fy/p_fs) -> 149.7006 | AF10: =IF(Inputs!$B10="","",Inputs!$K10*p_g) -> 588.6 | AG10: =IF(Inputs!$B10="","",p_E*P10) -> 2.7048488e+10 | AH10: =IF(Inputs!$B10="","",p_shear*p_fy*S10) -> 25000 | AI10: =IF(Inputs!$B10="","",IF(Inputs!$B10="channel",Inputs!$M10,Inputs!$I10*1000)) -> 1500 | AJ10: =IF(Inputs!$B10="","",IF(Inputs!$B10="channel",(Inputs!$H10+Inputs!$N10)*Inputs!$I10/(AI10/1000),Inputs!$H10)) -> 10 | AK10: =IF(Inputs!$B10="","",AE10*MIN(Q10,R10)*p_splice) -> 285476.69 | AL10: =IF(Inputs!$B10="","",AI10/Inputs!$L10) -> 7.5 | AM10: =IF(Inputs!$B10="","",U10*p_g/1000) -> 0.05300343 | AN10: =IF(Inputs!$B10="","",AJ10*p_g/1000) -> 0.0981 | AO10: =IF(Inputs!$B10="","",Z10*(AM10+AN10)*AI10^2+AA10*AF10*AI10) -> 263222.84 | AP10: =IF(Inputs!$B10="","",AD10*((AM10+AN10)*AI10+AF10)) -> 407.62757 | AQ10: =IF(Inputs!$B10="","",AB10*(AM10+AN10)*AI10^4/AG10+AC10*AF10*AI10^3/AG10) -> 1.8983083 | AR10: =IF(Inputs!$B10="","",MAX(0,(AK10-AA10*AF10*AI10)/(Z10*AI10^2)-AM10)*1000/p_g) -> 18.065729 | AS10: =IF(Inputs!$B10="","",MAX(0,(AH10-AD10*AF10)/(AD10*AI10)-AM10)*1000/p_g) -> 3352.4903 | AT10: =IF(Inputs!$B10="","",MAX(0,(AL10-AC10*AF10*AI10^3/AG10)/(AB10*AI10^4/AG10)-AM10)*1000/p_g) -> 244.30921 | AU10: =IF(Inputs!$B10="","",MIN(AR10,AS10,AT10)) -> 18.065729 | AV10: =IF(Inputs!$B10="","",IF(AU10=AR10,"bending",IF(AU10=AT10,"deflection","shear"))) -> bending | AW10: =IF(Inputs!$B10="","",IF(Inputs!$B10="ladder",((Inputs!$H10*2500/p_rungN/1000*p_g)*Inputs!$C10/8+(AF10/3)*Inputs!$C10/4)/(p_fy/p_fs*p_rungZ),"")) | AX10: =IF(Inputs!$B10="","",IF(Inputs!$B10="arm",AE10*MIN(Q10,R10),"")) | AY10: =IF(Inputs!$B10="","",IF(Inputs!$B10="arm",Inputs!$F10/p_cant,"")) | AZ10: =IF(Inputs!$B10="","",IF(Inputs!$B10="arm",Inputs!$H10*Inputs!$I10*p_g,"")) | BA10: =IF(Inputs!$B10="","",IF(Inputs!$B10="arm",AZ10+Inputs!$N10*Inputs!$I10*p_g,"")) | BB10: =IF(Inputs!$B10="","",IF(Inputs!$B10="arm",AF10/3,"")) | BC10: =IF(Inputs!$B10="","",IF(Inputs!$B10="arm",BA10*Inputs!$F10/2+BB10*Inputs!$F10,"")) | BD10: =IF(Inputs!$B10="","",IF(Inputs!$B10="arm",BA10+BB10,"")) | BE10: =IF(Inputs!$B10="","",IF(Inputs!$B10="arm",BA10*Inputs!$F10^3/(8*AG10)+BB10*Inputs!$F10^3/(3*AG10),"")) | BF10: =IF(Inputs!$B10="","",IF(Inputs!$B10="arm",(AX10-BB10*Inputs!$F10)/(Inputs!$F10/2)/p_g-Inputs!$N10*Inputs!$I10,"")) | BG10: =IF(Inputs!$B10="","",IF(Inputs!$B10="arm",(AH10-BB10)/p_g-Inputs!$N10*Inputs!$I10,"")) | BH10: =IF(Inputs!$B10="","",IF(Inputs!$B10="arm",(AY10-BB10*Inputs!$F10^3/(3*AG10))/(Inputs!$F10^3/(8*AG10))/p_g-Inputs!$N10*Inputs!$I10,"")) | BI10: =IF(Inputs!$B10="","",IF(Inputs!$B10="arm",MAX(0,MIN(BF10,BG10,BH10)),"")) | BJ10: =IF(Inputs!$B10="","",IF(Inputs!$B10="arm",BI10/Inputs!$I10,"")) | BK10: =IF(Inputs!$B10="","",IF(Inputs!$B10="arm",IF(BI10=MAX(0,BF10),"bending",IF(BI10=MAX(0,BH10),"deflection","shear")),"")) | BL10: =IF(Inputs!$B10="","",IF(Inputs!$B10="arm",AX10,AK10)) -> 285476.69 | BM10: =IF(Inputs!$B10="","",IF(Inputs!$B10="arm",BC10,AO10)) -> 263222.84 | BN10: =IF(Inputs!$B10="","",IF(Inputs!$B10="arm",BD10,AP10)) -> 407.62757 | BO10: =IF(Inputs!$B10="","",IF(Inputs!$B10="arm",BE10,AQ10)) -> 1.8983083 | BP10: =IF(Inputs!$B10="","",IF(Inputs!$B10="arm",AY10,AL10)) -> 7.5 | BQ10: =IF(Inputs!$B10="","",BM10/BL10) -> 0.9220467 | BR10: =IF(Inputs!$B10="","",BN10/AH10) -> 0.016305103 | BS10: =IF(Inputs!$B10="","",BO10/BP10) -> 0.25310777 | BT10: =IF(Inputs!$B10="","",MAX(BQ10,BR10,BS10,IF(Inputs!$B10="ladder",AW10,0))) -> 0.9220467 | BU10: =IF(Inputs!$B10="","",IF(Inputs!$B10="arm",BJ10,AU10)) -> 18.065729 | BV10: =IF(Inputs!$B10="","",IF(Inputs!$B10="arm",BK10,AV10)) -> bending | BW10: =IF(Inputs!$B10="","",IF(BT10<=1,"PASS","FAIL")) -> PASS | BX10: =IF(Inputs!$B10="","",IF(Inputs!$H10>0,BU10/Inputs!$H10-1,"")) -> 0.8065729
A11: =IF(Inputs!A11="","",Inputs!A11) -> Cantilever arm 620 mm, 41 x 41 x 2.5 | B11: =IF(Inputs!$B11="","",Inputs!$B11) -> arm | C11: =IF(Inputs!$B11="","",IF(OR(Inputs!$B11="perf",Inputs!$B11="trough"),MIN(0.5,IF(Inputs!$B11="perf",p_perfN*p_perfL*p_perfW/(p_perfSp*Inputs!$C11),p_trN*p_trL*p_trW/(p_trSp*Inputs!$C11))),0)) -> 0 | D11: =IF(Inputs!$B11="","",IF(Inputs!$B11="ladder",p_collar,IF(Inputs!$B11="perf",IF(AND(Inputs!$C11>=300,Inputs!$D11>=100),15,0),IF(Inputs!$B11="trough",0,p_lip)))) -> 9 | E11: =IF(Inputs!$B11="","",IF(Inputs!$B11="ladder",2*Inputs!$E11*Inputs!$D11,IF(OR(Inputs!$B11="perf",Inputs!$B11="trough"),(Inputs!$C11+4)*Inputs!$E11*(1-C11),Inputs!$C11*Inputs!$E11))) -> 102.5 | F11: =IF(Inputs!$B11="","",IF(Inputs!$B11="ladder",Inputs!$D11/2,Inputs!$E11/2)) -> 1.25 | G11: =IF(Inputs!$B11="","",IF(Inputs!$B11="ladder",2*Inputs!$E11*Inputs!$D11^3/12,IF(OR(Inputs!$B11="perf",Inputs!$B11="trough"),0,Inputs!$C11*Inputs!$E11^3/12))) -> 53.385417 | H11: =IF(Inputs!$B11="","",IF(Inputs!$B11="ladder",2*D11*Inputs!$E11,2*Inputs!$E11*Inputs!$D11)) -> 205 | I11: =IF(Inputs!$B11="","",IF(Inputs!$B11="ladder",Inputs!$E11/2,Inputs!$D11/2)) -> 20.5 | J11: =IF(Inputs!$B11="","",IF(Inputs!$B11="ladder",2*D11*Inputs!$E11^3/12,2*Inputs!$E11*Inputs!$D11^3/12)) -> 28717.083 | K11: =IF(Inputs!$B11="","",2*D11*Inputs!$E11) -> 45 | L11: =IF(Inputs!$B11="","",Inputs!$D11-Inputs!$E11/2) -> 39.75 | M11: =IF(Inputs!$B11="","",2*D11*Inputs!$E11^3/12) -> 23.4375 | N11: =IF(Inputs!$B11="","",E11+H11+K11) -> 352.5 | O11: =IF(Inputs!$B11="","",(E11*F11+H11*I11+K11*L11)/N11) -> 17.359929 | P11: =IF(Inputs!$B11="","",(G11+E11*(F11-O11)^2)+(J11+H11*(I11-O11)^2)+(M11+K11*(L11-O11)^2)) -> 79976.209 | Q11: =IF(Inputs!$B11="","",P11/O11) -> 4606.9433 | R11: =IF(Inputs!$B11="","",P11/(Inputs!$D11-O11)) -> 3383.0782 | S11: =IF(Inputs!$B11="","",2*Inputs!$D11*Inputs!$E11) -> 205 | T11: =IF(Inputs!$B11="","",N11*0.00785+IF(Inputs!$B11="ladder",p_rungN/2.5*(p_rungW*p_rungT+2*p_rungT*p_rungH)*Inputs!$C11*0.00000785,0)) -> 2.767125 | U11: =IF(Inputs!$B11="","",IF(Inputs!$G11="",T11,Inputs!$G11)) -> 2.796 | V11: =IF(Inputs!$B11="","",Inputs!$D11/Inputs!$E11) -> 16.4 | W11: =IF(Inputs!$B11="","",IF(D11>0,D11/Inputs!$E11,0)) -> 3.6 | X11: =IF(Inputs!$B11="","",IF(OR(Inputs!$B11="perf",Inputs!$B11="trough"),(Inputs!$C11+4)/Inputs!$E11,IF(OR(Inputs!$B11="channel",Inputs!$B11="arm"),Inputs!$C11/Inputs!$E11,0))) -> 16.4 | Y11: =IF(Inputs!$B11="","",IF(V11>p_webS,"web; ","")&IF(W11>p_flS,"flange; ","")&IF(X11>p_plS,"base plate; ","")) | Z11: =IF(Inputs!$B11="","",IFERROR(INDEX(sup_kw,MATCH(Inputs!$J11,sup_names,0)),INDEX(sup_kw,1))) -> 0.125 | AA11: =IF(Inputs!$B11="","",IFERROR(INDEX(sup_kp,MATCH(Inputs!$J11,sup_names,0)),INDEX(sup_kp,1))) -> 0.25 | AB11: =IF(Inputs!$B11="","",IFERROR(INDEX(sup_dw,MATCH(Inputs!$J11,sup_names,0)),INDEX(sup_dw,1))) -> 0.013020833 | AC11: =IF(Inputs!$B11="","",IFERROR(INDEX(sup_dp,MATCH(Inputs!$J11,sup_names,0)),INDEX(sup_dp,1))) -> 0.020833333 | AD11: =IF(Inputs!$B11="","",IFERROR(INDEX(sup_kv,MATCH(Inputs!$J11,sup_names,0)),INDEX(sup_kv,1))) -> 0.5 | AE11: =IF(Inputs!$B11="","",p_fy/p_fs) -> 149.7006 | AF11: =IF(Inputs!$B11="","",Inputs!$K11*p_g) -> 882.9 | AG11: =IF(Inputs!$B11="","",p_E*P11) -> 1.5995242e+10 | AH11: =IF(Inputs!$B11="","",p_shear*p_fy*S11) -> 20500 | AI11: =IF(Inputs!$B11="","",IF(Inputs!$B11="channel",Inputs!$M11,Inputs!$I11*1000)) -> 2000 | AJ11: =IF(Inputs!$B11="","",IF(Inputs!$B11="channel",(Inputs!$H11+Inputs!$N11)*Inputs!$I11/(AI11/1000),Inputs!$H11)) -> 20 | AK11: =IF(Inputs!$B11="","",AE11*MIN(Q11,R11)*p_splice) -> 278546.86 | AL11: =IF(Inputs!$B11="","",AI11/Inputs!$L11) -> 10 | AM11: =IF(Inputs!$B11="","",U11*p_g/1000) -> 0.02742876 | AN11: =IF(Inputs!$B11="","",AJ11*p_g/1000) -> 0.1962 | AO11: =IF(Inputs!$B11="","",Z11*(AM11+AN11)*AI11^2+AA11*AF11*AI11) -> 553264.38 | AP11: =IF(Inputs!$B11="","",AD11*((AM11+AN11)*AI11+AF11)) -> 665.07876 | AQ11: =IF(Inputs!$B11="","",AB11*(AM11+AN11)*AI11^4/AG11+AC11*AF11*AI11^3/AG11) -> 12.11231 | AR11: =IF(Inputs!$B11="","",MAX(0,(AK11-AA11*AF11*AI11)/(Z11*AI11^2)-AM11)*1000/p_g) -> 0 | AS11: =IF(Inputs!$B11="","",MAX(0,(AH11-AD11*AF11)/(AD11*AI11)-AM11)*1000/p_g) -> 2041.9084 | AT11: =IF(Inputs!$B11="","",MAX(0,(AL11-AC11*AF11*AI11^3/AG11)/(AB11*AI11^4/AG11)-AM11)*1000/p_g) -> 3.4681801 | AU11: =IF(Inputs!$B11="","",MIN(AR11,AS11,AT11)) -> 0 | AV11: =IF(Inputs!$B11="","",IF(AU11=AR11,"bending",IF(AU11=AT11,"deflection","shear"))) -> bending | AW11: =IF(Inputs!$B11="","",IF(Inputs!$B11="ladder",((Inputs!$H11*2500/p_rungN/1000*p_g)*Inputs!$C11/8+(AF11/3)*Inputs!$C11/4)/(p_fy/p_fs*p_rungZ),"")) | AX11: =IF(Inputs!$B11="","",IF(Inputs!$B11="arm",AE11*MIN(Q11,R11),"")) -> 506448.83 | AY11: =IF(Inputs!$B11="","",IF(Inputs!$B11="arm",Inputs!$F11/p_cant,"")) -> 6.2 | AZ11: =IF(Inputs!$B11="","",IF(Inputs!$B11="arm",Inputs!$H11*Inputs!$I11*p_g,"")) -> 392.4 | BA11: =IF(Inputs!$B11="","",IF(Inputs!$B11="arm",AZ11+Inputs!$N11*Inputs!$I11*p_g,"")) -> 549.36 | BB11: =IF(Inputs!$B11="","",IF(Inputs!$B11="arm",AF11/3,"")) -> 294.3 | BC11: =IF(Inputs!$B11="","",IF(Inputs!$B11="arm",BA11*Inputs!$F11/2+BB11*Inputs!$F11,"")) -> 352767.6 | BD11: =IF(Inputs!$B11="","",IF(Inputs!$B11="arm",BA11+BB11,"")) -> 843.66 | BE11: =IF(Inputs!$B11="","",IF(Inputs!$B11="arm",BA11*Inputs!$F11^3/(8*AG11)+BB11*Inputs!$F11^3/(3*AG11),"")) -> 2.4848615 | BF11: =IF(Inputs!$B11="","",IF(Inputs!$B11="arm",(AX11-BB11*Inputs!$F11)/(Inputs!$F11/2)/p_g-Inputs!$N11*Inputs!$I11,"")) -> 90.534752 | BG11: =IF(Inputs!$B11="","",IF(Inputs!$B11="arm",(AH11-BB11)/p_g-Inputs!$N11*Inputs!$I11,"")) -> 2043.7044 | BH11: =IF(Inputs!$B11="","",IF(Inputs!$B11="arm",(AY11-BB11*Inputs!$F11^3/(3*AG11))/(Inputs!$F11^3/(8*AG11))/p_g-Inputs!$N11*Inputs!$I11,"")) -> 243.33481 | BI11: =IF(Inputs!$B11="","",IF(Inputs!$B11="arm",MAX(0,MIN(BF11,BG11,BH11)),"")) -> 90.534752 | BJ11: =IF(Inputs!$B11="","",IF(Inputs!$B11="arm",BI11/Inputs!$I11,"")) -> 45.267376 | BK11: =IF(Inputs!$B11="","",IF(Inputs!$B11="arm",IF(BI11=MAX(0,BF11),"bending",IF(BI11=MAX(0,BH11),"deflection","shear")),"")) -> bending | BL11: =IF(Inputs!$B11="","",IF(Inputs!$B11="arm",AX11,AK11)) -> 506448.83 | BM11: =IF(Inputs!$B11="","",IF(Inputs!$B11="arm",BC11,AO11)) -> 352767.6 | BN11: =IF(Inputs!$B11="","",IF(Inputs!$B11="arm",BD11,AP11)) -> 843.66 | BO11: =IF(Inputs!$B11="","",IF(Inputs!$B11="arm",BE11,AQ11)) -> 2.4848615 | BP11: =IF(Inputs!$B11="","",IF(Inputs!$B11="arm",AY11,AL11)) -> 6.2 | BQ11: =IF(Inputs!$B11="","",BM11/BL11) -> 0.69655131 | BR11: =IF(Inputs!$B11="","",BN11/AH11) -> 0.041154146 | BS11: =IF(Inputs!$B11="","",BO11/BP11) -> 0.40078411 | BT11: =IF(Inputs!$B11="","",MAX(BQ11,BR11,BS11,IF(Inputs!$B11="ladder",AW11,0))) -> 0.69655131 | BU11: =IF(Inputs!$B11="","",IF(Inputs!$B11="arm",BJ11,AU11)) -> 45.267376 | BV11: =IF(Inputs!$B11="","",IF(Inputs!$B11="arm",BK11,AV11)) -> bending | BW11: =IF(Inputs!$B11="","",IF(BT11<=1,"PASS","FAIL")) -> PASS | BX11: =IF(Inputs!$B11="","",IF(Inputs!$H11>0,BU11/Inputs!$H11-1,"")) -> 1.2633688
A12: =IF(Inputs!A12="","",Inputs!A12) -> Cantilever arm 320 mm, 41 x 41 x 2.5 | B12: =IF(Inputs!$B12="","",Inputs!$B12) -> arm | C12: =IF(Inputs!$B12="","",IF(OR(Inputs!$B12="perf",Inputs!$B12="trough"),MIN(0.5,IF(Inputs!$B12="perf",p_perfN*p_perfL*p_perfW/(p_perfSp*Inputs!$C12),p_trN*p_trL*p_trW/(p_trSp*Inputs!$C12))),0)) -> 0 | D12: =IF(Inputs!$B12="","",IF(Inputs!$B12="ladder",p_collar,IF(Inputs!$B12="perf",IF(AND(Inputs!$C12>=300,Inputs!$D12>=100),15,0),IF(Inputs!$B12="trough",0,p_lip)))) -> 9 | E12: =IF(Inputs!$B12="","",IF(Inputs!$B12="ladder",2*Inputs!$E12*Inputs!$D12,IF(OR(Inputs!$B12="perf",Inputs!$B12="trough"),(Inputs!$C12+4)*Inputs!$E12*(1-C12),Inputs!$C12*Inputs!$E12))) -> 102.5 | F12: =IF(Inputs!$B12="","",IF(Inputs!$B12="ladder",Inputs!$D12/2,Inputs!$E12/2)) -> 1.25 | G12: =IF(Inputs!$B12="","",IF(Inputs!$B12="ladder",2*Inputs!$E12*Inputs!$D12^3/12,IF(OR(Inputs!$B12="perf",Inputs!$B12="trough"),0,Inputs!$C12*Inputs!$E12^3/12))) -> 53.385417 | H12: =IF(Inputs!$B12="","",IF(Inputs!$B12="ladder",2*D12*Inputs!$E12,2*Inputs!$E12*Inputs!$D12)) -> 205 | I12: =IF(Inputs!$B12="","",IF(Inputs!$B12="ladder",Inputs!$E12/2,Inputs!$D12/2)) -> 20.5 | J12: =IF(Inputs!$B12="","",IF(Inputs!$B12="ladder",2*D12*Inputs!$E12^3/12,2*Inputs!$E12*Inputs!$D12^3/12)) -> 28717.083 | K12: =IF(Inputs!$B12="","",2*D12*Inputs!$E12) -> 45 | L12: =IF(Inputs!$B12="","",Inputs!$D12-Inputs!$E12/2) -> 39.75 | M12: =IF(Inputs!$B12="","",2*D12*Inputs!$E12^3/12) -> 23.4375 | N12: =IF(Inputs!$B12="","",E12+H12+K12) -> 352.5 | O12: =IF(Inputs!$B12="","",(E12*F12+H12*I12+K12*L12)/N12) -> 17.359929 | P12: =IF(Inputs!$B12="","",(G12+E12*(F12-O12)^2)+(J12+H12*(I12-O12)^2)+(M12+K12*(L12-O12)^2)) -> 79976.209 | Q12: =IF(Inputs!$B12="","",P12/O12) -> 4606.9433 | R12: =IF(Inputs!$B12="","",P12/(Inputs!$D12-O12)) -> 3383.0782 | S12: =IF(Inputs!$B12="","",2*Inputs!$D12*Inputs!$E12) -> 205 | T12: =IF(Inputs!$B12="","",N12*0.00785+IF(Inputs!$B12="ladder",p_rungN/2.5*(p_rungW*p_rungT+2*p_rungT*p_rungH)*Inputs!$C12*0.00000785,0)) -> 2.767125 | U12: =IF(Inputs!$B12="","",IF(Inputs!$G12="",T12,Inputs!$G12)) -> 2.8 | V12: =IF(Inputs!$B12="","",Inputs!$D12/Inputs!$E12) -> 16.4 | W12: =IF(Inputs!$B12="","",IF(D12>0,D12/Inputs!$E12,0)) -> 3.6 | X12: =IF(Inputs!$B12="","",IF(OR(Inputs!$B12="perf",Inputs!$B12="trough"),(Inputs!$C12+4)/Inputs!$E12,IF(OR(Inputs!$B12="channel",Inputs!$B12="arm"),Inputs!$C12/Inputs!$E12,0))) -> 16.4 | Y12: =IF(Inputs!$B12="","",IF(V12>p_webS,"web; ","")&IF(W12>p_flS,"flange; ","")&IF(X12>p_plS,"base plate; ","")) | Z12: =IF(Inputs!$B12="","",IFERROR(INDEX(sup_kw,MATCH(Inputs!$J12,sup_names,0)),INDEX(sup_kw,1))) -> 0.125 | AA12: =IF(Inputs!$B12="","",IFERROR(INDEX(sup_kp,MATCH(Inputs!$J12,sup_names,0)),INDEX(sup_kp,1))) -> 0.25 | AB12: =IF(Inputs!$B12="","",IFERROR(INDEX(sup_dw,MATCH(Inputs!$J12,sup_names,0)),INDEX(sup_dw,1))) -> 0.013020833 | AC12: =IF(Inputs!$B12="","",IFERROR(INDEX(sup_dp,MATCH(Inputs!$J12,sup_names,0)),INDEX(sup_dp,1))) -> 0.020833333 | AD12: =IF(Inputs!$B12="","",IFERROR(INDEX(sup_kv,MATCH(Inputs!$J12,sup_names,0)),INDEX(sup_kv,1))) -> 0.5 | AE12: =IF(Inputs!$B12="","",p_fy/p_fs) -> 149.7006 | AF12: =IF(Inputs!$B12="","",Inputs!$K12*p_g) -> 882.9 | AG12: =IF(Inputs!$B12="","",p_E*P12) -> 1.5995242e+10 | AH12: =IF(Inputs!$B12="","",p_shear*p_fy*S12) -> 20500 | AI12: =IF(Inputs!$B12="","",IF(Inputs!$B12="channel",Inputs!$M12,Inputs!$I12*1000)) -> 2000 | AJ12: =IF(Inputs!$B12="","",IF(Inputs!$B12="channel",(Inputs!$H12+Inputs!$N12)*Inputs!$I12/(AI12/1000),Inputs!$H12)) -> 20 | AK12: =IF(Inputs!$B12="","",AE12*MIN(Q12,R12)*p_splice) -> 278546.86 | AL12: =IF(Inputs!$B12="","",AI12/Inputs!$L12) -> 10 | AM12: =IF(Inputs!$B12="","",U12*p_g/1000) -> 0.027468 | AN12: =IF(Inputs!$B12="","",AJ12*p_g/1000) -> 0.1962 | AO12: =IF(Inputs!$B12="","",Z12*(AM12+AN12)*AI12^2+AA12*AF12*AI12) -> 553284 | AP12: =IF(Inputs!$B12="","",AD12*((AM12+AN12)*AI12+AF12)) -> 665.118 | AQ12: =IF(Inputs!$B12="","",AB12*(AM12+AN12)*AI12^4/AG12+AC12*AF12*AI12^3/AG12) -> 12.112821 | AR12: =IF(Inputs!$B12="","",MAX(0,(AK12-AA12*AF12*AI12)/(Z12*AI12^2)-AM12)*1000/p_g) -> 0 | AS12: =IF(Inputs!$B12="","",MAX(0,(AH12-AD12*AF12)/(AD12*AI12)-AM12)*1000/p_g) -> 2041.9044 | AT12: =IF(Inputs!$B12="","",MAX(0,(AL12-AC12*AF12*AI12^3/AG12)/(AB12*AI12^4/AG12)-AM12)*1000/p_g) -> 3.4641801 | AU12: =IF(Inputs!$B12="","",MIN(AR12,AS12,AT12)) -> 0 | AV12: =IF(Inputs!$B12="","",IF(AU12=AR12,"bending",IF(AU12=AT12,"deflection","shear"))) -> bending | AW12: =IF(Inputs!$B12="","",IF(Inputs!$B12="ladder",((Inputs!$H12*2500/p_rungN/1000*p_g)*Inputs!$C12/8+(AF12/3)*Inputs!$C12/4)/(p_fy/p_fs*p_rungZ),"")) | AX12: =IF(Inputs!$B12="","",IF(Inputs!$B12="arm",AE12*MIN(Q12,R12),"")) -> 506448.83 | AY12: =IF(Inputs!$B12="","",IF(Inputs!$B12="arm",Inputs!$F12/p_cant,"")) -> 3.2 | AZ12: =IF(Inputs!$B12="","",IF(Inputs!$B12="arm",Inputs!$H12*Inputs!$I12*p_g,"")) -> 392.4 | BA12: =IF(Inputs!$B12="","",IF(Inputs!$B12="arm",AZ12+Inputs!$N12*Inputs!$I12*p_g,"")) -> 549.36 | BB12: =IF(Inputs!$B12="","",IF(Inputs!$B12="arm",AF12/3,"")) -> 294.3 | BC12: =IF(Inputs!$B12="","",IF(Inputs!$B12="arm",BA12*Inputs!$F12/2+BB12*Inputs!$F12,"")) -> 182073.6 | BD12: =IF(Inputs!$B12="","",IF(Inputs!$B12="arm",BA12+BB12,"")) -> 843.66 | BE12: =IF(Inputs!$B12="","",IF(Inputs!$B12="arm",BA12*Inputs!$F12^3/(8*AG12)+BB12*Inputs!$F12^3/(3*AG12),"")) -> 0.34164656 | BF12: =IF(Inputs!$B12="","",IF(Inputs!$B12="arm",(AX12-BB12*Inputs!$F12)/(Inputs!$F12/2)/p_g-Inputs!$N12*Inputs!$I12,"")) -> 246.66108 | BG12: =IF(Inputs!$B12="","",IF(Inputs!$B12="arm",(AH12-BB12)/p_g-Inputs!$N12*Inputs!$I12,"")) -> 2043.7044 | BH12: =IF(Inputs!$B12="","",IF(Inputs!$B12="arm",(AY12-BB12*Inputs!$F12^3/(3*AG12))/(Inputs!$F12^3/(8*AG12))/p_g-Inputs!$N12*Inputs!$I12,"")) -> 1177.8311 | BI12: =IF(Inputs!$B12="","",IF(Inputs!$B12="arm",MAX(0,MIN(BF12,BG12,BH12)),"")) -> 246.66108 | BJ12: =IF(Inputs!$B12="","",IF(Inputs!$B12="arm",BI12/Inputs!$I12,"")) -> 123.33054 | BK12: =IF(Inputs!$B12="","",IF(Inputs!$B12="arm",IF(BI12=MAX(0,BF12),"bending",IF(BI12=MAX(0,BH12),"deflection","shear")),"")) -> bending | BL12: =IF(Inputs!$B12="","",IF(Inputs!$B12="arm",AX12,AK12)) -> 506448.83 | BM12: =IF(Inputs!$B12="","",IF(Inputs!$B12="arm",BC12,AO12)) -> 182073.6 | BN12: =IF(Inputs!$B12="","",IF(Inputs!$B12="arm",BD12,AP12)) -> 843.66 | BO12: =IF(Inputs!$B12="","",IF(Inputs!$B12="arm",BE12,AQ12)) -> 0.34164656 | BP12: =IF(Inputs!$B12="","",IF(Inputs!$B12="arm",AY12,AL12)) -> 3.2 | BQ12: =IF(Inputs!$B12="","",BM12/BL12) -> 0.35951035 | BR12: =IF(Inputs!$B12="","",BN12/AH12) -> 0.041154146 | BS12: =IF(Inputs!$B12="","",BO12/BP12) -> 0.10676455 | BT12: =IF(Inputs!$B12="","",MAX(BQ12,BR12,BS12,IF(Inputs!$B12="ladder",AW12,0))) -> 0.35951035 | BU12: =IF(Inputs!$B12="","",IF(Inputs!$B12="arm",BJ12,AU12)) -> 123.33054 | BV12: =IF(Inputs!$B12="","",IF(Inputs!$B12="arm",BK12,AV12)) -> bending | BW12: =IF(Inputs!$B12="","",IF(BT12<=1,"PASS","FAIL")) -> PASS | BX12: =IF(Inputs!$B12="","",IF(Inputs!$H12>0,BU12/Inputs!$H12-1,"")) -> 5.1665271
