Workbook

Sheet Read Me
A1: Cooling tower: should-cost model
A2: Thermal sizing (Merkel number) and bottom-up costing of a mechanical or natural-draught cooling tower. Not a vendor price list: every rate is an editable assumption.
A4: Purpose | B4: Estimate the ex-works price of a cooling tower from heat load, range, approach and design wet-bulb. The thermal duty sets the water flow; the Merkel number demanded by range, approach and wet-bulb sets the fill depth; the liquid-to-air ratio is chosen to give the cheapest fill-plus-fan combination; quantities then follow and are priced.
A5: How to use | B5: Edit the yellow cells on Inputs (duty and tower type) and, if you have quotes, on Rates. Everything else is a live formula. Results are on Summary. The L/G scan is on Thermal; the priced build-up is on Costing.
A6: Sheets | B6: Inputs: duty and type. Summary: key results, cost stack, per-TR and per-m3/h figures, benchmark check. Thermal: psychrometrics, Merkel integral and the L/G scan. Costing: geometry, quantities, rates and amounts. Rates: tower-type table, fill rates and every price and constant (named cells r_...). Presets: five sample towers.
A7: Method | B7: Merkel number by the four-point Chebyshev integral of 1/(h_sat - h_air) at 10, 40, 60 and 90% of the range. Fill characteristic KaV/L = c x (L/G)^-n per metre of fill, so depth = Merkel / (c x (L/G)^-n), clamped between the minimum and 2.2 x the maximum depth on Rates. The L/G scan runs from the minimum to the maximum on Rates in steps of 0.05.
A8: Conventions | B8: Yellow fill = input. Blue font = a typed assumption you may change. Black = formula. Green fill = key output. Amounts in Indian rupees, ex-GST, ex-works.
A9: Reasonableness | B9: At the default rates: FRP counterflow about Rs 4,700-5,200 per TR, HDG steel about Rs 3,000, RCC power-plant towers about Rs 1,900, small crossflow about Rs 6,500. The fill characteristic constants (c, n) are generic, not a vendor’s fill data: replace them with the manufacturer’s curves before relying on the fill depth.
A10: Limits | B10: An approach below 2.8 K is not practical for a mechanical-draught tower and is flagged. Hot-water basin, pumps, piping, civil basin and electrical supply are excluded. Make-up water is shown, not costed.
A11: Companion | B11: The same model runs in the Should-Cost dashboards (cooling-towers.html), with a section view, a 3D model and a month selector for steel prices.

Sheet Inputs
A1: Cooling tower: duty and type
A4: Tag / tower name | B4: CT-01 1,000 TR chiller plant (FRP)
A5: Heat rejected | B5: 3517 | C5: kW | D5: =B5/3.517 -> 1000
A6: Range (hot water - cold water) | B6: 5 | C6: K
A7: Approach (cold water - wet-bulb) | B7: 4 | C7: K
A8: Design wet-bulb | B8: 28 | C8: °C
A9: Tower type | B9: Counterflow, induced draught, FRP | D9: pick from list
A10: Fan drive | B10: No | D10: No = direct on line, Yes = VFD

Sheet Summary
A1: Cooling tower: should-cost summary
A3: =Inputs!B4 -> CT-01 1,000 TR chiller plant (FRP) | C3: =t_status -> OK
A5: Cost group | B5: Rs | C5: Share | D5: Note
A6: Fill & drift | B6: =SUMIF(Costing!F16:F33,"Fill & drift",Costing!E16:E33) -> 1667068.8 | C6: =B6/B$13 -> 0.32570029 | D6: Fill pack, eliminators, distribution
A7: Casing, structure & basin | B7: =SUMIF(Costing!F16:F33,"Casing, structure & basin",Costing!E16:E33) -> 999830.83 | C7: =B7/B$13 -> 0.19533999 | D7: Casing or shell, basin, louvres
A8: Fans & drives | B8: =SUMIF(Costing!F16:F33,"Fans & drives",Costing!E16:E33) -> 918235.12 | C8: =B8/B$13 -> 0.17939838 | D8: Fans, gearboxes, motors, VFDs
A9: Accessories | B9: =SUMIF(Costing!F16:F33,"Accessories",Costing!E16:E33) -> 118000 | C9: =B9/B$13 -> 0.023054018 | D9: Ladders, controls, vibration switches
A10: Assembly & supply | B10: =SUMIF(Costing!F16:F33,"Assembly & supply",Costing!E16:E33) -> 685079.92 | C10: =B10/B$13 -> 0.13384614 | D10: Erection and assembly labour, transport
A11: Overheads | B11: =Costing!E35 -> 351057.17 | C11: =B11/B$13 -> 0.068587106
A12: Margin | B12: =Costing!E36 -> 379141.74 | C12: =B12/B$13 -> 0.074074074
A13: SHOULD-COST, ex-works (Rs) | B13: =SUM(B6:B12) -> 5118413.6 | C13: =B13/B$13 -> 1
A14: Check against Costing sheet | B14: =IF(ABS(B13-Costing!E37)<1,"OK","MISMATCH") -> OK
A16: Key results
A17: Should-cost (Rs crore) | B17: =B13/10000000 -> 0.51184136
A18: Rs per TR | B18: =B13/(i_kw/3.517) -> 5118.4136
A19: Rs per m3/h of water | B19: =B13/t_flow -> 8462.7736
A20: Heat rejected (TR) | B20: =i_kw/3.517 -> 1000
A21: Water flow (m3/h) | B21: =t_flow -> 604.81513
A22: Hot / cold water (°C) | B22: =TEXT(t_tIn,"0.0")&" / "&TEXT(t_tOut,"0.0") -> 37.0 / 32.0
A23: L/G ratio chosen | B23: =t_lg -> 1.3
A24: Merkel number demanded | B24: =t_me -> 0.92370511
A25: Fill depth (m) | B25: =t_depth -> 1.0351158
A26: Plan area (m2) | B26: =t_plan -> 43.201081
A27: Cells x cell side (m) | B27: =g_cells&" x "&TEXT(g_side,"0.0")&" m" -> 1 x 6.6 m
A28: Height (m) | B28: =g_height -> 3.9351158
A29: Fan shaft power, total (kW) | B29: =t_fanKw -> 27.188079
A30: Motor per cell (kW) | B30: =g_motorKw -> 31.5
A31: Fan diameter (m) | B31: =g_fanDia -> 4.4578791
A32: Make-up water (m3/h) | B32: =t_flow*r_makeup*i_range -> 4.6268358
A34: Benchmark
A35: Band for this type, Rs per TR | B35: =TEXT(INDEX(r_bLo,t_row),"#,##0")&" - "&TEXT(INDEX(r_bHi,t_row),"#,##0") -> 4,200 - 7,000
A36: This tower against the band | B36: =IF(B18<INDEX(r_bLo,t_row),"below",IF(B18>INDEX(r_bHi,t_row),"above","inside")) -> inside
A37: Approach check | B37: =IF(i_approach<3.5,"Approach under 3.5 K: fill depth and cost climb steeply","OK") -> OK

Sheet Thermal
A1: Thermal sizing
A2: Duty, psychrometrics, Merkel integral and the L/G scan.
A3: Status | B3: =IF(i_approach<2.8,"Approach below 2.8 K: not practical for a mechanical-draught tower",IF(COUNT(K25:K49)=0,"No feasible L/G ratio for this duty","OK")) -> OK
A5: Cold water out | B5: =i_wb+i_approach -> 32
A6: Hot water in | B6: =t_tOut+i_range -> 37
A7: Water flow m3/h | B7: =i_kw/(r_heatF*i_range) -> 604.81513
A8: Tower type row | B8: =MATCH(i_type,r_tList,0) -> 1
A9: Fill characteristic c | B9: =INDEX(r_tC,t_row) -> 1.05
A10: Fill exponent n | B10: =INDEX(r_tN,t_row) -> 0.62
A11: Plan loading m3/h per m2 | B11: =INDEX(r_tLoad,t_row) -> 14
A12: Natural draught? | B12: =INDEX(r_tNat,t_row) -> 0
A13: Plan area m2 | B13: =t_flow/t_load -> 43.201081
A14: Air enthalpy at wet-bulb (kJ/kg) | B14: =1.006*i_wb+0.622*(0.61078*EXP(17.27*i_wb/(i_wb+237.3)))/(r_pressure-0.61078*EXP(17.27*i_wb/(i_wb+237.3)))*(2501+1.86*i_wb) -> 89.702477
A16: Chebyshev points
A17: Point (fraction of range) | B17: x | C17: Water temp | D17: Saturated enthalpy
A18: Point 1 | B18: 0.1 | C18: =t_tOut+B18*i_range -> 32.5 | D18: =1.006*C18+0.622*(0.61078*EXP(17.27*C18/(C18+237.3)))/(r_pressure-0.61078*EXP(17.27*C18/(C18+237.3)))*(2501+1.86*C18) -> 113.49441
A19: Point 2 | B19: 0.4 | C19: =t_tOut+B19*i_range -> 34 | D19: =1.006*C19+0.622*(0.61078*EXP(17.27*C19/(C19+237.3)))/(r_pressure-0.61078*EXP(17.27*C19/(C19+237.3)))*(2501+1.86*C19) -> 122.57059
A20: Point 3 | B20: 0.6 | C20: =t_tOut+B20*i_range -> 35 | D20: =1.006*C20+0.622*(0.61078*EXP(17.27*C20/(C20+237.3)))/(r_pressure-0.61078*EXP(17.27*C20/(C20+237.3)))*(2501+1.86*C20) -> 128.98129
A21: Point 4 | B21: 0.9 | C21: =t_tOut+B21*i_range -> 36.5 | D21: =1.006*C21+0.622*(0.61078*EXP(17.27*C21/(C21+237.3)))/(r_pressure-0.61078*EXP(17.27*C21/(C21+237.3)))*(2501+1.86*C21) -> 139.17766
A23: L/G scan
A24: Step | B24: L/G | C24: Valid? | D24: Sum 1/(hs - h) | E24: Merkel demand | F24: KaV/L per m | G24: Fill depth m | H24: Air kg/s | I24: Air m3/s | J24: Fan shaft kW | K24: Cost proxy Rs | L24: Fill m3
A25: 0 | B25: =r_lgMin+r_lgStep*A25 -> 0.9 | C25: =IF(B25<=r_lgMax+0.000000001,1,0) -> 1 | D25: =IF($D$18-(t_hIn+$B$18*i_range*r_cpw*B25)>0,1/($D$18-(t_hIn+$B$18*i_range*r_cpw*B25)),1000000000)+IF($D$19-(t_hIn+$B$19*i_range*r_cpw*B25)>0,1/($D$19-(t_hIn+$B$19*i_range*r_cpw*B25)),1000000000)+IF($D$20-(t_hIn+$B$20*i_range*r_cpw*B25)>0,1/($D$20-(t_hIn+$B$20*i_range*r_cpw*B25)),1000000000)+IF($D$21-(t_hIn+$B$21*i_range*r_cpw*B25)>0,1/($D$21-(t_hIn+$B$21*i_range*r_cpw*B25)),1000000000) -> 0.15161133 | E25: =i_range*r_cpw/4*D25 -> 0.79330628 | F25: =t_c*B25^(-t_n) -> 1.1208795 | G25: =E25/F25 -> 0.70775337 | H25: =t_flow*1000/3600/B25 -> 186.67134 | I25: =H25/r_rhoAir -> 162.3229 | J25: =IF(t_nat=1,0,I25*INDEX(r_tDp,t_row)/(r_fanEff*1000)) -> 39.27167 | K25: =IF(AND(C25=1,E25<=r_meMax),L25*INDEX(r_fillRate,MATCH(INDEX(r_tFill,t_row),r_fillList,0))+J25*r_fanProxy,"") -> 3304147.2 | L25: =t_plan*G25 -> 30.575711
A26: 1 | B26: =r_lgMin+r_lgStep*A26 -> 0.95 | C26: =IF(B26<=r_lgMax+0.000000001,1,0) -> 1 | D26: =IF($D$18-(t_hIn+$B$18*i_range*r_cpw*B26)>0,1/($D$18-(t_hIn+$B$18*i_range*r_cpw*B26)),1000000000)+IF($D$19-(t_hIn+$B$19*i_range*r_cpw*B26)>0,1/($D$19-(t_hIn+$B$19*i_range*r_cpw*B26)),1000000000)+IF($D$20-(t_hIn+$B$20*i_range*r_cpw*B26)>0,1/($D$20-(t_hIn+$B$20*i_range*r_cpw*B26)),1000000000)+IF($D$21-(t_hIn+$B$21*i_range*r_cpw*B26)>0,1/($D$21-(t_hIn+$B$21*i_range*r_cpw*B26)),1000000000) -> 0.15423132 | E26: =i_range*r_cpw/4*D26 -> 0.80701539 | F26: =t_c*B26^(-t_n) -> 1.0839286 | G26: =E26/F26 -> 0.7445282 | H26: =t_flow*1000/3600/B26 -> 176.84653 | I26: =H26/r_rhoAir -> 153.77959 | J26: =IF(t_nat=1,0,I26*INDEX(r_tDp,t_row)/(r_fanEff*1000)) -> 37.20474 | K26: =IF(AND(C26=1,E26<=r_meMax),L26*INDEX(r_fillRate,MATCH(INDEX(r_tFill,t_row),r_fillList,0))+J26*r_fanProxy,"") -> 3229381.5 | L26: =t_plan*G26 -> 32.164423
A27: 2 | B27: =r_lgMin+r_lgStep*A27 -> 1 | C27: =IF(B27<=r_lgMax+0.000000001,1,0) -> 1 | D27: =IF($D$18-(t_hIn+$B$18*i_range*r_cpw*B27)>0,1/($D$18-(t_hIn+$B$18*i_range*r_cpw*B27)),1000000000)+IF($D$19-(t_hIn+$B$19*i_range*r_cpw*B27)>0,1/($D$19-(t_hIn+$B$19*i_range*r_cpw*B27)),1000000000)+IF($D$20-(t_hIn+$B$20*i_range*r_cpw*B27)>0,1/($D$20-(t_hIn+$B$20*i_range*r_cpw*B27)),1000000000)+IF($D$21-(t_hIn+$B$21*i_range*r_cpw*B27)>0,1/($D$21-(t_hIn+$B$21*i_range*r_cpw*B27)),1000000000) -> 0.15697104 | E27: =i_range*r_cpw/4*D27 -> 0.82135099 | F27: =t_c*B27^(-t_n) -> 1.05 | G27: =E27/F27 -> 0.78223904 | H27: =t_flow*1000/3600/B27 -> 168.0042 | I27: =H27/r_rhoAir -> 146.09061 | J27: =IF(t_nat=1,0,I27*INDEX(r_tDp,t_row)/(r_fanEff*1000)) -> 35.344503 | K27: =IF(AND(C27=1,E27<=r_meMax),L27*INDEX(r_fillRate,MATCH(INDEX(r_tFill,t_row),r_fillList,0))+J27*r_fanProxy,"") -> 3168270.9 | L27: =t_plan*G27 -> 33.793572
A28: 3 | B28: =r_lgMin+r_lgStep*A28 -> 1.05 | C28: =IF(B28<=r_lgMax+0.000000001,1,0) -> 1 | D28: =IF($D$18-(t_hIn+$B$18*i_range*r_cpw*B28)>0,1/($D$18-(t_hIn+$B$18*i_range*r_cpw*B28)),1000000000)+IF($D$19-(t_hIn+$B$19*i_range*r_cpw*B28)>0,1/($D$19-(t_hIn+$B$19*i_range*r_cpw*B28)),1000000000)+IF($D$20-(t_hIn+$B$20*i_range*r_cpw*B28)>0,1/($D$20-(t_hIn+$B$20*i_range*r_cpw*B28)),1000000000)+IF($D$21-(t_hIn+$B$21*i_range*r_cpw*B28)>0,1/($D$21-(t_hIn+$B$21*i_range*r_cpw*B28)),1000000000) -> 0.15983986 | E28: =i_range*r_cpw/4*D28 -> 0.83636207 | F28: =t_c*B28^(-t_n) -> 1.0187132 | G28: =E28/F28 -> 0.82099856 | H28: =t_flow*1000/3600/B28 -> 160.004 | I28: =H28/r_rhoAir -> 139.13392 | J28: =IF(t_nat=1,0,I28*INDEX(r_tDp,t_row)/(r_fanEff*1000)) -> 33.661431 | K28: =IF(AND(C28=1,E28<=r_meMax),L28*INDEX(r_fillRate,MATCH(INDEX(r_tFill,t_row),r_fillList,0))+J28*r_fanProxy,"") -> 3119194.7 | L28: =t_plan*G28 -> 35.468025
A29: 4 | B29: =r_lgMin+r_lgStep*A29 -> 1.1 | C29: =IF(B29<=r_lgMax+0.000000001,1,0) -> 1 | D29: =IF($D$18-(t_hIn+$B$18*i_range*r_cpw*B29)>0,1/($D$18-(t_hIn+$B$18*i_range*r_cpw*B29)),1000000000)+IF($D$19-(t_hIn+$B$19*i_range*r_cpw*B29)>0,1/($D$19-(t_hIn+$B$19*i_range*r_cpw*B29)),1000000000)+IF($D$20-(t_hIn+$B$20*i_range*r_cpw*B29)>0,1/($D$20-(t_hIn+$B$20*i_range*r_cpw*B29)),1000000000)+IF($D$21-(t_hIn+$B$21*i_range*r_cpw*B29)>0,1/($D$21-(t_hIn+$B$21*i_range*r_cpw*B29)),1000000000) -> 0.16284819 | E29: =i_range*r_cpw/4*D29 -> 0.85210316 | F29: =t_c*B29^(-t_n) -> 0.98975074 | G29: =E29/F29 -> 0.86092702 | H29: =t_flow*1000/3600/B29 -> 152.73109 | I29: =H29/r_rhoAir -> 132.80965 | J29: =IF(t_nat=1,0,I29*INDEX(r_tDp,t_row)/(r_fanEff*1000)) -> 32.131366 | K29: =IF(AND(C29=1,E29<=r_meMax),L29*INDEX(r_fillRate,MATCH(INDEX(r_tFill,t_row),r_fillList,0))+J29*r_fanProxy,"") -> 3080864.3 | L29: =t_plan*G29 -> 37.192978
A30: 5 | B30: =r_lgMin+r_lgStep*A30 -> 1.15 | C30: =IF(B30<=r_lgMax+0.000000001,1,0) -> 1 | D30: =IF($D$18-(t_hIn+$B$18*i_range*r_cpw*B30)>0,1/($D$18-(t_hIn+$B$18*i_range*r_cpw*B30)),1000000000)+IF($D$19-(t_hIn+$B$19*i_range*r_cpw*B30)>0,1/($D$19-(t_hIn+$B$19*i_range*r_cpw*B30)),1000000000)+IF($D$20-(t_hIn+$B$20*i_range*r_cpw*B30)>0,1/($D$20-(t_hIn+$B$20*i_range*r_cpw*B30)),1000000000)+IF($D$21-(t_hIn+$B$21*i_range*r_cpw*B30)>0,1/($D$21-(t_hIn+$B$21*i_range*r_cpw*B30)),1000000000) -> 0.16600768 | E30: =i_range*r_cpw/4*D30 -> 0.8686352 | F30: =t_c*B30^(-t_n) -> 0.96284557 | G30: =E30/F30 -> 0.90215423 | H30: =t_flow*1000/3600/B30 -> 146.09061 | I30: =H30/r_rhoAir -> 127.03531 | J30: =IF(t_nat=1,0,I30*INDEX(r_tDp,t_row)/(r_fanEff*1000)) -> 30.73435 | K30: =IF(AND(C30=1,E30<=r_meMax),L30*INDEX(r_fillRate,MATCH(INDEX(r_tFill,t_row),r_fillList,0))+J30*r_fanProxy,"") -> 3052256.2 | L30: =t_plan*G30 -> 38.974038
A31: 6 | B31: =r_lgMin+r_lgStep*A31 -> 1.2 | C31: =IF(B31<=r_lgMax+0.000000001,1,0) -> 1 | D31: =IF($D$18-(t_hIn+$B$18*i_range*r_cpw*B31)>0,1/($D$18-(t_hIn+$B$18*i_range*r_cpw*B31)),1000000000)+IF($D$19-(t_hIn+$B$19*i_range*r_cpw*B31)>0,1/($D$19-(t_hIn+$B$19*i_range*r_cpw*B31)),1000000000)+IF($D$20-(t_hIn+$B$20*i_range*r_cpw*B31)>0,1/($D$20-(t_hIn+$B$20*i_range*r_cpw*B31)),1000000000)+IF($D$21-(t_hIn+$B$21*i_range*r_cpw*B31)>0,1/($D$21-(t_hIn+$B$21*i_range*r_cpw*B31)),1000000000) -> 0.1693314 | E31: =i_range*r_cpw/4*D31 -> 0.88602656 | F31: =t_c*B31^(-t_n) -> 0.93777128 | G31: =E31/F31 -> 0.9448216 | H31: =t_flow*1000/3600/B31 -> 140.0035 | I31: =H31/r_rhoAir -> 121.74218 | J31: =IF(t_nat=1,0,I31*INDEX(r_tDp,t_row)/(r_fanEff*1000)) -> 29.453752 | K31: =IF(AND(C31=1,E31<=r_meMax),L31*INDEX(r_fillRate,MATCH(INDEX(r_tFill,t_row),r_fillList,0))+J31*r_fanProxy,"") -> 3032561.9 | L31: =t_plan*G31 -> 40.817314
A32: 7 | B32: =r_lgMin+r_lgStep*A32 -> 1.25 | C32: =IF(B32<=r_lgMax+0.000000001,1,0) -> 1 | D32: =IF($D$18-(t_hIn+$B$18*i_range*r_cpw*B32)>0,1/($D$18-(t_hIn+$B$18*i_range*r_cpw*B32)),1000000000)+IF($D$19-(t_hIn+$B$19*i_range*r_cpw*B32)>0,1/($D$19-(t_hIn+$B$19*i_range*r_cpw*B32)),1000000000)+IF($D$20-(t_hIn+$B$20*i_range*r_cpw*B32)>0,1/($D$20-(t_hIn+$B$20*i_range*r_cpw*B32)),1000000000)+IF($D$21-(t_hIn+$B$21*i_range*r_cpw*B32)>0,1/($D$21-(t_hIn+$B$21*i_range*r_cpw*B32)),1000000000) -> 0.17283405 | E32: =i_range*r_cpw/4*D32 -> 0.90435418 | F32: =t_c*B32^(-t_n) -> 0.91433447 | G32: =E32/F32 -> 0.98908464 | H32: =t_flow*1000/3600/B32 -> 134.40336 | I32: =H32/r_rhoAir -> 116.87249 | J32: =IF(t_nat=1,0,I32*INDEX(r_tDp,t_row)/(r_fanEff*1000)) -> 28.275602 | K32: =IF(AND(C32=1,E32<=r_meMax),L32*INDEX(r_fillRate,MATCH(INDEX(r_tFill,t_row),r_fillList,0))+J32*r_fanProxy,"") -> 3021151.4 | L32: =t_plan*G32 -> 42.729526
A33: 8 | B33: =r_lgMin+r_lgStep*A33 -> 1.3 | C33: =IF(B33<=r_lgMax+0.000000001,1,0) -> 1 | D33: =IF($D$18-(t_hIn+$B$18*i_range*r_cpw*B33)>0,1/($D$18-(t_hIn+$B$18*i_range*r_cpw*B33)),1000000000)+IF($D$19-(t_hIn+$B$19*i_range*r_cpw*B33)>0,1/($D$19-(t_hIn+$B$19*i_range*r_cpw*B33)),1000000000)+IF($D$20-(t_hIn+$B$20*i_range*r_cpw*B33)>0,1/($D$20-(t_hIn+$B$20*i_range*r_cpw*B33)),1000000000)+IF($D$21-(t_hIn+$B$21*i_range*r_cpw*B33)>0,1/($D$21-(t_hIn+$B$21*i_range*r_cpw*B33)),1000000000) -> 0.17653227 | E33: =i_range*r_cpw/4*D33 -> 0.92370511 | F33: =t_c*B33^(-t_n) -> 0.89236889 | G33: =E33/F33 -> 1.0351158 | H33: =t_flow*1000/3600/B33 -> 129.234 | I33: =H33/r_rhoAir -> 112.37739 | J33: =IF(t_nat=1,0,I33*INDEX(r_tDp,t_row)/(r_fanEff*1000)) -> 27.188079 | K33: =IF(AND(C33=1,E33<=r_meMax),L33*INDEX(r_fillRate,MATCH(INDEX(r_tFill,t_row),r_fillList,0))+J33*r_fanProxy,"") -> 3017546.5 | L33: =t_plan*G33 -> 44.71812
A34: 9 | B34: =r_lgMin+r_lgStep*A34 -> 1.35 | C34: =IF(B34<=r_lgMax+0.000000001,1,0) -> 1 | D34: =IF($D$18-(t_hIn+$B$18*i_range*r_cpw*B34)>0,1/($D$18-(t_hIn+$B$18*i_range*r_cpw*B34)),1000000000)+IF($D$19-(t_hIn+$B$19*i_range*r_cpw*B34)>0,1/($D$19-(t_hIn+$B$19*i_range*r_cpw*B34)),1000000000)+IF($D$20-(t_hIn+$B$20*i_range*r_cpw*B34)>0,1/($D$20-(t_hIn+$B$20*i_range*r_cpw*B34)),1000000000)+IF($D$21-(t_hIn+$B$21*i_range*r_cpw*B34)>0,1/($D$21-(t_hIn+$B$21*i_range*r_cpw*B34)),1000000000) -> 0.18044496 | E34: =i_range*r_cpw/4*D34 -> 0.94417828 | F34: =t_c*B34^(-t_n) -> 0.87173074 | G34: =E34/F34 -> 1.0831077 | H34: =t_flow*1000/3600/B34 -> 124.44756 | I34: =H34/r_rhoAir -> 108.21527 | J34: =IF(t_nat=1,0,I34*INDEX(r_tDp,t_row)/(r_fanEff*1000)) -> 26.181113 | K34: =IF(AND(C34=1,E34<=r_meMax),L34*INDEX(r_fillRate,MATCH(INDEX(r_tFill,t_row),r_fillList,0))+J34*r_fanProxy,"") -> 3021400.9 | L34: =t_plan*G34 -> 46.791423
A35: 10 | B35: =r_lgMin+r_lgStep*A35 -> 1.4 | C35: =IF(B35<=r_lgMax+0.000000001,1,0) -> 1 | D35: =IF($D$18-(t_hIn+$B$18*i_range*r_cpw*B35)>0,1/($D$18-(t_hIn+$B$18*i_range*r_cpw*B35)),1000000000)+IF($D$19-(t_hIn+$B$19*i_range*r_cpw*B35)>0,1/($D$19-(t_hIn+$B$19*i_range*r_cpw*B35)),1000000000)+IF($D$20-(t_hIn+$B$20*i_range*r_cpw*B35)>0,1/($D$20-(t_hIn+$B$20*i_range*r_cpw*B35)),1000000000)+IF($D$21-(t_hIn+$B$21*i_range*r_cpw*B35)>0,1/($D$21-(t_hIn+$B$21*i_range*r_cpw*B35)),1000000000) -> 0.18459372 | E35: =i_range*r_cpw/4*D35 -> 0.96588662 | F35: =t_c*B35^(-t_n) -> 0.85229495 | G35: =E35/F35 -> 1.1332774 | H35: =t_flow*1000/3600/B35 -> 120.003 | I35: =H35/r_rhoAir -> 104.35044 | J35: =IF(t_nat=1,0,I35*INDEX(r_tDp,t_row)/(r_fanEff*1000)) -> 25.246073 | K35: =IF(AND(C35=1,E35<=r_meMax),L35*INDEX(r_fillRate,MATCH(INDEX(r_tFill,t_row),r_fillList,0))+J35*r_fanProxy,"") -> 3032487.5 | L35: =t_plan*G35 -> 48.958809
A36: 11 | B36: =r_lgMin+r_lgStep*A36 -> 1.45 | C36: =IF(B36<=r_lgMax+0.000000001,1,0) -> 1 | D36: =IF($D$18-(t_hIn+$B$18*i_range*r_cpw*B36)>0,1/($D$18-(t_hIn+$B$18*i_range*r_cpw*B36)),1000000000)+IF($D$19-(t_hIn+$B$19*i_range*r_cpw*B36)>0,1/($D$19-(t_hIn+$B$19*i_range*r_cpw*B36)),1000000000)+IF($D$20-(t_hIn+$B$20*i_range*r_cpw*B36)>0,1/($D$20-(t_hIn+$B$20*i_range*r_cpw*B36)),1000000000)+IF($D$21-(t_hIn+$B$21*i_range*r_cpw*B36)>0,1/($D$21-(t_hIn+$B$21*i_range*r_cpw*B36)),1000000000) -> 0.18900332 | E36: =i_range*r_cpw/4*D36 -> 0.98895985 | F36: =t_c*B36^(-t_n) -> 0.83395216 | G36: =E36/F36 -> 1.1858712 | H36: =t_flow*1000/3600/B36 -> 115.86497 | I36: =H36/r_rhoAir -> 100.75215 | J36: =IF(t_nat=1,0,I36*INDEX(r_tDp,t_row)/(r_fanEff*1000)) -> 24.375519 | K36: =IF(AND(C36=1,E36<=r_meMax),L36*INDEX(r_fillRate,MATCH(INDEX(r_tFill,t_row),r_fillList,0))+J36*r_fanProxy,"") -> 3050689.6 | L36: =t_plan*G36 -> 51.230918
... A49: 24 | B49: =r_lgMin+r_lgStep*A49 -> 2.1 | C49: =IF(B49<=r_lgMax+0.000000001,1,0) -> 1 | D49: =IF($D$18-(t_hIn+$B$18*i_range*r_cpw*B49)>0,1/($D$18-(t_hIn+$B$18*i_range*r_cpw*B49)),1000000000)+IF($D$19-(t_hIn+$B$19*i_range*r_cpw*B49)>0,1/($D$19-(t_hIn+$B$19*i_range*r_cpw*B49)),1000000000)+IF($D$20-(t_hIn+$B$20*i_range*r_cpw*B49)>0,1/($D$20-(t_hIn+$B$20*i_range*r_cpw*B49)),1000000000)+IF($D$21-(t_hIn+$B$21*i_range*r_cpw*B49)>0,1/($D$21-(t_hIn+$B$21*i_range*r_cpw*B49)),1000000000) -> 0.29528008 | E49: =i_range*r_cpw/4*D49 -> 1.545053 | F49: =t_c*B49^(-t_n) -> 0.66284706 | G49: =E49/F49 -> 2.3309344 | H49: =t_flow*1000/3600/B49 -> 80.002002 | I49: =H49/r_rhoAir -> 69.566958 | J49: =IF(t_nat=1,0,I49*INDEX(r_tDp,t_row)/(r_fanEff*1000)) -> 16.830716 | K49: =IF(AND(C49=1,E49<=r_meMax),L49*INDEX(r_fillRate,MATCH(INDEX(r_tFill,t_row),r_fillList,0))+J49*r_fanProxy,"") -> 4131508.4 | L49: =t_plan*G49 -> 100.69889
A51: Selected L/G
A52: Best step (first minimum cost) | B52: =MATCH(MIN(K25:K49),K25:K49,0) -> 9
A53: L/G | B53: =INDEX(B25:B49,t_best) -> 1.3
A54: Merkel demand | B54: =INDEX(E25:E49,t_best) -> 0.92370511
A55: Fill depth before clamping m | B55: =INDEX(G25:G49,t_best) -> 1.0351158
A56: Fill depth used m | B56: =MIN(MAX(t_depthRaw,r_depthMin),r_depthMax*r_depthMult) -> 1.0351158
...

Sheet Costing
A1: Geometry and priced build-up
A2: Quantities from the thermal sizing; rates from Rates.
A4: Number of cells | B4: =MAX(1,ROUNDUP(t_flow/INDEX(r_tCell,t_row),0)) -> 1
A5: Plan area per cell m2 | B5: =t_plan/g_cells -> 43.201081
A6: Cell side m | B6: =SQRT(g_planCell) -> 6.5727529
A7: Height m | B7: =t_depth+r_hBase+IF(t_nat=1,0,r_hFan)+IF(INDEX(r_tCasing,t_row)="RCC",r_hRcc,0) -> 3.9351158
A8: Motor per cell kW | B8: =IF(t_nat=1,0,ROUNDUP(t_fanKw*r_motorMargin/g_cells*2,0)/2) -> 31.5
A9: Fan diameter m | B9: =IF(t_nat=1,0,SQRT(4*(t_airM3s/g_cells)/(PI()*r_velocity))) -> 4.4578791
A10: Perimeter m (all cells) | B10: =4*g_side*g_cells -> 26.291012
A11: Louvre face m2 | B11: =g_perim*(t_depth+r_faceAdd) -> 42.988848
A12: Casing | B12: =INDEX(r_tCasing,t_row) -> FRP
A13: Fill | B13: =INDEX(r_tFill,t_row) -> Film PVC
A15: Item | B15: Qty | C15: Unit | D15: Rate Rs | E15: Amount Rs | F15: Group
A16: Fill, installed | B16: =t_fillM3 -> 44.71812 | C16: m3 | D16: =INDEX(r_fillRate,MATCH(g_fill,r_fillList,0)) -> 31000 | E16: =B16*D16 -> 1386261.7 | F16: Fill & drift
A17: Drift eliminators | B17: =t_plan -> 43.201081 | C17: m2 | D17: =r_eliminator -> 2300 | E17: =B17*D17 -> 99362.486 | F17: Fill & drift
A18: Water distribution headers and nozzles | B18: =t_plan -> 43.201081 | C18: m2 | D18: =r_distribution -> 4200 | E18: =B18*D18 -> 181444.54 | F18: Fill & drift
A19: FRP casing, panels and framing | B19: =IF(g_casing="FRP",g_perim*g_height+t_plan,0) -> 146.65926 | C19: m2 | D19: =r_frpPerM2 -> 5200 | E19: =B19*D19 -> 762628.13 | F19: Casing, structure & basin
A20: Cold-water basin, FRP | B20: =IF(g_casing="FRP",t_plan,0) -> 43.201081 | C20: m2 | D20: =r_basinFrp -> 3600 | E20: =B20*D20 -> 155523.89 | F20: Casing, structure & basin
A21: Hot-dip galvanised structure and casing | B21: =IF(g_casing="HDG steel",t_plan*r_hdgKg*(g_height/r_hdgRefH),0) -> 0 | C21: kg | D21: =r_hdgRate -> 108 | E21: =B21*D21 -> 0 | F21: Casing, structure & basin
A22: Steel basin and sheeting | B22: =IF(g_casing="HDG steel",t_plan*r_basinSteel,0) -> 0 | C22: kg | D22: =r_hdgRate*r_basinSteelF -> 97.2 | E22: =B22*D22 -> 0 | F22: Casing, structure & basin
A23: RCC shell, columns, fan deck and basin | B23: =IF(g_casing="RCC",t_plan*r_rccM3*IF(t_nat=1,r_natRcc,1),0) -> 0 | C23: m3 | D23: =r_rccPerM3 -> 9800 | E23: =B23*D23 -> 0 | F23: Casing, structure & basin
A24: Air-inlet louvres | B24: =g_face -> 42.988848 | C24: m2 | D24: =r_louvre -> 1900 | E24: =B24*D24 -> 81678.811 | F24: Casing, structure & basin
A25: Axial fans (each) | B25: =IF(t_nat=1,0,g_cells) -> 1 | C25: nos | D25: =r_fanBase*g_fanDia^r_fanExp -> 618985.12 | E25: =B25*D25 -> 618985.12 | F25: Fans & drives
A26: Gearbox and drive shaft | B26: =g_motorKw*g_cells -> 31.5 | C26: kW | D26: =r_gearbox -> 5200 | E26: =B26*D26 -> 163800 | F26: Fans & drives
A27: Fan motors, IE3 | B27: =g_motorKw*g_cells -> 31.5 | C27: kW | D27: =r_motor -> 4300 | E27: =B27*D27 -> 135450 | F27: Fans & drives
A28: VFDs | B28: =IF(i_vfd="Yes",g_motorKw*g_cells,0) -> 0 | C28: kW | D28: =r_vfd -> 7500 | E28: =B28*D28 -> 0 | F28: Fans & drives
A29: Ladders, handrails, level and make-up controls | B29: =g_cells -> 1 | C29: cells | D29: =r_accessories -> 90000 | E29: =B29*D29 -> 90000 | F29: Accessories
A30: Vibration switches | B30: =g_cells -> 1 | C30: nos | D30: =r_vib -> 28000 | E30: =B30*D30 -> 28000 | F30: Accessories
A31: Material subtotal | E31: =SUM(E16:E30) -> 3703134.7
A32: Erection and assembly labour | B32: 1 | C32: lot | D32: =E31*r_labour -> 592501.55 | E32: =B32*D32 -> 592501.55 | F32: Assembly & supply
A33: Transport to site | B33: 1 | C33: lot | D33: =E31*r_transport -> 92578.368 | E33: =B33*D33 -> 92578.368 | F33: Assembly & supply
A34: Direct cost | E34: =E31+E32+E33 -> 4388214.6
A35: Overheads | E35: =E34*r_overheads -> 351057.17
A36: Margin | E36: =(E34+E35)*r_margin -> 379141.74
A37: SHOULD-COST, ex-works (Rs) | E37: =E34+E35+E36 -> 5118413.6

Sheet Rates
A1: Rates and constants
A2: Blue = assumption. Each value is a named cell (r_...).
A5: Tower types
A6: Type | B6: Fill | C6: c (KaV/L per m) | D6: n | E6: Loading m3/h per m2 | F6: Fan dP Pa | G6: Casing | H6: Max cell m3/h | I6: Natural (1)
A7: Counterflow, induced draught, FRP | B7: Film PVC | C7: 1.05 | D7: 0.62 | E7: 14 | F7: 150 | G7: FRP | H7: 700 | I7: 0
A8: Crossflow, induced draught, FRP | B8: Splash / low-clog film | C8: 0.8 | D8: 0.58 | E8: 12 | F8: 110 | G8: FRP | H8: 600 | I8: 0
A9: Counterflow, induced draught, RCC | B9: Film PVC | C9: 1.05 | D9: 0.62 | E9: 14 | F9: 150 | G9: RCC | H9: 3500 | I9: 0
A10: Counterflow, induced draught, HDG steel | B10: Film PVC | C10: 1.05 | D10: 0.62 | E10: 14 | F10: 150 | G10: HDG steel | H10: 1200 | I10: 0
A11: Natural draught, hyperbolic (RCC) | B11: Film PVC | C11: 1 | D11: 0.6 | E11: 10 | F11: 0 | G11: RCC | H11: 60000 | I11: 1
A13: Fill rates, installed
A14: Film PVC | B14: 31000 | C14: Rs/m3
A15: Splash / low-clog film | B15: 17000 | C15: Rs/m3
A17: Psychrometrics and L/G scan
A18: Barometric pressure | B18: 101.325 | C18: kPa
A19: L/G scan minimum | B19: 0.9
A20: L/G scan maximum | B20: 2.1
A21: L/G step | B21: 0.05
A22: Specific heat of water | B22: 4.186 | C22: kJ/kg K
A23: Heat to flow: kW per (m3/h x K) | B23: 1.163
A24: Air density at fan | B24: 1.15 | C24: kg/m3
A25: Maximum Merkel number considered | B25: 25
A26: Minimum fill depth | B26: 0.9 | C26: m
A27: Maximum fill depth | B27: 1.8 | C27: m
A28: Clamp multiple of maximum depth | B28: 2.2 | C28: x
A29: Fan cost proxy in the L/G choice | B29: 60000 | C29: Rs per shaft kW
A31: Fill, drift and distribution
A32: Drift eliminators | B32: 2300 | C32: Rs/m2 plan
A33: Water distribution headers and nozzles | B33: 4200 | C33: Rs/m2 plan
A34: Air-inlet louvres | B34: 1900 | C34: Rs/m2 face
A35: Louvre height beyond fill depth | B35: 0.6 | C35: m
A37: Casing, structure and basin
A38: FRP casing, panels, framing | B38: 5200 | C38: Rs/m2
A39: Cold-water basin, FRP | B39: 3600 | C39: Rs/m2 plan
A40: Hot-dip galvanised steel | B40: 108 | C40: Rs/kg
A41: Steel per m2 plan at 8 m height | B41: 85 | C41: kg/m2
A42: Reference height for steel | B42: 8 | C42: m
A43: Steel basin and sheeting | B43: 70 | C43: kg/m2 plan
A44: Basin steel price factor | B44: 0.9 | C44: x
A45: RCC | B45: 9800 | C45: Rs/m3
A46: RCC per m2 plan | B46: 0.55 | C46: m3/m2
...

Sheet Presets
A1: Sample towers (copy the values into Inputs)
A4: Tower | B4: kW | C4: Range K | D4: Approach K | E4: Wet-bulb | F4: Type | G4: VFD
A5: CT-01 1,000 TR chiller plant (FRP) | B5: 3517 | C5: 5 | D5: 4 | E5: 28 | F5: Counterflow, induced draught, FRP | G5: No
A6: CT-02 3,000 TR plant (FRP, VFD) | B6: 10551 | C6: 5 | D6: 4 | E6: 28 | F6: Counterflow, induced draught, FRP | G6: Yes
A7: CT-03 Process, steel (HDG) | B7: 6000 | C7: 8 | D7: 5 | E7: 27 | F7: Counterflow, induced draught, HDG steel | G7: No
A8: CT-04 Power plant, RCC | B8: 60000 | C8: 10 | D8: 7 | E8: 28 | F8: Counterflow, induced draught, RCC | G8: No
A9: CT-05 Small crossflow (FRP) | B9: 800 | C9: 5 | D9: 4.5 | E9: 28 | F9: Crossflow, induced draught, FRP | G9: No
