Workbook

Sheet Read Me
A1: HT switchgear board: should-cost model
A2: Bottom-up cost of a switchboard from its bay schedule. Not a vendor price list: every rate is an editable assumption.
A4: Purpose | B4: Estimate the ex-works price of a 3.3-33 kV metal-clad VCB board from the schedule of bays. Each bay is costed from its sheet steel, switching device, instrument transformers, protection, wiring and test; the board adds the main busbar, DC system, labour, test, packing, overheads and margin.
A5: How to use | B5: Edit the yellow cells on Inputs (board rating and the bay schedule) and, if you have quotes, on Rates. Everything else is a live formula. Results are on Summary; the per-bay build-up is on Bay Costing.
A6: Sheets | B6: Inputs: board specification and bay schedule. Rates: every price, constant and multiplier (named cells, prefix r_). Bay Costing: cost per bay type and board-level items. Summary: cost stack, per-bay and per-ampere figures. Presets: three sample boards to copy into Inputs.
A7: Conventions | B7: Yellow fill = input. Blue font = a typed assumption you may change. Black = formula. Green fill = key output. All amounts are Indian rupees, ex-GST, ex-works.
A8: Basis of the numbers | B8: Device prices scale with rating from an assumed base price: VCB = base(kV) x (A/1250)^0.45 x (kA/25)^0.5. Panel steel, CT, VT and surge-arrester prices are tabulated by voltage class. Steel, copper and aluminium follow commodity prices you type into Rates.
A9: Reasonableness | B9: About Rs 8-10 lakh per 11 kV panel and Rs 20-25 lakh per 33 kV panel at the default rates. These are market ranges, not quotations. Calibrate Rates with two or three recent offers before relying on a figure.
A10: Limits | B10: Single board per workbook (copy the file for another). Busbar sized by current density only (no short-circuit or temperature-rise check). No GST, freight to site, erection or civil work. Fault levels above 40 kA need manufacturer confirmation.
A11: Companion | B11: The same model runs interactively in the Should-Cost dashboards (switchgear.html), with a 3D view and a month selector for the commodity prices.

Sheet Inputs
A1: HT board: specification and bay schedule
A4: Tag / board name | B4: HT-01 11 kV plant board, 13 panels
A5: System voltage | B5: 11 | C5: kV
A6: Busbar rating | B6: 1250 | C6: A
A7: Fault level (3 s) | B7: 25 | C7: kA
A8: Degree of protection | B8: IP42
A9: Arc-fault protection (IAC) | B9: No
A10: Protection relay | B10: Numeric O/C + E/F | D10: pick from list
A13: Bay schedule
A14: Bay type | B14: Quantity | C14: Size | D14: Unit
A15: Incomer VCB panel | B15: 2 | C15: 1250 | D15: A
A16: Outgoing feeder VCB panel | B16: 6 | C16: 630 | D16: A
A17: Bus coupler VCB panel | B17: 1 | C17: 1250 | D17: A
A18: Motor feeder VCB panel | B18: 2 | C18: 400 | D18: A
A19: Bus PT, metering and surge-arrester panel | B19: 2
A21: Size: rated current (A) for breakers and feeders, motor kW for starters, kVAr for APFC banks. Quantity 0 removes a bay type.

Sheet Summary
A1: HT board: should-cost summary
A3: =Inputs!B4 -> HT-01 11 kV plant board, 13 panels
A5: Cost group | B5: Rs | C5: Share | D5: Note
A6: Enclosure & structure | B6: =SUMPRODUCT('Bay Costing'!B5:B9,'Bay Costing'!E5:E9+'Bay Costing'!F5:F9+'Bay Costing'!G5:G9) -> 886939.2 | C6: =B6/B$15 -> 0.07990292 | D6: Sheet steel, pre-treatment, powder coat, doors
A7: Busbars & insulation | B7: =SUMIF('Bay Costing'!J13:J21,"Busbars & insulation",'Bay Costing'!I13:I21) -> 841691.91 | C7: =B7/B$15 -> 0.075826665 | D7: Main (and vertical) busbar, sleeving
A8: Switching devices | B8: =SUMPRODUCT('Bay Costing'!B5:B9,'Bay Costing'!H5:H9) -> 3818683.4 | C8: =B8/B$15 -> 0.34401902 | D8: VCBs
A9: Protection & metering | B9: =SUMPRODUCT('Bay Costing'!B5:B9,'Bay Costing'!I5:I9+'Bay Costing'!J5:J9+'Bay Costing'!K5:K9) -> 1482500 | C9: =B9/B$15 -> 0.13355603 | D9: CTs, VTs, relays, meters, arresters
A10: Wiring & auxiliaries | B10: =SUMPRODUCT('Bay Costing'!B5:B9,'Bay Costing'!L5:L9)+SUMIF('Bay Costing'!J13:J21,"Wiring & auxiliaries",'Bay Costing'!I13:I21) -> 1013700 | C10: =B10/B$15 -> 0.091322596 | D10: Control wiring, interlocks, DC system, arc detection
A11: Assembly, test, packing & transport | B11: =SUMIF('Bay Costing'!J13:J21,"Assembly & test",'Bay Costing'!I13:I21) -> 1214375.4 | C11: =B11/B$15 -> 0.10940112 | D11: Labour, routine and type tests, packing
A12: Direct cost | B12: =SUM(B6:B11) -> 9257889.9 | C12: =B12/B$15 -> 0.83402836
A13: Overheads | B13: =B12*r_overheads -> 833210.09 | C13: =B13/B$15 -> 0.075062552
A14: Margin | B14: =(B12+B13)*r_margin -> 1009110 | C14: =B14/B$15 -> 0.090909091
A15: SHOULD-COST, ex-works (Rs) | B15: =B12+B13+B14 -> 11100210 | C15: =B15/B$15 -> 1
A16: Should-cost (Rs crore) | B16: =B15/10000000 -> 1.110021
A17: Number of bays (units) | B17: ='Bay Costing'!B27 -> 13
A18: Cost per bay (Rs) | B18: =B15/B17 -> 853862.31
A19: Cost per ampere of busbar (Rs/A) | B19: =B15/Inputs!B6 -> 8880.168
A20: Sheet steel (kg) | B20: ='Bay Costing'!B32 -> 8820
A21: Busbar mass (kg) | B21: ='Bay Costing'!B13 -> 542.34375
A23: Checks
A24: Largest bay rating within the busbar rating? | B24: =IF(MAX(Inputs!C15*(Inputs!B15>0),Inputs!C16*(Inputs!B16>0),Inputs!C17*(Inputs!B17>0),Inputs!C18*(Inputs!B18>0))<=Inputs!B6,"OK","CHECK: a bay exceeds the busbar") -> OK
A25: Fault level within the usual range? | B25: =IF(Inputs!B7<=40,"OK","CHECK: confirm with manufacturer") -> OK

Sheet Bay Costing
A1: Cost per bay and board-level items
A2: Rows follow the bay schedule on Inputs. Rs per bay unless stated.
A3: Enclosure multiplier (IP x form x arc) | E3: =INDEX(r_ipMult,MATCH(i_ip,r_ipList,0))*IF(i_arc="Yes",r_arcMult,1) -> 1
A4: Bay type | B4: Qty | C4: Size A | D4: Steel kg / bay | E4: Sheet steel | F4: Powder coat | G4: Gaskets, doors | H4: VCB | I4: CT set | J4: Relay and meter | K4: VT / arrester | L4: Aux + wiring | M4: Total per bay | N4: Total (qty x)
A5: Incomer VCB panel | B5: =Inputs!B15 -> 2 | C5: =Inputs!C15 -> 1250 | D5: =INDEX(r_panelKg,MATCH(i_kv,r_kvList,0))*1*IF(C5>1600,1.15,1)*c_mult -> 700 | E5: =D5*r_crca -> 53200 | F5: =D5*r_powder -> 9800 | G5: =D5*(r_gasket+r_hdwr*r_crca) -> 7392 | H5: =INDEX(r_vcbBase,MATCH(i_kv,r_kvList,0))*(C5/1250)^r_vcbAmpExp*(i_kA/25)^r_vcbKaExp -> 450000 | I5: =INDEX(r_ctSet,MATCH(i_kv,r_kvList,0))*(1+r_ctKaGrow*(i_kA/25-1)) -> 34000 | J5: =INDEX(r_relayRate,MATCH(i_relay,r_relayList,0))*r_ccMult+r_meterHt -> 69500 | K5: =INDEX(r_vtSet,MATCH(i_kv,r_kvList,0))*r_vtIncF -> 62400 | L5: =r_htAux*IF(i_kv>=22,r_htAux22,1)+r_wiring*r_wiringF -> 48400 | M5: =SUM(E5:L5) -> 734692 | N5: =B5*M5 -> 1469384
A6: Outgoing feeder VCB panel | B6: =Inputs!B16 -> 6 | C6: =Inputs!C16 -> 630 | D6: =INDEX(r_panelKg,MATCH(i_kv,r_kvList,0))*1*IF(C6>1600,1.15,1)*c_mult -> 700 | E6: =D6*r_crca -> 53200 | F6: =D6*r_powder -> 9800 | G6: =D6*(r_gasket+r_hdwr*r_crca) -> 7392 | H6: =INDEX(r_vcbBase,MATCH(i_kv,r_kvList,0))*(C6/1250)^r_vcbAmpExp*(i_kA/25)^r_vcbKaExp -> 330602.59 | I6: =INDEX(r_ctSet,MATCH(i_kv,r_kvList,0))*(1+r_ctKaGrow*(i_kA/25-1)) -> 34000 | J6: =INDEX(r_relayRate,MATCH(i_relay,r_relayList,0))*1+r_meterHt -> 60000 | K6: 0 | L6: =r_htAux*IF(i_kv>=22,r_htAux22,1)+r_wiring*r_wiringF -> 48400 | M6: =SUM(E6:L6) -> 543394.59 | N6: =B6*M6 -> 3260367.6
A7: Bus coupler VCB panel | B7: =Inputs!B17 -> 1 | C7: =Inputs!C17 -> 1250 | D7: =INDEX(r_panelKg,MATCH(i_kv,r_kvList,0))*1*IF(C7>1600,1.15,1)*c_mult -> 700 | E7: =D7*r_crca -> 53200 | F7: =D7*r_powder -> 9800 | G7: =D7*(r_gasket+r_hdwr*r_crca) -> 7392 | H7: =INDEX(r_vcbBase,MATCH(i_kv,r_kvList,0))*(C7/1250)^r_vcbAmpExp*(i_kA/25)^r_vcbKaExp -> 450000 | I7: =INDEX(r_ctSet,MATCH(i_kv,r_kvList,0))*(1+r_ctKaGrow*(i_kA/25-1)) -> 34000 | J7: =INDEX(r_relayRate,MATCH(i_relay,r_relayList,0))*r_ccMult+r_meterHt -> 69500 | K7: 0 | L7: =r_htAux*IF(i_kv>=22,r_htAux22,1)+r_wiring*r_wiringF -> 48400 | M7: =SUM(E7:L7) -> 672292 | N7: =B7*M7 -> 672292
A8: Motor feeder VCB panel | B8: =Inputs!B18 -> 2 | C8: =Inputs!C18 -> 400 | D8: =INDEX(r_panelKg,MATCH(i_kv,r_kvList,0))*1*IF(C8>1600,1.15,1)*c_mult -> 700 | E8: =D8*r_crca -> 53200 | F8: =D8*r_powder -> 9800 | G8: =D8*(r_gasket+r_hdwr*r_crca) -> 7392 | H8: =INDEX(r_vcbBase,MATCH(i_kv,r_kvList,0))*(C8/1250)^r_vcbAmpExp*(i_kA/25)^r_vcbKaExp*r_mtrDisc -> 242533.94 | I8: =INDEX(r_ctSet,MATCH(i_kv,r_kvList,0))*(1+r_ctKaGrow*(i_kA/25-1)) -> 34000 | J8: =INDEX(r_relayRate,MATCH(i_relay,r_relayList,0))*1+r_meterHt -> 60000 | K8: 0 | L8: =r_htAux*IF(i_kv>=22,r_htAux22,1)+r_wiring*r_wiringF -> 48400 | M8: =SUM(E8:L8) -> 455325.94 | N8: =B8*M8 -> 910651.87
A9: Bus PT, metering and surge-arrester panel | B9: =Inputs!B19 -> 2 | C9: 0 | D9: =INDEX(r_panelKg,MATCH(i_kv,r_kvList,0))*0.8*IF(C9>1600,1.15,1)*c_mult -> 560 | E9: =D9*r_crca -> 42560 | F9: =D9*r_powder -> 7840 | G9: =D9*(r_gasket+r_hdwr*r_crca) -> 5913.6 | H9: 0 | I9: 0 | J9: =INDEX(r_relayRate,MATCH(i_relay,r_relayList,0))*r_ptRelayF+r_meterHt -> 48600 | K9: =INDEX(r_vtSet,MATCH(i_kv,r_kvList,0))+INDEX(r_laSet,MATCH(i_kv,r_kvList,0)) -> 99000 | L9: =r_wiring*r_wiringF -> 10400 | M9: =SUM(E9:L9) -> 214313.6 | N9: =B9*M9 -> 428627.2
A11: Board-level items
A12: Item | B12: Qty | C12: Unit | E12: Rate Rs | I12: Amount Rs | J12: Group
A13: Main busbar (copper) | B13: =3*B31*B30*8.9/1000 -> 542.34375 | C13: kg | E13: =r_copper+r_busFab -> 1495 | I13: =B13*E13 -> 810803.91 | J13: Busbars & insulation
A14: Busbar sleeving, supports and barriers | B14: =B30*3 -> 78 | C14: m | E14: =r_sleeve*r_sleeveHt -> 396 | I14: =B14*E14 -> 30888 | J14: Busbars & insulation
A15: 110 V DC system | B15: =1 -> 1 | C15: set | E15: =r_dcSystem+r_dcPerBay*B27 -> 402000 | I15: =B15*E15 -> 402000 | J15: Wiring & auxiliaries
A16: Arc-flash detection and fast tripping | B16: =IF(i_arc="Yes",1,0) -> 0 | C16: set | E16: =r_arcBoard+r_arcBay*B27 -> 202000 | I16: =B16*E16 -> 0 | J16: Wiring & auxiliaries
A17: Earth bar, nameplates, end covers | B17: =ROUNDUP(B28,0) -> 13 | C17: column | E17: =r_labelEarth -> 4500 | I17: =B17*E17 -> 58500 | J17: Wiring & auxiliaries
A18: Assembly, fabrication and wiring labour | B18: =B32 -> 8820 | C18: kg | E18: =r_assembly*r_assemblyF -> 57 | I18: =B18*E18 -> 502740 | J18: Assembly & test
A19: Routine tests, FAT and inspection | B19: =B27 -> 13 | C19: bay | E19: =r_testBay*r_testF -> 11700 | I19: =B19*E19 -> 152100 | J19: Assembly & test
A20: Type-test and certification allowance | B20: =1 -> 1 | C20: lot | E20: =(SUM(N5:N9)+I13+I14+I15+I16+I17)*r_typeTest -> 160870.29 | I20: =B20*E20 -> 160870.29 | J20: Assembly & test
A21: Packing and transport | B21: =1 -> 1 | C21: lot | E21: =(SUM(N5:N9)+SUM(I13:I20))*(r_packing+r_transport) -> 398665.12 | I21: =B21*E21 -> 398665.12 | J21: Assembly & test
A26: Helper figures
A27: Number of bays (units) | B27: =SUM(B5:B9) -> 13
A28: Columns / panels | B28: =SUM(B5:B9) -> 13
A29: Board length m (columns x width) | B29: =B28*r_bayW -> 10.4
A30: Busbar run length m (board + 1.2 m risers per column) | B30: =B29+1.2*ROUNDUP(B28,0) -> 26
A31: Busbar section mm2 per phase | B31: =i_busA/r_htJ -> 781.25
A32: Sheet steel total kg | B32: =SUMPRODUCT(B5:B9,D5:D9) -> 8820

Sheet Rates
A1: Rates and constants
A2: Blue = assumption. Replace with quotes. Each value is a named cell (r_...), so formulas stay readable.
A5: Commodity rates
A6: Copper (busbar) | B6: 1400 | C6: Rs/kg | D6: Commodity file / LME x USDINR
A7: CRCA sheet | B7: 76 | C7: Rs/kg
A9: Voltage-class tables
A10: kV | B10: VCB base Rs (1250 A, 25 kA) | C10: Panel steel kg | D10: CT set Rs | E10: VT set Rs | F10: Surge arrester Rs
A11: 3.3 | B11: 380000 | C11: 620 | D11: 26000 | E11: 60000 | F11: 14000
A12: 6.6 | B12: 390000 | C12: 640 | D12: 28000 | E12: 66000 | F12: 16000
A13: 11 | B13: 450000 | C13: 700 | D13: 34000 | E13: 78000 | F13: 21000
A14: 22 | B14: 720000 | C14: 1050 | D14: 62000 | E14: 140000 | F14: 48000
A15: 33 | B15: 950000 | C15: 1450 | D15: 88000 | E15: 210000 | F15: 70000
A17: Switching devices and protection
A18: VCB rating exponent (A/1250) | B18: 0.45
A19: VCB fault-level exponent (kA/25) | B19: 0.5
A20: Motor-feeder VCB factor | B20: 0.9 | C20: x
A21: CT price growth per unit of (kA/25 - 1) | B21: 0.15
A22: Multi-function meter | B22: 22000 | C22: Rs
A23: Earth switch, interlocks, trip-circuit supervision, heaters, lamps | B23: 38000 | C23: Rs/bay
A24: Factor for 22 kV and above | B24: 1.6 | C24: x
A25: Incomer / coupler relay factor | B25: 1.25 | C25: x
A26: PT-panel relay factor | B26: 0.7 | C26: x
A27: Incomer VT factor (of VT set) | B27: 0.8 | C27: x
A29: Protection relay prices
A30: Electromechanical | B30: 14000 | C30: Rs
A31: Numeric O/C + E/F | B31: 38000 | C31: Rs
A32: IED, IEC 61850 + disturbance record | B32: 98000 | C32: Rs
A34: Busbar and DC system
A35: Busbar current density (copper) | B35: 1.6 | C35: A/mm2
A36: Panel width | B36: 0.8 | C36: m
A37: Busbar fabrication, plating | B37: 95 | C37: Rs/kg
A38: Sleeving, supports, barriers | B38: 220 | C38: Rs/m per phase
A39: HT sleeving factor | B39: 1.8 | C39: x
A40: 110 V DC system (battery, charger), base | B40: 220000 | C40: Rs
A41: DC distribution per bay | B41: 14000 | C41: Rs/bay
A42: Arc-flash detection, base | B42: 85000 | C42: Rs
A43: Arc-flash detection per bay | B43: 9000 | C43: Rs/bay
A44: HT wiring factor | B44: 1.6 | C44: x
A45: Control wiring and terminals | B45: 6500 | C45: Rs/bay
A46: HT assembly labour factor | B46: 1.5 | C46: x
...

Sheet Presets
A1: Sample boards (copy the values into Inputs)
A4: Board | B4: kV | C4: Busbar A | D4: kA
A5: HT-01 11 kV plant board, 13 panels | B5: 11 | C5: 1250 | D5: 25 | E5: inc=2@1250; fdr=6@630; cpl=1@1250; mtr=2@400; pt=2 | G5: IP42, arc No, Numeric O/C + E/F
A6: HT-02 33 kV main board, 8 panels | B6: 33 | C6: 2000 | D6: 31.5 | E6: inc=2@2000; fdr=4@1250; cpl=1@2000; mtr=0; pt=1 | G6: IP42, arc Yes, IED, IEC 61850 + disturbance record
A7: HT-03 6.6 kV motor board, 10 panels | B7: 6.6 | C7: 1250 | D7: 40 | E7: inc=1@1250; fdr=1@630; cpl=0; mtr=7@400; pt=1 | G7: IP42, arc No, Numeric O/C + E/F
