Workbook

Sheet Read Me
A1: LT switchgear board: should-cost model
A2: Bottom-up cost of a switchboard from its bay schedule. Not a vendor price list: every rate is an editable assumption.
A4: Purpose | B4: Estimate the ex-works price of a 415 V LT board (PCC / MCC / APFC) from the schedule of bays. Each bay is costed from its sheet steel, switching device, instrument transformers, protection, wiring and test; the board adds the main busbar, labour, test, packing, overheads and margin.
A5: How to use | B5: Edit the yellow cells on Inputs (board rating and the bay schedule) and, if you have quotes, on Rates. Everything else is a live formula. Results are on Summary; the per-bay build-up is on Bay Costing.
A6: Sheets | B6: Inputs: board specification and bay schedule. Rates: every price, constant and multiplier (named cells, prefix r_). Bay Costing: cost per bay type and board-level items. Summary: cost stack, per-bay and per-ampere figures. Presets: three sample boards to copy into Inputs.
A7: Conventions | B7: Yellow fill = input. Blue font = a typed assumption you may change. Black = formula. Green fill = key output. All amounts are Indian rupees, ex-GST, ex-works.
A8: Basis of the numbers | B8: Device prices scale with rating from an assumed base price: ACB = 2.1 lakh x (A/1000)^0.9 x (kA/50)^0.3 (x1.25 for 4-pole); MCCB = 80 x A^1.05 x (kA/36)^0.35; starters, VFDs and APFC banks scale with kW / kVAr. Steel, copper and aluminium follow commodity prices you type into Rates.
A9: Reasonableness | B9: About Rs 1-4 lakh per LT bay at the default rates (an MCC starter module Rs 0.5-1.5 lakh, an ACB bay Rs 5-12 lakh). These are market ranges, not quotations. Calibrate Rates with two or three recent offers before relying on a figure.
A10: Limits | B10: Single board per workbook (copy the file for another). Busbar sized by current density only (no short-circuit or temperature-rise check). No GST, freight to site, erection or civil work. Fault levels above 65 kA need manufacturer confirmation.
A11: Companion | B11: The same model runs interactively in the Should-Cost dashboards (switchgear.html), with a 3D view and a month selector for the commodity prices.

Sheet Inputs
A1: LT board: specification and bay schedule
A4: Tag / board name | B4: LT-01 PCC 3200 A, 2 incomers + coupler
A5: System voltage | B5: 0.415 | C5: kV (fixed)
A6: Busbar rating | B6: 3200 | C6: A
A7: Fault level (1 s) | B7: 50 | C7: kA
A8: Degree of protection | B8: IP54
A9: Arc-fault protection (IAC) | B9: No
A10: Separation form | B10: Form 4b
A11: Busbar material | B11: Aluminium
A13: Bay schedule
A14: Bay type | B14: Quantity | C14: Size | D14: Unit
A15: ACB incomer | B15: 2 | C15: 3200 | D15: A
A16: ACB bus coupler | B16: 1 | C16: 3200 | D16: A
A17: ACB outgoing feeder | B17: 4 | C17: 800 | D17: A
A18: MCCB feeder (each) | B18: 12 | C18: 250 | D18: A
A19: MCC starter, DOL | B19: 0 | C19: 15 | D19: kW
A20: MCC starter, star-delta | B20: 0 | C20: 55 | D20: kW
A21: MCC starter, VFD | B21: 0 | C21: 30 | D21: kW
A22: APFC bank | B22: 0 | C22: 200 | D22: kVAr
A24: Size: rated current (A) for breakers and feeders, motor kW for starters, kVAr for APFC banks. Quantity 0 removes a bay type.

Sheet Summary
A1: LT board: should-cost summary
A3: =Inputs!B4 -> LT-01 PCC 3200 A, 2 incomers + coupler
A5: Cost group | B5: Rs | C5: Share | D5: Note
A6: Enclosure & structure | B6: =SUMPRODUCT('Bay Costing'!B5:B12,'Bay Costing'!E5:E12+'Bay Costing'!F5:F12+'Bay Costing'!G5:G12) -> 313760.07 | C6: =B6/B$15 -> 0.048039662 | D6: Sheet steel, pre-treatment, powder coat, doors
A7: Busbars & insulation | B7: =SUMIF('Bay Costing'!J16:J24,"Busbars & insulation",'Bay Costing'!I16:I24) -> 408256 | C7: =B7/B$15 -> 0.062507891 | D7: Main (and vertical) busbar, sleeving
A8: Switching devices | B8: =SUMPRODUCT('Bay Costing'!B5:B12,'Bay Costing'!H5:H12) -> 3285302 | C8: =B8/B$15 -> 0.5030111 | D8: ACBs, MCCBs, starters, VFDs, APFC
A9: Protection & metering | B9: =SUMPRODUCT('Bay Costing'!B5:B12,'Bay Costing'!I5:I12) -> 576100 | C9: =B9/B$15 -> 0.08820641 | D9: CTs, VTs, relays, meters
A10: Wiring & auxiliaries | B10: =SUMPRODUCT('Bay Costing'!B5:B12,'Bay Costing'!J5:J12)+SUMIF('Bay Costing'!J16:J24,"Wiring & auxiliaries",'Bay Costing'!I16:I24) -> 266500 | C10: =B10/B$15 -> 0.040803694 | D10: Control wiring, interlocks, lamps, selectors
A11: Assembly, test, packing & transport | B11: =SUMIF('Bay Costing'!J16:J24,"Assembly & test",'Bay Costing'!I16:I24) -> 597347.44 | C11: =B11/B$15 -> 0.091459596 | D11: Labour, routine and type tests, packing
A12: Direct cost | B12: =SUM(B6:B11) -> 5447265.5 | C12: =B12/B$15 -> 0.83402836
A13: Overheads | B13: =B12*r_overheads -> 490253.9 | C13: =B13/B$15 -> 0.075062552
A14: Margin | B14: =(B12+B13)*r_margin -> 593751.94 | C14: =B14/B$15 -> 0.090909091
A15: SHOULD-COST, ex-works (Rs) | B15: =B12+B13+B14 -> 6531271.4 | C15: =B15/B$15 -> 1
A16: Should-cost (Rs crore) | B16: =B15/10000000 -> 0.65312714
A17: Number of bays (units) | B17: ='Bay Costing'!B30 -> 19
A18: Cost per bay (Rs) | B18: =B15/B17 -> 343751.13
A19: Cost per ampere of busbar (Rs/A) | B19: =B15/Inputs!B6 -> 2041.0223
A20: Sheet steel (kg) | B20: ='Bay Costing'!B35 -> 3120.128
A21: Busbar mass (kg) | B21: ='Bay Costing'!B16+'Bay Costing'!B17 -> 864
A23: Checks
A24: Largest bay rating within the busbar rating? | B24: =IF(MAX(Inputs!C15*(Inputs!B15>0),Inputs!C16*(Inputs!B16>0),Inputs!C17*(Inputs!B17>0),Inputs!C18*(Inputs!B18>0))<=Inputs!B6,"OK","CHECK: a bay exceeds the busbar") -> OK
A25: Fault level within the usual range? | B25: =IF(Inputs!B7<=65,"OK","CHECK: confirm with manufacturer") -> OK

Sheet Bay Costing
A1: Cost per bay and board-level items
A2: Rows follow the bay schedule on Inputs. Rs per bay unless stated.
A3: Enclosure multiplier (IP x form x arc) | E3: =INDEX(r_ipMult,MATCH(i_ip,r_ipList,0))*INDEX(r_formMult,MATCH(i_form,r_formList,0))*IF(i_arc="Yes",r_arcMult,1) -> 1.408
A4: Bay type | B4: Qty | C4: Size | D4: Steel kg / bay | E4: Sheet steel | F4: Powder coat | G4: Gaskets, doors | H4: Device | I4: Protection & metering | J4: Aux + wiring | K4: Total per bay | L4: Total (qty x) | M4: Columns
A5: ACB incomer | B5: =Inputs!B15 -> 2 | C5: =Inputs!C15 -> 3200 | D5: =(r_acbKgBase+r_acbKgPerA*C5)*c_mult -> 450.56 | E5: =D5*r_crca -> 34242.56 | F5: =D5*r_powder -> 6307.84 | G5: =D5*(r_gasket+r_hdwr*r_crca) -> 4757.9136 | H5: =r_acbBase*(C5/1000)^r_acbAmpExp*(i_kA/50)^r_acbKaExp*r_acbPoles4 -> 747763.54 | I5: =r_ctLt*4+r_relayLt*3+r_mfm+r_ammeterSet -> 60700 | J5: =r_acbAux+r_lamps*3+r_selector*2+r_wiring -> 28300 | K5: =SUM(E5:J5) -> 882071.86 | L5: =B5*K5 -> 1764143.7 | M5: =B5 -> 2
A6: ACB bus coupler | B6: =Inputs!B16 -> 1 | C6: =Inputs!C16 -> 3200 | D6: =(r_acbKgBase+r_acbKgPerA*C6)*c_mult -> 450.56 | E6: =D6*r_crca -> 34242.56 | F6: =D6*r_powder -> 6307.84 | G6: =D6*(r_gasket+r_hdwr*r_crca) -> 4757.9136 | H6: =r_acbBase*(C6/1000)^r_acbAmpExp*(i_kA/50)^r_acbKaExp*r_acbPoles4 -> 747763.54 | I6: =r_ctLt*4+r_relayLt*3+r_mfm+r_ammeterSet -> 60700 | J6: =r_acbAux+r_lamps*3+r_selector*2+r_wiring -> 28300 | K6: =SUM(E6:J6) -> 882071.86 | L6: =B6*K6 -> 882071.86 | M6: =B6 -> 1
A7: ACB outgoing feeder | B7: =Inputs!B17 -> 4 | C7: =Inputs!C17 -> 800 | D7: =(r_acbKgBase+r_acbKgPerA*C7)*c_mult -> 281.6 | E7: =D7*r_crca -> 21401.6 | F7: =D7*r_powder -> 3942.4 | G7: =D7*(r_gasket+r_hdwr*r_crca) -> 2973.696 | H7: =r_acbBase*(C7/1000)^r_acbAmpExp*(i_kA/50)^r_acbKaExp*1 -> 171790.95 | I7: =r_ctLt*4+r_relayLt*3+r_mfm+r_ammeterSet -> 60700 | J7: =r_acbAux+r_lamps*3+r_selector*2+r_wiring -> 28300 | K7: =SUM(E7:J7) -> 289108.65 | L7: =B7*K7 -> 1156434.6 | M7: =B7 -> 4
A8: MCCB feeder (each) | B8: =Inputs!B18 -> 12 | C8: =Inputs!C18 -> 250 | D8: =(r_mccbKgBase+r_mccbKgPerA*C8)*c_mult -> 53.504 | E8: =D8*r_crca -> 4066.304 | F8: =D8*r_powder -> 749.056 | G8: =D8*(r_gasket+r_hdwr*r_crca) -> 565.00224 | H8: =r_mccbBase*C8^r_mccbAmpExp*(i_kA/36)^r_mccbKaExp -> 29570.633 | I8: =r_ctLt+r_mccbAux+r_lamps -> 12600 | J8: =r_wiring*r_mccbWiringF -> 1950 | K8: =SUM(E8:J8) -> 49500.995 | L8: =B8*K8 -> 594011.94 | M8: =B8/r_mccbPerCol -> 3
A9: MCC starter, DOL | B9: =Inputs!B19 -> 0 | C9: =Inputs!C19 -> 15 | D9: =(r_mccKgBase+r_mccKgPerKw*C9^0.8)*c_mult*1 -> 41.164706 | E9: =D9*r_crca -> 3128.5177 | F9: =D9*r_powder -> 576.30588 | G9: =D9*(r_gasket+r_hdwr*r_crca) -> 434.69929 | H9: =(r_dolBase+r_dolPerKw*C9^r_kwExp)*1 -> 12146.389 | I9: =r_ctLt+r_relayLt+r_lamps*3+r_selector*2 -> 22100 | J9: =r_wiring -> 6500 | K9: =SUM(E9:J9) -> 44885.912 | L9: =B9*K9 -> 0 | M9: =B9/r_mccPerCol -> 0
A10: MCC starter, star-delta | B10: =Inputs!B20 -> 0 | C10: =Inputs!C20 -> 55 | D10: =(r_mccKgBase+r_mccKgPerKw*C10^0.8)*c_mult*1 -> 54.639024 | E10: =D10*r_crca -> 4152.5658 | F10: =D10*r_powder -> 764.94633 | G10: =D10*(r_gasket+r_hdwr*r_crca) -> 576.98809 | H10: =(r_dolBase+r_dolPerKw*C10^r_kwExp)*r_sdFactor -> 42215.136 | I10: =r_ctLt+r_relayLt+r_lamps*3+r_selector*2 -> 22100 | J10: =r_wiring -> 6500 | K10: =SUM(E10:J10) -> 76309.636 | L10: =B10*K10 -> 0 | M10: =B10/r_mccPerCol -> 0
A11: MCC starter, VFD | B11: =Inputs!B21 -> 0 | C11: =Inputs!C21 -> 30 | D11: =(r_mccKgBase+r_mccKgPerKw*C11^0.8)*c_mult*r_vfdKgF -> 62.948646 | E11: =D11*r_crca -> 4784.0971 | F11: =D11*r_powder -> 881.28104 | G11: =D11*(r_gasket+r_hdwr*r_crca) -> 664.7377 | H11: =r_vfdBase*C11^r_vfdExp -> 167143.58 | I11: =r_ctLt+r_relayLt+r_lamps*3+r_selector*2 -> 22100 | J11: =r_wiring -> 6500 | K11: =SUM(E11:J11) -> 202073.69 | L11: =B11*K11 -> 0 | M11: =B11/r_mccPerCol -> 0
A12: APFC bank | B12: =Inputs!B22 -> 0 | C12: =Inputs!C22 -> 200 | D12: =(r_apfcKgBase+r_apfcKgPerKvar*C12)*c_mult -> 295.68 | E12: =D12*r_crca -> 22471.68 | F12: =D12*r_powder -> 4139.52 | G12: =D12*(r_gasket+r_hdwr*r_crca) -> 3122.3808 | H12: =r_apfcBase+r_apfcPerKvar*C12 -> 192000 | I12: =r_apfcCtl -> 28000 | J12: =r_wiring -> 6500 | K12: =SUM(E12:J12) -> 256233.58 | L12: =B12*K12 -> 0 | M12: =B12 -> 0
A14: Board-level items
A15: Item | B15: Qty | C15: Unit | E15: Rate Rs | I15: Amount Rs | J15: Group
A16: Main busbar (per busbar material) | B16: =4*B34*B33*IF(i_busMat="Copper",8.9,2.7)/1000 -> 864 | C16: kg | E16: =IF(i_busMat="Copper",r_copper,r_aluminium)+r_busFab -> 444 | I16: =B16*E16 -> 383616 | J16: Busbars & insulation
A17: Vertical busbars, MCC sections | B17: =IF((B9+B10+B11)>0,4*B34*r_vertFrac*2.2*ROUNDUP((B9+B10+B11)/r_mccPerCol,0)*IF(i_busMat="Copper",8.9,2.7)/1000,0) -> 0 | C17: kg | E17: =IF(i_busMat="Copper",r_copper,r_aluminium)+r_busFab -> 444 | I17: =B17*E17 -> 0 | J17: Busbars & insulation
A18: Busbar sleeving, supports and barriers | B18: =B33*4 -> 80 | C18: m | E18: =r_sleeve*IF(i_form="Form 4b",r_sleeve4b,1) -> 308 | I18: =B18*E18 -> 24640 | J18: Busbars & insulation
A19: Arc-flash relay and sensors | B19: =IF(i_arc="Yes",1,0) -> 0 | C19: set | E19: =r_arcBoard*0.5 -> 42500 | I19: =B19*E19 -> 0 | J19: Wiring & auxiliaries
A20: Earth bar, nameplates, end covers | B20: =ROUNDUP(B31,0) -> 10 | C20: column | E20: =r_labelEarth -> 4500 | I20: =B20*E20 -> 45000 | J20: Wiring & auxiliaries
A21: Assembly, fabrication and wiring labour | B21: =B35 -> 3120.128 | C21: kg | E21: =r_assembly*IF(i_form="Form 4b",r_assemblyF4b,1) -> 45.6 | I21: =B21*E21 -> 142277.84 | J21: Assembly & test
A22: Routine tests, FAT and inspection | B22: =B30 -> 19 | C22: bay | E22: =r_testBay -> 6500 | I22: =B22*E22 -> 123500 | J22: Assembly & test
A23: Type-test and certification allowance | B23: =1 -> 1 | C23: lot | E23: =(SUM(L5:L12)+I16+I17+I18+I19+I20)*r_typeTest -> 96998.362 | I23: =B23*E23 -> 96998.362 | J23: Assembly & test
A24: Packing and transport | B24: =1 -> 1 | C24: lot | E24: =(SUM(L5:L12)+SUM(I16:I23))*(r_packing+r_transport) -> 234571.24 | I24: =B24*E24 -> 234571.24 | J24: Assembly & test
A29: Helper figures
A30: Number of bays (units) | B30: =SUM(B5:B12) -> 19
A31: Columns / panels | B31: =SUM(M5:M12) -> 10
A32: Board length m (columns x width) | B32: =B31*r_bayW -> 8
A33: Busbar run length m (board + 1.2 m risers per column) | B33: =B32+1.2*ROUNDUP(B31,0) -> 20
A34: Busbar section mm2 per phase | B34: =i_busA*IF(i_busMat="Copper",r_cuA,r_alA) -> 4000
A35: Sheet steel total kg | B35: =SUMPRODUCT(B5:B12,D5:D12) -> 3120.128

Sheet Rates
A1: Rates and constants
A2: Blue = assumption. Replace with quotes. Each value is a named cell (r_...), so formulas stay readable.
A5: Commodity rates
A6: Copper (busbar) | B6: 1400 | C6: Rs/kg | D6: Commodity file / LME x USDINR
A7: Aluminium (busbar) | B7: 349 | C7: Rs/kg
A8: CRCA sheet | B8: 76 | C8: Rs/kg
A10: Switching devices
A11: ACB base price at 1,000 A, 50 kA, 3-pole | B11: 210000 | C11: Rs
A12: ACB rating exponent | B12: 0.9
A13: ACB fault-level exponent (kA/50) | B13: 0.3
A14: Factor for 4-pole (incomers, couplers) | B14: 1.25 | C14: x
A15: MCCB price = base x A^exp x (kA/36)^exp | B15: 80 | C15: Rs
A16: MCCB rating exponent | B16: 1.05
A17: MCCB fault-level exponent | B17: 0.35
A18: DOL starter base (MPCB, contactor, overload) | B18: 3000 | C18: Rs
A19: DOL starter per kW^exp | B19: 1200 | C19: Rs
A20: Starter kW exponent | B20: 0.75
A21: Star-delta factor | B21: 1.55 | C21: x
A22: VFD = base x kW^exp | B22: 11000 | C22: Rs
A23: VFD kW exponent | B23: 0.8
A24: APFC bank base (controller, switching) | B24: 62000 | C24: Rs
A25: APFC capacitors and reactors per kVAr | B25: 650 | C25: Rs/kVAr
A27: Protection, metering and accessories
A28: CT (each) | B28: 4800 | C28: Rs
A29: Microprocessor release / relay element | B29: 9500 | C29: Rs
A30: Multi-function meter | B30: 7500 | C30: Rs
A31: Ammeter / voltmeter set | B31: 5500 | C31: Rs
A32: Indicating lamp | B32: 1800 | C32: Rs
A33: Selector switch | B33: 1200 | C33: Rs
A34: MCCB shunt trip / aux | B34: 6000 | C34: Rs
A35: ACB shunt trip, closing coil, interlocks | B35: 14000 | C35: Rs
A36: APFC controller, CTs and metering | B36: 28000 | C36: Rs
A38: Sheet steel per bay (kg)
A39: ACB bay: base | B39: 160 | C39: kg
A40: ACB bay: per ampere | B40: 0.05 | C40: kg/A
A41: MCCB feeder: base | B41: 28 | C41: kg
A42: MCCB feeder: per ampere | B42: 0.04 | C42: kg/A
A43: MCC module: base | B43: 24 | C43: kg
A44: MCC module: per kW^0.8 | B44: 0.6 | C44: kg
A45: VFD module factor | B45: 1.35 | C45: x
...

Sheet Presets
A1: Sample boards (copy the values into Inputs)
A4: Board | B4: kV | C4: Busbar A | D4: kA
A5: LT-01 PCC 3200 A, 2 incomers + coupler | B5: 0.415 | C5: 3200 | D5: 50 | E5: aci=2@3200; acc=1@3200; acf=4@800; mcf=12@250; dol=0; sd=0; vfd=0; pf=0 | G5: IP54, Form 4b, Aluminium busbar
A6: LT-02 MCC, 40 starters | B6: 0.415 | C6: 1000 | D6: 50 | E6: aci=1@1000; acc=0; acf=0; mcf=4@125; dol=28@11; sd=6@55; vfd=6@30; pf=0 | G6: IP54, Form 3b, Copper busbar
A7: LT-03 APFC panel 600 kVAr | B7: 0.415 | C7: 1000 | D7: 36 | E7: aci=1@1000; acc=0; acf=0; mcf=0; dol=0; sd=0; vfd=0; pf=3@200 | G7: IP42, Form 2b, Aluminium busbar
