Workbook

Sheet Figure
S14: Inlet damper | T14: Auto
T15: Manual
S16: Filter
S18: Belt driven fan
S19: Direct fan | T19: EC
T20: Plug
S23: Outlet damper | T23: Auto
T24: Manual
S25: BMS
S26: Sensor | T26: Humidity
T27: Temperature

Sheet AHU Batch Calculator
B1: AHU — BATCH SHOULD-COST CALCULATOR
B2: One row per AHU. Airflow (CFM) drives coil face area, which drives casing size, which drives sheet, insulation, coil and fan cost.
B3: Refresh prices: | C3: https://www.lme.com/metals/non-ferrous/lme-copper | F3: https://steel.gov.in/monthly-summery
B4: MATERIAL MASTER | C4: Copper tube | D4: Aluminium fin | E4: GI sheet | F4: Pre-coated GI | G4: SS 304 | H4: PUF | I4: Rockwool
B5: Density (kg/m³) | C5: 8960 | D5: 2700 | E5: 7850 | F5: 7850 | G5: 7900 | H5: 40 | I5: 64 | K5: Copper tube ₹750-950/kg and aluminium sheet ₹200-275/kg per Apr-2026 market listings. PUF and rockwool rates are unsourced placeholders.
B6: Price (Rs/kg) | C6: 1400 | D6: 260 | E6: 80 | F6: 95 | G6: 260 | H6: 350 | I6: 85 | M6: Add | N6: Add
M7: EC fan | N7: Smart Panel | AH7: Manual
B8: AHU tag / label | C8: Airflow CFM | E8: Cooling duty TR | F8: Heating duty kW | G8: ESP Pa | H8: Casing | I8: Panel thk mm | J8: Casing material | K8: Insulation | L8: Insul thk mm | M8: Fan type | N8: VFD | O8: Coil rows | P8: FPI | Q8: Tube material | R8: Fin material | S8: Filter config | T8: Mounting | U8: Fresh air | V8: Mixing box | W8: Heating coil | X8: Humidi- fier | Y8: TOTAL COST Rs | Z8: Rs per CFM | AA8: Rs per TR | AB8: Total wt kg | AC8: Copper kg | AD8: Aluminium kg | AE8: Sheet kg | AF8: Insulation kg | AG8: Motor kW | AH8: Size WxHxL m | AJ8: CMH | AK8: m3/s | AL8: face area | AM8: cross-sec | AN8: W m | AO8: H m | AP8: filter L | AQ8: total L | AR8: surface m2 | AS8: n skins | AT8: sheet dens | AU8: sheet px | AV8: SHEET kg | AW8: ins dens | AX8: ins px | AY8: ins vol | AZ8: INSUL kg | BA8: frame m | BB8: frame kg | BC8: frame Rs | BD8: Hf m | BE8: Lf m | BF8: tubes/row | BG8: tubes tot | BH8: tube len | BI8: tube kg/m | BJ8: COPPER kg | BK8: n fins | BL8: coil depth | BM8: fin area | BN8: ALU kg | BO8: ISP Pa | BP8: TSP Pa | BQ8: fan kW | BR8: MOTOR kW | BS8: fan Rs | BT8: vfd Rs | BU8: filter m2 | BV8: filter Rs | BW8: damper m2 | BX8: damper Rs | BY8: pan kg | BZ8: pan Rs | CA8: A material | CB8: B boughtout | CC8: C conversion | CD8: D overhead | CE8: E margin | CF8: TOTAL | CH8: Material Rs (A) | CI8: Labour+Conv. Rs (B+C) | CJ8: OH+Margin Rs (D+E)
B9: AHU-01 Office floor | C9: 50000 | E9: 30 | F9: 0 | G9: 300 | H9: Double skin | I9: 1.5 | J9: Pre-coated GI | K9: PUF | L9: 25 | M9: Plug fan | N9: Y | O9: 6 | P9: 12 | Q9: Copper tube | R9: Aluminium fin | S9: Pre+Fine | T9: Floor mounted | U9: Mixed (return+fresh) | V9: Y | W9: N | X9: N | Y9: =IF($C9="","",CF9) -> 2225561.1 | Z9: =IF($C9="","",Y9/$C9) -> 44.511221 | AA9: =IF($C9="","",IF(E9=0,"",CF9/E9)) -> 74185.369 | AB9: =IF($C9="","",BJ9+BN9+AV9+AZ9+BB9+BY9) -> 2408.0157 | AC9: =IF($C9="","",BJ9) -> 360.78871 | AD9: =IF($C9="","",BN9) -> 159.52968 | AE9: =IF($C9="","",AV9) -> 1720.5277 | AF9: =IF($C9="","",AZ9) -> 65.230805 | AG9: =IF($C9="","",BR9) -> 30 | AH9: =IF($C9="","",ROUND(AN9,2)&" x "&ROUND(AO9,2)&" x "&ROUND(AQ9,2)) -> 3.8 x 2.92 x 3.2 | AJ9: =IF($C9="","",$C9*'Assumptions & Ref'!$C$10) -> 84950 | AK9: =IF($C9="","",AJ9/3600) -> 23.597222 | AL9: =IF($C9="","",AK9/'Assumptions & Ref'!$C$6) -> 9.4388889 | AM9: =IF($C9="","",AL9/'Assumptions & Ref'!$C$8) -> 11.104575 | AN9: =IF($C9="","",SQRT(AM9*'Assumptions & Ref'!$C$9)) -> 3.7994668 | AO9: =IF($C9="","",SQRT(AM9/'Assumptions & Ref'!$C$9)) -> 2.9226667 | AP9: =IF($C9="","",'Assumptions & Ref'!$C$14+IF(OR(S9="Pre+Fine",S9="Pre+Fine+HEPA"),'Assumptions & Ref'!$C$15,0)+IF(S9="Pre+Fine+HEPA",'Assumptions & Ref'!$C$16,0)) -> 0.75 | AQ9: =IF($C9="","",IF(V9="Y",'Assumptions & Ref'!$C$13,0)+AP9+'Assumptions & Ref'!$C$17+O9*'Assumptions & Ref'!$C$18+IF(W9="Y",'Assumptions & Ref'!$C$19,0)+'Assumptions & Ref'!$C$20+IF(X9="Y",'Assumptions & Ref'!$C$21,0)) -> 3.2 | AR9: =IF($C9="","",2*(AN9+AO9)*AQ9+2*AN9*AO9) -> 65.230805 | AS9: =IF($C9="","",IF(H9="Double skin",2,1)) -> 2 | AT9: =IF($C9="","",INDEX($C$5:$I$5,MATCH(J9,$C$4:$I$4,0))) -> 7850 | AU9: =IF($C9="","",INDEX($C$6:$I$6,MATCH(J9,$C$4:$I$4,0))) -> 95 | AV9: =IF($C9="","",AR9*AS9*I9/1000*AT9*(1+'Assumptions & Ref'!$C$75)) -> 1720.5277 | AW9: =IF($C9="","",INDEX($C$5:$I$5,MATCH(K9,$C$4:$I$4,0))) -> 40 | AX9: =IF($C9="","",INDEX($C$6:$I$6,MATCH(K9,$C$4:$I$4,0))) -> 350 | AY9: =IF($C9="","",AR9*L9/1000) -> 1.6307701 | AZ9: =IF($C9="","",AY9*AW9) -> 65.230805 | BA9: =IF($C9="","",4*(AN9+AO9+AQ9)) -> 39.688534 | BB9: =IF($C9="","",BA9*'Assumptions & Ref'!$C$76) -> 73.423788 | BC9: =IF($C9="","",BB9*'Assumptions & Ref'!$C$77) -> 24964.088 | BD9: =IF($C9="","",SQRT(AL9/'Assumptions & Ref'!$C$9)) -> 2.6945656 | BE9: =IF($C9="","",SQRT(AL9*'Assumptions & Ref'!$C$9)) -> 3.5029353 | BF9: =IF($C9="","",BD9*1000/'Assumptions & Ref'!$C$27) -> 107.78262 | BG9: =IF($C9="","",BF9*O9) -> 646.69574 | BH9: =IF($C9="","",BG9*BE9*(1+'Assumptions & Ref'!$C$29)) -> 2605.1333 | BI9: =IF($C9="","",PI()*('Assumptions & Ref'!$C$25-'Assumptions & Ref'!$C$26)/1000*'Assumptions & Ref'!$C$26/1000*$C$5) -> 0.13849146 | BJ9: =IF($C9="","",BH9*BI9) -> 360.78871 | BK9: =IF($C9="","",BE9*1000*P9/25.4) -> 1654.9301 | BL9: =IF($C9="","",O9*'Assumptions & Ref'!$C$28/1000) -> 0.1299 | BM9: =IF($C9="","",BD9*BL9*(1-'Assumptions & Ref'!$C$31)) -> 0.29752046 | BN9: =IF($C9="","",BK9*BM9*'Assumptions & Ref'!$C$30/1000*INDEX($C$5:$I$5,MATCH(R9,$C$4:$I$4,0))) -> 159.52968 | BO9: =IF($C9="","",'Assumptions & Ref'!$C$34+O9*'Assumptions & Ref'!$C$35+'Assumptions & Ref'!$C$36+IF(OR(S9="Pre+Fine",S9="Pre+Fine+HEPA"),'Assumptions & Ref'!$C$37,0)+IF(S9="Pre+Fine+HEPA",'Assumptions & Ref'!$C$38,0)) -> 422 | BP9: =IF($C9="","",G9+BO9) -> 722 | BQ9: =IF($C9="","",AK9*BP9/(1000*IF(M9="Plug fan",'Assumptions & Ref'!$C$39,'Assumptions & Ref'!$C$40)*'Assumptions & Ref'!$C$41)) -> 27.838553 | BR9: =IF($C9="","",IFERROR(INDEX('Assumptions & Ref'!$B$44:$B$61,MATCH(BQ9,'Assumptions & Ref'!$B$44:$B$61,1)+IF(INDEX('Assumptions & Ref'!$B$44:$B$61,MATCH(BQ9,'Assumptions & Ref'!$B$44:$B$61,1))>=BQ9,0,1)),INDEX('Assumptions & Ref'!$B$44:$B$61,1))) -> 30 | BS9: =IF($C9="","",BR9*IF(M9="Plug fan",'Assumptions & Ref'!$C$64,'Assumptions & Ref'!$C$65)) -> 435000 | BT9: =IF($C9="","",IF(N9="Y",BR9*'Assumptions & Ref'!$C$66,0)) -> 225000 | BU9: =IF($C9="","",AM9) -> 11.104575 | BV9: =IF($C9="","",BU9*('Assumptions & Ref'!$C$67+IF(OR(S9="Pre+Fine",S9="Pre+Fine+HEPA"),'Assumptions & Ref'!$C$68,0)+IF(S9="Pre+Fine+HEPA",'Assumptions & Ref'!$C$69,0))) -> 51081.046 | BW9: =IF($C9="","",AM9*IF(U9="Mixed (return+fresh)",2,1)) -> 22.20915 | BX9: =IF($C9="","",BW9*'Assumptions & Ref'!$C$70) -> 115487.58 | BY9: =IF($C9="","",AN9*('Assumptions & Ref'!$C$17+O9*'Assumptions & Ref'!$C$18+0.2)*'Assumptions & Ref'!$C$81/1000*$G$5) -> 28.514998 | BZ9: =IF($C9="","",BY9*$G$6) -> 7413.8995 | CA9: =IF($C9="","",BJ9*$C$6+BN9*INDEX($C$6:$I$6,MATCH(R9,$C$4:$I$4,0))+AV9*AU9+AZ9*AX9+BC9+BZ9) -> 765240.81 | CB9: =IF($C9="","",BS9+BT9+BV9+BX9) -> 826568.63 | CC9: =IF($C9="","",(AV9+BB9)*'Assumptions & Ref'!$C$78+(BJ9+BN9)*'Assumptions & Ref'!$C$80) -> 214652.46 | CD9: =IF($C9="","",'Assumptions & Ref'!$C$84*(CA9+CB9+CC9)) -> 180646.19 | CE9: =IF($C9="","",'Assumptions & Ref'!$C$85*(CA9+CB9+CC9+CD9)) -> 238452.97 | CF9: =IF($C9="","",CA9+CB9+CC9+CD9+CE9) -> 2225561.1 | CH9: =IF($C9="","",CA9) -> 765240.81 | CI9: =IF($C9="","",CB9+CC9) -> 1041221.1 | CJ9: =IF($C9="","",CD9+CE9) -> 419099.16
B10: AHU-02 Lobby | C10: 45000 | E10: 18 | F10: 0 | G10: 250 | H10: Double skin | I10: 0.8 | J10: Pre-coated GI | K10: PUF | L10: 25 | M10: Plug fan | N10: Y | O10: 4 | P10: 12 | Q10: Copper tube | R10: Aluminium fin | S10: Pre+Fine | T10: Ceiling suspended | U10: Mixed (return+fresh) | V10: Y | W10: N | X10: N | Y10: =IF($C10="","",CF10) -> 1484723.5 | Z10: =IF($C10="","",Y10/$C10) -> 32.993856 | AA10: =IF($C10="","",IF(E10=0,"",CF10/E10)) -> 82484.641 | AB10: =IF($C10="","",BJ10+BN10+AV10+AZ10+BB10+BY10) -> 1303.4274 | AC10: =IF($C10="","",BJ10) -> 216.47323 | AD10: =IF($C10="","",BN10) -> 95.717807 | AE10: =IF($C10="","",AV10) -> 837.37435 | AF10: =IF($C10="","",AZ10) -> 59.526725 | AG10: =IF($C10="","",BR10) -> 22 | AH10: =IF($C10="","",ROUND(AN10,2)&" x "&ROUND(AO10,2)&" x "&ROUND(AQ10,2)) -> 3.6 x 2.77 x 3.1 | AJ10: =IF($C10="","",$C10*'Assumptions & Ref'!$C$10) -> 76455 | AK10: =IF($C10="","",AJ10/3600) -> 21.2375 | AL10: =IF($C10="","",AK10/'Assumptions & Ref'!$C$6) -> 8.495 | AM10: =IF($C10="","",AL10/'Assumptions & Ref'!$C$8) -> 9.9941176 | AN10: =IF($C10="","",SQRT(AM10*'Assumptions & Ref'!$C$9)) -> 3.6044907 | AO10: =IF($C10="","",SQRT(AM10/'Assumptions & Ref'!$C$9)) -> 2.7726851 | AP10: =IF($C10="","",'Assumptions & Ref'!$C$14+IF(OR(S10="Pre+Fine",S10="Pre+Fine+HEPA"),'Assumptions & Ref'!$C$15,0)+IF(S10="Pre+Fine+HEPA",'Assumptions & Ref'!$C$16,0)) -> 0.75 | AQ10: =IF($C10="","",IF(V10="Y",'Assumptions & Ref'!$C$13,0)+AP10+'Assumptions & Ref'!$C$17+O10*'Assumptions & Ref'!$C$18+IF(W10="Y",'Assumptions & Ref'!$C$19,0)+'Assumptions & Ref'!$C$20+IF(X10="Y",'Assumptions & Ref'!$C$21,0)) -> 3.1 | AR10: =IF($C10="","",2*(AN10+AO10)*AQ10+2*AN10*AO10) -> 59.526725 | AS10: =IF($C10="","",IF(H10="Double skin",2,1)) -> 2 | AT10: =IF($C10="","",INDEX($C$5:$I$5,MATCH(J10,$C$4:$I$4,0))) -> 7850 | AU10: =IF($C10="","",INDEX($C$6:$I$6,MATCH(J10,$C$4:$I$4,0))) -> 95 | AV10: =IF($C10="","",AR10*AS10*I10/1000*AT10*(1+'Assumptions & Ref'!$C$75)) -> 837.37435 | AW10: =IF($C10="","",INDEX($C$5:$I$5,MATCH(K10,$C$4:$I$4,0))) -> 40 | AX10: =IF($C10="","",INDEX($C$6:$I$6,MATCH(K10,$C$4:$I$4,0))) -> 350 | AY10: =IF($C10="","",AR10*L10/1000) -> 1.4881681 | AZ10: =IF($C10="","",AY10*AW10) -> 59.526725 | BA10: =IF($C10="","",4*(AN10+AO10+AQ10)) -> 37.908703 | BB10: =IF($C10="","",BA10*'Assumptions & Ref'!$C$76) -> 70.131101 | BC10: =IF($C10="","",BB10*'Assumptions & Ref'!$C$77) -> 23844.574 | BD10: =IF($C10="","",SQRT(AL10/'Assumptions & Ref'!$C$9)) -> 2.5562894 | BE10: =IF($C10="","",SQRT(AL10*'Assumptions & Ref'!$C$9)) -> 3.3231762 | BF10: =IF($C10="","",BD10*1000/'Assumptions & Ref'!$C$27) -> 102.25158 | BG10: =IF($C10="","",BF10*O10) -> 409.0063 | BH10: =IF($C10="","",BG10*BE10*(1+'Assumptions & Ref'!$C$29)) -> 1563.08 | BI10: =IF($C10="","",PI()*('Assumptions & Ref'!$C$25-'Assumptions & Ref'!$C$26)/1000*'Assumptions & Ref'!$C$26/1000*$C$5) -> 0.13849146 | BJ10: =IF($C10="","",BH10*BI10) -> 216.47323 | BK10: =IF($C10="","",BE10*1000*P10/25.4) -> 1570.0045 | BL10: =IF($C10="","",O10*'Assumptions & Ref'!$C$28/1000) -> 0.0866 | BM10: =IF($C10="","",BD10*BL10*(1-'Assumptions & Ref'!$C$31)) -> 0.18816846 | BN10: =IF($C10="","",BK10*BM10*'Assumptions & Ref'!$C$30/1000*INDEX($C$5:$I$5,MATCH(R10,$C$4:$I$4,0))) -> 95.717807 | BO10: =IF($C10="","",'Assumptions & Ref'!$C$34+O10*'Assumptions & Ref'!$C$35+'Assumptions & Ref'!$C$36+IF(OR(S10="Pre+Fine",S10="Pre+Fine+HEPA"),'Assumptions & Ref'!$C$37,0)+IF(S10="Pre+Fine+HEPA",'Assumptions & Ref'!$C$38,0)) -> 378 | BP10: =IF($C10="","",G10+BO10) -> 628 | BQ10: =IF($C10="","",AK10*BP10/(1000*IF(M10="Plug fan",'Assumptions & Ref'!$C$39,'Assumptions & Ref'!$C$40)*'Assumptions & Ref'!$C$41)) -> 21.792729 | BR10: =IF($C10="","",IFERROR(INDEX('Assumptions & Ref'!$B$44:$B$61,MATCH(BQ10,'Assumptions & Ref'!$B$44:$B$61,1)+IF(INDEX('Assumptions & Ref'!$B$44:$B$61,MATCH(BQ10,'Assumptions & Ref'!$B$44:$B$61,1))>=BQ10,0,1)),INDEX('Assumptions & Ref'!$B$44:$B$61,1))) -> 22 | BS10: =IF($C10="","",BR10*IF(M10="Plug fan",'Assumptions & Ref'!$C$64,'Assumptions & Ref'!$C$65)) -> 319000 | BT10: =IF($C10="","",IF(N10="Y",BR10*'Assumptions & Ref'!$C$66,0)) -> 165000 | BU10: =IF($C10="","",AM10) -> 9.9941176 | BV10: =IF($C10="","",BU10*('Assumptions & Ref'!$C$67+IF(OR(S10="Pre+Fine",S10="Pre+Fine+HEPA"),'Assumptions & Ref'!$C$68,0)+IF(S10="Pre+Fine+HEPA",'Assumptions & Ref'!$C$69,0))) -> 45972.941 | BW10: =IF($C10="","",AM10*IF(U10="Mixed (return+fresh)",2,1)) -> 19.988235 | BX10: =IF($C10="","",BW10*'Assumptions & Ref'!$C$70) -> 103938.82 | BY10: =IF($C10="","",AN10*('Assumptions & Ref'!$C$17+O10*'Assumptions & Ref'!$C$18+0.2)*'Assumptions & Ref'!$C$81/1000*$G$5) -> 24.204155 | BZ10: =IF($C10="","",BY10*$G$6) -> 6293.0802 | CA10: =IF($C10="","",BJ10*$C$6+BN10*INDEX($C$6:$I$6,MATCH(R10,$C$4:$I$4,0))+AV10*AU10+AZ10*AX10+BC10+BZ10) -> 458471.72 | CB10: =IF($C10="","",BS10+BT10+BV10+BX10) -> 633911.76 | CC10: =IF($C10="","",(AV10+BB10)*'Assumptions & Ref'!$C$78+(BJ10+BN10)*'Assumptions & Ref'!$C$80) -> 112749.26 | CD10: =IF($C10="","",'Assumptions & Ref'!$C$84*(CA10+CB10+CC10)) -> 120513.27 | CE10: =IF($C10="","",'Assumptions & Ref'!$C$85*(CA10+CB10+CC10+CD10)) -> 159077.52 | CF10: =IF($C10="","",CA10+CB10+CC10+CD10+CE10) -> 1484723.5 | CH10: =IF($C10="","",CA10) -> 458471.72 | CI10: =IF($C10="","",CB10+CC10) -> 746661.02 | CJ10: =IF($C10="","",CD10+CE10) -> 279590.8
B11: AHU-03 Cleanroom | C11: 40000 | E11: 26 | F11: 0 | G11: 600 | H11: Double skin | I11: 1 | J11: SS 304 | K11: PUF | L11: 50 | M11: Plug fan | N11: Y | O11: 8 | P11: 14 | Q11: Copper tube | R11: Aluminium fin | S11: Pre+Fine+HEPA | T11: Floor mounted | U11: 100% fresh air | V11: N | W11: N | X11: N | Y11: =IF($C11="","",CF11) -> 2798016.7 | Z11: =IF($C11="","",Y11/$C11) -> 69.950416 | AA11: =IF($C11="","",IF(E11=0,"",CF11/E11)) -> 107616.03 | AB11: =IF($C11="","",BJ11+BN11+AV11+AZ11+BB11+BY11) -> 1787.5706 | AC11: =IF($C11="","",BJ11) -> 384.84129 | AD11: =IF($C11="","",BN11) -> 198.52582 | AE11: =IF($C11="","",AV11) -> 995.34794 | AF11: =IF($C11="","",AZ11) -> 112.49412 | AG11: =IF($C11="","",BR11) -> 45 | AH11: =IF($C11="","",ROUND(AN11,2)&" x "&ROUND(AO11,2)&" x "&ROUND(AQ11,2)) -> 3.4 x 2.61 x 3.2 | AJ11: =IF($C11="","",$C11*'Assumptions & Ref'!$C$10) -> 67960 | AK11: =IF($C11="","",AJ11/3600) -> 18.877778 | AL11: =IF($C11="","",AK11/'Assumptions & Ref'!$C$6) -> 7.5511111 | AM11: =IF($C11="","",AL11/'Assumptions & Ref'!$C$8) -> 8.8836601 | AN11: =IF($C11="","",SQRT(AM11*'Assumptions & Ref'!$C$9)) -> 3.3983464 | AO11: =IF($C11="","",SQRT(AM11/'Assumptions & Ref'!$C$9)) -> 2.6141126 | AP11: =IF($C11="","",'Assumptions & Ref'!$C$14+IF(OR(S11="Pre+Fine",S11="Pre+Fine+HEPA"),'Assumptions & Ref'!$C$15,0)+IF(S11="Pre+Fine+HEPA",'Assumptions & Ref'!$C$16,0)) -> 1.25 | AQ11: =IF($C11="","",IF(V11="Y",'Assumptions & Ref'!$C$13,0)+AP11+'Assumptions & Ref'!$C$17+O11*'Assumptions & Ref'!$C$18+IF(W11="Y",'Assumptions & Ref'!$C$19,0)+'Assumptions & Ref'!$C$20+IF(X11="Y",'Assumptions & Ref'!$C$21,0)) -> 3.2 | AR11: =IF($C11="","",2*(AN11+AO11)*AQ11+2*AN11*AO11) -> 56.247058 | AS11: =IF($C11="","",IF(H11="Double skin",2,1)) -> 2 | AT11: =IF($C11="","",INDEX($C$5:$I$5,MATCH(J11,$C$4:$I$4,0))) -> 7900 | AU11: =IF($C11="","",INDEX($C$6:$I$6,MATCH(J11,$C$4:$I$4,0))) -> 260 | AV11: =IF($C11="","",AR11*AS11*I11/1000*AT11*(1+'Assumptions & Ref'!$C$75)) -> 995.34794 | AW11: =IF($C11="","",INDEX($C$5:$I$5,MATCH(K11,$C$4:$I$4,0))) -> 40 | AX11: =IF($C11="","",INDEX($C$6:$I$6,MATCH(K11,$C$4:$I$4,0))) -> 350 | AY11: =IF($C11="","",AR11*L11/1000) -> 2.8123529 | AZ11: =IF($C11="","",AY11*AW11) -> 112.49412 | BA11: =IF($C11="","",4*(AN11+AO11+AQ11)) -> 36.849836 | BB11: =IF($C11="","",BA11*'Assumptions & Ref'!$C$76) -> 68.172197 | BC11: =IF($C11="","",BB11*'Assumptions & Ref'!$C$77) -> 23178.547 | BD11: =IF($C11="","",SQRT(AL11/'Assumptions & Ref'!$C$9)) -> 2.4100927 | BE11: =IF($C11="","",SQRT(AL11*'Assumptions & Ref'!$C$9)) -> 3.1331206 | BF11: =IF($C11="","",BD11*1000/'Assumptions & Ref'!$C$27) -> 96.40371 | BG11: =IF($C11="","",BF11*O11) -> 771.22968 | BH11: =IF($C11="","",BG11*BE11*(1+'Assumptions & Ref'!$C$29)) -> 2778.8089 | BI11: =IF($C11="","",PI()*('Assumptions & Ref'!$C$25-'Assumptions & Ref'!$C$26)/1000*'Assumptions & Ref'!$C$26/1000*$C$5) -> 0.13849146 | BJ11: =IF($C11="","",BH11*BI11) -> 384.84129 | BK11: =IF($C11="","",BE11*1000*P11/25.4) -> 1726.9168 | BL11: =IF($C11="","",O11*'Assumptions & Ref'!$C$28/1000) -> 0.1732 | BM11: =IF($C11="","",BD11*BL11*(1-'Assumptions & Ref'!$C$31)) -> 0.35481385 | BN11: =IF($C11="","",BK11*BM11*'Assumptions & Ref'!$C$30/1000*INDEX($C$5:$I$5,MATCH(R11,$C$4:$I$4,0))) -> 198.52582 | BO11: =IF($C11="","",'Assumptions & Ref'!$C$34+O11*'Assumptions & Ref'!$C$35+'Assumptions & Ref'!$C$36+IF(OR(S11="Pre+Fine",S11="Pre+Fine+HEPA"),'Assumptions & Ref'!$C$37,0)+IF(S11="Pre+Fine+HEPA",'Assumptions & Ref'!$C$38,0)) -> 716 | BP11: =IF($C11="","",G11+BO11) -> 1316 | BQ11: =IF($C11="","",AK11*BP11/(1000*IF(M11="Plug fan",'Assumptions & Ref'!$C$39,'Assumptions & Ref'!$C$40)*'Assumptions & Ref'!$C$41)) -> 40.593391 | BR11: =IF($C11="","",IFERROR(INDEX('Assumptions & Ref'!$B$44:$B$61,MATCH(BQ11,'Assumptions & Ref'!$B$44:$B$61,1)+IF(INDEX('Assumptions & Ref'!$B$44:$B$61,MATCH(BQ11,'Assumptions & Ref'!$B$44:$B$61,1))>=BQ11,0,1)),INDEX('Assumptions & Ref'!$B$44:$B$61,1))) -> 45 | BS11: =IF($C11="","",BR11*IF(M11="Plug fan",'Assumptions & Ref'!$C$64,'Assumptions & Ref'!$C$65)) -> 652500 | BT11: =IF($C11="","",IF(N11="Y",BR11*'Assumptions & Ref'!$C$66,0)) -> 337500 | BU11: =IF($C11="","",AM11) -> 8.8836601 | BV11: =IF($C11="","",BU11*('Assumptions & Ref'!$C$67+IF(OR(S11="Pre+Fine",S11="Pre+Fine+HEPA"),'Assumptions & Ref'!$C$68,0)+IF(S11="Pre+Fine+HEPA",'Assumptions & Ref'!$C$69,0))) -> 165236.08 | BW11: =IF($C11="","",AM11*IF(U11="Mixed (return+fresh)",2,1)) -> 8.8836601 | BX11: =IF($C11="","",BW11*'Assumptions & Ref'!$C$70) -> 46195.033 | BY11: =IF($C11="","",AN11*('Assumptions & Ref'!$C$17+O11*'Assumptions & Ref'!$C$18+0.2)*'Assumptions & Ref'!$C$81/1000*$G$5) -> 28.189283 | BZ11: =IF($C11="","",BY11*$G$6) -> 7329.2137 | CA11: =IF($C11="","",BJ11*$C$6+BN11*INDEX($C$6:$I$6,MATCH(R11,$C$4:$I$4,0))+AV11*AU11+AZ11*AX11+BC11+BZ11) -> 919065.69 | CB11: =IF($C11="","",BS11+BT11+BV11+BX11) -> 1201431.1 | CC11: =IF($C11="","",(AV11+BB11)*'Assumptions & Ref'!$C$78+(BJ11+BN11)*'Assumptions & Ref'!$C$80) -> 150620.62 | CD11: =IF($C11="","",'Assumptions & Ref'!$C$84*(CA11+CB11+CC11)) -> 227111.74 | CE11: =IF($C11="","",'Assumptions & Ref'!$C$85*(CA11+CB11+CC11+CD11)) -> 299787.5 | CF11: =IF($C11="","",CA11+CB11+CC11+CD11+CE11) -> 2798016.7 | CH11: =IF($C11="","",CA11) -> 919065.69 | CI11: =IF($C11="","",CB11+CC11) -> 1352051.7 | CJ11: =IF($C11="","",CD11+CE11) -> 526899.24
B12: AHU-04 Basement CSU | C12: 4000 | E12: 20 | F12: 0 | G12: 200 | H12: Single skin | I12: 0.63 | J12: GI sheet | K12: Rockwool | L12: 25 | M12: Belt-driven | N12: N | O12: 4 | P12: 10 | Q12: Copper tube | R12: Aluminium fin | S12: Pre only | T12: Floor mounted | U12: Return air | V12: N | W12: N | X12: N | Y12: =IF($C12="","",CF12) -> 106271.7 | Z12: =IF($C12="","",Y12/$C12) -> 26.567924 | AA12: =IF($C12="","",IF(E12=0,"",CF12/E12)) -> 5313.5849 | AB12: =IF($C12="","",BJ12+BN12+AV12+AZ12+BB12+BY12) -> 131.12298 | AC12: =IF($C12="","",BJ12) -> 19.242065 | AD12: =IF($C12="","",BN12) -> 7.0902079 | AE12: =IF($C12="","",AV12) -> 53.019416 | AF12: =IF($C12="","",AZ12) -> 15.315342 | AG12: =IF($C12="","",BR12) -> 2.2 | AH12: =IF($C12="","",ROUND(AN12,2)&" x "&ROUND(AO12,2)&" x "&ROUND(AQ12,2)) -> 1.07 x 0.83 x 2.05 | AJ12: =IF($C12="","",$C12*'Assumptions & Ref'!$C$10) -> 6796 | AK12: =IF($C12="","",AJ12/3600) -> 1.8877778 | AL12: =IF($C12="","",AK12/'Assumptions & Ref'!$C$6) -> 0.75511111 | AM12: =IF($C12="","",AL12/'Assumptions & Ref'!$C$8) -> 0.88836601 | AN12: =IF($C12="","",SQRT(AM12*'Assumptions & Ref'!$C$9)) -> 1.0746515 | AO12: =IF($C12="","",SQRT(AM12/'Assumptions & Ref'!$C$9)) -> 0.82665499 | AP12: =IF($C12="","",'Assumptions & Ref'!$C$14+IF(OR(S12="Pre+Fine",S12="Pre+Fine+HEPA"),'Assumptions & Ref'!$C$15,0)+IF(S12="Pre+Fine+HEPA",'Assumptions & Ref'!$C$16,0)) -> 0.3 | AQ12: =IF($C12="","",IF(V12="Y",'Assumptions & Ref'!$C$13,0)+AP12+'Assumptions & Ref'!$C$17+O12*'Assumptions & Ref'!$C$18+IF(W12="Y",'Assumptions & Ref'!$C$19,0)+'Assumptions & Ref'!$C$20+IF(X12="Y",'Assumptions & Ref'!$C$21,0)) -> 2.05 | AR12: =IF($C12="","",2*(AN12+AO12)*AQ12+2*AN12*AO12) -> 9.5720886 | AS12: =IF($C12="","",IF(H12="Double skin",2,1)) -> 1 | AT12: =IF($C12="","",INDEX($C$5:$I$5,MATCH(J12,$C$4:$I$4,0))) -> 7850 | AU12: =IF($C12="","",INDEX($C$6:$I$6,MATCH(J12,$C$4:$I$4,0))) -> 80 | AV12: =IF($C12="","",AR12*AS12*I12/1000*AT12*(1+'Assumptions & Ref'!$C$75)) -> 53.019416 | AW12: =IF($C12="","",INDEX($C$5:$I$5,MATCH(K12,$C$4:$I$4,0))) -> 64 | AX12: =IF($C12="","",INDEX($C$6:$I$6,MATCH(K12,$C$4:$I$4,0))) -> 85 | AY12: =IF($C12="","",AR12*L12/1000) -> 0.23930221 | AZ12: =IF($C12="","",AY12*AW12) -> 15.315342 | BA12: =IF($C12="","",4*(AN12+AO12+AQ12)) -> 15.805226 | BB12: =IF($C12="","",BA12*'Assumptions & Ref'!$C$76) -> 29.239668 | BC12: =IF($C12="","",BB12*'Assumptions & Ref'!$C$77) -> 9941.4871 | BD12: =IF($C12="","",SQRT(AL12/'Assumptions & Ref'!$C$9)) -> 0.76213824 | BE12: =IF($C12="","",SQRT(AL12*'Assumptions & Ref'!$C$9)) -> 0.99077972 | BF12: =IF($C12="","",BD12*1000/'Assumptions & Ref'!$C$27) -> 30.48553 | BG12: =IF($C12="","",BF12*O12) -> 121.94212 | BH12: =IF($C12="","",BG12*BE12*(1+'Assumptions & Ref'!$C$29)) -> 138.94044 | BI12: =IF($C12="","",PI()*('Assumptions & Ref'!$C$25-'Assumptions & Ref'!$C$26)/1000*'Assumptions & Ref'!$C$26/1000*$C$5) -> 0.13849146 | BJ12: =IF($C12="","",BH12*BI12) -> 19.242065 | BK12: =IF($C12="","",BE12*1000*P12/25.4) -> 390.07075 | BL12: =IF($C12="","",O12*'Assumptions & Ref'!$C$28/1000) -> 0.0866 | BM12: =IF($C12="","",BD12*BL12*(1-'Assumptions & Ref'!$C$31)) -> 0.056100996 | BN12: =IF($C12="","",BK12*BM12*'Assumptions & Ref'!$C$30/1000*INDEX($C$5:$I$5,MATCH(R12,$C$4:$I$4,0))) -> 7.0902079 | BO12: =IF($C12="","",'Assumptions & Ref'!$C$34+O12*'Assumptions & Ref'!$C$35+'Assumptions & Ref'!$C$36+IF(OR(S12="Pre+Fine",S12="Pre+Fine+HEPA"),'Assumptions & Ref'!$C$37,0)+IF(S12="Pre+Fine+HEPA",'Assumptions & Ref'!$C$38,0)) -> 258 | BP12: =IF($C12="","",G12+BO12) -> 458 | BQ12: =IF($C12="","",AK12*BP12/(1000*IF(M12="Plug fan",'Assumptions & Ref'!$C$39,'Assumptions & Ref'!$C$40)*'Assumptions & Ref'!$C$41)) -> 1.5494663 | BR12: =IF($C12="","",IFERROR(INDEX('Assumptions & Ref'!$B$44:$B$61,MATCH(BQ12,'Assumptions & Ref'!$B$44:$B$61,1)+IF(INDEX('Assumptions & Ref'!$B$44:$B$61,MATCH(BQ12,'Assumptions & Ref'!$B$44:$B$61,1))>=BQ12,0,1)),INDEX('Assumptions & Ref'!$B$44:$B$61,1))) -> 2.2 | BS12: =IF($C12="","",BR12*IF(M12="Plug fan",'Assumptions & Ref'!$C$64,'Assumptions & Ref'!$C$65)) -> 24200 | BT12: =IF($C12="","",IF(N12="Y",BR12*'Assumptions & Ref'!$C$66,0)) -> 0 | BU12: =IF($C12="","",AM12) -> 0.88836601 | BV12: =IF($C12="","",BU12*('Assumptions & Ref'!$C$67+IF(OR(S12="Pre+Fine",S12="Pre+Fine+HEPA"),'Assumptions & Ref'!$C$68,0)+IF(S12="Pre+Fine+HEPA",'Assumptions & Ref'!$C$69,0))) -> 1243.7124 | BW12: =IF($C12="","",AM12*IF(U12="Mixed (return+fresh)",2,1)) -> 0.88836601 | BX12: =IF($C12="","",BW12*'Assumptions & Ref'!$C$70) -> 4619.5033 | BY12: =IF($C12="","",AN12*('Assumptions & Ref'!$C$17+O12*'Assumptions & Ref'!$C$18+0.2)*'Assumptions & Ref'!$C$81/1000*$G$5) -> 7.2162847 | BZ12: =IF($C12="","",BY12*$G$6) -> 1876.234 | CA12: =IF($C12="","",BJ12*$C$6+BN12*INDEX($C$6:$I$6,MATCH(R12,$C$4:$I$4,0))+AV12*AU12+AZ12*AX12+BC12+BZ12) -> 46143.423 | CB12: =IF($C12="","",BS12+BT12+BV12+BX12) -> 30063.216 | CC12: =IF($C12="","",(AV12+BB12)*'Assumptions & Ref'!$C$78+(BJ12+BN12)*'Assumptions & Ref'!$C$80) -> 10052.856 | CD12: =IF($C12="","",'Assumptions & Ref'!$C$84*(CA12+CB12+CC12)) -> 8625.9495 | CE12: =IF($C12="","",'Assumptions & Ref'!$C$85*(CA12+CB12+CC12+CD12)) -> 11386.253 | CF12: =IF($C12="","",CA12+CB12+CC12+CD12+CE12) -> 106271.7 | CH12: =IF($C12="","",CA12) -> 46143.423 | CI12: =IF($C12="","",CB12+CC12) -> 40116.072 | CJ12: =IF($C12="","",CD12+CE12) -> 20012.203
B13: AHU-05 Treated fresh air | C13: 5000 | E13: 25 | F13: 0 | G13: 400 | H13: Double skin | I13: 0.8 | J13: Pre-coated GI | K13: PUF | L13: 50 | M13: Plug fan | N13: Y | O13: 8 | P13: 14 | Q13: Copper tube | R13: Aluminium fin | S13: Pre+Fine | T13: Rooftop | U13: 100% fresh air | V13: N | W13: N | X13: N | Y13: =IF($C13="","",CF13) -> 291505.62 | Z13: =IF($C13="","",Y13/$C13) -> 58.301124 | AA13: =IF($C13="","",IF(E13=0,"",CF13/E13)) -> 11660.225 | AB13: =IF($C13="","",BJ13+BN13+AV13+AZ13+BB13+BY13) -> 338.7156 | AC13: =IF($C13="","",BJ13) -> 48.105162 | AD13: =IF($C13="","",BN13) -> 24.815728 | AE13: =IF($C13="","",AV13) -> 192.71827 | AF13: =IF($C13="","",AZ13) -> 27.399663 | AG13: =IF($C13="","",BR13) -> 3.7 | AH13: =IF($C13="","",ROUND(AN13,2)&" x "&ROUND(AO13,2)&" x "&ROUND(AQ13,2)) -> 1.2 x 0.92 x 2.7 | AJ13: =IF($C13="","",$C13*'Assumptions & Ref'!$C$10) -> 8495 | AK13: =IF($C13="","",AJ13/3600) -> 2.3597222 | AL13: =IF($C13="","",AK13/'Assumptions & Ref'!$C$6) -> 0.94388889 | AM13: =IF($C13="","",AL13/'Assumptions & Ref'!$C$8) -> 1.1104575 | AN13: =IF($C13="","",SQRT(AM13*'Assumptions & Ref'!$C$9)) -> 1.2014969 | AO13: =IF($C13="","",SQRT(AM13/'Assumptions & Ref'!$C$9)) -> 0.92422838 | AP13: =IF($C13="","",'Assumptions & Ref'!$C$14+IF(OR(S13="Pre+Fine",S13="Pre+Fine+HEPA"),'Assumptions & Ref'!$C$15,0)+IF(S13="Pre+Fine+HEPA",'Assumptions & Ref'!$C$16,0)) -> 0.75 | AQ13: =IF($C13="","",IF(V13="Y",'Assumptions & Ref'!$C$13,0)+AP13+'Assumptions & Ref'!$C$17+O13*'Assumptions & Ref'!$C$18+IF(W13="Y",'Assumptions & Ref'!$C$19,0)+'Assumptions & Ref'!$C$20+IF(X13="Y",'Assumptions & Ref'!$C$21,0)) -> 2.7 | AR13: =IF($C13="","",2*(AN13+AO13)*AQ13+2*AN13*AO13) -> 13.699831 | AS13: =IF($C13="","",IF(H13="Double skin",2,1)) -> 2 | AT13: =IF($C13="","",INDEX($C$5:$I$5,MATCH(J13,$C$4:$I$4,0))) -> 7850 | AU13: =IF($C13="","",INDEX($C$6:$I$6,MATCH(J13,$C$4:$I$4,0))) -> 95 | AV13: =IF($C13="","",AR13*AS13*I13/1000*AT13*(1+'Assumptions & Ref'!$C$75)) -> 192.71827 | AW13: =IF($C13="","",INDEX($C$5:$I$5,MATCH(K13,$C$4:$I$4,0))) -> 40 | AX13: =IF($C13="","",INDEX($C$6:$I$6,MATCH(K13,$C$4:$I$4,0))) -> 350 | AY13: =IF($C13="","",AR13*L13/1000) -> 0.68499157 | AZ13: =IF($C13="","",AY13*AW13) -> 27.399663 | BA13: =IF($C13="","",4*(AN13+AO13+AQ13)) -> 19.302901 | BB13: =IF($C13="","",BA13*'Assumptions & Ref'!$C$76) -> 35.710367 | BC13: =IF($C13="","",BB13*'Assumptions & Ref'!$C$77) -> 12141.525 | BD13: =IF($C13="","",SQRT(AL13/'Assumptions & Ref'!$C$9)) -> 0.85209646 | BE13: =IF($C13="","",SQRT(AL13*'Assumptions & Ref'!$C$9)) -> 1.1077254 | BF13: =IF($C13="","",BD13*1000/'Assumptions & Ref'!$C$27) -> 34.083858 | BG13: =IF($C13="","",BF13*O13) -> 272.67087 | BH13: =IF($C13="","",BG13*BE13*(1+'Assumptions & Ref'!$C$29)) -> 347.35111 | BI13: =IF($C13="","",PI()*('Assumptions & Ref'!$C$25-'Assumptions & Ref'!$C$26)/1000*'Assumptions & Ref'!$C$26/1000*$C$5) -> 0.13849146 | BJ13: =IF($C13="","",BH13*BI13) -> 48.105162 | BK13: =IF($C13="","",BE13*1000*P13/25.4) -> 610.55731 | BL13: =IF($C13="","",O13*'Assumptions & Ref'!$C$28/1000) -> 0.1732 | BM13: =IF($C13="","",BD13*BL13*(1-'Assumptions & Ref'!$C$31)) -> 0.12544564 | BN13: =IF($C13="","",BK13*BM13*'Assumptions & Ref'!$C$30/1000*INDEX($C$5:$I$5,MATCH(R13,$C$4:$I$4,0))) -> 24.815728 | BO13: =IF($C13="","",'Assumptions & Ref'!$C$34+O13*'Assumptions & Ref'!$C$35+'Assumptions & Ref'!$C$36+IF(OR(S13="Pre+Fine",S13="Pre+Fine+HEPA"),'Assumptions & Ref'!$C$37,0)+IF(S13="Pre+Fine+HEPA",'Assumptions & Ref'!$C$38,0)) -> 466 | BP13: =IF($C13="","",G13+BO13) -> 866 | BQ13: =IF($C13="","",AK13*BP13/(1000*IF(M13="Plug fan",'Assumptions & Ref'!$C$39,'Assumptions & Ref'!$C$40)*'Assumptions & Ref'!$C$41)) -> 3.3390841 | BR13: =IF($C13="","",IFERROR(INDEX('Assumptions & Ref'!$B$44:$B$61,MATCH(BQ13,'Assumptions & Ref'!$B$44:$B$61,1)+IF(INDEX('Assumptions & Ref'!$B$44:$B$61,MATCH(BQ13,'Assumptions & Ref'!$B$44:$B$61,1))>=BQ13,0,1)),INDEX('Assumptions & Ref'!$B$44:$B$61,1))) -> 3.7 | BS13: =IF($C13="","",BR13*IF(M13="Plug fan",'Assumptions & Ref'!$C$64,'Assumptions & Ref'!$C$65)) -> 53650 | BT13: =IF($C13="","",IF(N13="Y",BR13*'Assumptions & Ref'!$C$66,0)) -> 27750 | BU13: =IF($C13="","",AM13) -> 1.1104575 | BV13: =IF($C13="","",BU13*('Assumptions & Ref'!$C$67+IF(OR(S13="Pre+Fine",S13="Pre+Fine+HEPA"),'Assumptions & Ref'!$C$68,0)+IF(S13="Pre+Fine+HEPA",'Assumptions & Ref'!$C$69,0))) -> 5108.1046 | BW13: =IF($C13="","",AM13*IF(U13="Mixed (return+fresh)",2,1)) -> 1.1104575 | BX13: =IF($C13="","",BW13*'Assumptions & Ref'!$C$70) -> 5774.3791 | BY13: =IF($C13="","",AN13*('Assumptions & Ref'!$C$17+O13*'Assumptions & Ref'!$C$18+0.2)*'Assumptions & Ref'!$C$81/1000*$G$5) -> 9.9664167 | BZ13: =IF($C13="","",BY13*$G$6) -> 2591.2683 | CA13: =IF($C13="","",BJ13*$C$6+BN13*INDEX($C$6:$I$6,MATCH(R13,$C$4:$I$4,0))+AV13*AU13+AZ13*AX13+BC13+BZ13) -> 116430.23 | CB13: =IF($C13="","",BS13+BT13+BV13+BX13) -> 92282.484 | CC13: =IF($C13="","",(AV13+BB13)*'Assumptions & Ref'!$C$78+(BJ13+BN13)*'Assumptions & Ref'!$C$80) -> 27898.996 | CD13: =IF($C13="","",'Assumptions & Ref'!$C$84*(CA13+CB13+CC13)) -> 23661.171 | CE13: =IF($C13="","",'Assumptions & Ref'!$C$85*(CA13+CB13+CC13+CD13)) -> 31232.745 | CF13: =IF($C13="","",CA13+CB13+CC13+CD13+CE13) -> 291505.62 | CH13: =IF($C13="","",CA13) -> 116430.23 | CI13: =IF($C13="","",CB13+CC13) -> 120181.48 | CJ13: =IF($C13="","",CD13+CE13) -> 54893.916
B14: AHU-06 Auditorium | C14: 20000 | E14: 60 | F14: 0 | G14: 350 | H14: Double skin | I14: 0.8 | J14: Pre-coated GI | K14: PUF | L14: 25 | M14: Plug fan | N14: Y | O14: 6 | P14: 12 | Q14: Copper tube | R14: Aluminium fin | S14: Pre+Fine | T14: Floor mounted | U14: Mixed (return+fresh) | V14: Y | W14: N | X14: Y | Y14: =IF($C14="","",CF14) -> 970914.06 | Z14: =IF($C14="","",Y14/$C14) -> 48.545703 | AA14: =IF($C14="","",IF(E14=0,"",CF14/E14)) -> 16181.901 | AB14: =IF($C14="","",BJ14+BN14+AV14+AZ14+BB14+BY14) -> 906.4311 | AC14: =IF($C14="","",BJ14) -> 144.31548 | AD14: =IF($C14="","",BN14) -> 63.811871 | AE14: =IF($C14="","",AV14) -> 579.49386 | AF14: =IF($C14="","",AZ14) -> 41.194684 | AG14: =IF($C14="","",BR14) -> 15 | AH14: =IF($C14="","",ROUND(AN14,2)&" x "&ROUND(AO14,2)&" x "&ROUND(AQ14,2)) -> 2.4 x 1.85 x 3.8 | AJ14: =IF($C14="","",$C14*'Assumptions & Ref'!$C$10) -> 33980 | AK14: =IF($C14="","",AJ14/3600) -> 9.4388889 | AL14: =IF($C14="","",AK14/'Assumptions & Ref'!$C$6) -> 3.7755556 | AM14: =IF($C14="","",AL14/'Assumptions & Ref'!$C$8) -> 4.4418301 | AN14: =IF($C14="","",SQRT(AM14*'Assumptions & Ref'!$C$9)) -> 2.4029938 | AO14: =IF($C14="","",SQRT(AM14/'Assumptions & Ref'!$C$9)) -> 1.8484568 | AP14: =IF($C14="","",'Assumptions & Ref'!$C$14+IF(OR(S14="Pre+Fine",S14="Pre+Fine+HEPA"),'Assumptions & Ref'!$C$15,0)+IF(S14="Pre+Fine+HEPA",'Assumptions & Ref'!$C$16,0)) -> 0.75 | AQ14: =IF($C14="","",IF(V14="Y",'Assumptions & Ref'!$C$13,0)+AP14+'Assumptions & Ref'!$C$17+O14*'Assumptions & Ref'!$C$18+IF(W14="Y",'Assumptions & Ref'!$C$19,0)+'Assumptions & Ref'!$C$20+IF(X14="Y",'Assumptions & Ref'!$C$21,0)) -> 3.8 | AR14: =IF($C14="","",2*(AN14+AO14)*AQ14+2*AN14*AO14) -> 41.194684 | AS14: =IF($C14="","",IF(H14="Double skin",2,1)) -> 2 | AT14: =IF($C14="","",INDEX($C$5:$I$5,MATCH(J14,$C$4:$I$4,0))) -> 7850 | AU14: =IF($C14="","",INDEX($C$6:$I$6,MATCH(J14,$C$4:$I$4,0))) -> 95 | AV14: =IF($C14="","",AR14*AS14*I14/1000*AT14*(1+'Assumptions & Ref'!$C$75)) -> 579.49386 | AW14: =IF($C14="","",INDEX($C$5:$I$5,MATCH(K14,$C$4:$I$4,0))) -> 40 | AX14: =IF($C14="","",INDEX($C$6:$I$6,MATCH(K14,$C$4:$I$4,0))) -> 350 | AY14: =IF($C14="","",AR14*L14/1000) -> 1.0298671 | AZ14: =IF($C14="","",AY14*AW14) -> 41.194684 | BA14: =IF($C14="","",4*(AN14+AO14+AQ14)) -> 32.205802 | BB14: =IF($C14="","",BA14*'Assumptions & Ref'!$C$76) -> 59.580734 | BC14: =IF($C14="","",BB14*'Assumptions & Ref'!$C$77) -> 20257.45 | BD14: =IF($C14="","",SQRT(AL14/'Assumptions & Ref'!$C$9)) -> 1.7041929 | BE14: =IF($C14="","",SQRT(AL14*'Assumptions & Ref'!$C$9)) -> 2.2154508 | BF14: =IF($C14="","",BD14*1000/'Assumptions & Ref'!$C$27) -> 68.167717 | BG14: =IF($C14="","",BF14*O14) -> 409.0063 | BH14: =IF($C14="","",BG14*BE14*(1+'Assumptions & Ref'!$C$29)) -> 1042.0533 | BI14: =IF($C14="","",PI()*('Assumptions & Ref'!$C$25-'Assumptions & Ref'!$C$26)/1000*'Assumptions & Ref'!$C$26/1000*$C$5) -> 0.13849146 | BJ14: =IF($C14="","",BH14*BI14) -> 144.31548 | BK14: =IF($C14="","",BE14*1000*P14/25.4) -> 1046.6697 | BL14: =IF($C14="","",O14*'Assumptions & Ref'!$C$28/1000) -> 0.1299 | BM14: =IF($C14="","",BD14*BL14*(1-'Assumptions & Ref'!$C$31)) -> 0.18816846 | BN14: =IF($C14="","",BK14*BM14*'Assumptions & Ref'!$C$30/1000*INDEX($C$5:$I$5,MATCH(R14,$C$4:$I$4,0))) -> 63.811871 | BO14: =IF($C14="","",'Assumptions & Ref'!$C$34+O14*'Assumptions & Ref'!$C$35+'Assumptions & Ref'!$C$36+IF(OR(S14="Pre+Fine",S14="Pre+Fine+HEPA"),'Assumptions & Ref'!$C$37,0)+IF(S14="Pre+Fine+HEPA",'Assumptions & Ref'!$C$38,0)) -> 422 | BP14: =IF($C14="","",G14+BO14) -> 772 | BQ14: =IF($C14="","",AK14*BP14/(1000*IF(M14="Plug fan",'Assumptions & Ref'!$C$39,'Assumptions & Ref'!$C$40)*'Assumptions & Ref'!$C$41)) -> 11.906572 | BR14: =IF($C14="","",IFERROR(INDEX('Assumptions & Ref'!$B$44:$B$61,MATCH(BQ14,'Assumptions & Ref'!$B$44:$B$61,1)+IF(INDEX('Assumptions & Ref'!$B$44:$B$61,MATCH(BQ14,'Assumptions & Ref'!$B$44:$B$61,1))>=BQ14,0,1)),INDEX('Assumptions & Ref'!$B$44:$B$61,1))) -> 15 | BS14: =IF($C14="","",BR14*IF(M14="Plug fan",'Assumptions & Ref'!$C$64,'Assumptions & Ref'!$C$65)) -> 217500 | BT14: =IF($C14="","",IF(N14="Y",BR14*'Assumptions & Ref'!$C$66,0)) -> 112500 | BU14: =IF($C14="","",AM14) -> 4.4418301 | BV14: =IF($C14="","",BU14*('Assumptions & Ref'!$C$67+IF(OR(S14="Pre+Fine",S14="Pre+Fine+HEPA"),'Assumptions & Ref'!$C$68,0)+IF(S14="Pre+Fine+HEPA",'Assumptions & Ref'!$C$69,0))) -> 20432.418 | BW14: =IF($C14="","",AM14*IF(U14="Mixed (return+fresh)",2,1)) -> 8.8836601 | BX14: =IF($C14="","",BW14*'Assumptions & Ref'!$C$70) -> 46195.033 | BY14: =IF($C14="","",AN14*('Assumptions & Ref'!$C$17+O14*'Assumptions & Ref'!$C$18+0.2)*'Assumptions & Ref'!$C$81/1000*$G$5) -> 18.034468 | BZ14: =IF($C14="","",BY14*$G$6) -> 4688.9618 | CA14: =IF($C14="","",BJ14*$C$6+BN14*INDEX($C$6:$I$6,MATCH(R14,$C$4:$I$4,0))+AV14*AU14+AZ14*AX14+BC14+BZ14) -> 313049.23 | CB14: =IF($C14="","",BS14+BT14+BV14+BX14) -> 396627.45 | CC14: =IF($C14="","",(AV14+BB14)*'Assumptions & Ref'!$C$78+(BJ14+BN14)*'Assumptions & Ref'!$C$80) -> 78402.912 | CD14: =IF($C14="","",'Assumptions & Ref'!$C$84*(CA14+CB14+CC14)) -> 78807.96 | CE14: =IF($C14="","",'Assumptions & Ref'!$C$85*(CA14+CB14+CC14+CD14)) -> 104026.51 | CF14: =IF($C14="","",CA14+CB14+CC14+CD14+CE14) -> 970914.06 | CH14: =IF($C14="","",CA14) -> 313049.23 | CI14: =IF($C14="","",CB14+CC14) -> 475030.36 | CJ14: =IF($C14="","",CD14+CE14) -> 182834.47
Y15: =IF($C15="","",CF15) | Z15: =IF($C15="","",Y15/$C15) | AA15: =IF($C15="","",IF(E15=0,"",CF15/E15)) | AB15: =IF($C15="","",BJ15+BN15+AV15+AZ15+BB15+BY15) | AC15: =IF($C15="","",BJ15) | AD15: =IF($C15="","",BN15) | AE15: =IF($C15="","",AV15) | AF15: =IF($C15="","",AZ15) | AG15: =IF($C15="","",BR15) | AH15: =IF($C15="","",ROUND(AN15,2)&" x "&ROUND(AO15,2)&" x "&ROUND(AQ15,2)) | AJ15: =IF($C15="","",$C15*'Assumptions & Ref'!$C$10) | AK15: =IF($C15="","",AJ15/3600) | AL15: =IF($C15="","",AK15/'Assumptions & Ref'!$C$6) | AM15: =IF($C15="","",AL15/'Assumptions & Ref'!$C$8) | AN15: =IF($C15="","",SQRT(AM15*'Assumptions & Ref'!$C$9)) | AO15: =IF($C15="","",SQRT(AM15/'Assumptions & Ref'!$C$9)) | AP15: =IF($C15="","",'Assumptions & Ref'!$C$14+IF(OR(S15="Pre+Fine",S15="Pre+Fine+HEPA"),'Assumptions & Ref'!$C$15,0)+IF(S15="Pre+Fine+HEPA",'Assumptions & Ref'!$C$16,0)) | AQ15: =IF($C15="","",IF(V15="Y",'Assumptions & Ref'!$C$13,0)+AP15+'Assumptions & Ref'!$C$17+O15*'Assumptions & Ref'!$C$18+IF(W15="Y",'Assumptions & Ref'!$C$19,0)+'Assumptions & Ref'!$C$20+IF(X15="Y",'Assumptions & Ref'!$C$21,0)) | AR15: =IF($C15="","",2*(AN15+AO15)*AQ15+2*AN15*AO15) | AS15: =IF($C15="","",IF(H15="Double skin",2,1)) | AT15: =IF($C15="","",INDEX($C$5:$I$5,MATCH(J15,$C$4:$I$4,0))) | AU15: =IF($C15="","",INDEX($C$6:$I$6,MATCH(J15,$C$4:$I$4,0))) | AV15: =IF($C15="","",AR15*AS15*I15/1000*AT15*(1+'Assumptions & Ref'!$C$75)) | AW15: =IF($C15="","",INDEX($C$5:$I$5,MATCH(K15,$C$4:$I$4,0))) | AX15: =IF($C15="","",INDEX($C$6:$I$6,MATCH(K15,$C$4:$I$4,0))) | AY15: =IF($C15="","",AR15*L15/1000) | AZ15: =IF($C15="","",AY15*AW15) | BA15: =IF($C15="","",4*(AN15+AO15+AQ15)) | BB15: =IF($C15="","",BA15*'Assumptions & Ref'!$C$76) | BC15: =IF($C15="","",BB15*'Assumptions & Ref'!$C$77) | BD15: =IF($C15="","",SQRT(AL15/'Assumptions & Ref'!$C$9)) | BE15: =IF($C15="","",SQRT(AL15*'Assumptions & Ref'!$C$9)) | BF15: =IF($C15="","",BD15*1000/'Assumptions & Ref'!$C$27) | BG15: =IF($C15="","",BF15*O15) | BH15: =IF($C15="","",BG15*BE15*(1+'Assumptions & Ref'!$C$29)) | BI15: =IF($C15="","",PI()*('Assumptions & Ref'!$C$25-'Assumptions & Ref'!$C$26)/1000*'Assumptions & Ref'!$C$26/1000*$C$5) | BJ15: =IF($C15="","",BH15*BI15) | BK15: =IF($C15="","",BE15*1000*P15/25.4) | BL15: =IF($C15="","",O15*'Assumptions & Ref'!$C$28/1000) | BM15: =IF($C15="","",BD15*BL15*(1-'Assumptions & Ref'!$C$31)) | BN15: =IF($C15="","",BK15*BM15*'Assumptions & Ref'!$C$30/1000*INDEX($C$5:$I$5,MATCH(R15,$C$4:$I$4,0))) | BO15: =IF($C15="","",'Assumptions & Ref'!$C$34+O15*'Assumptions & Ref'!$C$35+'Assumptions & Ref'!$C$36+IF(OR(S15="Pre+Fine",S15="Pre+Fine+HEPA"),'Assumptions & Ref'!$C$37,0)+IF(S15="Pre+Fine+HEPA",'Assumptions & Ref'!$C$38,0)) | BP15: =IF($C15="","",G15+BO15) | BQ15: =IF($C15="","",AK15*BP15/(1000*IF(M15="Plug fan",'Assumptions & Ref'!$C$39,'Assumptions & Ref'!$C$40)*'Assumptions & Ref'!$C$41)) | BR15: =IF($C15="","",IFERROR(INDEX('Assumptions & Ref'!$B$44:$B$61,MATCH(BQ15,'Assumptions & Ref'!$B$44:$B$61,1)+IF(INDEX('Assumptions & Ref'!$B$44:$B$61,MATCH(BQ15,'Assumptions & Ref'!$B$44:$B$61,1))>=BQ15,0,1)),INDEX('Assumptions & Ref'!$B$44:$B$61,1))) | BS15: =IF($C15="","",BR15*IF(M15="Plug fan",'Assumptions & Ref'!$C$64,'Assumptions & Ref'!$C$65)) | BT15: =IF($C15="","",IF(N15="Y",BR15*'Assumptions & Ref'!$C$66,0)) | BU15: =IF($C15="","",AM15) | BV15: =IF($C15="","",BU15*('Assumptions & Ref'!$C$67+IF(OR(S15="Pre+Fine",S15="Pre+Fine+HEPA"),'Assumptions & Ref'!$C$68,0)+IF(S15="Pre+Fine+HEPA",'Assumptions & Ref'!$C$69,0))) | BW15: =IF($C15="","",AM15*IF(U15="Mixed (return+fresh)",2,1)) | BX15: =IF($C15="","",BW15*'Assumptions & Ref'!$C$70) | BY15: =IF($C15="","",AN15*('Assumptions & Ref'!$C$17+O15*'Assumptions & Ref'!$C$18+0.2)*'Assumptions & Ref'!$C$81/1000*$G$5) | BZ15: =IF($C15="","",BY15*$G$6) | CA15: =IF($C15="","",BJ15*$C$6+BN15*INDEX($C$6:$I$6,MATCH(R15,$C$4:$I$4,0))+AV15*AU15+AZ15*AX15+BC15+BZ15) | CB15: =IF($C15="","",BS15+BT15+BV15+BX15) | CC15: =IF($C15="","",(AV15+BB15)*'Assumptions & Ref'!$C$78+(BJ15+BN15)*'Assumptions & Ref'!$C$80) | CD15: =IF($C15="","",'Assumptions & Ref'!$C$84*(CA15+CB15+CC15)) | CE15: =IF($C15="","",'Assumptions & Ref'!$C$85*(CA15+CB15+CC15+CD15)) | CF15: =IF($C15="","",CA15+CB15+CC15+CD15+CE15) | CH15: =IF($C15="","",CA15) | CI15: =IF($C15="","",CB15+CC15) | CJ15: =IF($C15="","",CD15+CE15)
Y16: =IF($C16="","",CF16) | Z16: =IF($C16="","",Y16/$C16) | AA16: =IF($C16="","",IF(E16=0,"",CF16/E16)) | AB16: =IF($C16="","",BJ16+BN16+AV16+AZ16+BB16+BY16) | AC16: =IF($C16="","",BJ16) | AD16: =IF($C16="","",BN16) | AE16: =IF($C16="","",AV16) | AF16: =IF($C16="","",AZ16) | AG16: =IF($C16="","",BR16) | AH16: =IF($C16="","",ROUND(AN16,2)&" x "&ROUND(AO16,2)&" x "&ROUND(AQ16,2)) | AJ16: =IF($C16="","",$C16*'Assumptions & Ref'!$C$10) | AK16: =IF($C16="","",AJ16/3600) | AL16: =IF($C16="","",AK16/'Assumptions & Ref'!$C$6) | AM16: =IF($C16="","",AL16/'Assumptions & Ref'!$C$8) | AN16: =IF($C16="","",SQRT(AM16*'Assumptions & Ref'!$C$9)) | AO16: =IF($C16="","",SQRT(AM16/'Assumptions & Ref'!$C$9)) | AP16: =IF($C16="","",'Assumptions & Ref'!$C$14+IF(OR(S16="Pre+Fine",S16="Pre+Fine+HEPA"),'Assumptions & Ref'!$C$15,0)+IF(S16="Pre+Fine+HEPA",'Assumptions & Ref'!$C$16,0)) | AQ16: =IF($C16="","",IF(V16="Y",'Assumptions & Ref'!$C$13,0)+AP16+'Assumptions & Ref'!$C$17+O16*'Assumptions & Ref'!$C$18+IF(W16="Y",'Assumptions & Ref'!$C$19,0)+'Assumptions & Ref'!$C$20+IF(X16="Y",'Assumptions & Ref'!$C$21,0)) | AR16: =IF($C16="","",2*(AN16+AO16)*AQ16+2*AN16*AO16) | AS16: =IF($C16="","",IF(H16="Double skin",2,1)) | AT16: =IF($C16="","",INDEX($C$5:$I$5,MATCH(J16,$C$4:$I$4,0))) | AU16: =IF($C16="","",INDEX($C$6:$I$6,MATCH(J16,$C$4:$I$4,0))) | AV16: =IF($C16="","",AR16*AS16*I16/1000*AT16*(1+'Assumptions & Ref'!$C$75)) | AW16: =IF($C16="","",INDEX($C$5:$I$5,MATCH(K16,$C$4:$I$4,0))) | AX16: =IF($C16="","",INDEX($C$6:$I$6,MATCH(K16,$C$4:$I$4,0))) | AY16: =IF($C16="","",AR16*L16/1000) | AZ16: =IF($C16="","",AY16*AW16) | BA16: =IF($C16="","",4*(AN16+AO16+AQ16)) | BB16: =IF($C16="","",BA16*'Assumptions & Ref'!$C$76) | BC16: =IF($C16="","",BB16*'Assumptions & Ref'!$C$77) | BD16: =IF($C16="","",SQRT(AL16/'Assumptions & Ref'!$C$9)) | BE16: =IF($C16="","",SQRT(AL16*'Assumptions & Ref'!$C$9)) | BF16: =IF($C16="","",BD16*1000/'Assumptions & Ref'!$C$27) | BG16: =IF($C16="","",BF16*O16) | BH16: =IF($C16="","",BG16*BE16*(1+'Assumptions & Ref'!$C$29)) | BI16: =IF($C16="","",PI()*('Assumptions & Ref'!$C$25-'Assumptions & Ref'!$C$26)/1000*'Assumptions & Ref'!$C$26/1000*$C$5) | BJ16: =IF($C16="","",BH16*BI16) | BK16: =IF($C16="","",BE16*1000*P16/25.4) | BL16: =IF($C16="","",O16*'Assumptions & Ref'!$C$28/1000) | BM16: =IF($C16="","",BD16*BL16*(1-'Assumptions & Ref'!$C$31)) | BN16: =IF($C16="","",BK16*BM16*'Assumptions & Ref'!$C$30/1000*INDEX($C$5:$I$5,MATCH(R16,$C$4:$I$4,0))) | BO16: =IF($C16="","",'Assumptions & Ref'!$C$34+O16*'Assumptions & Ref'!$C$35+'Assumptions & Ref'!$C$36+IF(OR(S16="Pre+Fine",S16="Pre+Fine+HEPA"),'Assumptions & Ref'!$C$37,0)+IF(S16="Pre+Fine+HEPA",'Assumptions & Ref'!$C$38,0)) | BP16: =IF($C16="","",G16+BO16) | BQ16: =IF($C16="","",AK16*BP16/(1000*IF(M16="Plug fan",'Assumptions & Ref'!$C$39,'Assumptions & Ref'!$C$40)*'Assumptions & Ref'!$C$41)) | BR16: =IF($C16="","",IFERROR(INDEX('Assumptions & Ref'!$B$44:$B$61,MATCH(BQ16,'Assumptions & Ref'!$B$44:$B$61,1)+IF(INDEX('Assumptions & Ref'!$B$44:$B$61,MATCH(BQ16,'Assumptions & Ref'!$B$44:$B$61,1))>=BQ16,0,1)),INDEX('Assumptions & Ref'!$B$44:$B$61,1))) | BS16: =IF($C16="","",BR16*IF(M16="Plug fan",'Assumptions & Ref'!$C$64,'Assumptions & Ref'!$C$65)) | BT16: =IF($C16="","",IF(N16="Y",BR16*'Assumptions & Ref'!$C$66,0)) | BU16: =IF($C16="","",AM16) | BV16: =IF($C16="","",BU16*('Assumptions & Ref'!$C$67+IF(OR(S16="Pre+Fine",S16="Pre+Fine+HEPA"),'Assumptions & Ref'!$C$68,0)+IF(S16="Pre+Fine+HEPA",'Assumptions & Ref'!$C$69,0))) | BW16: =IF($C16="","",AM16*IF(U16="Mixed (return+fresh)",2,1)) | BX16: =IF($C16="","",BW16*'Assumptions & Ref'!$C$70) | BY16: =IF($C16="","",AN16*('Assumptions & Ref'!$C$17+O16*'Assumptions & Ref'!$C$18+0.2)*'Assumptions & Ref'!$C$81/1000*$G$5) | BZ16: =IF($C16="","",BY16*$G$6) | CA16: =IF($C16="","",BJ16*$C$6+BN16*INDEX($C$6:$I$6,MATCH(R16,$C$4:$I$4,0))+AV16*AU16+AZ16*AX16+BC16+BZ16) | CB16: =IF($C16="","",BS16+BT16+BV16+BX16) | CC16: =IF($C16="","",(AV16+BB16)*'Assumptions & Ref'!$C$78+(BJ16+BN16)*'Assumptions & Ref'!$C$80) | CD16: =IF($C16="","",'Assumptions & Ref'!$C$84*(CA16+CB16+CC16)) | CE16: =IF($C16="","",'Assumptions & Ref'!$C$85*(CA16+CB16+CC16+CD16)) | CF16: =IF($C16="","",CA16+CB16+CC16+CD16+CE16) | CH16: =IF($C16="","",CA16) | CI16: =IF($C16="","",CB16+CC16) | CJ16: =IF($C16="","",CD16+CE16)
Y17: =IF($C17="","",CF17) | Z17: =IF($C17="","",Y17/$C17) | AA17: =IF($C17="","",IF(E17=0,"",CF17/E17)) | AB17: =IF($C17="","",BJ17+BN17+AV17+AZ17+BB17+BY17) | AC17: =IF($C17="","",BJ17) | AD17: =IF($C17="","",BN17) | AE17: =IF($C17="","",AV17) | AF17: =IF($C17="","",AZ17) | AG17: =IF($C17="","",BR17) | AH17: =IF($C17="","",ROUND(AN17,2)&" x "&ROUND(AO17,2)&" x "&ROUND(AQ17,2)) | AJ17: =IF($C17="","",$C17*'Assumptions & Ref'!$C$10) | AK17: =IF($C17="","",AJ17/3600) | AL17: =IF($C17="","",AK17/'Assumptions & Ref'!$C$6) | AM17: =IF($C17="","",AL17/'Assumptions & Ref'!$C$8) | AN17: =IF($C17="","",SQRT(AM17*'Assumptions & Ref'!$C$9)) | AO17: =IF($C17="","",SQRT(AM17/'Assumptions & Ref'!$C$9)) | AP17: =IF($C17="","",'Assumptions & Ref'!$C$14+IF(OR(S17="Pre+Fine",S17="Pre+Fine+HEPA"),'Assumptions & Ref'!$C$15,0)+IF(S17="Pre+Fine+HEPA",'Assumptions & Ref'!$C$16,0)) | AQ17: =IF($C17="","",IF(V17="Y",'Assumptions & Ref'!$C$13,0)+AP17+'Assumptions & Ref'!$C$17+O17*'Assumptions & Ref'!$C$18+IF(W17="Y",'Assumptions & Ref'!$C$19,0)+'Assumptions & Ref'!$C$20+IF(X17="Y",'Assumptions & Ref'!$C$21,0)) | AR17: =IF($C17="","",2*(AN17+AO17)*AQ17+2*AN17*AO17) | AS17: =IF($C17="","",IF(H17="Double skin",2,1)) | AT17: =IF($C17="","",INDEX($C$5:$I$5,MATCH(J17,$C$4:$I$4,0))) | AU17: =IF($C17="","",INDEX($C$6:$I$6,MATCH(J17,$C$4:$I$4,0))) | AV17: =IF($C17="","",AR17*AS17*I17/1000*AT17*(1+'Assumptions & Ref'!$C$75)) | AW17: =IF($C17="","",INDEX($C$5:$I$5,MATCH(K17,$C$4:$I$4,0))) | AX17: =IF($C17="","",INDEX($C$6:$I$6,MATCH(K17,$C$4:$I$4,0))) | AY17: =IF($C17="","",AR17*L17/1000) | AZ17: =IF($C17="","",AY17*AW17) | BA17: =IF($C17="","",4*(AN17+AO17+AQ17)) | BB17: =IF($C17="","",BA17*'Assumptions & Ref'!$C$76) | BC17: =IF($C17="","",BB17*'Assumptions & Ref'!$C$77) | BD17: =IF($C17="","",SQRT(AL17/'Assumptions & Ref'!$C$9)) | BE17: =IF($C17="","",SQRT(AL17*'Assumptions & Ref'!$C$9)) | BF17: =IF($C17="","",BD17*1000/'Assumptions & Ref'!$C$27) | BG17: =IF($C17="","",BF17*O17) | BH17: =IF($C17="","",BG17*BE17*(1+'Assumptions & Ref'!$C$29)) | BI17: =IF($C17="","",PI()*('Assumptions & Ref'!$C$25-'Assumptions & Ref'!$C$26)/1000*'Assumptions & Ref'!$C$26/1000*$C$5) | BJ17: =IF($C17="","",BH17*BI17) | BK17: =IF($C17="","",BE17*1000*P17/25.4) | BL17: =IF($C17="","",O17*'Assumptions & Ref'!$C$28/1000) | BM17: =IF($C17="","",BD17*BL17*(1-'Assumptions & Ref'!$C$31)) | BN17: =IF($C17="","",BK17*BM17*'Assumptions & Ref'!$C$30/1000*INDEX($C$5:$I$5,MATCH(R17,$C$4:$I$4,0))) | BO17: =IF($C17="","",'Assumptions & Ref'!$C$34+O17*'Assumptions & Ref'!$C$35+'Assumptions & Ref'!$C$36+IF(OR(S17="Pre+Fine",S17="Pre+Fine+HEPA"),'Assumptions & Ref'!$C$37,0)+IF(S17="Pre+Fine+HEPA",'Assumptions & Ref'!$C$38,0)) | BP17: =IF($C17="","",G17+BO17) | BQ17: =IF($C17="","",AK17*BP17/(1000*IF(M17="Plug fan",'Assumptions & Ref'!$C$39,'Assumptions & Ref'!$C$40)*'Assumptions & Ref'!$C$41)) | BR17: =IF($C17="","",IFERROR(INDEX('Assumptions & Ref'!$B$44:$B$61,MATCH(BQ17,'Assumptions & Ref'!$B$44:$B$61,1)+IF(INDEX('Assumptions & Ref'!$B$44:$B$61,MATCH(BQ17,'Assumptions & Ref'!$B$44:$B$61,1))>=BQ17,0,1)),INDEX('Assumptions & Ref'!$B$44:$B$61,1))) | BS17: =IF($C17="","",BR17*IF(M17="Plug fan",'Assumptions & Ref'!$C$64,'Assumptions & Ref'!$C$65)) | BT17: =IF($C17="","",IF(N17="Y",BR17*'Assumptions & Ref'!$C$66,0)) | BU17: =IF($C17="","",AM17) | BV17: =IF($C17="","",BU17*('Assumptions & Ref'!$C$67+IF(OR(S17="Pre+Fine",S17="Pre+Fine+HEPA"),'Assumptions & Ref'!$C$68,0)+IF(S17="Pre+Fine+HEPA",'Assumptions & Ref'!$C$69,0))) | BW17: =IF($C17="","",AM17*IF(U17="Mixed (return+fresh)",2,1)) | BX17: =IF($C17="","",BW17*'Assumptions & Ref'!$C$70) | BY17: =IF($C17="","",AN17*('Assumptions & Ref'!$C$17+O17*'Assumptions & Ref'!$C$18+0.2)*'Assumptions & Ref'!$C$81/1000*$G$5) | BZ17: =IF($C17="","",BY17*$G$6) | CA17: =IF($C17="","",BJ17*$C$6+BN17*INDEX($C$6:$I$6,MATCH(R17,$C$4:$I$4,0))+AV17*AU17+AZ17*AX17+BC17+BZ17) | CB17: =IF($C17="","",BS17+BT17+BV17+BX17) | CC17: =IF($C17="","",(AV17+BB17)*'Assumptions & Ref'!$C$78+(BJ17+BN17)*'Assumptions & Ref'!$C$80) | CD17: =IF($C17="","",'Assumptions & Ref'!$C$84*(CA17+CB17+CC17)) | CE17: =IF($C17="","",'Assumptions & Ref'!$C$85*(CA17+CB17+CC17+CD17)) | CF17: =IF($C17="","",CA17+CB17+CC17+CD17+CE17) | CH17: =IF($C17="","",CA17) | CI17: =IF($C17="","",CB17+CC17) | CJ17: =IF($C17="","",CD17+CE17)
Y18: =IF($C18="","",CF18) | Z18: =IF($C18="","",Y18/$C18) | AA18: =IF($C18="","",IF(E18=0,"",CF18/E18)) | AB18: =IF($C18="","",BJ18+BN18+AV18+AZ18+BB18+BY18) | AC18: =IF($C18="","",BJ18) | AD18: =IF($C18="","",BN18) | AE18: =IF($C18="","",AV18) | AF18: =IF($C18="","",AZ18) | AG18: =IF($C18="","",BR18) | AH18: =IF($C18="","",ROUND(AN18,2)&" x "&ROUND(AO18,2)&" x "&ROUND(AQ18,2)) | AJ18: =IF($C18="","",$C18*'Assumptions & Ref'!$C$10) | AK18: =IF($C18="","",AJ18/3600) | AL18: =IF($C18="","",AK18/'Assumptions & Ref'!$C$6) | AM18: =IF($C18="","",AL18/'Assumptions & Ref'!$C$8) | AN18: =IF($C18="","",SQRT(AM18*'Assumptions & Ref'!$C$9)) | AO18: =IF($C18="","",SQRT(AM18/'Assumptions & Ref'!$C$9)) | AP18: =IF($C18="","",'Assumptions & Ref'!$C$14+IF(OR(S18="Pre+Fine",S18="Pre+Fine+HEPA"),'Assumptions & Ref'!$C$15,0)+IF(S18="Pre+Fine+HEPA",'Assumptions & Ref'!$C$16,0)) | AQ18: =IF($C18="","",IF(V18="Y",'Assumptions & Ref'!$C$13,0)+AP18+'Assumptions & Ref'!$C$17+O18*'Assumptions & Ref'!$C$18+IF(W18="Y",'Assumptions & Ref'!$C$19,0)+'Assumptions & Ref'!$C$20+IF(X18="Y",'Assumptions & Ref'!$C$21,0)) | AR18: =IF($C18="","",2*(AN18+AO18)*AQ18+2*AN18*AO18) | AS18: =IF($C18="","",IF(H18="Double skin",2,1)) | AT18: =IF($C18="","",INDEX($C$5:$I$5,MATCH(J18,$C$4:$I$4,0))) | AU18: =IF($C18="","",INDEX($C$6:$I$6,MATCH(J18,$C$4:$I$4,0))) | AV18: =IF($C18="","",AR18*AS18*I18/1000*AT18*(1+'Assumptions & Ref'!$C$75)) | AW18: =IF($C18="","",INDEX($C$5:$I$5,MATCH(K18,$C$4:$I$4,0))) | AX18: =IF($C18="","",INDEX($C$6:$I$6,MATCH(K18,$C$4:$I$4,0))) | AY18: =IF($C18="","",AR18*L18/1000) | AZ18: =IF($C18="","",AY18*AW18) | BA18: =IF($C18="","",4*(AN18+AO18+AQ18)) | BB18: =IF($C18="","",BA18*'Assumptions & Ref'!$C$76) | BC18: =IF($C18="","",BB18*'Assumptions & Ref'!$C$77) | BD18: =IF($C18="","",SQRT(AL18/'Assumptions & Ref'!$C$9)) | BE18: =IF($C18="","",SQRT(AL18*'Assumptions & Ref'!$C$9)) | BF18: =IF($C18="","",BD18*1000/'Assumptions & Ref'!$C$27) | BG18: =IF($C18="","",BF18*O18) | BH18: =IF($C18="","",BG18*BE18*(1+'Assumptions & Ref'!$C$29)) | BI18: =IF($C18="","",PI()*('Assumptions & Ref'!$C$25-'Assumptions & Ref'!$C$26)/1000*'Assumptions & Ref'!$C$26/1000*$C$5) | BJ18: =IF($C18="","",BH18*BI18) | BK18: =IF($C18="","",BE18*1000*P18/25.4) | BL18: =IF($C18="","",O18*'Assumptions & Ref'!$C$28/1000) | BM18: =IF($C18="","",BD18*BL18*(1-'Assumptions & Ref'!$C$31)) | BN18: =IF($C18="","",BK18*BM18*'Assumptions & Ref'!$C$30/1000*INDEX($C$5:$I$5,MATCH(R18,$C$4:$I$4,0))) | BO18: =IF($C18="","",'Assumptions & Ref'!$C$34+O18*'Assumptions & Ref'!$C$35+'Assumptions & Ref'!$C$36+IF(OR(S18="Pre+Fine",S18="Pre+Fine+HEPA"),'Assumptions & Ref'!$C$37,0)+IF(S18="Pre+Fine+HEPA",'Assumptions & Ref'!$C$38,0)) | BP18: =IF($C18="","",G18+BO18) | BQ18: =IF($C18="","",AK18*BP18/(1000*IF(M18="Plug fan",'Assumptions & Ref'!$C$39,'Assumptions & Ref'!$C$40)*'Assumptions & Ref'!$C$41)) | BR18: =IF($C18="","",IFERROR(INDEX('Assumptions & Ref'!$B$44:$B$61,MATCH(BQ18,'Assumptions & Ref'!$B$44:$B$61,1)+IF(INDEX('Assumptions & Ref'!$B$44:$B$61,MATCH(BQ18,'Assumptions & Ref'!$B$44:$B$61,1))>=BQ18,0,1)),INDEX('Assumptions & Ref'!$B$44:$B$61,1))) | BS18: =IF($C18="","",BR18*IF(M18="Plug fan",'Assumptions & Ref'!$C$64,'Assumptions & Ref'!$C$65)) | BT18: =IF($C18="","",IF(N18="Y",BR18*'Assumptions & Ref'!$C$66,0)) | BU18: =IF($C18="","",AM18) | BV18: =IF($C18="","",BU18*('Assumptions & Ref'!$C$67+IF(OR(S18="Pre+Fine",S18="Pre+Fine+HEPA"),'Assumptions & Ref'!$C$68,0)+IF(S18="Pre+Fine+HEPA",'Assumptions & Ref'!$C$69,0))) | BW18: =IF($C18="","",AM18*IF(U18="Mixed (return+fresh)",2,1)) | BX18: =IF($C18="","",BW18*'Assumptions & Ref'!$C$70) | BY18: =IF($C18="","",AN18*('Assumptions & Ref'!$C$17+O18*'Assumptions & Ref'!$C$18+0.2)*'Assumptions & Ref'!$C$81/1000*$G$5) | BZ18: =IF($C18="","",BY18*$G$6) | CA18: =IF($C18="","",BJ18*$C$6+BN18*INDEX($C$6:$I$6,MATCH(R18,$C$4:$I$4,0))+AV18*AU18+AZ18*AX18+BC18+BZ18) | CB18: =IF($C18="","",BS18+BT18+BV18+BX18) | CC18: =IF($C18="","",(AV18+BB18)*'Assumptions & Ref'!$C$78+(BJ18+BN18)*'Assumptions & Ref'!$C$80) | CD18: =IF($C18="","",'Assumptions & Ref'!$C$84*(CA18+CB18+CC18)) | CE18: =IF($C18="","",'Assumptions & Ref'!$C$85*(CA18+CB18+CC18+CD18)) | CF18: =IF($C18="","",CA18+CB18+CC18+CD18+CE18) | CH18: =IF($C18="","",CA18) | CI18: =IF($C18="","",CB18+CC18) | CJ18: =IF($C18="","",CD18+CE18)
Y19: =IF($C19="","",CF19) | Z19: =IF($C19="","",Y19/$C19) | AA19: =IF($C19="","",IF(E19=0,"",CF19/E19)) | AB19: =IF($C19="","",BJ19+BN19+AV19+AZ19+BB19+BY19) | AC19: =IF($C19="","",BJ19) | AD19: =IF($C19="","",BN19) | AE19: =IF($C19="","",AV19) | AF19: =IF($C19="","",AZ19) | AG19: =IF($C19="","",BR19) | AH19: =IF($C19="","",ROUND(AN19,2)&" x "&ROUND(AO19,2)&" x "&ROUND(AQ19,2)) | AJ19: =IF($C19="","",$C19*'Assumptions & Ref'!$C$10) | AK19: =IF($C19="","",AJ19/3600) | AL19: =IF($C19="","",AK19/'Assumptions & Ref'!$C$6) | AM19: =IF($C19="","",AL19/'Assumptions & Ref'!$C$8) | AN19: =IF($C19="","",SQRT(AM19*'Assumptions & Ref'!$C$9)) | AO19: =IF($C19="","",SQRT(AM19/'Assumptions & Ref'!$C$9)) | AP19: =IF($C19="","",'Assumptions & Ref'!$C$14+IF(OR(S19="Pre+Fine",S19="Pre+Fine+HEPA"),'Assumptions & Ref'!$C$15,0)+IF(S19="Pre+Fine+HEPA",'Assumptions & Ref'!$C$16,0)) | AQ19: =IF($C19="","",IF(V19="Y",'Assumptions & Ref'!$C$13,0)+AP19+'Assumptions & Ref'!$C$17+O19*'Assumptions & Ref'!$C$18+IF(W19="Y",'Assumptions & Ref'!$C$19,0)+'Assumptions & Ref'!$C$20+IF(X19="Y",'Assumptions & Ref'!$C$21,0)) | AR19: =IF($C19="","",2*(AN19+AO19)*AQ19+2*AN19*AO19) | AS19: =IF($C19="","",IF(H19="Double skin",2,1)) | AT19: =IF($C19="","",INDEX($C$5:$I$5,MATCH(J19,$C$4:$I$4,0))) | AU19: =IF($C19="","",INDEX($C$6:$I$6,MATCH(J19,$C$4:$I$4,0))) | AV19: =IF($C19="","",AR19*AS19*I19/1000*AT19*(1+'Assumptions & Ref'!$C$75)) | AW19: =IF($C19="","",INDEX($C$5:$I$5,MATCH(K19,$C$4:$I$4,0))) | AX19: =IF($C19="","",INDEX($C$6:$I$6,MATCH(K19,$C$4:$I$4,0))) | AY19: =IF($C19="","",AR19*L19/1000) | AZ19: =IF($C19="","",AY19*AW19) | BA19: =IF($C19="","",4*(AN19+AO19+AQ19)) | BB19: =IF($C19="","",BA19*'Assumptions & Ref'!$C$76) | BC19: =IF($C19="","",BB19*'Assumptions & Ref'!$C$77) | BD19: =IF($C19="","",SQRT(AL19/'Assumptions & Ref'!$C$9)) | BE19: =IF($C19="","",SQRT(AL19*'Assumptions & Ref'!$C$9)) | BF19: =IF($C19="","",BD19*1000/'Assumptions & Ref'!$C$27) | BG19: =IF($C19="","",BF19*O19) | BH19: =IF($C19="","",BG19*BE19*(1+'Assumptions & Ref'!$C$29)) | BI19: =IF($C19="","",PI()*('Assumptions & Ref'!$C$25-'Assumptions & Ref'!$C$26)/1000*'Assumptions & Ref'!$C$26/1000*$C$5) | BJ19: =IF($C19="","",BH19*BI19) | BK19: =IF($C19="","",BE19*1000*P19/25.4) | BL19: =IF($C19="","",O19*'Assumptions & Ref'!$C$28/1000) | BM19: =IF($C19="","",BD19*BL19*(1-'Assumptions & Ref'!$C$31)) | BN19: =IF($C19="","",BK19*BM19*'Assumptions & Ref'!$C$30/1000*INDEX($C$5:$I$5,MATCH(R19,$C$4:$I$4,0))) | BO19: =IF($C19="","",'Assumptions & Ref'!$C$34+O19*'Assumptions & Ref'!$C$35+'Assumptions & Ref'!$C$36+IF(OR(S19="Pre+Fine",S19="Pre+Fine+HEPA"),'Assumptions & Ref'!$C$37,0)+IF(S19="Pre+Fine+HEPA",'Assumptions & Ref'!$C$38,0)) | BP19: =IF($C19="","",G19+BO19) | BQ19: =IF($C19="","",AK19*BP19/(1000*IF(M19="Plug fan",'Assumptions & Ref'!$C$39,'Assumptions & Ref'!$C$40)*'Assumptions & Ref'!$C$41)) | BR19: =IF($C19="","",IFERROR(INDEX('Assumptions & Ref'!$B$44:$B$61,MATCH(BQ19,'Assumptions & Ref'!$B$44:$B$61,1)+IF(INDEX('Assumptions & Ref'!$B$44:$B$61,MATCH(BQ19,'Assumptions & Ref'!$B$44:$B$61,1))>=BQ19,0,1)),INDEX('Assumptions & Ref'!$B$44:$B$61,1))) | BS19: =IF($C19="","",BR19*IF(M19="Plug fan",'Assumptions & Ref'!$C$64,'Assumptions & Ref'!$C$65)) | BT19: =IF($C19="","",IF(N19="Y",BR19*'Assumptions & Ref'!$C$66,0)) | BU19: =IF($C19="","",AM19) | BV19: =IF($C19="","",BU19*('Assumptions & Ref'!$C$67+IF(OR(S19="Pre+Fine",S19="Pre+Fine+HEPA"),'Assumptions & Ref'!$C$68,0)+IF(S19="Pre+Fine+HEPA",'Assumptions & Ref'!$C$69,0))) | BW19: =IF($C19="","",AM19*IF(U19="Mixed (return+fresh)",2,1)) | BX19: =IF($C19="","",BW19*'Assumptions & Ref'!$C$70) | BY19: =IF($C19="","",AN19*('Assumptions & Ref'!$C$17+O19*'Assumptions & Ref'!$C$18+0.2)*'Assumptions & Ref'!$C$81/1000*$G$5) | BZ19: =IF($C19="","",BY19*$G$6) | CA19: =IF($C19="","",BJ19*$C$6+BN19*INDEX($C$6:$I$6,MATCH(R19,$C$4:$I$4,0))+AV19*AU19+AZ19*AX19+BC19+BZ19) | CB19: =IF($C19="","",BS19+BT19+BV19+BX19) | CC19: =IF($C19="","",(AV19+BB19)*'Assumptions & Ref'!$C$78+(BJ19+BN19)*'Assumptions & Ref'!$C$80) | CD19: =IF($C19="","",'Assumptions & Ref'!$C$84*(CA19+CB19+CC19)) | CE19: =IF($C19="","",'Assumptions & Ref'!$C$85*(CA19+CB19+CC19+CD19)) | CF19: =IF($C19="","",CA19+CB19+CC19+CD19+CE19) | CH19: =IF($C19="","",CA19) | CI19: =IF($C19="","",CB19+CC19) | CJ19: =IF($C19="","",CD19+CE19)
