Workbook
Name IQ_CH: 110000
Name IQ_CQ: 5000
Name IQ_CY: 10000
Name IQ_DAILY: 500000
Name IQ_FH: 100000
Name IQ_FQ: 500
Name IQ_FY: 1000
Name IQ_LTM: 2000
Name IQ_MONTH: 15000
Name IQ_NTM: 6000
Name IQ_WEEK: 50000
Name IQ_YTD: 3000

Sheet Summary
C2: Category | D2: Total INR Cr. (as per cost model)
B3: A | C3: Ladder type, perforated type & U-shaped troughs | D3: =SUM('Cable Tray & Accessories'!F8:F17)/10^7 -> 14.100601
B4: B | C4: Bend, TEE & Reducer | D4: =SUM('Cable Tray & Accessories'!F20:F37)/10^7 -> 0.071049789
B5: C | C5: Channel & Cantilever Arm | D5: =SUM('Cable Tray & Accessories'!F39:F43)/10^7 -> 2.7241413
C6: Total | D6: =SUM(D3:D5) -> 16.895792

Sheet Cable Tray & Accessories
A1: 3X800MW NTPC Nabinagar Thermal Project at Bihar State
A2: Supply of Cable Trays & Accessories
A3: Price Schedule
A4: S.No | B4: Item Description | C4: UOM | D4: Total Qty | E4: Unit FOR Rate | F4: Total FOR Value | G4: Remarks
B5: Lump sum price for the design , manufacture, testing at manufacturers works & delivery including packing, transportation to site of the Cable trays & Accessories
A6: A | B6: Cable Tray
A7: A1 | B7: Cable Tray - Ladder Type
A8: i | B8: 600 mm(Wide), 100mm(Height), 2mm(Thickness) | C8: KM | D8: 107 | E8: ='Ladder 600x100x2'!D113*1000 -> 845424.63 | F8: =D8*E8 -> 90460435
A9: II | B9: 300 mm(Wide), 100mm(Height), 2mm(Thickness) | C9: KM | D9: 20 | E9: ='Ladder 300x100x2'!D113*1000 -> 679444.46 | F9: =D9*E9 -> 13588889
A10: iii | B10: 150 mm(Wide), 100mm(Height), 2mm(Thickness) | C10: KM | D10: 8 | E10: ='Ladder 150x100x2'!D113*1000 -> 596454.38 | F10: =D10*E10 -> 4771635
A11: A2 | B11: Cable Tray - Perforated Type
A12: i | B12: 600 mm(Wide), 100mm(Height), 2mm(Thickness) | C12: KM | D12: 13.5 | E12: ='Perforated 600x100x2'!D93*1000 -> 1519478.6 | F12: =D12*E12 -> 20512961
A13: II | B13: 300 mm(Wide), 100mm(Height), 2mm(Thickness) | C13: KM | D13: 5 | E13: ='Perforated 300x100x2'!D93*1000 -> 978059.14 | F13: =D13*E13 -> 4890295.7
A14: iii | B14: 150 mm(Wide), 100mm(Height), 2mm(Thickness) | C14: KM | D14: 5 | E14: ='Perforated 150x100x2'!D93*1000 -> 653207.48 | F14: =D14*E14 -> 3266037.4
A15: A3 | B15: Cable Tray - Troughs, U-Shaped
A16: i | B16: 75 mm(Wide), 25mm(Depth), 2mm(Thickness) | C16: KM | D16: 8 | E16: ='U Trough 75x25x2'!D93*1000 -> 242294 | F16: =D16*E16 -> 1938352
A17: II | B17: 50 mm(Wide), 25mm(Depth), 2mm(Thickness) | C17: KM | D17: 8 | E17: ='U Trough 50x25x2'!D93*1000 -> 197175.71 | F17: =D17*E17 -> 1577405.7
A18: B | B18: Cable Tray - Bend, TEE & Reducer
A19: B1 | B19: Ladder Type Horizontal Bend 90deg Bending Radius 1200mm
A20: i | B20: 600 mm (Wide) - 2.36 m (Approx), 100mm(Height), 2mm(Thickness) | C20: No | D20: 50 | E20: ='H Bend 600x100x2'!D112 -> 1959.6243 | F20: =D20*E20 -> 97981.216
A21: II | B21: 300 mm (Wide) - 2.36 m (Approx), 100mm(Height), 2mm(Thickness) | C21: No | D21: 25 | E21: ='H Bend 300x100x2'!D112 -> 1586.169 | F21: =D21*E21 -> 39654.224
A22: iii | B22: 150 mm (Wide) - 2.12 m (Approx), 100mm(Height), 2mm(Thickness) | C22: No | D22: 25 | E22: ='H Bend 150x100x2'!D112 -> 1399.4413 | F22: =D22*E22 -> 34986.032
A23: B2 | B23: Ladder Type Vertical Bend - 90deg (UP) Bending Radius 1050mm
A24: i | B24: 600 mm (Wide) - 1.9 m (Approx), 100mm(Height), 2mm(Thickness) | C24: No | D24: 25 | E24: ='Vertical bend up 600x100x2'!D112 -> 1654.6227 | F24: =D24*E24 -> 41365.569
A25: II | B25: 300 mm (Wide) - 1.9 m (Approx), 100mm(Height), 2mm(Thickness) | C25: No | D25: 13 | E25: ='Vertical bend up 300x100x2'!D112 -> 1322.6624 | F25: =D25*E25 -> 17194.611
A26: iii | B26: 150 mm (Wide) - 1.9 m (Approx), 100mm(Height), 2mm(Thickness) | C26: No | D26: 13 | E26: ='Vertical bend up 150x100x2'!D112 -> 1156.6822 | F26: =D26*E26 -> 15036.869
A27: B3 | B27: Ladder Type Vertical Bend - 90deg (Down) Bending Radius 1050mm
A28: i | B28: 600 mm (Wide) - 1.9 m (Approx), 100mm(Height), 2mm(Thickness) | C28: No | D28: 25 | E28: ='Vertical bend down 600x100x2'!D112 -> 1654.6227 | F28: =D28*E28 -> 41365.569
A29: II | B29: 300 mm (Wide) - 1.9 m (Approx), 100mm(Height), 2mm(Thickness) | C29: No | D29: 12 | E29: ='Vertical bend down 300x100x2'!D112 -> 1322.6624 | F29: =D29*E29 -> 15871.949
A30: iii | B30: 150 mm (Wide) - 1.9 m (Approx), 100mm(Height), 2mm(Thickness) | C30: No | D30: 12 | E30: ='Vertical bend down 150x100x2'!D112 -> 1156.6822 | F30: =D30*E30 -> 13880.187
A31: B4 | B31: Ladder Type Horizontal - Tee, Bending Radius - 1200mm
A32: i | B32: 600 mm (Wide) - 4.2 m (Approx), 100mm(Height), 2mm(Thickness) | C32: No | D32: 50 | E32: ='Horizontal Tee 600x100x2'!D112 -> 3511.591 | F32: =D32*E32 -> 175579.55
A33: II | B33: 300 mm (Wide) - 3.9 m (Approx), 100mm(Height), 2mm(Thickness) | C33: No | D33: 25 | E33: ='Horizontal Tee 300x100x2'!D112 -> 2806.1753 | F33: =D33*E33 -> 70154.382
A34: iii | B34: 150 mm (Wide) - 3.7 m (Approx), 100mm(Height), 2mm(Thickness) | C34: No | D34: 25 | E34: ='Horizontal Tee 150x100x2'!D112 -> 2453.4674 | F34: =D34*E34 -> 61336.686
A35: B5 | B35: Ladder Type Horizontal - Cross, Bending Radius - 1050mm
A36: i | B36: 600 mm (Wide) - 5.8 m (Approx), 100mm(Height), 2mm(Thickness) | C36: No | D36: 10 | E36: ='Horizontal Cross 600x100x2'!D112 -> 4781.7454 | F36: =D36*E36 -> 47817.454
A37: II | B37: 300 mm (Wide) - 5.8 m (Approx), 100mm(Height), 2mm(Thickness) | C37: No | D37: 10 | E37: ='Horizontal Cross 300x100x2'!D112 -> 3827.3595 | F37: =D37*E37 -> 38273.595
A38: C | B38: Channel & Cantilever Arm
A39: i | B39: C1 Channel - 41mm (Length) X 41mm (Width), 2.5mm (Thickness) | C39: Mtr | D39: 25000 | E39: ='Channel 41x41x2.5'!D91 -> 293.36812 | F39: =D39*E39 -> 7334202.9
A40: II | B40: C2 Channel - 41mm (Length) X 82mm (Width), 2.5mm (Thickness) | C40: Mtr | D40: 22000 | E40: ='Channel 41x82x2.5'!D91 -> 468.1662 | F40: =D40*E40 -> 10299656
...

Sheet Backup>

Sheet Horizontal Cross 300x100x2
A1: Cable Tray Costing : Ladder Type Horizontal Cross, Bending Radius 1050 mm
B5: Input for raw material and conversion costs | M5: Cable Tray configuration
B6: Cost of 1 kg of MS (Rs) | D6: 73 | F6: Coating thickness of Zinc (micron) | H6: 86 | M6: Runners | Q6: Rungs
B7: Transportation and handling cost of raw material to vendor shop (% of raw material cost) | D7: 0 | F7: Specific weight of Zinc (kg/m3) | H7: 7135 | M7: Number of runners | O7: 2 | Q7: No of rungs per 2500 meter of runner | U7: 10
B8: Specific weight of MS (kg/m3) | D8: 7850 | F8: Cost of Zinc (Rs/kg) | H8: 425.6 | M8: Tray width (mm) | O8: 300 | Q8: Length of rung (mm) | U8: =O8 -> 300
B9: Cost of engg and fabrication (% of material cost) | D9: 0 | F9: Wastage during galvalization | H9: 0 | M9: Tray Depth (mm) | O9: 100 | Q9: Width of rung (mm) | U9: 50
B10: Quality test and inspection charges (%) | D10: 0 | F10: Recoverable scrap - Ash per meter of tray (%) | H10: 0.12 | M10: Tray thickness (mm) | O10: 2 | Q10: Collar / Height of rung (mm) | U10: 20
B11: Salvage value of scrap for MS plates(% of overall value) | D11: 0.5 | F11: Recoverable scrap - Dross per meter of tray (%) | H11: 0.08 | M11: Tray collar (mm) | O11: 25 | Q11: Thickness of rung (mm) | U11: 2
B12: Wastage allowance during fabrication | D12: 0 | F12: Recoverable scrap salvage value - Ash (%) | H12: 0.26 | M12: Tray length (mm) | O12: 5800 | Q12: No of slots per 40 mm of length | U12: 1
B13: Transportation and handling cost of finished goods to site (Rs/kg) | D13: 0 | F13: Recoverable scrap salvage value - Dross (%) | H13: 0.52 | M13: No of holes per 2500 mm length | O13: 20 | Q13: Length of 1 slot (mm) | U13: 25
B14: Overheads for vendor (%) | D14: 0 | F14: Cost of galvanization (% of material cost) | H14: 0 | M14: Dia of 1 hole (mm) | O14: 10 | Q14: Width of 1 slot (mm) | U14: 10
B15: Profit margin for vendor (%) | D15: 2.5
B16: Cost of contract Performance Bank Guarantee | D16: 0
B17: Labour,Fabrication,Overhead,Profit Margin (INR/ kg) | D17: =6.5*1.2 -> 7.8
B20: Detailed Costing
B21: Cable tray MS material cost | M21: Galvalization
B22: Runner | F22: Rung | M22: Zinc Requirement
B23: Number of runners per meter length | D23: =O7 -> 2 | F23: No of rungs in this fitting (U7 x length / 2500, rounded) | J23: =ROUND(U7*D28/2500,0) -> 23 | M23: Runner | Q23: Rung
B24: Tray width (mm) | D24: =O8 -> 300 | F24: Length of rung (mm) | J24: =U8 -> 300 | M24: Surface area for 1 m length (m2) | O24: =2*(2*(2*D27+D25)/1000*D28/1000) -> 3.48 | Q24: Surface area for 1 rung (m2) | T24: =2*J24/1000*(J25+2*J26)/1000 -> 0.054
B25: Tray Depth (mm) | D25: =O9 -> 100 | F25: Width of rung (mm) | J25: =U9 -> 50 | M25: Surface area holes along thickness for 1 m length (m2) | O25: =D37*3.14*D38/1000*D26/1000*D28/125 -> 0.0582784 | Q25: Surface area of slots along thickness for 1 rung (m2) | T25: =(2*(J38+J39)/1000*D26/1000)*D24/40 -> 0.00105
B26: Tray thickness (mm) | D26: =O10 -> 2 | F26: Collar / Height of rung (mm) | J26: =U10 -> 20 | M26: Top surface area of holes for 1 m length (m2) | O26: =D37*3.14*(D38/2/1000)^2*D28/125 -> 0.072848 | Q26: Top surface area of slots 1 rung (m2) | T26: =J38/1000*J39/1000*D24/40 -> 0.001875
B27: Tray collar (mm) | D27: =O11 -> 25 | F27: Thickness of rung (mm) | J27: =U11 -> 2
B28: Tray length (mm) | D28: =O12 -> 5800 | M28: Overall surface area for 1 meter of runner (m2) | O28: =O24+O25-O26 -> 3.4654304 | Q28: Overall rung surface area for 1 meter of runner (m2) | T28: =(T24+T25-T26)*J23 -> 1.223025
F29: Volume of 1 rung (m3) | J29: =(2*J26+J25)/1000*J24/1000*J27/1000 -> 5.4e-05
F30: Weight of 1 rung (kg) | J30: =J29*D8 -> 0.4239 | M30: Total surface area per meter of cable tray (m2) | O30: =O28+T28 -> 4.6884554
B31: Volume of runner (m3) | D31: =2*(D25+D27*2)/1000*D26/1000*D28/1000 -> 0.00348 | F31: Cost of 1 rung (Rs) | J31: =J30*(D6*(1+D7)) -> 30.9447
B32: Weight of runner per meter length (kg) | D32: =D31*D8 -> 27.318 | F32: Cost of rungs per meter of runner | J32: =J31*J23 -> 711.7281 | M32: Weight of Zinc required for galvanization (kg) | O32: =O30*H6*10^-6*H7 -> 2.8768831
B33: Cost of runner per meter length (Rs) | D33: =D32*(D6*(1+D7)) -> 1994.214 | M33: Wastage during galvalization | O33: =H9 -> 0
M34: Total weight of Zinc required for galvanization (kg) | O34: =(1+O33)*O32 -> 2.8768831
B35: Scrap salvage due to holes / slots | M35: Cost of Zinc galvanization per meter of runner (Rs) | O35: =O34*H8 -> 1224.4015
B36: Runner | F36: Rung
B37: No of holes per 2500 mm length | D37: =O13 -> 20 | F37: No of slots per 40 mm of length | J37: =U12 -> 1 | M37: Recoverable scrap - Ash per meter of tray (kg) | O37: =H10*O32 -> 0.34522597 | Q37: Recoverable scrap salvage - Ash (Rs/kg) | T37: =H12*$H$8 -> 110.656
B38: Dia of 1 hole (mm) | D38: =O14 -> 10 | F38: Length of 1 slot (mm) | J38: =U13 -> 25 | M38: Recoverable scrap - Dross per meter of tray (kg) | O38: =H11*O32 -> 0.23015065 | Q38: Recoverable scrap salvage - Dross (Rs/kg) | T38: =H13*$H$8 -> 221.312
B39: Volume of holes (m3) | D39: =2*D37*3.14*(D38/2/1000)^2*D26/1000 -> 6.28e-06 | F39: Width of 1 slot (mm) | J39: =U14 -> 10 | M39: Salvage value of scrap per meter of cable (Rs) | O39: =O37*T37+O38*T38 -> 89.136426
F40: Volume of 1 slot (m3) | J40: =J38/1000*J39/1000*J27/1000 -> 5e-07
B41: Weight of holes per 2500 mm of runner (kg) | D41: =D39*D8 -> 0.049298 | F41: Volume slots per rung (m3) | J41: =D24/40*J40 -> 3.75e-06 | M41: Net cost of Zinc galvanization per meter of runner (Rs) | O41: =O35-O39 -> 1135.265
B42: Value of scrap generated per meter of runner (Rs) | D42: =D41*D6 -> 3.598754 | F42: Weight of slots per rung (kg) | J42: =J41*D8 -> 0.0294375
B43: Salvage value of scrap (% of overall value) | D43: =D11 -> 0.5 | F43: Weight of slots per 2500mm of runner (kg) | J43: =J42*J23 -> 0.6770625
B44: Salvage value of MS scrap per meter of runner (Rs) | D44: =D42*D43 -> 1.799377 | F44: Value of scrap generated per meter of runner (Rs) | J44: =J43*D6 -> 49.425562
F45: Salvage value of MS scrap per meter of runner (Rs) | J45: =J44*D43 -> 24.712781
...

Sheet Horizontal Cross 600x100x2
A1: Cable Tray Costing : Ladder Type Horizontal Cross, Bending Radius 1050 mm
B5: Input for raw material and conversion costs | M5: Cable Tray configuration
B6: Cost of 1 kg of MS (Rs) | D6: 73 | F6: Coating thickness of Zinc (micron) | H6: 86 | M6: Runners | Q6: Rungs
B7: Transportation and handling cost of raw material to vendor shop (% of raw material cost) | D7: 0 | F7: Specific weight of Zinc (kg/m3) | H7: 7135 | M7: Number of runners | O7: 2 | Q7: No of rungs per 2500 meter of runner | U7: 10
B8: Specific weight of MS (kg/m3) | D8: 7850 | F8: Cost of Zinc (Rs/kg) | H8: 425.6 | M8: Tray width (mm) | O8: 600 | Q8: Length of rung (mm) | U8: =O8 -> 600
B9: Cost of engg and fabrication (% of material cost) | D9: 0 | F9: Wastage during galvalization | H9: 0 | M9: Tray Depth (mm) | O9: 100 | Q9: Width of rung (mm) | U9: 50
B10: Quality test and inspection charges (%) | D10: 0 | F10: Recoverable scrap - Ash per meter of tray (%) | H10: 0.12 | M10: Tray thickness (mm) | O10: 2 | Q10: Collar / Height of rung (mm) | U10: 20
B11: Salvage value of scrap for MS plates(% of overall value) | D11: 0.5 | F11: Recoverable scrap - Dross per meter of tray (%) | H11: 0.08 | M11: Tray collar (mm) | O11: 25 | Q11: Thickness of rung (mm) | U11: 2
B12: Wastage allowance during fabrication | D12: 0 | F12: Recoverable scrap salvage value - Ash (%) | H12: 0.26 | M12: Tray length (mm) | O12: 5800 | Q12: No of slots per 40 mm of length | U12: 1
B13: Transportation and handling cost of finished goods to site (Rs/kg) | D13: 0 | F13: Recoverable scrap salvage value - Dross (%) | H13: 0.52 | M13: No of holes per 2500 mm length | O13: 20 | Q13: Length of 1 slot (mm) | U13: 25
B14: Overheads for vendor (%) | D14: 0 | F14: Cost of galvanization (% of material cost) | H14: 0 | M14: Dia of 1 hole (mm) | O14: 10 | Q14: Width of 1 slot (mm) | U14: 10
B15: Profit margin for vendor (%) | D15: 2.5
B16: Cost of contract Performance Bank Guarantee | D16: 0
B17: Labour,Fabrication,Overhead,Profit Margin (INR/ kg) | D17: =6.5*1.2 -> 7.8
B20: Detailed Costing
B21: Cable tray MS material cost | M21: Galvalization
B22: Runner | F22: Rung | M22: Zinc Requirement
B23: Number of runners per meter length | D23: =O7 -> 2 | F23: No of rungs in this fitting (U7 x length / 2500, rounded) | J23: =ROUND(U7*D28/2500,0) -> 23 | M23: Runner | Q23: Rung
B24: Tray width (mm) | D24: =O8 -> 600 | F24: Length of rung (mm) | J24: =U8 -> 600 | M24: Surface area for 1 m length (m2) | O24: =2*(2*(2*D27+D25)/1000*D28/1000) -> 3.48 | Q24: Surface area for 1 rung (m2) | T24: =2*J24/1000*(J25+2*J26)/1000 -> 0.108
B25: Tray Depth (mm) | D25: =O9 -> 100 | F25: Width of rung (mm) | J25: =U9 -> 50 | M25: Surface area holes along thickness for 1 m length (m2) | O25: =D37*3.14*D38/1000*D26/1000*D28/125 -> 0.0582784 | Q25: Surface area of slots along thickness for 1 rung (m2) | T25: =(2*(J38+J39)/1000*D26/1000)*D24/40 -> 0.0021
B26: Tray thickness (mm) | D26: =O10 -> 2 | F26: Collar / Height of rung (mm) | J26: =U10 -> 20 | M26: Top surface area of holes for 1 m length (m2) | O26: =D37*3.14*(D38/2/1000)^2*D28/125 -> 0.072848 | Q26: Top surface area of slots 1 rung (m2) | T26: =J38/1000*J39/1000*D24/40 -> 0.00375
B27: Tray collar (mm) | D27: =O11 -> 25 | F27: Thickness of rung (mm) | J27: =U11 -> 2
B28: Tray length (mm) | D28: =O12 -> 5800 | M28: Overall surface area for 1 meter of runner (m2) | O28: =O24+O25-O26 -> 3.4654304 | Q28: Overall rung surface area for 1 meter of runner (m2) | T28: =(T24+T25-T26)*J23 -> 2.44605
F29: Volume of 1 rung (m3) | J29: =(2*J26+J25)/1000*J24/1000*J27/1000 -> 0.000108
F30: Weight of 1 rung (kg) | J30: =J29*D8 -> 0.8478 | M30: Total surface area per meter of cable tray (m2) | O30: =O28+T28 -> 5.9114804
B31: Volume of runner (m3) | D31: =2*(D25+D27*2)/1000*D26/1000*D28/1000 -> 0.00348 | F31: Cost of 1 rung (Rs) | J31: =J30*(D6*(1+D7)) -> 61.8894
B32: Weight of runner per meter length (kg) | D32: =D31*D8 -> 27.318 | F32: Cost of rungs per meter of runner | J32: =J31*J23 -> 1423.4562 | M32: Weight of Zinc required for galvanization (kg) | O32: =O30*H6*10^-6*H7 -> 3.6273435
B33: Cost of runner per meter length (Rs) | D33: =D32*(D6*(1+D7)) -> 1994.214 | M33: Wastage during galvalization | O33: =H9 -> 0
M34: Total weight of Zinc required for galvanization (kg) | O34: =(1+O33)*O32 -> 3.6273435
B35: Scrap salvage due to holes / slots | M35: Cost of Zinc galvanization per meter of runner (Rs) | O35: =O34*H8 -> 1543.7974
B36: Runner | F36: Rung
B37: No of holes per 2500 mm length | D37: =O13 -> 20 | F37: No of slots per 40 mm of length | J37: =U12 -> 1 | M37: Recoverable scrap - Ash per meter of tray (kg) | O37: =H10*O32 -> 0.43528122 | Q37: Recoverable scrap salvage - Ash (Rs/kg) | T37: =H12*$H$8 -> 110.656
B38: Dia of 1 hole (mm) | D38: =O14 -> 10 | F38: Length of 1 slot (mm) | J38: =U13 -> 25 | M38: Recoverable scrap - Dross per meter of tray (kg) | O38: =H11*O32 -> 0.29018748 | Q38: Recoverable scrap salvage - Dross (Rs/kg) | T38: =H13*$H$8 -> 221.312
B39: Volume of holes (m3) | D39: =2*D37*3.14*(D38/2/1000)^2*D26/1000 -> 6.28e-06 | F39: Width of 1 slot (mm) | J39: =U14 -> 10 | M39: Salvage value of scrap per meter of cable (Rs) | O39: =O37*T37+O38*T38 -> 112.38845
F40: Volume of 1 slot (m3) | J40: =J38/1000*J39/1000*J27/1000 -> 5e-07
B41: Weight of holes per 2500 mm of runner (kg) | D41: =D39*D8 -> 0.049298 | F41: Volume slots per rung (m3) | J41: =D24/40*J40 -> 7.5e-06 | M41: Net cost of Zinc galvanization per meter of runner (Rs) | O41: =O35-O39 -> 1431.4089
B42: Value of scrap generated per meter of runner (Rs) | D42: =D41*D6 -> 3.598754 | F42: Weight of slots per rung (kg) | J42: =J41*D8 -> 0.058875
B43: Salvage value of scrap (% of overall value) | D43: =D11 -> 0.5 | F43: Weight of slots per 2500mm of runner (kg) | J43: =J42*J23 -> 1.354125
B44: Salvage value of MS scrap per meter of runner (Rs) | D44: =D42*D43 -> 1.799377 | F44: Value of scrap generated per meter of runner (Rs) | J44: =J43*D6 -> 98.851125
F45: Salvage value of MS scrap per meter of runner (Rs) | J45: =J44*D43 -> 49.425562
...

Sheet Channel 41x41x2.5
A1: Cable Tray Costing : C1 Channel - 41 mm (W) x 41 mm (D), 2.5 mm thickness
B5: Input for raw material and conversion costs | M5: Channel / cantilever arm configuration
B6: Cost of steel(Rs/kg) | D6: 73 | F6: Coating thickness of Zinc (micron) | H6: 86 | M6: Channel type | O6: Standard strut slotted channel
B7: Transportation and handling cost of raw material to vendor shop (% of raw material cost) | D7: 0 | F7: Specific weight of Zinc (kg/m3) | H7: 7135 | M7: Channel width - back face (mm) | O7: 41
B8: Specific weight of MS (kg/m3) | D8: 7850 | F8: Cost of Zinc (Rs/kg) | H8: 425.6 | M8: Channel depth (mm) | O8: 41
B9: Cost of engg and fabrication (% of material cost) | D9: 0 | F9: Wastage during galvalization | H9: 0 | M9: Channel thickness (mm) | O9: 2.5
B10: Quality test and inspection charges (%) | D10: 0 | F10: Recoverable scrap - Ash per meter of tray (%) | H10: 0.12 | M10: Lip / return of channel (mm) | O10: 9
B11: Salvage value of scrap for MS plates(% of overall value) | D11: 0.3 | F11: Recoverable scrap - Dross per meter of tray (%) | H11: 0.08 | M11: Length (mm) | O11: 1000
B12: Wastage allowance during fabrication | D12: 0 | F12: Recoverable scrap salvage value - Ash (%) | H12: 0.26 | M12: Length of a slot (mm) | O12: 28
B13: Transportation and handling cost of finished goods to site (Rs/kg) | D13: 0 | F13: Recoverable scrap salvage value - Dross (%) | H13: 0.52 | M13: Width of a slot (mm) | O13: 13
B14: Overheads for vendor (%) | D14: 0 | F14: Cost of galvanization (% of material cost) | H14: 0 | M14: Pitch of slots along length (mm) | O14: 50
B15: Profit & overhead margin (INR/kg) | D15: 2.5 | M15: No of slots per channel | O15: =ROUNDDOWN(O11/O14,0) -> 20
B16: Cost of contract Performance Bank Guarantee | D16: 0
B17: Labour & Fabrication Charges (INR/ kg) | D17: =6.5*1.2 -> 7.8
B25: Detailed Costing
B26: Channel MS material cost | M26: Galvalization
M27: Zinc Requirement
B28: Developed (strip) width of channel (mm) | D28: =O7+2*O8+2*O10 -> 141
B29: Cross-section area of channel (mm2) | D29: =D28*O9 -> 352.5 | M29: Gross surface area - both faces (m2) | O29: =2*D28/1000*D30/1000 -> 0.282
B30: Length (mm) | D30: =O11 -> 1000 | M30: Surface area of slots along thickness (m2) | O30: =2*(O12+O13)/1000*O9/1000*D42 -> 0.0041
M31: Top surface area of slots - both faces (m2) | O31: =2*O12/1000*O13/1000*D42 -> 0.01456
B32: Channel thickness (mm) | D32: =O9 -> 2.5
M33: Overall surface area (m2) | O33: =O29+O30-O31 -> 0.27154
B35: Volume of steel (m3) | D35: =D29*D30/10^9 -> 0.0003525 | M35: Total surface area for galvanization (m2) | O35: =O33 -> 0.27154
B36: Weight of steel (kg) | D36: =D35*D8 -> 2.767125
B37: Cost of steel (Rs) | D37: =D36*(D6*(1+D7)) -> 202.00012 | M37: Weight of Zinc required for galvanization (kg) | O37: =O35*H6*10^-6*H7 -> 0.16661966
M38: Wastage during galvalization | O38: =H9 -> 0
B39: Scrap salvage due to slots | M39: Total weight of Zinc required for galvanization (kg) | O39: =(1+O38)*O37 -> 0.16661966
M40: Cost of Zinc galvanization (Rs) | O40: =O39*H8 -> 70.913327
B41: No of slots per channel | D41: =O15 -> 20
B42: Total no of slots | D42: =D41 -> 20 | M42: Recoverable scrap - Ash (kg) | O42: =H10*O37 -> 0.019994359 | Q42: Recoverable scrap salvage - Ash (Rs/kg) | T42: =H12*$H$8 -> 110.656
B43: Total volume of slots (m3) | D43: =D42*O12/1000*O13/1000*O9/1000 -> 1.82e-05 | M43: Recoverable scrap - Dross (kg) | O43: =H11*O37 -> 0.013329573 | Q43: Recoverable scrap salvage - Dross (Rs/kg) | T43: =H13*$H$8 -> 221.312
B44: Weight of slots (kg) | D44: =D43*D8 -> 0.14287 | M44: Salvage value of zinc scrap (Rs) | O44: =O42*T42+O43*T43 -> 5.1624902
B45: Value of scrap generated (Rs) | D45: =D44*D6 -> 10.42951
B46: Salvage value of scrap (% of overall value) | D46: =D11 -> 0.3 | M46: Net cost of Zinc galvanization (Rs) | O46: =O40-O44 -> 65.750837
B47: Salvage value of MS scrap (Rs) | D47: =D45*D46 -> 3.128853
B49: Cost of material (Rs) | D49: =D37-D47 -> 198.87127
B51: Total cost of channel steel (Rs) per metre | D51: =D49 -> 198.87127
B52: Wastage allowance during fabrication | D52: =D12 -> 0
B53: Net cost of channel steel (Rs) per metre | D53: =(1+D52)*D51 -> 198.87127
...

Sheet Channel 41x82x2.5
A1: Cable Tray Costing : C1 Channel - 41 mm (W) x 41 mm (D), 2.5 mm thickness
B5: Input for raw material and conversion costs | M5: Channel / cantilever arm configuration
B6: Cost of steel(Rs/kg) | D6: 73 | F6: Coating thickness of Zinc (micron) | H6: 86 | M6: Channel type | O6: Standard strut slotted channel
B7: Transportation and handling cost of raw material to vendor shop (% of raw material cost) | D7: 0 | F7: Specific weight of Zinc (kg/m3) | H7: 7135 | M7: Channel width - back face (mm) | O7: 41
B8: Specific weight of MS (kg/m3) | D8: 7850 | F8: Cost of Zinc (Rs/kg) | H8: 425.6 | M8: Channel depth (mm) | O8: 82
B9: Cost of engg and fabrication (% of material cost) | D9: 0 | F9: Wastage during galvalization | H9: 0 | M9: Channel thickness (mm) | O9: 2.5
B10: Quality test and inspection charges (%) | D10: 0 | F10: Recoverable scrap - Ash per meter of tray (%) | H10: 0.12 | M10: Lip / return of channel (mm) | O10: 9
B11: Salvage value of scrap for MS plates(% of overall value) | D11: 0.3 | F11: Recoverable scrap - Dross per meter of tray (%) | H11: 0.08 | M11: Length (mm) | O11: 1000
B12: Wastage allowance during fabrication | D12: 0 | F12: Recoverable scrap salvage value - Ash (%) | H12: 0.26 | M12: Length of a slot (mm) | O12: 28
B13: Transportation and handling cost of finished goods to site (Rs/kg) | D13: 0 | F13: Recoverable scrap salvage value - Dross (%) | H13: 0.52 | M13: Width of a slot (mm) | O13: 13
B14: Overheads for vendor (%) | D14: 0 | F14: Cost of galvanization (% of material cost) | H14: 0 | M14: Pitch of slots along length (mm) | O14: 50
B15: Profit & overhead margin (INR/kg) | D15: 2.5 | M15: No of slots per channel | O15: =ROUNDDOWN(O11/O14,0) -> 20
B16: Cost of contract Performance Bank Guarantee | D16: 0
B17: Labour & Fabrication Charges (INR/ kg) | D17: =6.5*1.2 -> 7.8
B25: Detailed Costing
B26: Channel MS material cost | M26: Galvalization
M27: Zinc Requirement
B28: Developed (strip) width of channel (mm) | D28: =O7+2*O8+2*O10 -> 223
B29: Cross-section area of channel (mm2) | D29: =D28*O9 -> 557.5 | M29: Gross surface area - both faces (m2) | O29: =2*D28/1000*D30/1000 -> 0.446
B30: Length (mm) | D30: =O11 -> 1000 | M30: Surface area of slots along thickness (m2) | O30: =2*(O12+O13)/1000*O9/1000*D42 -> 0.0041
M31: Top surface area of slots - both faces (m2) | O31: =2*O12/1000*O13/1000*D42 -> 0.01456
B32: Channel thickness (mm) | D32: =O9 -> 2.5
M33: Overall surface area (m2) | O33: =O29+O30-O31 -> 0.43554
B35: Volume of steel (m3) | D35: =D29*D30/10^9 -> 0.0005575 | M35: Total surface area for galvanization (m2) | O35: =O33 -> 0.43554
B36: Weight of steel (kg) | D36: =D35*D8 -> 4.376375
B37: Cost of steel (Rs) | D37: =D36*(D6*(1+D7)) -> 319.47538 | M37: Weight of Zinc required for galvanization (kg) | O37: =O35*H6*10^-6*H7 -> 0.2672517
M38: Wastage during galvalization | O38: =H9 -> 0
B39: Scrap salvage due to slots | M39: Total weight of Zinc required for galvanization (kg) | O39: =(1+O38)*O37 -> 0.2672517
M40: Cost of Zinc galvanization (Rs) | O40: =O39*H8 -> 113.74232
B41: No of slots per channel | D41: =O15 -> 20
B42: Total no of slots | D42: =D41 -> 20 | M42: Recoverable scrap - Ash (kg) | O42: =H10*O37 -> 0.032070204 | Q42: Recoverable scrap salvage - Ash (Rs/kg) | T42: =H12*$H$8 -> 110.656
B43: Total volume of slots (m3) | D43: =D42*O12/1000*O13/1000*O9/1000 -> 1.82e-05 | M43: Recoverable scrap - Dross (kg) | O43: =H11*O37 -> 0.021380136 | Q43: Recoverable scrap salvage - Dross (Rs/kg) | T43: =H13*$H$8 -> 221.312
B44: Weight of slots (kg) | D44: =D43*D8 -> 0.14287 | M44: Salvage value of zinc scrap (Rs) | O44: =O42*T42+O43*T43 -> 8.2804411
B45: Value of scrap generated (Rs) | D45: =D44*D6 -> 10.42951
B46: Salvage value of scrap (% of overall value) | D46: =D11 -> 0.3 | M46: Net cost of Zinc galvanization (Rs) | O46: =O40-O44 -> 105.46188
B47: Salvage value of MS scrap (Rs) | D47: =D45*D46 -> 3.128853
B49: Cost of material (Rs) | D49: =D37-D47 -> 316.34652
B51: Total cost of channel steel (Rs) per metre | D51: =D49 -> 316.34652
B52: Wastage allowance during fabrication | D52: =D12 -> 0
B53: Net cost of channel steel (Rs) per metre | D53: =(1+D52)*D51 -> 316.34652
...

Sheet Cantilever Arm 750
A1: Cable Tray Costing Cantilever Arm - 750 mm length, 2.5 mm thk (per piece, arm only - without base plate)
B5: Input for raw material and conversion costs | M5: Cantilever arm configuration
B6: Cost of steel(Rs/kg) | D6: 73 | F6: Coating thickness of Zinc (micron) | H6: 86
B7: Transportation and handling cost of raw material to vendor shop (% of raw material cost) | D7: 0 | F7: Specific weight of Zinc (kg/m3) | H7: 7135 | M7: Arm section - width (mm) | O7: 41
B8: Specific weight of MS (kg/m3) | D8: 7850 | F8: Cost of Zinc (Rs/kg) | H8: 425.6 | M8: Arm section - depth (mm) | O8: 41
B9: Cost of engg and fabrication (% of material cost) | D9: 0 | F9: Wastage during galvalization | H9: 0 | M9: Arm thickness (mm) | O9: 2.5
B10: Quality test and inspection charges (%) | D10: 0 | F10: Recoverable scrap - Ash per meter of tray (%) | H10: 0.12 | M10: Arm section - lip / return (mm) | O10: 9
B11: Salvage value of scrap for MS plates(% of overall value) | D11: 0.3 | F11: Recoverable scrap - Dross per meter of tray (%) | H11: 0.08 | M11: Arm length (mm) | O11: 750
B12: Wastage allowance during fabrication | D12: 0 | F12: Recoverable scrap salvage value - Ash (%) | H12: 0.26 | M12: Length of a slot in arm (mm) | O12: 28
B13: Transportation and handling cost of finished goods to site (Rs/kg) | D13: 0 | F13: Recoverable scrap salvage value - Dross (%) | H13: 0.52 | M13: Width of a slot in arm (mm) | O13: 13
B14: Overheads for vendor (%) | D14: 0 | F14: Cost of galvanization (% of material cost) | H14: 0 | M14: Pitch of slots along arm (mm) | O14: 50
B15: Profit & overhead margin (INR/kg) | D15: 2.5 | M15: No of slots per arm | O15: =ROUNDDOWN(O11/O14,0) -> 15
B16: Cost of contract Performance Bank Guarantee | D16: 0
B17: Labour & Fabrication Charges (INR/ kg) | D17: =6.5*1.2 -> 7.8
B25: Detailed Costing
B26: Cantilever arm MS material cost | M26: Galvalization
M27: Zinc Requirement
B28: Developed (strip) width of arm section (mm) | D28: =O7+2*O8+2*O10 -> 141
B29: Cross-section area of arm (mm2) | D29: =D28*O9 -> 352.5 | M29: Gross surface area - both faces (m2) | O29: =2*D28/1000*D30/1000 -> 0.2115
B30: Arm length (mm) | D30: =O11 -> 750 | M30: Surface area of slots along thickness (m2) | O30: =2*(O12+O13)/1000*O9/1000*D42 -> 0.003075
M31: Top surface area of slots - both faces (m2) | O31: =2*O12/1000*O13/1000*D42 -> 0.01092
B32: Arm thickness (mm) | D32: =O9 -> 2.5
M33: Overall surface area (m2) | O33: =O29+O30-O31 -> 0.203655
B35: Volume of steel in arm (m3) | D35: =D29*D30/10^9 -> 0.000264375 | M35: Total surface area for galvanization (m2) | O35: =O33 -> 0.203655
B36: Weight of arm (kg) | D36: =D35*D8 -> 2.0753438
B37: Cost of steel for arm (Rs) | D37: =D36*(D6*(1+D7)) -> 151.50009 | M37: Weight of Zinc required for galvanization (kg) | O37: =O35*H6*10^-6*H7 -> 0.12496474
M38: Wastage during galvalization | O38: =H9 -> 0
B39: Scrap salvage due to slots | M39: Total weight of Zinc required for galvanization (kg) | O39: =(1+O38)*O37 -> 0.12496474
M40: Cost of Zinc galvanization (Rs) | O40: =O39*H8 -> 53.184995
B41: No of slots per arm | D41: =O15 -> 15
B42: Total no of slots | D42: =D41 -> 15 | M42: Recoverable scrap - Ash (kg) | O42: =H10*O37 -> 0.014995769 | Q42: Recoverable scrap salvage - Ash (Rs/kg) | T42: =H12*$H$8 -> 110.656
B43: Total volume of slots (m3) | D43: =D42*O12/1000*O13/1000*O9/1000 -> 1.365e-05 | M43: Recoverable scrap - Dross (kg) | O43: =H11*O37 -> 0.0099971796 | Q43: Recoverable scrap salvage - Dross (Rs/kg) | T43: =H13*$H$8 -> 221.312
B44: Weight of slots (kg) | D44: =D43*D8 -> 0.1071525 | M44: Salvage value of zinc scrap (Rs) | O44: =O42*T42+O43*T43 -> 3.8718677
B45: Value of scrap generated (Rs) | D45: =D44*D6 -> 7.8221325
B46: Salvage value of scrap (% of overall value) | D46: =D11 -> 0.3 | M46: Net cost of Zinc galvanization (Rs) | O46: =O40-O44 -> 49.313128
B47: Salvage value of MS scrap (Rs) | D47: =D45*D46 -> 2.3466397
B49: Cost of material (Rs) | D49: =D37-D47 -> 149.15345
B51: Total cost of arm steel (Rs) per piece | D51: =D49 -> 149.15345
B52: Wastage allowance during fabrication | D52: =D12 -> 0
B53: Net cost of arm steel (Rs) per piece | D53: =(1+D52)*D51 -> 149.15345
...

Sheet Cantilever Arm 620
A1: Cable Tray Costing Cantilever Arm - 750 mm length, 2.5 mm thk (per piece, arm only - without base plate)
B5: Input for raw material and conversion costs | M5: Cantilever arm configuration
B6: Cost of steel(Rs/kg) | D6: 73 | F6: Coating thickness of Zinc (micron) | H6: 86
B7: Transportation and handling cost of raw material to vendor shop (% of raw material cost) | D7: 0 | F7: Specific weight of Zinc (kg/m3) | H7: 7135 | M7: Arm section - width (mm) | O7: 41
B8: Specific weight of MS (kg/m3) | D8: 7850 | F8: Cost of Zinc (Rs/kg) | H8: 425.6 | M8: Arm section - depth (mm) | O8: 41
B9: Cost of engg and fabrication (% of material cost) | D9: 0 | F9: Wastage during galvalization | H9: 0 | M9: Arm thickness (mm) | O9: 2.5
B10: Quality test and inspection charges (%) | D10: 0 | F10: Recoverable scrap - Ash per meter of tray (%) | H10: 0.12 | M10: Arm section - lip / return (mm) | O10: 9
B11: Salvage value of scrap for MS plates(% of overall value) | D11: 0.3 | F11: Recoverable scrap - Dross per meter of tray (%) | H11: 0.08 | M11: Arm length (mm) | O11: 620
B12: Wastage allowance during fabrication | D12: 0 | F12: Recoverable scrap salvage value - Ash (%) | H12: 0.26 | M12: Length of a slot in arm (mm) | O12: 28
B13: Transportation and handling cost of finished goods to site (Rs/kg) | D13: 0 | F13: Recoverable scrap salvage value - Dross (%) | H13: 0.52 | M13: Width of a slot in arm (mm) | O13: 13
B14: Overheads for vendor (%) | D14: 0 | F14: Cost of galvanization (% of material cost) | H14: 0 | M14: Pitch of slots along arm (mm) | O14: 50
B15: Profit & overhead margin (INR/kg) | D15: 2.5 | M15: No of slots per arm | O15: =ROUNDDOWN(O11/O14,0) -> 12
B16: Cost of contract Performance Bank Guarantee | D16: 0
B17: Labour & Fabrication Charges (INR/ kg) | D17: =6.5*1.2 -> 7.8
B25: Detailed Costing
B26: Cantilever arm MS material cost | M26: Galvalization
M27: Zinc Requirement
B28: Developed (strip) width of arm section (mm) | D28: =O7+2*O8+2*O10 -> 141
B29: Cross-section area of arm (mm2) | D29: =D28*O9 -> 352.5 | M29: Gross surface area - both faces (m2) | O29: =2*D28/1000*D30/1000 -> 0.17484
B30: Arm length (mm) | D30: =O11 -> 620 | M30: Surface area of slots along thickness (m2) | O30: =2*(O12+O13)/1000*O9/1000*D42 -> 0.00246
M31: Top surface area of slots - both faces (m2) | O31: =2*O12/1000*O13/1000*D42 -> 0.008736
B32: Arm thickness (mm) | D32: =O9 -> 2.5
M33: Overall surface area (m2) | O33: =O29+O30-O31 -> 0.168564
B35: Volume of steel in arm (m3) | D35: =D29*D30/10^9 -> 0.00021855 | M35: Total surface area for galvanization (m2) | O35: =O33 -> 0.168564
B36: Weight of arm (kg) | D36: =D35*D8 -> 1.7156175
B37: Cost of steel for arm (Rs) | D37: =D36*(D6*(1+D7)) -> 125.24008 | M37: Weight of Zinc required for galvanization (kg) | O37: =O35*H6*10^-6*H7 -> 0.10343256
M38: Wastage during galvalization | O38: =H9 -> 0
B39: Scrap salvage due to slots | M39: Total weight of Zinc required for galvanization (kg) | O39: =(1+O38)*O37 -> 0.10343256
M40: Cost of Zinc galvanization (Rs) | O40: =O39*H8 -> 44.020896
B41: No of slots per arm | D41: =O15 -> 12
B42: Total no of slots | D42: =D41 -> 12 | M42: Recoverable scrap - Ash (kg) | O42: =H10*O37 -> 0.012411907 | Q42: Recoverable scrap salvage - Ash (Rs/kg) | T42: =H12*$H$8 -> 110.656
B43: Total volume of slots (m3) | D43: =D42*O12/1000*O13/1000*O9/1000 -> 1.092e-05 | M43: Recoverable scrap - Dross (kg) | O43: =H11*O37 -> 0.0082746045 | Q43: Recoverable scrap salvage - Dross (Rs/kg) | T43: =H13*$H$8 -> 221.312
B44: Weight of slots (kg) | D44: =D43*D8 -> 0.085722 | M44: Salvage value of zinc scrap (Rs) | O44: =O42*T42+O43*T43 -> 3.2047212
B45: Value of scrap generated (Rs) | D45: =D44*D6 -> 6.257706
B46: Salvage value of scrap (% of overall value) | D46: =D11 -> 0.3 | M46: Net cost of Zinc galvanization (Rs) | O46: =O40-O44 -> 40.816175
B47: Salvage value of MS scrap (Rs) | D47: =D45*D46 -> 1.8773118
B49: Cost of material (Rs) | D49: =D37-D47 -> 123.36277
B51: Total cost of arm steel (Rs) per piece | D51: =D49 -> 123.36277
B52: Wastage allowance during fabrication | D52: =D12 -> 0
B53: Net cost of arm steel (Rs) per piece | D53: =(1+D52)*D51 -> 123.36277
...

Sheet Cantilever Arm 320
A1: Cable Tray Costing Cantilever Arm - 750 mm length, 2.5 mm thk (per piece, arm only - without base plate)
B5: Input for raw material and conversion costs | M5: Cantilever arm configuration
B6: Cost of steel(Rs/kg) | D6: 73 | F6: Coating thickness of Zinc (micron) | H6: 86
B7: Transportation and handling cost of raw material to vendor shop (% of raw material cost) | D7: 0 | F7: Specific weight of Zinc (kg/m3) | H7: 7135 | M7: Arm section - width (mm) | O7: 41
B8: Specific weight of MS (kg/m3) | D8: 7850 | F8: Cost of Zinc (Rs/kg) | H8: 425.6 | M8: Arm section - depth (mm) | O8: 41
B9: Cost of engg and fabrication (% of material cost) | D9: 0 | F9: Wastage during galvalization | H9: 0 | M9: Arm thickness (mm) | O9: 2.5
B10: Quality test and inspection charges (%) | D10: 0 | F10: Recoverable scrap - Ash per meter of tray (%) | H10: 0.12 | M10: Arm section - lip / return (mm) | O10: 9
B11: Salvage value of scrap for MS plates(% of overall value) | D11: 0.3 | F11: Recoverable scrap - Dross per meter of tray (%) | H11: 0.08 | M11: Arm length (mm) | O11: 320
B12: Wastage allowance during fabrication | D12: 0 | F12: Recoverable scrap salvage value - Ash (%) | H12: 0.26 | M12: Length of a slot in arm (mm) | O12: 28
B13: Transportation and handling cost of finished goods to site (Rs/kg) | D13: 0 | F13: Recoverable scrap salvage value - Dross (%) | H13: 0.52 | M13: Width of a slot in arm (mm) | O13: 13
B14: Overheads for vendor (%) | D14: 0 | F14: Cost of galvanization (% of material cost) | H14: 0 | M14: Pitch of slots along arm (mm) | O14: 50
B15: Profit & overhead margin (INR/kg) | D15: 2.5 | M15: No of slots per arm | O15: =ROUNDDOWN(O11/O14,0) -> 6
B16: Cost of contract Performance Bank Guarantee | D16: 0
B17: Labour & Fabrication Charges (INR/ kg) | D17: =6.5*1.2 -> 7.8
B25: Detailed Costing
B26: Cantilever arm MS material cost | M26: Galvalization
M27: Zinc Requirement
B28: Developed (strip) width of arm section (mm) | D28: =O7+2*O8+2*O10 -> 141
B29: Cross-section area of arm (mm2) | D29: =D28*O9 -> 352.5 | M29: Gross surface area - both faces (m2) | O29: =2*D28/1000*D30/1000 -> 0.09024
B30: Arm length (mm) | D30: =O11 -> 320 | M30: Surface area of slots along thickness (m2) | O30: =2*(O12+O13)/1000*O9/1000*D42 -> 0.00123
M31: Top surface area of slots - both faces (m2) | O31: =2*O12/1000*O13/1000*D42 -> 0.004368
B32: Arm thickness (mm) | D32: =O9 -> 2.5
M33: Overall surface area (m2) | O33: =O29+O30-O31 -> 0.087102
B35: Volume of steel in arm (m3) | D35: =D29*D30/10^9 -> 0.0001128 | M35: Total surface area for galvanization (m2) | O35: =O33 -> 0.087102
B36: Weight of arm (kg) | D36: =D35*D8 -> 0.88548
B37: Cost of steel for arm (Rs) | D37: =D36*(D6*(1+D7)) -> 64.64004 | M37: Weight of Zinc required for galvanization (kg) | O37: =O35*H6*10^-6*H7 -> 0.053446658
M38: Wastage during galvalization | O38: =H9 -> 0
B39: Scrap salvage due to slots | M39: Total weight of Zinc required for galvanization (kg) | O39: =(1+O38)*O37 -> 0.053446658
M40: Cost of Zinc galvanization (Rs) | O40: =O39*H8 -> 22.746898
B41: No of slots per arm | D41: =O15 -> 6
B42: Total no of slots | D42: =D41 -> 6 | M42: Recoverable scrap - Ash (kg) | O42: =H10*O37 -> 0.006413599 | Q42: Recoverable scrap salvage - Ash (Rs/kg) | T42: =H12*$H$8 -> 110.656
B43: Total volume of slots (m3) | D43: =D42*O12/1000*O13/1000*O9/1000 -> 5.46e-06 | M43: Recoverable scrap - Dross (kg) | O43: =H11*O37 -> 0.0042757327 | Q43: Recoverable scrap salvage - Dross (Rs/kg) | T43: =H13*$H$8 -> 221.312
B44: Weight of slots (kg) | D44: =D43*D8 -> 0.042861 | M44: Salvage value of zinc scrap (Rs) | O44: =O42*T42+O43*T43 -> 1.6559742
B45: Value of scrap generated (Rs) | D45: =D44*D6 -> 3.128853
B46: Salvage value of scrap (% of overall value) | D46: =D11 -> 0.3 | M46: Net cost of Zinc galvanization (Rs) | O46: =O40-O44 -> 21.090924
B47: Salvage value of MS scrap (Rs) | D47: =D45*D46 -> 0.9386559
B49: Cost of material (Rs) | D49: =D37-D47 -> 63.701384
B51: Total cost of arm steel (Rs) per piece | D51: =D49 -> 63.701384
B52: Wastage allowance during fabrication | D52: =D12 -> 0
B53: Net cost of arm steel (Rs) per piece | D53: =(1+D52)*D51 -> 63.701384
...

Sheet Horizontal Tee 600x100x2
A1: Cable Tray Costing: Ladder Type Horizontal Tee, Bending Radius 1200 mm
B5: Input for raw material and conversion costs | M5: Cable Tray configuration
B6: Cost of 1 kg of MS (Rs) | D6: 73 | F6: Coating thickness of Zinc (micron) | H6: 86 | M6: Runners | Q6: Rungs
B7: Transportation and handling cost of raw material to vendor shop (% of raw material cost) | D7: 0 | F7: Specific weight of Zinc (kg/m3) | H7: 7135 | M7: Number of runners | O7: 2 | Q7: No of rungs per 2500 meter of runner | U7: 10
B8: Specific weight of MS (kg/m3) | D8: 7850 | F8: Cost of Zinc (Rs/kg) | H8: 425.6 | M8: Tray width (mm) | O8: 600 | Q8: Length of rung (mm) | U8: =O8 -> 600
B9: Cost of engg and fabrication (% of material cost) | D9: 0 | F9: Wastage during galvalization | H9: 0 | M9: Tray Depth (mm) | O9: 100 | Q9: Width of rung (mm) | U9: 50
B10: Quality test and inspection charges (%) | D10: 0 | F10: Recoverable scrap - Ash per meter of tray (%) | H10: 0.12 | M10: Tray thickness (mm) | O10: 2 | Q10: Collar / Height of rung (mm) | U10: 20
B11: Salvage value of scrap for MS plates(% of overall value) | D11: 0.5 | F11: Recoverable scrap - Dross per meter of tray (%) | H11: 0.08 | M11: Tray collar (mm) | O11: 25 | Q11: Thickness of rung (mm) | U11: 2
B12: Wastage allowance during fabrication | D12: 0 | F12: Recoverable scrap salvage value - Ash (%) | H12: 0.26 | M12: Tray length (mm) | O12: 4200 | Q12: No of slots per 40 mm of length | U12: 1
B13: Transportation and handling cost of finished goods to site (Rs/kg) | D13: 0 | F13: Recoverable scrap salvage value - Dross (%) | H13: 0.52 | M13: No of holes per 2500 mm length | O13: 20 | Q13: Length of 1 slot (mm) | U13: 25
B14: Overheads for vendor (%) | D14: 0 | F14: Cost of galvanization (% of material cost) | H14: 0 | M14: Dia of 1 hole (mm) | O14: 10 | Q14: Width of 1 slot (mm) | U14: 10
B15: Profit margin for vendor (%) | D15: 2.5
B16: Cost of contract Performance Bank Guarantee | D16: 0
B17: Labour,Fabrication,Overhead,Profit Margin (INR/ kg) | D17: =6.5*1.2 -> 7.8
B20: Detailed Costing
B21: Cable tray MS material cost | M21: Galvalization
B22: Runner | F22: Rung | M22: Zinc Requirement
B23: Number of runners per meter length | D23: =O7 -> 2 | F23: No of rungs in this fitting (U7 x length / 2500, rounded) | J23: =ROUND(U7*D28/2500,0) -> 17 | M23: Runner | Q23: Rung
B24: Tray width (mm) | D24: =O8 -> 600 | F24: Length of rung (mm) | J24: =U8 -> 600 | M24: Surface area for 1 m length (m2) | O24: =2*(2*(2*D27+D25)/1000*D28/1000) -> 2.52 | Q24: Surface area for 1 rung (m2) | T24: =2*J24/1000*(J25+2*J26)/1000 -> 0.108
B25: Tray Depth (mm) | D25: =O9 -> 100 | F25: Width of rung (mm) | J25: =U9 -> 50 | M25: Surface area holes along thickness for 1 m length (m2) | O25: =D37*3.14*D38/1000*D26/1000*D28/125 -> 0.0422016 | Q25: Surface area of slots along thickness for 1 rung (m2) | T25: =(2*(J38+J39)/1000*D26/1000)*D24/40 -> 0.0021
B26: Tray thickness (mm) | D26: =O10 -> 2 | F26: Collar / Height of rung (mm) | J26: =U10 -> 20 | M26: Top surface area of holes for 1 m length (m2) | O26: =D37*3.14*(D38/2/1000)^2*D28/125 -> 0.052752 | Q26: Top surface area of slots 1 rung (m2) | T26: =J38/1000*J39/1000*D24/40 -> 0.00375
B27: Tray collar (mm) | D27: =O11 -> 25 | F27: Thickness of rung (mm) | J27: =U11 -> 2
B28: Tray length (mm) | D28: =O12 -> 4200 | M28: Overall surface area for 1 meter of runner (m2) | O28: =O24+O25-O26 -> 2.5094496 | Q28: Overall rung surface area for 1 meter of runner (m2) | T28: =(T24+T25-T26)*J23 -> 1.80795
F29: Volume of 1 rung (m3) | J29: =(2*J26+J25)/1000*J24/1000*J27/1000 -> 0.000108
F30: Weight of 1 rung (kg) | J30: =J29*D8 -> 0.8478 | M30: Total surface area per meter of cable tray (m2) | O30: =O28+T28 -> 4.3173996
B31: Volume of runner (m3) | D31: =2*(D25+D27*2)/1000*D26/1000*D28/1000 -> 0.00252 | F31: Cost of 1 rung (Rs) | J31: =J30*(D6*(1+D7)) -> 61.8894
B32: Weight of runner per meter length (kg) | D32: =D31*D8 -> 19.782 | F32: Cost of rungs per meter of runner | J32: =J31*J23 -> 1052.1198 | M32: Weight of Zinc required for galvanization (kg) | O32: =O30*H6*10^-6*H7 -> 2.6491996
B33: Cost of runner per meter length (Rs) | D33: =D32*(D6*(1+D7)) -> 1444.086 | M33: Wastage during galvalization | O33: =H9 -> 0
M34: Total weight of Zinc required for galvanization (kg) | O34: =(1+O33)*O32 -> 2.6491996
B35: Scrap salvage due to holes / slots | M35: Cost of Zinc galvanization per meter of runner (Rs) | O35: =O34*H8 -> 1127.4993
B36: Runner | F36: Rung
B37: No of holes per 2500 mm length | D37: =O13 -> 20 | F37: No of slots per 40 mm of length | J37: =U12 -> 1 | M37: Recoverable scrap - Ash per meter of tray (kg) | O37: =H10*O32 -> 0.31790395 | Q37: Recoverable scrap salvage - Ash (Rs/kg) | T37: =H12*$H$8 -> 110.656
B38: Dia of 1 hole (mm) | D38: =O14 -> 10 | F38: Length of 1 slot (mm) | J38: =U13 -> 25 | M38: Recoverable scrap - Dross per meter of tray (kg) | O38: =H11*O32 -> 0.21193597 | Q38: Recoverable scrap salvage - Dross (Rs/kg) | T38: =H13*$H$8 -> 221.312
B39: Volume of holes (m3) | D39: =2*D37*3.14*(D38/2/1000)^2*D26/1000 -> 6.28e-06 | F39: Width of 1 slot (mm) | J39: =U14 -> 10 | M39: Salvage value of scrap per meter of cable (Rs) | O39: =O37*T37+O38*T38 -> 82.081952
F40: Volume of 1 slot (m3) | J40: =J38/1000*J39/1000*J27/1000 -> 5e-07
B41: Weight of holes per 2500 mm of runner (kg) | D41: =D39*D8 -> 0.049298 | F41: Volume slots per rung (m3) | J41: =D24/40*J40 -> 7.5e-06 | M41: Net cost of Zinc galvanization per meter of runner (Rs) | O41: =O35-O39 -> 1045.4174
B42: Value of scrap generated per meter of runner (Rs) | D42: =D41*D6 -> 3.598754 | F42: Weight of slots per rung (kg) | J42: =J41*D8 -> 0.058875
B43: Salvage value of scrap (% of overall value) | D43: =D11 -> 0.5 | F43: Weight of slots per 2500mm of runner (kg) | J43: =J42*J23 -> 1.000875
B44: Salvage value of MS scrap per meter of runner (Rs) | D44: =D42*D43 -> 1.799377 | F44: Value of scrap generated per meter of runner (Rs) | J44: =J43*D6 -> 73.063875
F45: Salvage value of MS scrap per meter of runner (Rs) | J45: =J44*D43 -> 36.531937
...

Sheet Horizontal Tee 300x100x2
A1: Cable Tray Costing: Ladder Type Horizontal Tee, Bending Radius 1200 mm
B5: Input for raw material and conversion costs | M5: Cable Tray configuration
B6: Cost of 1 kg of MS (Rs) | D6: 73 | F6: Coating thickness of Zinc (micron) | H6: 86 | M6: Runners | Q6: Rungs
B7: Transportation and handling cost of raw material to vendor shop (% of raw material cost) | D7: 0 | F7: Specific weight of Zinc (kg/m3) | H7: 7135 | M7: Number of runners | O7: 2 | Q7: No of rungs per 2500 meter of runner | U7: 10
B8: Specific weight of MS (kg/m3) | D8: 7850 | F8: Cost of Zinc (Rs/kg) | H8: 425.6 | M8: Tray width (mm) | O8: 300 | Q8: Length of rung (mm) | U8: =O8 -> 300
B9: Cost of engg and fabrication (% of material cost) | D9: 0 | F9: Wastage during galvalization | H9: 0 | M9: Tray Depth (mm) | O9: 100 | Q9: Width of rung (mm) | U9: 50
B10: Quality test and inspection charges (%) | D10: 0 | F10: Recoverable scrap - Ash per meter of tray (%) | H10: 0.12 | M10: Tray thickness (mm) | O10: 2 | Q10: Collar / Height of rung (mm) | U10: 20
B11: Salvage value of scrap for MS plates(% of overall value) | D11: 0.5 | F11: Recoverable scrap - Dross per meter of tray (%) | H11: 0.08 | M11: Tray collar (mm) | O11: 25 | Q11: Thickness of rung (mm) | U11: 2
B12: Wastage allowance during fabrication | D12: 0 | F12: Recoverable scrap salvage value - Ash (%) | H12: 0.26 | M12: Tray length (mm) | O12: 4200 | Q12: No of slots per 40 mm of length | U12: 1
B13: Transportation and handling cost of finished goods to site (Rs/kg) | D13: 0 | F13: Recoverable scrap salvage value - Dross (%) | H13: 0.52 | M13: No of holes per 2500 mm length | O13: 20 | Q13: Length of 1 slot (mm) | U13: 25
B14: Overheads for vendor (%) | D14: 0 | F14: Cost of galvanization (% of material cost) | H14: 0 | M14: Dia of 1 hole (mm) | O14: 10 | Q14: Width of 1 slot (mm) | U14: 10
B15: Profit margin for vendor (%) | D15: 2.5
B16: Cost of contract Performance Bank Guarantee | D16: 0
B17: Labour,Fabrication,Overhead,Profit Margin (INR/ kg) | D17: =6.5*1.2 -> 7.8
B20: Detailed Costing
B21: Cable tray MS material cost | M21: Galvalization
B22: Runner | F22: Rung | M22: Zinc Requirement
B23: Number of runners per meter length | D23: =O7 -> 2 | F23: No of rungs in this fitting (U7 x length / 2500, rounded) | J23: =ROUND(U7*D28/2500,0) -> 17 | M23: Runner | Q23: Rung
B24: Tray width (mm) | D24: =O8 -> 300 | F24: Length of rung (mm) | J24: =U8 -> 300 | M24: Surface area for 1 m length (m2) | O24: =2*(2*(2*D27+D25)/1000*D28/1000) -> 2.52 | Q24: Surface area for 1 rung (m2) | T24: =2*J24/1000*(J25+2*J26)/1000 -> 0.054
B25: Tray Depth (mm) | D25: =O9 -> 100 | F25: Width of rung (mm) | J25: =U9 -> 50 | M25: Surface area holes along thickness for 1 m length (m2) | O25: =D37*3.14*D38/1000*D26/1000*D28/125 -> 0.0422016 | Q25: Surface area of slots along thickness for 1 rung (m2) | T25: =(2*(J38+J39)/1000*D26/1000)*D24/40 -> 0.00105
B26: Tray thickness (mm) | D26: =O10 -> 2 | F26: Collar / Height of rung (mm) | J26: =U10 -> 20 | M26: Top surface area of holes for 1 m length (m2) | O26: =D37*3.14*(D38/2/1000)^2*D28/125 -> 0.052752 | Q26: Top surface area of slots 1 rung (m2) | T26: =J38/1000*J39/1000*D24/40 -> 0.001875
B27: Tray collar (mm) | D27: =O11 -> 25 | F27: Thickness of rung (mm) | J27: =U11 -> 2
B28: Tray length (mm) | D28: =O12 -> 4200 | M28: Overall surface area for 1 meter of runner (m2) | O28: =O24+O25-O26 -> 2.5094496 | Q28: Overall rung surface area for 1 meter of runner (m2) | T28: =(T24+T25-T26)*J23 -> 0.903975
F29: Volume of 1 rung (m3) | J29: =(2*J26+J25)/1000*J24/1000*J27/1000 -> 5.4e-05
F30: Weight of 1 rung (kg) | J30: =J29*D8 -> 0.4239 | M30: Total surface area per meter of cable tray (m2) | O30: =O28+T28 -> 3.4134246
B31: Volume of runner (m3) | D31: =2*(D25+D27*2)/1000*D26/1000*D28/1000 -> 0.00252 | F31: Cost of 1 rung (Rs) | J31: =J30*(D6*(1+D7)) -> 30.9447
B32: Weight of runner per meter length (kg) | D32: =D31*D8 -> 19.782 | F32: Cost of rungs per meter of runner | J32: =J31*J23 -> 526.0599 | M32: Weight of Zinc required for galvanization (kg) | O32: =O30*H6*10^-6*H7 -> 2.0945115
B33: Cost of runner per meter length (Rs) | D33: =D32*(D6*(1+D7)) -> 1444.086 | M33: Wastage during galvalization | O33: =H9 -> 0
M34: Total weight of Zinc required for galvanization (kg) | O34: =(1+O33)*O32 -> 2.0945115
B35: Scrap salvage due to holes / slots | M35: Cost of Zinc galvanization per meter of runner (Rs) | O35: =O34*H8 -> 891.42408
B36: Runner | F36: Rung
B37: No of holes per 2500 mm length | D37: =O13 -> 20 | F37: No of slots per 40 mm of length | J37: =U12 -> 1 | M37: Recoverable scrap - Ash per meter of tray (kg) | O37: =H10*O32 -> 0.25134138 | Q37: Recoverable scrap salvage - Ash (Rs/kg) | T37: =H12*$H$8 -> 110.656
B38: Dia of 1 hole (mm) | D38: =O14 -> 10 | F38: Length of 1 slot (mm) | J38: =U13 -> 25 | M38: Recoverable scrap - Dross per meter of tray (kg) | O38: =H11*O32 -> 0.16756092 | Q38: Recoverable scrap salvage - Dross (Rs/kg) | T38: =H13*$H$8 -> 221.312
B39: Volume of holes (m3) | D39: =2*D37*3.14*(D38/2/1000)^2*D26/1000 -> 6.28e-06 | F39: Width of 1 slot (mm) | J39: =U14 -> 10 | M39: Salvage value of scrap per meter of cable (Rs) | O39: =O37*T37+O38*T38 -> 64.895673
F40: Volume of 1 slot (m3) | J40: =J38/1000*J39/1000*J27/1000 -> 5e-07
B41: Weight of holes per 2500 mm of runner (kg) | D41: =D39*D8 -> 0.049298 | F41: Volume slots per rung (m3) | J41: =D24/40*J40 -> 3.75e-06 | M41: Net cost of Zinc galvanization per meter of runner (Rs) | O41: =O35-O39 -> 826.52841
B42: Value of scrap generated per meter of runner (Rs) | D42: =D41*D6 -> 3.598754 | F42: Weight of slots per rung (kg) | J42: =J41*D8 -> 0.0294375
B43: Salvage value of scrap (% of overall value) | D43: =D11 -> 0.5 | F43: Weight of slots per 2500mm of runner (kg) | J43: =J42*J23 -> 0.5004375
B44: Salvage value of MS scrap per meter of runner (Rs) | D44: =D42*D43 -> 1.799377 | F44: Value of scrap generated per meter of runner (Rs) | J44: =J43*D6 -> 36.531937
F45: Salvage value of MS scrap per meter of runner (Rs) | J45: =J44*D43 -> 18.265969
...

Sheet Horizontal Tee 150x100x2
A1: Cable Tray Costing: Ladder Type Horizontal Tee, Bending Radius 1200 mm
B5: Input for raw material and conversion costs | M5: Cable Tray configuration
B6: Cost of 1 kg of MS (Rs) | D6: 73 | F6: Coating thickness of Zinc (micron) | H6: 86 | M6: Runners | Q6: Rungs
B7: Transportation and handling cost of raw material to vendor shop (% of raw material cost) | D7: 0 | F7: Specific weight of Zinc (kg/m3) | H7: 7135 | M7: Number of runners | O7: 2 | Q7: No of rungs per 2500 meter of runner | U7: 10
B8: Specific weight of MS (kg/m3) | D8: 7850 | F8: Cost of Zinc (Rs/kg) | H8: 425.6 | M8: Tray width (mm) | O8: 150 | Q8: Length of rung (mm) | U8: =O8 -> 150
B9: Cost of engg and fabrication (% of material cost) | D9: 0 | F9: Wastage during galvalization | H9: 0 | M9: Tray Depth (mm) | O9: 100 | Q9: Width of rung (mm) | U9: 50
B10: Quality test and inspection charges (%) | D10: 0 | F10: Recoverable scrap - Ash per meter of tray (%) | H10: 0.12 | M10: Tray thickness (mm) | O10: 2 | Q10: Collar / Height of rung (mm) | U10: 20
B11: Salvage value of scrap for MS plates(% of overall value) | D11: 0.5 | F11: Recoverable scrap - Dross per meter of tray (%) | H11: 0.08 | M11: Tray collar (mm) | O11: 25 | Q11: Thickness of rung (mm) | U11: 2
B12: Wastage allowance during fabrication | D12: 0 | F12: Recoverable scrap salvage value - Ash (%) | H12: 0.26 | M12: Tray length (mm) | O12: 4200 | Q12: No of slots per 40 mm of length | U12: 1
B13: Transportation and handling cost of finished goods to site (Rs/kg) | D13: 0 | F13: Recoverable scrap salvage value - Dross (%) | H13: 0.52 | M13: No of holes per 2500 mm length | O13: 20 | Q13: Length of 1 slot (mm) | U13: 25
B14: Overheads for vendor (%) | D14: 0 | F14: Cost of galvanization (% of material cost) | H14: 0 | M14: Dia of 1 hole (mm) | O14: 10 | Q14: Width of 1 slot (mm) | U14: 10
B15: Profit margin for vendor (%) | D15: 2.5
B16: Cost of contract Performance Bank Guarantee | D16: 0
B17: Labour,Fabrication,Overhead,Profit Margin (INR/ kg) | D17: =6.5*1.2 -> 7.8
B20: Detailed Costing
B21: Cable tray MS material cost | M21: Galvalization
B22: Runner | F22: Rung | M22: Zinc Requirement
B23: Number of runners per meter length | D23: =O7 -> 2 | F23: No of rungs in this fitting (U7 x length / 2500, rounded) | J23: =ROUND(U7*D28/2500,0) -> 17 | M23: Runner | Q23: Rung
B24: Tray width (mm) | D24: =O8 -> 150 | F24: Length of rung (mm) | J24: =U8 -> 150 | M24: Surface area for 1 m length (m2) | O24: =2*(2*(2*D27+D25)/1000*D28/1000) -> 2.52 | Q24: Surface area for 1 rung (m2) | T24: =2*J24/1000*(J25+2*J26)/1000 -> 0.027
B25: Tray Depth (mm) | D25: =O9 -> 100 | F25: Width of rung (mm) | J25: =U9 -> 50 | M25: Surface area holes along thickness for 1 m length (m2) | O25: =D37*3.14*D38/1000*D26/1000*D28/125 -> 0.0422016 | Q25: Surface area of slots along thickness for 1 rung (m2) | T25: =(2*(J38+J39)/1000*D26/1000)*D24/40 -> 0.000525
B26: Tray thickness (mm) | D26: =O10 -> 2 | F26: Collar / Height of rung (mm) | J26: =U10 -> 20 | M26: Top surface area of holes for 1 m length (m2) | O26: =D37*3.14*(D38/2/1000)^2*D28/125 -> 0.052752 | Q26: Top surface area of slots 1 rung (m2) | T26: =J38/1000*J39/1000*D24/40 -> 0.0009375
B27: Tray collar (mm) | D27: =O11 -> 25 | F27: Thickness of rung (mm) | J27: =U11 -> 2
B28: Tray length (mm) | D28: =O12 -> 4200 | M28: Overall surface area for 1 meter of runner (m2) | O28: =O24+O25-O26 -> 2.5094496 | Q28: Overall rung surface area for 1 meter of runner (m2) | T28: =(T24+T25-T26)*J23 -> 0.4519875
F29: Volume of 1 rung (m3) | J29: =(2*J26+J25)/1000*J24/1000*J27/1000 -> 2.7e-05
F30: Weight of 1 rung (kg) | J30: =J29*D8 -> 0.21195 | M30: Total surface area per meter of cable tray (m2) | O30: =O28+T28 -> 2.9614371
B31: Volume of runner (m3) | D31: =2*(D25+D27*2)/1000*D26/1000*D28/1000 -> 0.00252 | F31: Cost of 1 rung (Rs) | J31: =J30*(D6*(1+D7)) -> 15.47235
B32: Weight of runner per meter length (kg) | D32: =D31*D8 -> 19.782 | F32: Cost of rungs per meter of runner | J32: =J31*J23 -> 263.02995 | M32: Weight of Zinc required for galvanization (kg) | O32: =O30*H6*10^-6*H7 -> 1.8171674
B33: Cost of runner per meter length (Rs) | D33: =D32*(D6*(1+D7)) -> 1444.086 | M33: Wastage during galvalization | O33: =H9 -> 0
M34: Total weight of Zinc required for galvanization (kg) | O34: =(1+O33)*O32 -> 1.8171674
B35: Scrap salvage due to holes / slots | M35: Cost of Zinc galvanization per meter of runner (Rs) | O35: =O34*H8 -> 773.38645
B36: Runner | F36: Rung
B37: No of holes per 2500 mm length | D37: =O13 -> 20 | F37: No of slots per 40 mm of length | J37: =U12 -> 1 | M37: Recoverable scrap - Ash per meter of tray (kg) | O37: =H10*O32 -> 0.21806009 | Q37: Recoverable scrap salvage - Ash (Rs/kg) | T37: =H12*$H$8 -> 110.656
B38: Dia of 1 hole (mm) | D38: =O14 -> 10 | F38: Length of 1 slot (mm) | J38: =U13 -> 25 | M38: Recoverable scrap - Dross per meter of tray (kg) | O38: =H11*O32 -> 0.14537339 | Q38: Recoverable scrap salvage - Dross (Rs/kg) | T38: =H13*$H$8 -> 221.312
B39: Volume of holes (m3) | D39: =2*D37*3.14*(D38/2/1000)^2*D26/1000 -> 6.28e-06 | F39: Width of 1 slot (mm) | J39: =U14 -> 10 | M39: Salvage value of scrap per meter of cable (Rs) | O39: =O37*T37+O38*T38 -> 56.302534
F40: Volume of 1 slot (m3) | J40: =J38/1000*J39/1000*J27/1000 -> 5e-07
B41: Weight of holes per 2500 mm of runner (kg) | D41: =D39*D8 -> 0.049298 | F41: Volume slots per rung (m3) | J41: =D24/40*J40 -> 1.875e-06 | M41: Net cost of Zinc galvanization per meter of runner (Rs) | O41: =O35-O39 -> 717.08392
B42: Value of scrap generated per meter of runner (Rs) | D42: =D41*D6 -> 3.598754 | F42: Weight of slots per rung (kg) | J42: =J41*D8 -> 0.01471875
B43: Salvage value of scrap (% of overall value) | D43: =D11 -> 0.5 | F43: Weight of slots per 2500mm of runner (kg) | J43: =J42*J23 -> 0.25021875
B44: Salvage value of MS scrap per meter of runner (Rs) | D44: =D42*D43 -> 1.799377 | F44: Value of scrap generated per meter of runner (Rs) | J44: =J43*D6 -> 18.265969
F45: Salvage value of MS scrap per meter of runner (Rs) | J45: =J44*D43 -> 9.1329844
...

Sheet Vertical bend down 600x100x2
A1: Cable Tray Costing : Ladder Type Vertical Bend 90 deg (DOWN), Bending Radius 1050 mm
B5: Input for raw material and conversion costs | M5: Cable Tray configuration
B6: Cost of 1 kg of MS (Rs) | D6: 73 | F6: Coating thickness of Zinc (micron) | H6: 86 | M6: Runners | Q6: Rungs
B7: Transportation and handling cost of raw material to vendor shop (% of raw material cost) | D7: 0 | F7: Specific weight of Zinc (kg/m3) | H7: 7135 | M7: Number of runners | O7: 2 | Q7: No of rungs per 2500 meter of runner | U7: 10
B8: Specific weight of MS (kg/m3) | D8: 7850 | F8: Cost of Zinc (Rs/kg) | H8: 425.6 | M8: Tray width (mm) | O8: 600 | Q8: Length of rung (mm) | U8: =O8 -> 600
B9: Cost of engg and fabrication (% of material cost) | D9: 0 | F9: Wastage during galvalization | H9: 0 | M9: Tray Depth (mm) | O9: 100 | Q9: Width of rung (mm) | U9: 50
B10: Quality test and inspection charges (%) | D10: 0 | F10: Recoverable scrap - Ash per meter of tray (%) | H10: 0.12 | M10: Tray thickness (mm) | O10: 2 | Q10: Collar / Height of rung (mm) | U10: 20
B11: Salvage value of scrap for MS plates(% of overall value) | D11: 0.5 | F11: Recoverable scrap - Dross per meter of tray (%) | H11: 0.08 | M11: Tray collar (mm) | O11: 25 | Q11: Thickness of rung (mm) | U11: 2
B12: Wastage allowance during fabrication | D12: 0 | F12: Recoverable scrap salvage value - Ash (%) | H12: 0.26 | M12: Tray length (mm) | O12: 1900 | Q12: No of slots per 40 mm of length | U12: 1
B13: Transportation and handling cost of finished goods to site (Rs/kg) | D13: 0 | F13: Recoverable scrap salvage value - Dross (%) | H13: 0.52 | M13: No of holes per 2500 mm length | O13: 20 | Q13: Length of 1 slot (mm) | U13: 25
B14: Overheads for vendor (%) | D14: 0 | F14: Cost of galvanization (% of material cost) | H14: 0 | M14: Dia of 1 hole (mm) | O14: 10 | Q14: Width of 1 slot (mm) | U14: 10
B15: Profit margin for vendor (%) | D15: 2.5
B16: Cost of contract Performance Bank Guarantee | D16: 0
B17: Labour,Fabrication,Overhead,Profit Margin (INR/ kg) | D17: =6.5*1.2 -> 7.8
B20: Detailed Costing
B21: Cable tray MS material cost | M21: Galvalization
B22: Runner | F22: Rung | M22: Zinc Requirement
B23: Number of runners per meter length | D23: =O7 -> 2 | F23: No of rungs in this fitting (U7 x length / 2500, rounded) | J23: =ROUND(U7*D28/2500,0) -> 8 | M23: Runner | Q23: Rung
B24: Tray width (mm) | D24: =O8 -> 600 | F24: Length of rung (mm) | J24: =U8 -> 600 | M24: Surface area for 1 m length (m2) | O24: =2*(2*(2*D27+D25)/1000*D28/1000) -> 1.14 | Q24: Surface area for 1 rung (m2) | T24: =2*J24/1000*(J25+2*J26)/1000 -> 0.108
