Workbook

Sheet Read Me
A1: Chiller should-cost model
A3: Purpose | B3: Bottom-up should-cost of a chiller from duty to supply price. Built to test against orders and BOQs (first point: D2 TKM, ME.HVAC.HS.1.1, 1,500 TR water-cooled centrifugal, 6.6 kV with VFD). Covers five types: water-cooled centrifugal HT and LT, water-cooled screw, air-cooled screw, air-cooled scroll.
A4: How to use | B4: Add or edit a row on Calculator (yellow cells): type, TR, chilled-water in/out, condenser-water in (or ambient dry-bulb for air-cooled) and range, full-load COP, VFD, ATC, fouling. Enter observed supply and E&C per unit when known; the back-test columns then show the gap. Summary shows the cost stack for any row. Rates sit on the Calculator tab from row 30; the type table sits on Assumptions & Ref.
A5: Method | B5: 1) Duty: evaporator kW = TR x 3.517; shaft kW = duty / COP; heat rejected = duty + shaft. 2) Temperatures: evaporating temp = CHW out minus evap approach; condensing temp from CW out (or ambient) plus approach; Carnot fraction is checked against a ceiling. 3) Heat exchangers: LMTD, fouled U (clean U with fouling resistance), surface area; tubes per pass from flow and velocity; tube length from area; shell diameter from tube count at set pitch; shell thickness from design pressure; steel mass of shell, tubesheets, water boxes and supports. Air-cooled: coil face area from air flow and face velocity. 4) Priced build-up: tubes (mass x rate), fabricated steel, insulation, compressor (power-law on shaft kW), motor, VFD, switchgear, lube, refrigerant, controls, ATC, piping allowance. 5) Stack: assembly and test, logistics, duty, overheads, guarantee provision, OEM margin; E&C as % of supply.
A6: Status of numbers | B6: Every rate and type parameter is an engineering-first placeholder, not a quote or a verified market price. The compressor assembly line is the largest unknown. Calibrate in this order: compressor rate and exponent, tube and shell parameters from an OEM selection, VFD and motor rates, then margin.
A7: Conventions | B7: Blue on yellow = input or typed assumption; black = formula; green font = link from another sheet; green fill = key result. Rupees, ex-GST. Supply scope follows the BOQ header: basic + packing and forwarding + transport + transit insurance + unloading.
A8: Limits | B8: Not modelled: part-load / IPLV performance, water-side pressure drop limits (BOQ: 20 ft evap, 35 ft cond), noise treatment, magnetic-bearing or oil-free premiums, brand and service-network premium beyond the margin line, 3-year AMC (BOQ HS.1.4, quantity on request), chiller plant manager (HS.1.2), pumps, piping.
A9: Checks column | B9: Flags TR above the type's practical max, tube length over the limit, COP above the Carnot-fraction ceiling for the lift, and implausible temperatures. A flag is an input-sanity warning, not an error.

Sheet Calculator
A1: Chiller should-cost: batch calculator
A2: One row per chiller configuration. Edit yellow cells (inputs, and rates in the master block from row 30). Results in groups 8-9. Amounts in Indian rupees, ex-GST, supply scope as BOQ (basic + P&F + freight + insurance).
A3: Colour code: blue on yellow = input or typed assumption; black = formula; green fill = key result. Rows 9-12 are illustrative duties, not orders; overwrite them. Column G is CW inlet for water-cooled and ambient dry-bulb for air-cooled.
A5: 1 Configuration (inputs) | Q5: 2 Type lookups | U5: 3 Thermal duty | AD5: 4 Evaporator | AM5: 5 Condenser (water / air) | AY5: 6 Drive | BA5: 7 Priced build-up, Rs per unit | BS5: 8 Stack and result | CL5: 9 Back-test vs observed
A6: Ref / tag | B6: Chiller type | C6: Capacity per unit | D6: Units | E6: CHW in | F6: CHW out | G6: CW in (WC) / ambient DB (AC) | H6: CW range (WC only) | I6: Full-load COP | J6: VFD | K6: Auto tube cleaning | L6: Evap fouling | M6: Cond fouling | N6: Observed supply per unit | O6: Observed E&C per unit | P6: Source / note | Q6: Type row | R6: Water-cooled | S6: HT motor | T6: BPHE evap | U6: Evaporator duty | V6: Compressor shaft power | W6: Heat rejected | X6: Evaporating temp | Y6: Condensing temp | Z6: Carnot COP | AA6: COP as fraction of Carnot | AB6: LMTD evaporator | AC6: LMTD condenser (WC) | AD6: U evap, fouled | AE6: Evap surface | AF6: CHW flow | AG6: Tubes per pass | AH6: Total tubes | AI6: Tube length | AJ6: Shell ID | AK6: Shell thickness | AL6: Steel (shell, tubesheets, boxes, supports) | AM6: U cond, fouled | AN6: Cond surface | AO6: CW flow | AP6: Tubes per pass | AQ6: Total tubes | AR6: Tube length | AS6: Shell ID | AT6: Shell thickness | AU6: Steel (shell, tubesheets, boxes, supports) | AV6: Air flow (AC) | AW6: Coil face area (AC) | AX6: Condenser fans (AC) | AY6: Motor rated (separate) | AZ6: Drive / VFD basis | BA6: Evap tubes | BB6: Evap shell, tubesheets, water boxes | BC6: Evap insulation | BD6: Evap brazed plate (scroll) | BE6: Cond tubes | BF6: Cond shell, tubesheets, water boxes | BG6: Air-cooled coil, fans, frame | BH6: Compressor assembly | BI6: Compressor motor | BJ6: VFD | BK6: Switchgear / starter | BL6: Lube and oil system | BM6: Refrigerant charge | BN6: Controls panel | BO6: Auto tube cleaning | BP6: Refrigerant piping, valves, instruments | BQ6: Anti-vibration, base, misc | BR6: Material subtotal | BS6: Assembly and test | BT6: Factory performance test | BU6: P&F, freight, insurance | BV6: Customs duty | BW6: Direct cost | BX6: Overheads | BY6: Guarantee provision | BZ6: OEM margin | CA6: SHOULD-COST SUPPLY per unit | CB6: Supply per TR | CC6: E&C per unit | CD6: Supply + E&C, all units | CE6: Group: heat exchangers | CF6: Group: compressor and drive | CG6: Group: refrigerant, controls, ATC, piping | CH6: Group: assembly and test | CI6: Group: logistics and duty | CJ6: Group: overheads, guarantee, margin | CK6: Stack check | CL6: Observed supply per TR | CM6: Model minus observed, per unit | CN6: Model vs observed | CO6: E&C model vs observed | CP6: Checks
C7: TR | D7: nos | E7: deg C | F7: deg C | G7: deg C | H7: K | I7: kW/kW | J7: Yes/No | K7: Yes/No | L7: m2K/kW | M7: m2K/kW | N7: Rs | O7: Rs | Q7: # | R7: 1/0 | S7: 1/0 | T7: 1/0 | U7: kW | V7: kW | W7: kW | X7: deg C | Y7: deg C | AB7: K | AC7: K | AD7: kW/m2K | AE7: m2 | AF7: m3/h | AG7: nos | AH7: nos | AI7: m | AJ7: m | AK7: mm | AL7: kg | AM7: kW/m2K | AN7: m2 | AO7: m3/h | AP7: nos | AQ7: nos | AR7: m | AS7: m | AT7: mm | AU7: kg | AV7: m3/s | AW7: m2 | AX7: nos | AY7: kW | AZ7: kW | BA7: Rs | BB7: Rs | BC7: Rs | BD7: Rs | BE7: Rs | BF7: Rs | BG7: Rs | BH7: Rs | BI7: Rs | BJ7: Rs | BK7: Rs | BL7: Rs | BM7: Rs | BN7: Rs | BO7: Rs | BP7: Rs | BQ7: Rs | BR7: Rs | BS7: Rs | BT7: Rs | BU7: Rs | BV7: Rs | BW7: Rs | BX7: Rs | BY7: Rs | BZ7: Rs | CA7: Rs | CB7: Rs/TR | CC7: Rs | CD7: Rs | CE7: Rs | CF7: Rs | CG7: Rs | CH7: Rs | CI7: Rs | CJ7: Rs | CL7: Rs/TR | CM7: Rs | CN7: % | CO7: %
A8: D2 TKM chiller, BOQ ME.HVAC.HS.1.1 | B8: Water-cooled centrifugal, HT 6.6 kV | C8: 1500 | D8: 5 | E8: 17 | F8: 7 | G8: 30 | H8: 5 | I8: 6.5 | J8: Yes | K8: Yes | L8: 0.0176 | M8: 0.044 | N8: 39259510 | O8: 314840 | P8: D2 TKM BOQ (Package 2D, Bidkin). 5 nos; COP min 6.5; CHW 17/7; CW 30/35; 6.6 kV VFD; ATC; 2-yr guarantee. | Q8: =IF($B8="","",MATCH(B8,tt_name,0)) -> 1 | R8: =IF($B8="","",INDEX(tt_wc,Q8)) -> 1 | S8: =IF($B8="","",IF(INDEX(tt_volt,Q8)="HT",1,0)) -> 1 | T8: =IF($B8="","",IF(INDEX(tt_evtype,Q8)="BPHE",1,0)) -> 0 | U8: =IF($B8="","",C8*3.517) -> 5275.5 | V8: =IF($B8="","",U8/I8) -> 811.61538 | W8: =IF($B8="","",U8+V8) -> 6087.1154 | X8: =IF($B8="","",F8-INDEX(tt_evapApp,Q8)) -> 5.5 | Y8: =IF($B8="","",IF(R8=1,G8+H8+INDEX(tt_condApp,Q8),G8+INDEX(tt_condApp,Q8))) -> 37 | Z8: =IF($B8="","",(X8+273.15)/(Y8-X8)) -> 8.8460317 | AA8: =IF($B8="","",I8/Z8) -> 0.73479275 | AB8: =IF($B8="","",(E8-F8)/LN((E8-X8)/(F8-X8))) -> 4.9094647 | AC8: =IF($B8="","",IF(R8=1,H8/LN((Y8-G8)/(Y8-G8-H8)),0)) -> 3.991178 | AD8: =IF($B8="","",1/(1/INDEX(tt_Ue,Q8)+L8)) -> 4.5955882 | AE8: =IF($B8="","",U8/(AD8*AB8)) -> 233.82362 | AF8: =IF($B8="","",U8/(r_cpw*(E8-F8))*3.6) -> 453.69804 | AG8: =IF($B8="","",IF(T8=1,0,ROUNDUP(AF8/3600/(INDEX(tt_vel,Q8)*r_tubeAi),0))) -> 270 | AH8: =IF($B8="","",AG8*INDEX(tt_evPass,Q8)) -> 810 | AI8: =IF($B8="","",IF(AH8=0,0,ROUNDUP(AE8/(AH8*PI()*r_tubeOD/1000)*10,0)/10)) -> 4.9 | AJ8: =IF($B8="","",IF(AH8=0,0,(SQRT(4*AH8*0.866*(r_pitch*r_tubeOD/1000)^2/r_fill/PI())+r_shellClr)*r_floodFac)) -> 1.2091138 | AK8: =IF($B8="","",IF(AH8=0,0,MAX(r_tmin,ROUNDUP((r_pDesE/10)*AJ8*1000/(2*r_stress-1.2*r_pDesE/10)+r_ca,0)))) -> 10 | AL8: =IF($B8="","",IF(AH8=0,0,(PI()*AJ8*(AI8+0.3)*AK8/1000+(1+r_wbFac)*2*PI()/4*AJ8^2*r_tsheet/1000)*r_rhoSt*(1+r_supFac))) -> 3688.5936 | AM8: =IF($B8="","",IF(R8=1,1/(1/INDEX(tt_Uc,Q8)+M8),0)) -> 4.0983607 | AN8: =IF($B8="","",IF(R8=1,W8/(AM8*AC8),0)) -> 372.13478 | AO8: =IF($B8="","",IF(R8=1,W8/(r_cpw*H8)*3.6,0)) -> 1046.9955 | AP8: =IF($B8="","",IF(R8=1,ROUNDUP(AO8/3600/(INDEX(tt_vel,Q8)*r_tubeAi),0),0)) -> 623 | AQ8: =IF($B8="","",AP8*INDEX(tt_cdPass,Q8)) -> 1246 | AR8: =IF($B8="","",IF(AQ8=0,0,ROUNDUP(AN8/(AQ8*PI()*r_tubeOD/1000)*10,0)/10)) -> 5 | AS8: =IF($B8="","",IF(AQ8=0,0,SQRT(4*AQ8*0.866*(r_pitch*r_tubeOD/1000)^2/r_fill/PI())+r_shellClr)) -> 1.0868088 | AT8: =IF($B8="","",IF(AQ8=0,0,MAX(r_tmin,ROUNDUP((r_pDesC/10)*AS8*1000/(2*r_stress-1.2*r_pDesC/10)+r_ca,0)))) -> 11 | AU8: =IF($B8="","",IF(AQ8=0,0,(PI()*AS8*(AR8+0.3)*AT8/1000+(1+r_wbFac)*2*PI()/4*AS8^2*r_tsheet/1000)*r_rhoSt*(1+r_supFac))) -> 3320.93 | AV8: =IF($B8="","",IF(R8=0,W8/(r_airCp*r_airRise*r_airRho),0)) -> 0 | AW8: =IF($B8="","",AV8/r_faceV) -> 0 | AX8: =IF($B8="","",IF(R8=0,ROUNDUP(AV8/r_fanFlow,0),0)) -> 0 | AY8: =IF($B8="","",IF(INDEX(tt_motSep,Q8)=1,ROUNDUP(V8/r_motEff*r_motMargin/10,0)*10,0)) -> 930 | AZ8: =IF($B8="","",IF(AY8>0,AY8,ROUNDUP(V8/r_motEff*r_motMargin/5,0)*5)) -> 930 | BA8: =IF($B8="","",AH8*AI8*r_tubeKgM*r_cuTube) -> 2480625 | BB8: =IF($B8="","",AL8*r_steelFab) -> 608617.94 | BC8: =IF($B8="","",IF(AH8=0,0,PI()*AJ8*AI8*1.15*r_insul)) -> 51371.495 | BD8: =IF($B8="","",IF(T8=1,AE8*r_bphe,0)) -> 0 | BE8: =IF($B8="","",AQ8*AR8*r_tubeKgM*r_cuTube) -> 3893750 | BF8: =IF($B8="","",AU8*r_steelFab) -> 547953.44 | BG8: =IF($B8="","",AW8*r_coilFace+AX8*r_fanAC+AW8*r_frameKg*r_steelFab) -> 0 | BH8: =IF($B8="","",INDEX(tt_compRate,Q8)*INDEX(tt_compPref,Q8)*(V8/INDEX(tt_compPref,Q8))^INDEX(tt_compN,Q8)) -> 12139183 | BI8: =IF($B8="","",AY8*IF(S8=1,r_motHT,r_motLT)) -> 3720000 | BJ8: =IF($B8="","",IF(J8="Yes",AZ8*IF(S8=1,r_vfdHT,r_vfdLT),0)) -> 10695000 | BK8: =IF($B8="","",IF(S8=1,r_swgrHT,r_swgrLTbase+r_swgrLTkw*AZ8)) -> 2200000 | BL8: =IF($B8="","",INDEX(tt_lube,Q8)) -> 600000 | BM8: =IF($B8="","",C8*INDEX(tt_refKg,Q8)*r_refrig) -> 495000 | BN8: =IF($B8="","",INDEX(tt_ctl,Q8)) -> 900000 | BO8: =IF($B8="","",IF(AND(K8="Yes",R8=1),AQ8*r_atcTube+r_atcFixed,0)) -> 2767400 | BP8: =IF($B8="","",r_pipePct*(BA8+BB8+BC8+BD8+BE8+BF8+BG8+BH8)) -> 1183290.1 | BQ8: =IF($B8="","",r_avm) -> 180000 | BR8: =IF($B8="","",SUM(BA8:BQ8)) -> 42462191 | BS8: =IF($B8="","",BR8*r_assyPct) -> 5944706.8 | BT8: =IF($B8="","",BR8*r_testPct) -> 636932.87 | BU8: =IF($B8="","",(BR8+BS8+BT8)*r_logPct) -> 1471314.9 | BV8: =IF($B8="","",BR8*r_dutyPct) -> 0 | BW8: =IF($B8="","",BR8+BS8+BT8+BU8+BV8) -> 50515146 | BX8: =IF($B8="","",BW8*r_ohPct) -> 5051514.6 | BY8: =IF($B8="","",BW8*r_warrPct) -> 1010302.9 | BZ8: =IF($B8="","",(BW8+BX8+BY8)*r_marginPct) -> 6789235.6 | CA8: =IF($B8="","",BW8+BX8+BY8+BZ8) -> 63366199 | CB8: =IF($B8="","",CA8/C8) -> 42244.133 | CC8: =IF($B8="","",CA8*r_ecPct) -> 506929.59 | CD8: =IF($B8="","",(CA8+CC8)*D8) -> 3.1936564e+08 | CE8: =IF($B8="","",BA8+BB8+BC8+BD8+BE8+BF8+BG8) -> 7582317.9 | CF8: =IF($B8="","",BH8+BI8+BJ8+BK8+BL8) -> 29354183 | CG8: =IF($B8="","",BM8+BN8+BO8+BP8+BQ8) -> 5525690.1 | CH8: =IF($B8="","",BS8+BT8) -> 6581639.7 | CI8: =IF($B8="","",BU8+BV8) -> 1471314.9 | CJ8: =IF($B8="","",BX8+BY8+BZ8) -> 12851053 | CK8: =IF($B8="","",IF(ABS(CE8+CF8+CG8+CH8+CI8+CJ8-CA8)<1,"OK","MISMATCH")) -> OK | CL8: =IF($B8="","",IF(N8="","",N8/C8)) -> 26173.007 | CM8: =IF($B8="","",IF(N8="","",CA8-N8)) -> 24106689 | CN8: =IF($B8="","",IF(N8="","",CA8/N8-1)) -> 0.61403439 | CO8: =IF($B8="","",IF(O8="","",CC8/O8-1)) -> 0.61011813 | CP8: =IF($B8="","",IF(C8>INDEX(tt_maxTR,Q8),"TR above type max; ","")&IF(AI8>r_Lmax,"Evap tube too long; ","")&IF(AR8>r_Lmax,"Cond tube too long; ","")&IF(AA8>r_carnotCap,"COP high vs lift; ","")&IF(AND(R8=1,G8+H8+INDEX(tt_condApp,Q8)>=X8+60),"Check temps; ","")) -> COP high vs lift;
A9: Illustrative: 400 TR LT centrifugal | B9: Water-cooled centrifugal, LT 415 V | C9: 400 | D9: 2 | E9: 12 | F9: 7 | G9: 32 | H9: 5 | I9: 5.8 | J9: Yes | K9: No | L9: 0.0176 | M9: 0.044 | P9: Illustrative duty. Not an actual order. | Q9: =IF($B9="","",MATCH(B9,tt_name,0)) -> 2 | R9: =IF($B9="","",INDEX(tt_wc,Q9)) -> 1 | S9: =IF($B9="","",IF(INDEX(tt_volt,Q9)="HT",1,0)) -> 0 | T9: =IF($B9="","",IF(INDEX(tt_evtype,Q9)="BPHE",1,0)) -> 0 | U9: =IF($B9="","",C9*3.517) -> 1406.8 | V9: =IF($B9="","",U9/I9) -> 242.55172 | W9: =IF($B9="","",U9+V9) -> 1649.3517 | X9: =IF($B9="","",F9-INDEX(tt_evapApp,Q9)) -> 5.5 | Y9: =IF($B9="","",IF(R9=1,G9+H9+INDEX(tt_condApp,Q9),G9+INDEX(tt_condApp,Q9))) -> 39 | Z9: =IF($B9="","",(X9+273.15)/(Y9-X9)) -> 8.3179104 | AA9: =IF($B9="","",I9/Z9) -> 0.69729051 | AB9: =IF($B9="","",(E9-F9)/LN((E9-X9)/(F9-X9))) -> 3.4098572 | AC9: =IF($B9="","",IF(R9=1,H9/LN((Y9-G9)/(Y9-G9-H9)),0)) -> 3.991178 | AD9: =IF($B9="","",1/(1/INDEX(tt_Ue,Q9)+L9)) -> 4.5955882 | AE9: =IF($B9="","",U9/(AD9*AB9)) -> 89.774927 | AF9: =IF($B9="","",U9/(r_cpw*(E9-F9))*3.6) -> 241.97229 | AG9: =IF($B9="","",IF(T9=1,0,ROUNDUP(AF9/3600/(INDEX(tt_vel,Q9)*r_tubeAi),0))) -> 144 | AH9: =IF($B9="","",AG9*INDEX(tt_evPass,Q9)) -> 432 | AI9: =IF($B9="","",IF(AH9=0,0,ROUNDUP(AE9/(AH9*PI()*r_tubeOD/1000)*10,0)/10)) -> 3.5 | AJ9: =IF($B9="","",IF(AH9=0,0,(SQRT(4*AH9*0.866*(r_pitch*r_tubeOD/1000)^2/r_fill/PI())+r_shellClr)*r_floodFac)) -> 0.91942179 | AK9: =IF($B9="","",IF(AH9=0,0,MAX(r_tmin,ROUNDUP((r_pDesE/10)*AJ9*1000/(2*r_stress-1.2*r_pDesE/10)+r_ca,0)))) -> 10 | AL9: =IF($B9="","",IF(AH9=0,0,(PI()*AJ9*(AI9+0.3)*AK9/1000+(1+r_wbFac)*2*PI()/4*AJ9^2*r_tsheet/1000)*r_rhoSt*(1+r_supFac))) -> 2094.3863 | AM9: =IF($B9="","",IF(R9=1,1/(1/INDEX(tt_Uc,Q9)+M9),0)) -> 4.0983607 | AN9: =IF($B9="","",IF(R9=1,W9/(AM9*AC9),0)) -> 100.83284 | AO9: =IF($B9="","",IF(R9=1,W9/(r_cpw*H9)*3.6,0)) -> 283.69165 | AP9: =IF($B9="","",IF(R9=1,ROUNDUP(AO9/3600/(INDEX(tt_vel,Q9)*r_tubeAi),0),0)) -> 169 | AQ9: =IF($B9="","",AP9*INDEX(tt_cdPass,Q9)) -> 338 | AR9: =IF($B9="","",IF(AQ9=0,0,ROUNDUP(AN9/(AQ9*PI()*r_tubeOD/1000)*10,0)/10)) -> 5 | AS9: =IF($B9="","",IF(AQ9=0,0,SQRT(4*AQ9*0.866*(r_pitch*r_tubeOD/1000)^2/r_fill/PI())+r_shellClr)) -> 0.61396359 | AT9: =IF($B9="","",IF(AQ9=0,0,MAX(r_tmin,ROUNDUP((r_pDesC/10)*AS9*1000/(2*r_stress-1.2*r_pDesC/10)+r_ca,0)))) -> 10 | AU9: =IF($B9="","",IF(AQ9=0,0,(PI()*AS9*(AR9+0.3)*AT9/1000+(1+r_wbFac)*2*PI()/4*AS9^2*r_tsheet/1000)*r_rhoSt*(1+r_supFac))) -> 1394.0259 | AV9: =IF($B9="","",IF(R9=0,W9/(r_airCp*r_airRise*r_airRho),0)) -> 0 | AW9: =IF($B9="","",AV9/r_faceV) -> 0 | AX9: =IF($B9="","",IF(R9=0,ROUNDUP(AV9/r_fanFlow,0),0)) -> 0 | AY9: =IF($B9="","",IF(INDEX(tt_motSep,Q9)=1,ROUNDUP(V9/r_motEff*r_motMargin/10,0)*10,0)) -> 280 | AZ9: =IF($B9="","",IF(AY9>0,AY9,ROUNDUP(V9/r_motEff*r_motMargin/5,0)*5)) -> 280 | BA9: =IF($B9="","",AH9*AI9*r_tubeKgM*r_cuTube) -> 945000 | BB9: =IF($B9="","",AL9*r_steelFab) -> 345573.74 | BC9: =IF($B9="","",IF(AH9=0,0,PI()*AJ9*AI9*1.15*r_insul)) -> 27902.415 | BD9: =IF($B9="","",IF(T9=1,AE9*r_bphe,0)) -> 0 | BE9: =IF($B9="","",AQ9*AR9*r_tubeKgM*r_cuTube) -> 1056250 | BF9: =IF($B9="","",AU9*r_steelFab) -> 230014.27 | BG9: =IF($B9="","",AW9*r_coilFace+AX9*r_fanAC+AW9*r_frameKg*r_steelFab) -> 0 | BH9: =IF($B9="","",INDEX(tt_compRate,Q9)*INDEX(tt_compPref,Q9)*(V9/INDEX(tt_compPref,Q9))^INDEX(tt_compN,Q9)) -> 4619050.9 | BI9: =IF($B9="","",AY9*IF(S9=1,r_motHT,r_motLT)) -> 644000 | BJ9: =IF($B9="","",IF(J9="Yes",AZ9*IF(S9=1,r_vfdHT,r_vfdLT),0)) -> 1680000 | BK9: =IF($B9="","",IF(S9=1,r_swgrHT,r_swgrLTbase+r_swgrLTkw*AZ9)) -> 206000 | BL9: =IF($B9="","",INDEX(tt_lube,Q9)) -> 400000 | BM9: =IF($B9="","",C9*INDEX(tt_refKg,Q9)*r_refrig) -> 132000 | BN9: =IF($B9="","",INDEX(tt_ctl,Q9)) -> 700000 | BO9: =IF($B9="","",IF(AND(K9="Yes",R9=1),AQ9*r_atcTube+r_atcFixed,0)) -> 0 | BP9: =IF($B9="","",r_pipePct*(BA9+BB9+BC9+BD9+BE9+BF9+BG9+BH9)) -> 433427.48 | BQ9: =IF($B9="","",r_avm) -> 180000 | BR9: =IF($B9="","",SUM(BA9:BQ9)) -> 11599219 | BS9: =IF($B9="","",BR9*r_assyPct) -> 1623890.6 | BT9: =IF($B9="","",BR9*r_testPct) -> 173988.28 | BU9: =IF($B9="","",(BR9+BS9+BT9)*r_logPct) -> 401912.93 | BV9: =IF($B9="","",BR9*r_dutyPct) -> 0 | BW9: =IF($B9="","",BR9+BS9+BT9+BU9+BV9) -> 13799011 | BX9: =IF($B9="","",BW9*r_ohPct) -> 1379901.1 | BY9: =IF($B9="","",BW9*r_warrPct) -> 275980.21 | BZ9: =IF($B9="","",(BW9+BX9+BY9)*r_marginPct) -> 1854587 | CA9: =IF($B9="","",BW9+BX9+BY9+BZ9) -> 17309479 | CB9: =IF($B9="","",CA9/C9) -> 43273.697 | CC9: =IF($B9="","",CA9*r_ecPct) -> 138475.83 | CD9: =IF($B9="","",(CA9+CC9)*D9) -> 34895910 | CE9: =IF($B9="","",BA9+BB9+BC9+BD9+BE9+BF9+BG9) -> 2604740.4 | CF9: =IF($B9="","",BH9+BI9+BJ9+BK9+BL9) -> 7549050.9 | CG9: =IF($B9="","",BM9+BN9+BO9+BP9+BQ9) -> 1445427.5 | CH9: =IF($B9="","",BS9+BT9) -> 1797878.9 | CI9: =IF($B9="","",BU9+BV9) -> 401912.93 | CJ9: =IF($B9="","",BX9+BY9+BZ9) -> 3510468.3 | CK9: =IF($B9="","",IF(ABS(CE9+CF9+CG9+CH9+CI9+CJ9-CA9)<1,"OK","MISMATCH")) -> OK | CL9: =IF($B9="","",IF(N9="","",N9/C9)) | CM9: =IF($B9="","",IF(N9="","",CA9-N9)) | CN9: =IF($B9="","",IF(N9="","",CA9/N9-1)) | CO9: =IF($B9="","",IF(O9="","",CC9/O9-1)) | CP9: =IF($B9="","",IF(C9>INDEX(tt_maxTR,Q9),"TR above type max; ","")&IF(AI9>r_Lmax,"Evap tube too long; ","")&IF(AR9>r_Lmax,"Cond tube too long; ","")&IF(AA9>r_carnotCap,"COP high vs lift; ","")&IF(AND(R9=1,G9+H9+INDEX(tt_condApp,Q9)>=X9+60),"Check temps; ","")) -> COP high vs lift;
A10: Illustrative: 250 TR water-cooled screw | B10: Water-cooled screw, LT 415 V | C10: 250 | D10: 2 | E10: 12 | F10: 7 | G10: 32 | H10: 5 | I10: 5 | J10: No | K10: No | L10: 0.0176 | M10: 0.044 | P10: Illustrative duty. Not an actual order. | Q10: =IF($B10="","",MATCH(B10,tt_name,0)) -> 3 | R10: =IF($B10="","",INDEX(tt_wc,Q10)) -> 1 | S10: =IF($B10="","",IF(INDEX(tt_volt,Q10)="HT",1,0)) -> 0 | T10: =IF($B10="","",IF(INDEX(tt_evtype,Q10)="BPHE",1,0)) -> 0 | U10: =IF($B10="","",C10*3.517) -> 879.25 | V10: =IF($B10="","",U10/I10) -> 175.85 | W10: =IF($B10="","",U10+V10) -> 1055.1 | X10: =IF($B10="","",F10-INDEX(tt_evapApp,Q10)) -> 5 | Y10: =IF($B10="","",IF(R10=1,G10+H10+INDEX(tt_condApp,Q10),G10+INDEX(tt_condApp,Q10))) -> 39.5 | Z10: =IF($B10="","",(X10+273.15)/(Y10-X10)) -> 8.0623188 | AA10: =IF($B10="","",I10/Z10) -> 0.62016897 | AB10: =IF($B10="","",(E10-F10)/LN((E10-X10)/(F10-X10))) -> 3.991178 | AC10: =IF($B10="","",IF(R10=1,H10/LN((Y10-G10)/(Y10-G10-H10)),0)) -> 4.5511961 | AD10: =IF($B10="","",1/(1/INDEX(tt_Ue,Q10)+L10)) -> 3.5617876 | AE10: =IF($B10="","",U10/(AD10*AB10)) -> 61.850506 | AF10: =IF($B10="","",U10/(r_cpw*(E10-F10))*3.6) -> 151.23268 | AG10: =IF($B10="","",IF(T10=1,0,ROUNDUP(AF10/3600/(INDEX(tt_vel,Q10)*r_tubeAi),0))) -> 100 | AH10: =IF($B10="","",AG10*INDEX(tt_evPass,Q10)) -> 200 | AI10: =IF($B10="","",IF(AH10=0,0,ROUNDUP(AE10/(AH10*PI()*r_tubeOD/1000)*10,0)/10)) -> 5.2 | AJ10: =IF($B10="","",IF(AH10=0,0,(SQRT(4*AH10*0.866*(r_pitch*r_tubeOD/1000)^2/r_fill/PI())+r_shellClr)*r_floodFac)) -> 0.66873142 | AK10: =IF($B10="","",IF(AH10=0,0,MAX(r_tmin,ROUNDUP((r_pDesE/10)*AJ10*1000/(2*r_stress-1.2*r_pDesE/10)+r_ca,0)))) -> 10 | AL10: =IF($B10="","",IF(AH10=0,0,(PI()*AJ10*(AI10+0.3)*AK10/1000+(1+r_wbFac)*2*PI()/4*AJ10^2*r_tsheet/1000)*r_rhoSt*(1+r_supFac))) -> 1604.3379 | AM10: =IF($B10="","",IF(R10=1,1/(1/INDEX(tt_Uc,Q10)+M10),0)) -> 3.7562604 | AN10: =IF($B10="","",IF(R10=1,W10/(AM10*AC10),0)) -> 61.718076 | AO10: =IF($B10="","",IF(R10=1,W10/(r_cpw*H10)*3.6,0)) -> 181.47922 | AP10: =IF($B10="","",IF(R10=1,ROUNDUP(AO10/3600/(INDEX(tt_vel,Q10)*r_tubeAi),0),0)) -> 120 | AQ10: =IF($B10="","",AP10*INDEX(tt_cdPass,Q10)) -> 240 | AR10: =IF($B10="","",IF(AQ10=0,0,ROUNDUP(AN10/(AQ10*PI()*r_tubeOD/1000)*10,0)/10)) -> 4.3 | AS10: =IF($B10="","",IF(AQ10=0,0,SQRT(4*AQ10*0.866*(r_pitch*r_tubeOD/1000)^2/r_fill/PI())+r_shellClr)) -> 0.53309147 | AT10: =IF($B10="","",IF(AQ10=0,0,MAX(r_tmin,ROUNDUP((r_pDesC/10)*AS10*1000/(2*r_stress-1.2*r_pDesC/10)+r_ca,0)))) -> 10 | AU10: =IF($B10="","",IF(AQ10=0,0,(PI()*AS10*(AR10+0.3)*AT10/1000+(1+r_wbFac)*2*PI()/4*AS10^2*r_tsheet/1000)*r_rhoSt*(1+r_supFac))) -> 1050.6956 | AV10: =IF($B10="","",IF(R10=0,W10/(r_airCp*r_airRise*r_airRho),0)) -> 0 | AW10: =IF($B10="","",AV10/r_faceV) -> 0 | AX10: =IF($B10="","",IF(R10=0,ROUNDUP(AV10/r_fanFlow,0),0)) -> 0 | AY10: =IF($B10="","",IF(INDEX(tt_motSep,Q10)=1,ROUNDUP(V10/r_motEff*r_motMargin/10,0)*10,0)) -> 0 | AZ10: =IF($B10="","",IF(AY10>0,AY10,ROUNDUP(V10/r_motEff*r_motMargin/5,0)*5)) -> 205 | BA10: =IF($B10="","",AH10*AI10*r_tubeKgM*r_cuTube) -> 650000 | BB10: =IF($B10="","",AL10*r_steelFab) -> 264715.75 | BC10: =IF($B10="","",IF(AH10=0,0,PI()*AJ10*AI10*1.15*r_insul)) -> 30151.854 | BD10: =IF($B10="","",IF(T10=1,AE10*r_bphe,0)) -> 0 | BE10: =IF($B10="","",AQ10*AR10*r_tubeKgM*r_cuTube) -> 645000 | BF10: =IF($B10="","",AU10*r_steelFab) -> 173364.77 | BG10: =IF($B10="","",AW10*r_coilFace+AX10*r_fanAC+AW10*r_frameKg*r_steelFab) -> 0 | BH10: =IF($B10="","",INDEX(tt_compRate,Q10)*INDEX(tt_compPref,Q10)*(V10/INDEX(tt_compPref,Q10))^INDEX(tt_compN,Q10)) -> 2095713.4 | BI10: =IF($B10="","",AY10*IF(S10=1,r_motHT,r_motLT)) -> 0 | BJ10: =IF($B10="","",IF(J10="Yes",AZ10*IF(S10=1,r_vfdHT,r_vfdLT),0)) -> 0 | BK10: =IF($B10="","",IF(S10=1,r_swgrHT,r_swgrLTbase+r_swgrLTkw*AZ10)) -> 172250 | BL10: =IF($B10="","",INDEX(tt_lube,Q10)) -> 0 | BM10: =IF($B10="","",C10*INDEX(tt_refKg,Q10)*r_refrig) -> 67500 | BN10: =IF($B10="","",INDEX(tt_ctl,Q10)) -> 500000 | BO10: =IF($B10="","",IF(AND(K10="Yes",R10=1),AQ10*r_atcTube+r_atcFixed,0)) -> 0 | BP10: =IF($B10="","",r_pipePct*(BA10+BB10+BC10+BD10+BE10+BF10+BG10+BH10)) -> 231536.75 | BQ10: =IF($B10="","",r_avm) -> 180000 | BR10: =IF($B10="","",SUM(BA10:BQ10)) -> 5010232.5 | BS10: =IF($B10="","",BR10*r_assyPct) -> 701432.55 | BT10: =IF($B10="","",BR10*r_testPct) -> 75153.488 | BU10: =IF($B10="","",(BR10+BS10+BT10)*r_logPct) -> 173604.56 | BV10: =IF($B10="","",BR10*r_dutyPct) -> 0 | BW10: =IF($B10="","",BR10+BS10+BT10+BU10+BV10) -> 5960423.1 | BX10: =IF($B10="","",BW10*r_ohPct) -> 596042.31 | BY10: =IF($B10="","",BW10*r_warrPct) -> 119208.46 | BZ10: =IF($B10="","",(BW10+BX10+BY10)*r_marginPct) -> 801080.87 | CA10: =IF($B10="","",BW10+BX10+BY10+BZ10) -> 7476754.8 | CB10: =IF($B10="","",CA10/C10) -> 29907.019 | CC10: =IF($B10="","",CA10*r_ecPct) -> 59814.038 | CD10: =IF($B10="","",(CA10+CC10)*D10) -> 15073138 | CE10: =IF($B10="","",BA10+BB10+BC10+BD10+BE10+BF10+BG10) -> 1763232.4 | CF10: =IF($B10="","",BH10+BI10+BJ10+BK10+BL10) -> 2267963.4 | CG10: =IF($B10="","",BM10+BN10+BO10+BP10+BQ10) -> 979036.75 | CH10: =IF($B10="","",BS10+BT10) -> 776586.04 | CI10: =IF($B10="","",BU10+BV10) -> 173604.56 | CJ10: =IF($B10="","",BX10+BY10+BZ10) -> 1516331.6 | CK10: =IF($B10="","",IF(ABS(CE10+CF10+CG10+CH10+CI10+CJ10-CA10)<1,"OK","MISMATCH")) -> OK | CL10: =IF($B10="","",IF(N10="","",N10/C10)) | CM10: =IF($B10="","",IF(N10="","",CA10-N10)) | CN10: =IF($B10="","",IF(N10="","",CA10/N10-1)) | CO10: =IF($B10="","",IF(O10="","",CC10/O10-1)) | CP10: =IF($B10="","",IF(C10>INDEX(tt_maxTR,Q10),"TR above type max; ","")&IF(AI10>r_Lmax,"Evap tube too long; ","")&IF(AR10>r_Lmax,"Cond tube too long; ","")&IF(AA10>r_carnotCap,"COP high vs lift; ","")&IF(AND(R10=1,G10+H10+INDEX(tt_condApp,Q10)>=X10+60),"Check temps; ",""))
A11: Illustrative: 150 TR air-cooled screw | B11: Air-cooled screw, LT 415 V | C11: 150 | D11: 2 | E11: 12 | F11: 7 | G11: 43 | I11: 3 | J11: No | K11: No | L11: 0.0176 | P11: Illustrative duty. Not an actual order. Col G = ambient DB. | Q11: =IF($B11="","",MATCH(B11,tt_name,0)) -> 4 | R11: =IF($B11="","",INDEX(tt_wc,Q11)) -> 0 | S11: =IF($B11="","",IF(INDEX(tt_volt,Q11)="HT",1,0)) -> 0 | T11: =IF($B11="","",IF(INDEX(tt_evtype,Q11)="BPHE",1,0)) -> 0 | U11: =IF($B11="","",C11*3.517) -> 527.55 | V11: =IF($B11="","",U11/I11) -> 175.85 | W11: =IF($B11="","",U11+V11) -> 703.4 | X11: =IF($B11="","",F11-INDEX(tt_evapApp,Q11)) -> 4 | Y11: =IF($B11="","",IF(R11=1,G11+H11+INDEX(tt_condApp,Q11),G11+INDEX(tt_condApp,Q11))) -> 58 | Z11: =IF($B11="","",(X11+273.15)/(Y11-X11)) -> 5.1324074 | AA11: =IF($B11="","",I11/Z11) -> 0.58452102 | AB11: =IF($B11="","",(E11-F11)/LN((E11-X11)/(F11-X11))) -> 5.0977272 | AC11: =IF($B11="","",IF(R11=1,H11/LN((Y11-G11)/(Y11-G11-H11)),0)) -> 0 | AD11: =IF($B11="","",1/(1/INDEX(tt_Ue,Q11)+L11)) -> 3.029385 | AE11: =IF($B11="","",U11/(AD11*AB11)) -> 34.161156 | AF11: =IF($B11="","",U11/(r_cpw*(E11-F11))*3.6) -> 90.739608 | AG11: =IF($B11="","",IF(T11=1,0,ROUNDUP(AF11/3600/(INDEX(tt_vel,Q11)*r_tubeAi),0))) -> 60 | AH11: =IF($B11="","",AG11*INDEX(tt_evPass,Q11)) -> 120 | AI11: =IF($B11="","",IF(AH11=0,0,ROUNDUP(AE11/(AH11*PI()*r_tubeOD/1000)*10,0)/10)) -> 4.8 | AJ11: =IF($B11="","",IF(AH11=0,0,(SQRT(4*AH11*0.866*(r_pitch*r_tubeOD/1000)^2/r_fill/PI())+r_shellClr)*r_floodFac)) -> 0.54842658 | AK11: =IF($B11="","",IF(AH11=0,0,MAX(r_tmin,ROUNDUP((r_pDesE/10)*AJ11*1000/(2*r_stress-1.2*r_pDesE/10)+r_ca,0)))) -> 10 | AL11: =IF($B11="","",IF(AH11=0,0,(PI()*AJ11*(AI11+0.3)*AK11/1000+(1+r_wbFac)*2*PI()/4*AJ11^2*r_tsheet/1000)*r_rhoSt*(1+r_supFac))) -> 1166.7153 | AM11: =IF($B11="","",IF(R11=1,1/(1/INDEX(tt_Uc,Q11)+M11),0)) -> 0 | AN11: =IF($B11="","",IF(R11=1,W11/(AM11*AC11),0)) -> 0 | AO11: =IF($B11="","",IF(R11=1,W11/(r_cpw*H11)*3.6,0)) -> 0 | AP11: =IF($B11="","",IF(R11=1,ROUNDUP(AO11/3600/(INDEX(tt_vel,Q11)*r_tubeAi),0),0)) -> 0 | AQ11: =IF($B11="","",AP11*INDEX(tt_cdPass,Q11)) -> 0 | AR11: =IF($B11="","",IF(AQ11=0,0,ROUNDUP(AN11/(AQ11*PI()*r_tubeOD/1000)*10,0)/10)) -> 0 | AS11: =IF($B11="","",IF(AQ11=0,0,SQRT(4*AQ11*0.866*(r_pitch*r_tubeOD/1000)^2/r_fill/PI())+r_shellClr)) -> 0 | AT11: =IF($B11="","",IF(AQ11=0,0,MAX(r_tmin,ROUNDUP((r_pDesC/10)*AS11*1000/(2*r_stress-1.2*r_pDesC/10)+r_ca,0)))) -> 0 | AU11: =IF($B11="","",IF(AQ11=0,0,(PI()*AS11*(AR11+0.3)*AT11/1000+(1+r_wbFac)*2*PI()/4*AS11^2*r_tsheet/1000)*r_rhoSt*(1+r_supFac))) -> 0 | AV11: =IF($B11="","",IF(R11=0,W11/(r_airCp*r_airRise*r_airRho),0)) -> 56.753634 | AW11: =IF($B11="","",AV11/r_faceV) -> 22.701454 | AX11: =IF($B11="","",IF(R11=0,ROUNDUP(AV11/r_fanFlow,0),0)) -> 12 | AY11: =IF($B11="","",IF(INDEX(tt_motSep,Q11)=1,ROUNDUP(V11/r_motEff*r_motMargin/10,0)*10,0)) -> 0 | AZ11: =IF($B11="","",IF(AY11>0,AY11,ROUNDUP(V11/r_motEff*r_motMargin/5,0)*5)) -> 205 | BA11: =IF($B11="","",AH11*AI11*r_tubeKgM*r_cuTube) -> 360000 | BB11: =IF($B11="","",AL11*r_steelFab) -> 192508.03 | BC11: =IF($B11="","",IF(AH11=0,0,PI()*AJ11*AI11*1.15*r_insul)) -> 22825.415 | BD11: =IF($B11="","",IF(T11=1,AE11*r_bphe,0)) -> 0 | BE11: =IF($B11="","",AQ11*AR11*r_tubeKgM*r_cuTube) -> 0 | BF11: =IF($B11="","",AU11*r_steelFab) -> 0 | BG11: =IF($B11="","",AW11*r_coilFace+AX11*r_fanAC+AW11*r_frameKg*r_steelFab) -> 1985764.9 | BH11: =IF($B11="","",INDEX(tt_compRate,Q11)*INDEX(tt_compPref,Q11)*(V11/INDEX(tt_compPref,Q11))^INDEX(tt_compN,Q11)) -> 2095713.4 | BI11: =IF($B11="","",AY11*IF(S11=1,r_motHT,r_motLT)) -> 0 | BJ11: =IF($B11="","",IF(J11="Yes",AZ11*IF(S11=1,r_vfdHT,r_vfdLT),0)) -> 0 | BK11: =IF($B11="","",IF(S11=1,r_swgrHT,r_swgrLTbase+r_swgrLTkw*AZ11)) -> 172250 | BL11: =IF($B11="","",INDEX(tt_lube,Q11)) -> 0 | BM11: =IF($B11="","",C11*INDEX(tt_refKg,Q11)*r_refrig) -> 36000 | BN11: =IF($B11="","",INDEX(tt_ctl,Q11)) -> 400000 | BO11: =IF($B11="","",IF(AND(K11="Yes",R11=1),AQ11*r_atcTube+r_atcFixed,0)) -> 0 | BP11: =IF($B11="","",r_pipePct*(BA11+BB11+BC11+BD11+BE11+BF11+BG11+BH11)) -> 279408.7 | BQ11: =IF($B11="","",r_avm) -> 180000 | BR11: =IF($B11="","",SUM(BA11:BQ11)) -> 5724470.4 | BS11: =IF($B11="","",BR11*r_assyPct) -> 801425.86 | BT11: =IF($B11="","",BR11*r_testPct) -> 85867.057 | BU11: =IF($B11="","",(BR11+BS11+BT11)*r_logPct) -> 198352.9 | BV11: =IF($B11="","",BR11*r_dutyPct) -> 0 | BW11: =IF($B11="","",BR11+BS11+BT11+BU11+BV11) -> 6810116.3 | BX11: =IF($B11="","",BW11*r_ohPct) -> 681011.63 | BY11: =IF($B11="","",BW11*r_warrPct) -> 136202.33 | BZ11: =IF($B11="","",(BW11+BX11+BY11)*r_marginPct) -> 915279.63 | CA11: =IF($B11="","",BW11+BX11+BY11+BZ11) -> 8542609.8 | CB11: =IF($B11="","",CA11/C11) -> 56950.732 | CC11: =IF($B11="","",CA11*r_ecPct) -> 68340.879 | CD11: =IF($B11="","",(CA11+CC11)*D11) -> 17221901 | CE11: =IF($B11="","",BA11+BB11+BC11+BD11+BE11+BF11+BG11) -> 2561098.3 | CF11: =IF($B11="","",BH11+BI11+BJ11+BK11+BL11) -> 2267963.4 | CG11: =IF($B11="","",BM11+BN11+BO11+BP11+BQ11) -> 895408.7 | CH11: =IF($B11="","",BS11+BT11) -> 887292.92 | CI11: =IF($B11="","",BU11+BV11) -> 198352.9 | CJ11: =IF($B11="","",BX11+BY11+BZ11) -> 1732493.6 | CK11: =IF($B11="","",IF(ABS(CE11+CF11+CG11+CH11+CI11+CJ11-CA11)<1,"OK","MISMATCH")) -> OK | CL11: =IF($B11="","",IF(N11="","",N11/C11)) | CM11: =IF($B11="","",IF(N11="","",CA11-N11)) | CN11: =IF($B11="","",IF(N11="","",CA11/N11-1)) | CO11: =IF($B11="","",IF(O11="","",CC11/O11-1)) | CP11: =IF($B11="","",IF(C11>INDEX(tt_maxTR,Q11),"TR above type max; ","")&IF(AI11>r_Lmax,"Evap tube too long; ","")&IF(AR11>r_Lmax,"Cond tube too long; ","")&IF(AA11>r_carnotCap,"COP high vs lift; ","")&IF(AND(R11=1,G11+H11+INDEX(tt_condApp,Q11)>=X11+60),"Check temps; ",""))
A12: Illustrative: 60 TR air-cooled scroll | B12: Air-cooled scroll, LT 415 V (modular) | C12: 60 | D12: 2 | E12: 12 | F12: 7 | G12: 43 | I12: 2.9 | J12: No | K12: No | L12: 0.0176 | P12: Illustrative duty. Not an actual order. Col G = ambient DB. | Q12: =IF($B12="","",MATCH(B12,tt_name,0)) -> 5 | R12: =IF($B12="","",INDEX(tt_wc,Q12)) -> 0 | S12: =IF($B12="","",IF(INDEX(tt_volt,Q12)="HT",1,0)) -> 0 | T12: =IF($B12="","",IF(INDEX(tt_evtype,Q12)="BPHE",1,0)) -> 1 | U12: =IF($B12="","",C12*3.517) -> 211.02 | V12: =IF($B12="","",U12/I12) -> 72.765517 | W12: =IF($B12="","",U12+V12) -> 283.78552 | X12: =IF($B12="","",F12-INDEX(tt_evapApp,Q12)) -> 4 | Y12: =IF($B12="","",IF(R12=1,G12+H12+INDEX(tt_condApp,Q12),G12+INDEX(tt_condApp,Q12))) -> 57 | Z12: =IF($B12="","",(X12+273.15)/(Y12-X12)) -> 5.2292453 | AA12: =IF($B12="","",I12/Z12) -> 0.55457334 | AB12: =IF($B12="","",(E12-F12)/LN((E12-X12)/(F12-X12))) -> 5.0977272 | AC12: =IF($B12="","",IF(R12=1,H12/LN((Y12-G12)/(Y12-G12-H12)),0)) -> 0 | AD12: =IF($B12="","",1/(1/INDEX(tt_Ue,Q12)+L12)) -> 4.1697554 | AE12: =IF($B12="","",U12/(AD12*AB12)) -> 9.9274212 | AF12: =IF($B12="","",U12/(r_cpw*(E12-F12))*3.6) -> 36.295843 | AG12: =IF($B12="","",IF(T12=1,0,ROUNDUP(AF12/3600/(INDEX(tt_vel,Q12)*r_tubeAi),0))) -> 0 | AH12: =IF($B12="","",AG12*INDEX(tt_evPass,Q12)) -> 0 | AI12: =IF($B12="","",IF(AH12=0,0,ROUNDUP(AE12/(AH12*PI()*r_tubeOD/1000)*10,0)/10)) -> 0 | AJ12: =IF($B12="","",IF(AH12=0,0,(SQRT(4*AH12*0.866*(r_pitch*r_tubeOD/1000)^2/r_fill/PI())+r_shellClr)*r_floodFac)) -> 0 | AK12: =IF($B12="","",IF(AH12=0,0,MAX(r_tmin,ROUNDUP((r_pDesE/10)*AJ12*1000/(2*r_stress-1.2*r_pDesE/10)+r_ca,0)))) -> 0 | AL12: =IF($B12="","",IF(AH12=0,0,(PI()*AJ12*(AI12+0.3)*AK12/1000+(1+r_wbFac)*2*PI()/4*AJ12^2*r_tsheet/1000)*r_rhoSt*(1+r_supFac))) -> 0 | AM12: =IF($B12="","",IF(R12=1,1/(1/INDEX(tt_Uc,Q12)+M12),0)) -> 0 | AN12: =IF($B12="","",IF(R12=1,W12/(AM12*AC12),0)) -> 0 | AO12: =IF($B12="","",IF(R12=1,W12/(r_cpw*H12)*3.6,0)) -> 0 | AP12: =IF($B12="","",IF(R12=1,ROUNDUP(AO12/3600/(INDEX(tt_vel,Q12)*r_tubeAi),0),0)) -> 0 | AQ12: =IF($B12="","",AP12*INDEX(tt_cdPass,Q12)) -> 0 | AR12: =IF($B12="","",IF(AQ12=0,0,ROUNDUP(AN12/(AQ12*PI()*r_tubeOD/1000)*10,0)/10)) -> 0 | AS12: =IF($B12="","",IF(AQ12=0,0,SQRT(4*AQ12*0.866*(r_pitch*r_tubeOD/1000)^2/r_fill/PI())+r_shellClr)) -> 0 | AT12: =IF($B12="","",IF(AQ12=0,0,MAX(r_tmin,ROUNDUP((r_pDesC/10)*AS12*1000/(2*r_stress-1.2*r_pDesC/10)+r_ca,0)))) -> 0 | AU12: =IF($B12="","",IF(AQ12=0,0,(PI()*AS12*(AR12+0.3)*AT12/1000+(1+r_wbFac)*2*PI()/4*AS12^2*r_tsheet/1000)*r_rhoSt*(1+r_supFac))) -> 0 | AV12: =IF($B12="","",IF(R12=0,W12/(r_airCp*r_airRise*r_airRho),0)) -> 22.897156 | AW12: =IF($B12="","",AV12/r_faceV) -> 9.1588623 | AX12: =IF($B12="","",IF(R12=0,ROUNDUP(AV12/r_fanFlow,0),0)) -> 5 | AY12: =IF($B12="","",IF(INDEX(tt_motSep,Q12)=1,ROUNDUP(V12/r_motEff*r_motMargin/10,0)*10,0)) -> 0 | AZ12: =IF($B12="","",IF(AY12>0,AY12,ROUNDUP(V12/r_motEff*r_motMargin/5,0)*5)) -> 85 | BA12: =IF($B12="","",AH12*AI12*r_tubeKgM*r_cuTube) -> 0 | BB12: =IF($B12="","",AL12*r_steelFab) -> 0 | BC12: =IF($B12="","",IF(AH12=0,0,PI()*AJ12*AI12*1.15*r_insul)) -> 0 | BD12: =IF($B12="","",IF(T12=1,AE12*r_bphe,0)) -> 109201.63 | BE12: =IF($B12="","",AQ12*AR12*r_tubeKgM*r_cuTube) -> 0 | BF12: =IF($B12="","",AU12*r_steelFab) -> 0 | BG12: =IF($B12="","",AW12*r_coilFace+AX12*r_fanAC+AW12*r_frameKg*r_steelFab) -> 809877.56 | BH12: =IF($B12="","",INDEX(tt_compRate,Q12)*INDEX(tt_compPref,Q12)*(V12/INDEX(tt_compPref,Q12))^INDEX(tt_compN,Q12)) -> 694556.28 | BI12: =IF($B12="","",AY12*IF(S12=1,r_motHT,r_motLT)) -> 0 | BJ12: =IF($B12="","",IF(J12="Yes",AZ12*IF(S12=1,r_vfdHT,r_vfdLT),0)) -> 0 | BK12: =IF($B12="","",IF(S12=1,r_swgrHT,r_swgrLTbase+r_swgrLTkw*AZ12)) -> 118250 | BL12: =IF($B12="","",INDEX(tt_lube,Q12)) -> 0 | BM12: =IF($B12="","",C12*INDEX(tt_refKg,Q12)*r_refrig) -> 10800 | BN12: =IF($B12="","",INDEX(tt_ctl,Q12)) -> 250000 | BO12: =IF($B12="","",IF(AND(K12="Yes",R12=1),AQ12*r_atcTube+r_atcFixed,0)) -> 0 | BP12: =IF($B12="","",r_pipePct*(BA12+BB12+BC12+BD12+BE12+BF12+BG12+BH12)) -> 96818.129 | BQ12: =IF($B12="","",r_avm) -> 180000 | BR12: =IF($B12="","",SUM(BA12:BQ12)) -> 2269503.6 | BS12: =IF($B12="","",BR12*r_assyPct) -> 317730.5 | BT12: =IF($B12="","",BR12*r_testPct) -> 34042.554 | BU12: =IF($B12="","",(BR12+BS12+BT12)*r_logPct) -> 78638.3 | BV12: =IF($B12="","",BR12*r_dutyPct) -> 0 | BW12: =IF($B12="","",BR12+BS12+BT12+BU12+BV12) -> 2699915 | BX12: =IF($B12="","",BW12*r_ohPct) -> 269991.5 | BY12: =IF($B12="","",BW12*r_warrPct) -> 53998.299 | BZ12: =IF($B12="","",(BW12+BX12+BY12)*r_marginPct) -> 362868.57 | CA12: =IF($B12="","",BW12+BX12+BY12+BZ12) -> 3386773.3 | CB12: =IF($B12="","",CA12/C12) -> 56446.222 | CC12: =IF($B12="","",CA12*r_ecPct) -> 27094.187 | CD12: =IF($B12="","",(CA12+CC12)*D12) -> 6827735 | CE12: =IF($B12="","",BA12+BB12+BC12+BD12+BE12+BF12+BG12) -> 919079.19 | CF12: =IF($B12="","",BH12+BI12+BJ12+BK12+BL12) -> 812806.28 | CG12: =IF($B12="","",BM12+BN12+BO12+BP12+BQ12) -> 537618.13 | CH12: =IF($B12="","",BS12+BT12) -> 351773.06 | CI12: =IF($B12="","",BU12+BV12) -> 78638.3 | CJ12: =IF($B12="","",BX12+BY12+BZ12) -> 686858.37 | CK12: =IF($B12="","",IF(ABS(CE12+CF12+CG12+CH12+CI12+CJ12-CA12)<1,"OK","MISMATCH")) -> OK | CL12: =IF($B12="","",IF(N12="","",N12/C12)) | CM12: =IF($B12="","",IF(N12="","",CA12-N12)) | CN12: =IF($B12="","",IF(N12="","",CA12/N12-1)) | CO12: =IF($B12="","",IF(O12="","",CC12/O12-1)) | CP12: =IF($B12="","",IF(C12>INDEX(tt_maxTR,Q12),"TR above type max; ","")&IF(AI12>r_Lmax,"Evap tube too long; ","")&IF(AR12>r_Lmax,"Cond tube too long; ","")&IF(AA12>r_carnotCap,"COP high vs lift; ","")&IF(AND(R12=1,G12+H12+INDEX(tt_condApp,Q12)>=X12+60),"Check temps; ",""))
Q13: =IF($B13="","",MATCH(B13,tt_name,0)) | R13: =IF($B13="","",INDEX(tt_wc,Q13)) | S13: =IF($B13="","",IF(INDEX(tt_volt,Q13)="HT",1,0)) | T13: =IF($B13="","",IF(INDEX(tt_evtype,Q13)="BPHE",1,0)) | U13: =IF($B13="","",C13*3.517) | V13: =IF($B13="","",U13/I13) | W13: =IF($B13="","",U13+V13) | X13: =IF($B13="","",F13-INDEX(tt_evapApp,Q13)) | Y13: =IF($B13="","",IF(R13=1,G13+H13+INDEX(tt_condApp,Q13),G13+INDEX(tt_condApp,Q13))) | Z13: =IF($B13="","",(X13+273.15)/(Y13-X13)) | AA13: =IF($B13="","",I13/Z13) | AB13: =IF($B13="","",(E13-F13)/LN((E13-X13)/(F13-X13))) | AC13: =IF($B13="","",IF(R13=1,H13/LN((Y13-G13)/(Y13-G13-H13)),0)) | AD13: =IF($B13="","",1/(1/INDEX(tt_Ue,Q13)+L13)) | AE13: =IF($B13="","",U13/(AD13*AB13)) | AF13: =IF($B13="","",U13/(r_cpw*(E13-F13))*3.6) | AG13: =IF($B13="","",IF(T13=1,0,ROUNDUP(AF13/3600/(INDEX(tt_vel,Q13)*r_tubeAi),0))) | AH13: =IF($B13="","",AG13*INDEX(tt_evPass,Q13)) | AI13: =IF($B13="","",IF(AH13=0,0,ROUNDUP(AE13/(AH13*PI()*r_tubeOD/1000)*10,0)/10)) | AJ13: =IF($B13="","",IF(AH13=0,0,(SQRT(4*AH13*0.866*(r_pitch*r_tubeOD/1000)^2/r_fill/PI())+r_shellClr)*r_floodFac)) | AK13: =IF($B13="","",IF(AH13=0,0,MAX(r_tmin,ROUNDUP((r_pDesE/10)*AJ13*1000/(2*r_stress-1.2*r_pDesE/10)+r_ca,0)))) | AL13: =IF($B13="","",IF(AH13=0,0,(PI()*AJ13*(AI13+0.3)*AK13/1000+(1+r_wbFac)*2*PI()/4*AJ13^2*r_tsheet/1000)*r_rhoSt*(1+r_supFac))) | AM13: =IF($B13="","",IF(R13=1,1/(1/INDEX(tt_Uc,Q13)+M13),0)) | AN13: =IF($B13="","",IF(R13=1,W13/(AM13*AC13),0)) | AO13: =IF($B13="","",IF(R13=1,W13/(r_cpw*H13)*3.6,0)) | AP13: =IF($B13="","",IF(R13=1,ROUNDUP(AO13/3600/(INDEX(tt_vel,Q13)*r_tubeAi),0),0)) | AQ13: =IF($B13="","",AP13*INDEX(tt_cdPass,Q13)) | AR13: =IF($B13="","",IF(AQ13=0,0,ROUNDUP(AN13/(AQ13*PI()*r_tubeOD/1000)*10,0)/10)) | AS13: =IF($B13="","",IF(AQ13=0,0,SQRT(4*AQ13*0.866*(r_pitch*r_tubeOD/1000)^2/r_fill/PI())+r_shellClr)) | AT13: =IF($B13="","",IF(AQ13=0,0,MAX(r_tmin,ROUNDUP((r_pDesC/10)*AS13*1000/(2*r_stress-1.2*r_pDesC/10)+r_ca,0)))) | AU13: =IF($B13="","",IF(AQ13=0,0,(PI()*AS13*(AR13+0.3)*AT13/1000+(1+r_wbFac)*2*PI()/4*AS13^2*r_tsheet/1000)*r_rhoSt*(1+r_supFac))) | AV13: =IF($B13="","",IF(R13=0,W13/(r_airCp*r_airRise*r_airRho),0)) | AW13: =IF($B13="","",AV13/r_faceV) | AX13: =IF($B13="","",IF(R13=0,ROUNDUP(AV13/r_fanFlow,0),0)) | AY13: =IF($B13="","",IF(INDEX(tt_motSep,Q13)=1,ROUNDUP(V13/r_motEff*r_motMargin/10,0)*10,0)) | AZ13: =IF($B13="","",IF(AY13>0,AY13,ROUNDUP(V13/r_motEff*r_motMargin/5,0)*5)) | BA13: =IF($B13="","",AH13*AI13*r_tubeKgM*r_cuTube) | BB13: =IF($B13="","",AL13*r_steelFab) | BC13: =IF($B13="","",IF(AH13=0,0,PI()*AJ13*AI13*1.15*r_insul)) | BD13: =IF($B13="","",IF(T13=1,AE13*r_bphe,0)) | BE13: =IF($B13="","",AQ13*AR13*r_tubeKgM*r_cuTube) | BF13: =IF($B13="","",AU13*r_steelFab) | BG13: =IF($B13="","",AW13*r_coilFace+AX13*r_fanAC+AW13*r_frameKg*r_steelFab) | BH13: =IF($B13="","",INDEX(tt_compRate,Q13)*INDEX(tt_compPref,Q13)*(V13/INDEX(tt_compPref,Q13))^INDEX(tt_compN,Q13)) | BI13: =IF($B13="","",AY13*IF(S13=1,r_motHT,r_motLT)) | BJ13: =IF($B13="","",IF(J13="Yes",AZ13*IF(S13=1,r_vfdHT,r_vfdLT),0)) | BK13: =IF($B13="","",IF(S13=1,r_swgrHT,r_swgrLTbase+r_swgrLTkw*AZ13)) | BL13: =IF($B13="","",INDEX(tt_lube,Q13)) | BM13: =IF($B13="","",C13*INDEX(tt_refKg,Q13)*r_refrig) | BN13: =IF($B13="","",INDEX(tt_ctl,Q13)) | BO13: =IF($B13="","",IF(AND(K13="Yes",R13=1),AQ13*r_atcTube+r_atcFixed,0)) | BP13: =IF($B13="","",r_pipePct*(BA13+BB13+BC13+BD13+BE13+BF13+BG13+BH13)) | BQ13: =IF($B13="","",r_avm) | BR13: =IF($B13="","",SUM(BA13:BQ13)) | BS13: =IF($B13="","",BR13*r_assyPct) | BT13: =IF($B13="","",BR13*r_testPct) | BU13: =IF($B13="","",(BR13+BS13+BT13)*r_logPct) | BV13: =IF($B13="","",BR13*r_dutyPct) | BW13: =IF($B13="","",BR13+BS13+BT13+BU13+BV13) | BX13: =IF($B13="","",BW13*r_ohPct) | BY13: =IF($B13="","",BW13*r_warrPct) | BZ13: =IF($B13="","",(BW13+BX13+BY13)*r_marginPct) | CA13: =IF($B13="","",BW13+BX13+BY13+BZ13) | CB13: =IF($B13="","",CA13/C13) | CC13: =IF($B13="","",CA13*r_ecPct) | CD13: =IF($B13="","",(CA13+CC13)*D13) | CE13: =IF($B13="","",BA13+BB13+BC13+BD13+BE13+BF13+BG13) | CF13: =IF($B13="","",BH13+BI13+BJ13+BK13+BL13) | CG13: =IF($B13="","",BM13+BN13+BO13+BP13+BQ13) | CH13: =IF($B13="","",BS13+BT13) | CI13: =IF($B13="","",BU13+BV13) | CJ13: =IF($B13="","",BX13+BY13+BZ13) | CK13: =IF($B13="","",IF(ABS(CE13+CF13+CG13+CH13+CI13+CJ13-CA13)<1,"OK","MISMATCH")) | CL13: =IF($B13="","",IF(N13="","",N13/C13)) | CM13: =IF($B13="","",IF(N13="","",CA13-N13)) | CN13: =IF($B13="","",IF(N13="","",CA13/N13-1)) | CO13: =IF($B13="","",IF(O13="","",CC13/O13-1)) | CP13: =IF($B13="","",IF(C13>INDEX(tt_maxTR,Q13),"TR above type max; ","")&IF(AI13>r_Lmax,"Evap tube too long; ","")&IF(AR13>r_Lmax,"Cond tube too long; ","")&IF(AA13>r_carnotCap,"COP high vs lift; ","")&IF(AND(R13=1,G13+H13+INDEX(tt_condApp,Q13)>=X13+60),"Check temps; ",""))
Q14: =IF($B14="","",MATCH(B14,tt_name,0)) | R14: =IF($B14="","",INDEX(tt_wc,Q14)) | S14: =IF($B14="","",IF(INDEX(tt_volt,Q14)="HT",1,0)) | T14: =IF($B14="","",IF(INDEX(tt_evtype,Q14)="BPHE",1,0)) | U14: =IF($B14="","",C14*3.517) | V14: =IF($B14="","",U14/I14) | W14: =IF($B14="","",U14+V14) | X14: =IF($B14="","",F14-INDEX(tt_evapApp,Q14)) | Y14: =IF($B14="","",IF(R14=1,G14+H14+INDEX(tt_condApp,Q14),G14+INDEX(tt_condApp,Q14))) | Z14: =IF($B14="","",(X14+273.15)/(Y14-X14)) | AA14: =IF($B14="","",I14/Z14) | AB14: =IF($B14="","",(E14-F14)/LN((E14-X14)/(F14-X14))) | AC14: =IF($B14="","",IF(R14=1,H14/LN((Y14-G14)/(Y14-G14-H14)),0)) | AD14: =IF($B14="","",1/(1/INDEX(tt_Ue,Q14)+L14)) | AE14: =IF($B14="","",U14/(AD14*AB14)) | AF14: =IF($B14="","",U14/(r_cpw*(E14-F14))*3.6) | AG14: =IF($B14="","",IF(T14=1,0,ROUNDUP(AF14/3600/(INDEX(tt_vel,Q14)*r_tubeAi),0))) | AH14: =IF($B14="","",AG14*INDEX(tt_evPass,Q14)) | AI14: =IF($B14="","",IF(AH14=0,0,ROUNDUP(AE14/(AH14*PI()*r_tubeOD/1000)*10,0)/10)) | AJ14: =IF($B14="","",IF(AH14=0,0,(SQRT(4*AH14*0.866*(r_pitch*r_tubeOD/1000)^2/r_fill/PI())+r_shellClr)*r_floodFac)) | AK14: =IF($B14="","",IF(AH14=0,0,MAX(r_tmin,ROUNDUP((r_pDesE/10)*AJ14*1000/(2*r_stress-1.2*r_pDesE/10)+r_ca,0)))) | AL14: =IF($B14="","",IF(AH14=0,0,(PI()*AJ14*(AI14+0.3)*AK14/1000+(1+r_wbFac)*2*PI()/4*AJ14^2*r_tsheet/1000)*r_rhoSt*(1+r_supFac))) | AM14: =IF($B14="","",IF(R14=1,1/(1/INDEX(tt_Uc,Q14)+M14),0)) | AN14: =IF($B14="","",IF(R14=1,W14/(AM14*AC14),0)) | AO14: =IF($B14="","",IF(R14=1,W14/(r_cpw*H14)*3.6,0)) | AP14: =IF($B14="","",IF(R14=1,ROUNDUP(AO14/3600/(INDEX(tt_vel,Q14)*r_tubeAi),0),0)) | AQ14: =IF($B14="","",AP14*INDEX(tt_cdPass,Q14)) | AR14: =IF($B14="","",IF(AQ14=0,0,ROUNDUP(AN14/(AQ14*PI()*r_tubeOD/1000)*10,0)/10)) | AS14: =IF($B14="","",IF(AQ14=0,0,SQRT(4*AQ14*0.866*(r_pitch*r_tubeOD/1000)^2/r_fill/PI())+r_shellClr)) | AT14: =IF($B14="","",IF(AQ14=0,0,MAX(r_tmin,ROUNDUP((r_pDesC/10)*AS14*1000/(2*r_stress-1.2*r_pDesC/10)+r_ca,0)))) | AU14: =IF($B14="","",IF(AQ14=0,0,(PI()*AS14*(AR14+0.3)*AT14/1000+(1+r_wbFac)*2*PI()/4*AS14^2*r_tsheet/1000)*r_rhoSt*(1+r_supFac))) | AV14: =IF($B14="","",IF(R14=0,W14/(r_airCp*r_airRise*r_airRho),0)) | AW14: =IF($B14="","",AV14/r_faceV) | AX14: =IF($B14="","",IF(R14=0,ROUNDUP(AV14/r_fanFlow,0),0)) | AY14: =IF($B14="","",IF(INDEX(tt_motSep,Q14)=1,ROUNDUP(V14/r_motEff*r_motMargin/10,0)*10,0)) | AZ14: =IF($B14="","",IF(AY14>0,AY14,ROUNDUP(V14/r_motEff*r_motMargin/5,0)*5)) | BA14: =IF($B14="","",AH14*AI14*r_tubeKgM*r_cuTube) | BB14: =IF($B14="","",AL14*r_steelFab) | BC14: =IF($B14="","",IF(AH14=0,0,PI()*AJ14*AI14*1.15*r_insul)) | BD14: =IF($B14="","",IF(T14=1,AE14*r_bphe,0)) | BE14: =IF($B14="","",AQ14*AR14*r_tubeKgM*r_cuTube) | BF14: =IF($B14="","",AU14*r_steelFab) | BG14: =IF($B14="","",AW14*r_coilFace+AX14*r_fanAC+AW14*r_frameKg*r_steelFab) | BH14: =IF($B14="","",INDEX(tt_compRate,Q14)*INDEX(tt_compPref,Q14)*(V14/INDEX(tt_compPref,Q14))^INDEX(tt_compN,Q14)) | BI14: =IF($B14="","",AY14*IF(S14=1,r_motHT,r_motLT)) | BJ14: =IF($B14="","",IF(J14="Yes",AZ14*IF(S14=1,r_vfdHT,r_vfdLT),0)) | BK14: =IF($B14="","",IF(S14=1,r_swgrHT,r_swgrLTbase+r_swgrLTkw*AZ14)) | BL14: =IF($B14="","",INDEX(tt_lube,Q14)) | BM14: =IF($B14="","",C14*INDEX(tt_refKg,Q14)*r_refrig) | BN14: =IF($B14="","",INDEX(tt_ctl,Q14)) | BO14: =IF($B14="","",IF(AND(K14="Yes",R14=1),AQ14*r_atcTube+r_atcFixed,0)) | BP14: =IF($B14="","",r_pipePct*(BA14+BB14+BC14+BD14+BE14+BF14+BG14+BH14)) | BQ14: =IF($B14="","",r_avm) | BR14: =IF($B14="","",SUM(BA14:BQ14)) | BS14: =IF($B14="","",BR14*r_assyPct) | BT14: =IF($B14="","",BR14*r_testPct) | BU14: =IF($B14="","",(BR14+BS14+BT14)*r_logPct) | BV14: =IF($B14="","",BR14*r_dutyPct) | BW14: =IF($B14="","",BR14+BS14+BT14+BU14+BV14) | BX14: =IF($B14="","",BW14*r_ohPct) | BY14: =IF($B14="","",BW14*r_warrPct) | BZ14: =IF($B14="","",(BW14+BX14+BY14)*r_marginPct) | CA14: =IF($B14="","",BW14+BX14+BY14+BZ14) | CB14: =IF($B14="","",CA14/C14) | CC14: =IF($B14="","",CA14*r_ecPct) | CD14: =IF($B14="","",(CA14+CC14)*D14) | CE14: =IF($B14="","",BA14+BB14+BC14+BD14+BE14+BF14+BG14) | CF14: =IF($B14="","",BH14+BI14+BJ14+BK14+BL14) | CG14: =IF($B14="","",BM14+BN14+BO14+BP14+BQ14) | CH14: =IF($B14="","",BS14+BT14) | CI14: =IF($B14="","",BU14+BV14) | CJ14: =IF($B14="","",BX14+BY14+BZ14) | CK14: =IF($B14="","",IF(ABS(CE14+CF14+CG14+CH14+CI14+CJ14-CA14)<1,"OK","MISMATCH")) | CL14: =IF($B14="","",IF(N14="","",N14/C14)) | CM14: =IF($B14="","",IF(N14="","",CA14-N14)) | CN14: =IF($B14="","",IF(N14="","",CA14/N14-1)) | CO14: =IF($B14="","",IF(O14="","",CC14/O14-1)) | CP14: =IF($B14="","",IF(C14>INDEX(tt_maxTR,Q14),"TR above type max; ","")&IF(AI14>r_Lmax,"Evap tube too long; ","")&IF(AR14>r_Lmax,"Cond tube too long; ","")&IF(AA14>r_carnotCap,"COP high vs lift; ","")&IF(AND(R14=1,G14+H14+INDEX(tt_condApp,Q14)>=X14+60),"Check temps; ",""))
Q15: =IF($B15="","",MATCH(B15,tt_name,0)) | R15: =IF($B15="","",INDEX(tt_wc,Q15)) | S15: =IF($B15="","",IF(INDEX(tt_volt,Q15)="HT",1,0)) | T15: =IF($B15="","",IF(INDEX(tt_evtype,Q15)="BPHE",1,0)) | U15: =IF($B15="","",C15*3.517) | V15: =IF($B15="","",U15/I15) | W15: =IF($B15="","",U15+V15) | X15: =IF($B15="","",F15-INDEX(tt_evapApp,Q15)) | Y15: =IF($B15="","",IF(R15=1,G15+H15+INDEX(tt_condApp,Q15),G15+INDEX(tt_condApp,Q15))) | Z15: =IF($B15="","",(X15+273.15)/(Y15-X15)) | AA15: =IF($B15="","",I15/Z15) | AB15: =IF($B15="","",(E15-F15)/LN((E15-X15)/(F15-X15))) | AC15: =IF($B15="","",IF(R15=1,H15/LN((Y15-G15)/(Y15-G15-H15)),0)) | AD15: =IF($B15="","",1/(1/INDEX(tt_Ue,Q15)+L15)) | AE15: =IF($B15="","",U15/(AD15*AB15)) | AF15: =IF($B15="","",U15/(r_cpw*(E15-F15))*3.6) | AG15: =IF($B15="","",IF(T15=1,0,ROUNDUP(AF15/3600/(INDEX(tt_vel,Q15)*r_tubeAi),0))) | AH15: =IF($B15="","",AG15*INDEX(tt_evPass,Q15)) | AI15: =IF($B15="","",IF(AH15=0,0,ROUNDUP(AE15/(AH15*PI()*r_tubeOD/1000)*10,0)/10)) | AJ15: =IF($B15="","",IF(AH15=0,0,(SQRT(4*AH15*0.866*(r_pitch*r_tubeOD/1000)^2/r_fill/PI())+r_shellClr)*r_floodFac)) | AK15: =IF($B15="","",IF(AH15=0,0,MAX(r_tmin,ROUNDUP((r_pDesE/10)*AJ15*1000/(2*r_stress-1.2*r_pDesE/10)+r_ca,0)))) | AL15: =IF($B15="","",IF(AH15=0,0,(PI()*AJ15*(AI15+0.3)*AK15/1000+(1+r_wbFac)*2*PI()/4*AJ15^2*r_tsheet/1000)*r_rhoSt*(1+r_supFac))) | AM15: =IF($B15="","",IF(R15=1,1/(1/INDEX(tt_Uc,Q15)+M15),0)) | AN15: =IF($B15="","",IF(R15=1,W15/(AM15*AC15),0)) | AO15: =IF($B15="","",IF(R15=1,W15/(r_cpw*H15)*3.6,0)) | AP15: =IF($B15="","",IF(R15=1,ROUNDUP(AO15/3600/(INDEX(tt_vel,Q15)*r_tubeAi),0),0)) | AQ15: =IF($B15="","",AP15*INDEX(tt_cdPass,Q15)) | AR15: =IF($B15="","",IF(AQ15=0,0,ROUNDUP(AN15/(AQ15*PI()*r_tubeOD/1000)*10,0)/10)) | AS15: =IF($B15="","",IF(AQ15=0,0,SQRT(4*AQ15*0.866*(r_pitch*r_tubeOD/1000)^2/r_fill/PI())+r_shellClr)) | AT15: =IF($B15="","",IF(AQ15=0,0,MAX(r_tmin,ROUNDUP((r_pDesC/10)*AS15*1000/(2*r_stress-1.2*r_pDesC/10)+r_ca,0)))) | AU15: =IF($B15="","",IF(AQ15=0,0,(PI()*AS15*(AR15+0.3)*AT15/1000+(1+r_wbFac)*2*PI()/4*AS15^2*r_tsheet/1000)*r_rhoSt*(1+r_supFac))) | AV15: =IF($B15="","",IF(R15=0,W15/(r_airCp*r_airRise*r_airRho),0)) | AW15: =IF($B15="","",AV15/r_faceV) | AX15: =IF($B15="","",IF(R15=0,ROUNDUP(AV15/r_fanFlow,0),0)) | AY15: =IF($B15="","",IF(INDEX(tt_motSep,Q15)=1,ROUNDUP(V15/r_motEff*r_motMargin/10,0)*10,0)) | AZ15: =IF($B15="","",IF(AY15>0,AY15,ROUNDUP(V15/r_motEff*r_motMargin/5,0)*5)) | BA15: =IF($B15="","",AH15*AI15*r_tubeKgM*r_cuTube) | BB15: =IF($B15="","",AL15*r_steelFab) | BC15: =IF($B15="","",IF(AH15=0,0,PI()*AJ15*AI15*1.15*r_insul)) | BD15: =IF($B15="","",IF(T15=1,AE15*r_bphe,0)) | BE15: =IF($B15="","",AQ15*AR15*r_tubeKgM*r_cuTube) | BF15: =IF($B15="","",AU15*r_steelFab) | BG15: =IF($B15="","",AW15*r_coilFace+AX15*r_fanAC+AW15*r_frameKg*r_steelFab) | BH15: =IF($B15="","",INDEX(tt_compRate,Q15)*INDEX(tt_compPref,Q15)*(V15/INDEX(tt_compPref,Q15))^INDEX(tt_compN,Q15)) | BI15: =IF($B15="","",AY15*IF(S15=1,r_motHT,r_motLT)) | BJ15: =IF($B15="","",IF(J15="Yes",AZ15*IF(S15=1,r_vfdHT,r_vfdLT),0)) | BK15: =IF($B15="","",IF(S15=1,r_swgrHT,r_swgrLTbase+r_swgrLTkw*AZ15)) | BL15: =IF($B15="","",INDEX(tt_lube,Q15)) | BM15: =IF($B15="","",C15*INDEX(tt_refKg,Q15)*r_refrig) | BN15: =IF($B15="","",INDEX(tt_ctl,Q15)) | BO15: =IF($B15="","",IF(AND(K15="Yes",R15=1),AQ15*r_atcTube+r_atcFixed,0)) | BP15: =IF($B15="","",r_pipePct*(BA15+BB15+BC15+BD15+BE15+BF15+BG15+BH15)) | BQ15: =IF($B15="","",r_avm) | BR15: =IF($B15="","",SUM(BA15:BQ15)) | BS15: =IF($B15="","",BR15*r_assyPct) | BT15: =IF($B15="","",BR15*r_testPct) | BU15: =IF($B15="","",(BR15+BS15+BT15)*r_logPct) | BV15: =IF($B15="","",BR15*r_dutyPct) | BW15: =IF($B15="","",BR15+BS15+BT15+BU15+BV15) | BX15: =IF($B15="","",BW15*r_ohPct) | BY15: =IF($B15="","",BW15*r_warrPct) | BZ15: =IF($B15="","",(BW15+BX15+BY15)*r_marginPct) | CA15: =IF($B15="","",BW15+BX15+BY15+BZ15) | CB15: =IF($B15="","",CA15/C15) | CC15: =IF($B15="","",CA15*r_ecPct) | CD15: =IF($B15="","",(CA15+CC15)*D15) | CE15: =IF($B15="","",BA15+BB15+BC15+BD15+BE15+BF15+BG15) | CF15: =IF($B15="","",BH15+BI15+BJ15+BK15+BL15) | CG15: =IF($B15="","",BM15+BN15+BO15+BP15+BQ15) | CH15: =IF($B15="","",BS15+BT15) | CI15: =IF($B15="","",BU15+BV15) | CJ15: =IF($B15="","",BX15+BY15+BZ15) | CK15: =IF($B15="","",IF(ABS(CE15+CF15+CG15+CH15+CI15+CJ15-CA15)<1,"OK","MISMATCH")) | CL15: =IF($B15="","",IF(N15="","",N15/C15)) | CM15: =IF($B15="","",IF(N15="","",CA15-N15)) | CN15: =IF($B15="","",IF(N15="","",CA15/N15-1)) | CO15: =IF($B15="","",IF(O15="","",CC15/O15-1)) | CP15: =IF($B15="","",IF(C15>INDEX(tt_maxTR,Q15),"TR above type max; ","")&IF(AI15>r_Lmax,"Evap tube too long; ","")&IF(AR15>r_Lmax,"Cond tube too long; ","")&IF(AA15>r_carnotCap,"COP high vs lift; ","")&IF(AND(R15=1,G15+H15+INDEX(tt_condApp,Q15)>=X15+60),"Check temps; ",""))
Q16: =IF($B16="","",MATCH(B16,tt_name,0)) | R16: =IF($B16="","",INDEX(tt_wc,Q16)) | S16: =IF($B16="","",IF(INDEX(tt_volt,Q16)="HT",1,0)) | T16: =IF($B16="","",IF(INDEX(tt_evtype,Q16)="BPHE",1,0)) | U16: =IF($B16="","",C16*3.517) | V16: =IF($B16="","",U16/I16) | W16: =IF($B16="","",U16+V16) | X16: =IF($B16="","",F16-INDEX(tt_evapApp,Q16)) | Y16: =IF($B16="","",IF(R16=1,G16+H16+INDEX(tt_condApp,Q16),G16+INDEX(tt_condApp,Q16))) | Z16: =IF($B16="","",(X16+273.15)/(Y16-X16)) | AA16: =IF($B16="","",I16/Z16) | AB16: =IF($B16="","",(E16-F16)/LN((E16-X16)/(F16-X16))) | AC16: =IF($B16="","",IF(R16=1,H16/LN((Y16-G16)/(Y16-G16-H16)),0)) | AD16: =IF($B16="","",1/(1/INDEX(tt_Ue,Q16)+L16)) | AE16: =IF($B16="","",U16/(AD16*AB16)) | AF16: =IF($B16="","",U16/(r_cpw*(E16-F16))*3.6) | AG16: =IF($B16="","",IF(T16=1,0,ROUNDUP(AF16/3600/(INDEX(tt_vel,Q16)*r_tubeAi),0))) | AH16: =IF($B16="","",AG16*INDEX(tt_evPass,Q16)) | AI16: =IF($B16="","",IF(AH16=0,0,ROUNDUP(AE16/(AH16*PI()*r_tubeOD/1000)*10,0)/10)) | AJ16: =IF($B16="","",IF(AH16=0,0,(SQRT(4*AH16*0.866*(r_pitch*r_tubeOD/1000)^2/r_fill/PI())+r_shellClr)*r_floodFac)) | AK16: =IF($B16="","",IF(AH16=0,0,MAX(r_tmin,ROUNDUP((r_pDesE/10)*AJ16*1000/(2*r_stress-1.2*r_pDesE/10)+r_ca,0)))) | AL16: =IF($B16="","",IF(AH16=0,0,(PI()*AJ16*(AI16+0.3)*AK16/1000+(1+r_wbFac)*2*PI()/4*AJ16^2*r_tsheet/1000)*r_rhoSt*(1+r_supFac))) | AM16: =IF($B16="","",IF(R16=1,1/(1/INDEX(tt_Uc,Q16)+M16),0)) | AN16: =IF($B16="","",IF(R16=1,W16/(AM16*AC16),0)) | AO16: =IF($B16="","",IF(R16=1,W16/(r_cpw*H16)*3.6,0)) | AP16: =IF($B16="","",IF(R16=1,ROUNDUP(AO16/3600/(INDEX(tt_vel,Q16)*r_tubeAi),0),0)) | AQ16: =IF($B16="","",AP16*INDEX(tt_cdPass,Q16)) | AR16: =IF($B16="","",IF(AQ16=0,0,ROUNDUP(AN16/(AQ16*PI()*r_tubeOD/1000)*10,0)/10)) | AS16: =IF($B16="","",IF(AQ16=0,0,SQRT(4*AQ16*0.866*(r_pitch*r_tubeOD/1000)^2/r_fill/PI())+r_shellClr)) | AT16: =IF($B16="","",IF(AQ16=0,0,MAX(r_tmin,ROUNDUP((r_pDesC/10)*AS16*1000/(2*r_stress-1.2*r_pDesC/10)+r_ca,0)))) | AU16: =IF($B16="","",IF(AQ16=0,0,(PI()*AS16*(AR16+0.3)*AT16/1000+(1+r_wbFac)*2*PI()/4*AS16^2*r_tsheet/1000)*r_rhoSt*(1+r_supFac))) | AV16: =IF($B16="","",IF(R16=0,W16/(r_airCp*r_airRise*r_airRho),0)) | AW16: =IF($B16="","",AV16/r_faceV) | AX16: =IF($B16="","",IF(R16=0,ROUNDUP(AV16/r_fanFlow,0),0)) | AY16: =IF($B16="","",IF(INDEX(tt_motSep,Q16)=1,ROUNDUP(V16/r_motEff*r_motMargin/10,0)*10,0)) | AZ16: =IF($B16="","",IF(AY16>0,AY16,ROUNDUP(V16/r_motEff*r_motMargin/5,0)*5)) | BA16: =IF($B16="","",AH16*AI16*r_tubeKgM*r_cuTube) | BB16: =IF($B16="","",AL16*r_steelFab) | BC16: =IF($B16="","",IF(AH16=0,0,PI()*AJ16*AI16*1.15*r_insul)) | BD16: =IF($B16="","",IF(T16=1,AE16*r_bphe,0)) | BE16: =IF($B16="","",AQ16*AR16*r_tubeKgM*r_cuTube) | BF16: =IF($B16="","",AU16*r_steelFab) | BG16: =IF($B16="","",AW16*r_coilFace+AX16*r_fanAC+AW16*r_frameKg*r_steelFab) | BH16: =IF($B16="","",INDEX(tt_compRate,Q16)*INDEX(tt_compPref,Q16)*(V16/INDEX(tt_compPref,Q16))^INDEX(tt_compN,Q16)) | BI16: =IF($B16="","",AY16*IF(S16=1,r_motHT,r_motLT)) | BJ16: =IF($B16="","",IF(J16="Yes",AZ16*IF(S16=1,r_vfdHT,r_vfdLT),0)) | BK16: =IF($B16="","",IF(S16=1,r_swgrHT,r_swgrLTbase+r_swgrLTkw*AZ16)) | BL16: =IF($B16="","",INDEX(tt_lube,Q16)) | BM16: =IF($B16="","",C16*INDEX(tt_refKg,Q16)*r_refrig) | BN16: =IF($B16="","",INDEX(tt_ctl,Q16)) | BO16: =IF($B16="","",IF(AND(K16="Yes",R16=1),AQ16*r_atcTube+r_atcFixed,0)) | BP16: =IF($B16="","",r_pipePct*(BA16+BB16+BC16+BD16+BE16+BF16+BG16+BH16)) | BQ16: =IF($B16="","",r_avm) | BR16: =IF($B16="","",SUM(BA16:BQ16)) | BS16: =IF($B16="","",BR16*r_assyPct) | BT16: =IF($B16="","",BR16*r_testPct) | BU16: =IF($B16="","",(BR16+BS16+BT16)*r_logPct) | BV16: =IF($B16="","",BR16*r_dutyPct) | BW16: =IF($B16="","",BR16+BS16+BT16+BU16+BV16) | BX16: =IF($B16="","",BW16*r_ohPct) | BY16: =IF($B16="","",BW16*r_warrPct) | BZ16: =IF($B16="","",(BW16+BX16+BY16)*r_marginPct) | CA16: =IF($B16="","",BW16+BX16+BY16+BZ16) | CB16: =IF($B16="","",CA16/C16) | CC16: =IF($B16="","",CA16*r_ecPct) | CD16: =IF($B16="","",(CA16+CC16)*D16) | CE16: =IF($B16="","",BA16+BB16+BC16+BD16+BE16+BF16+BG16) | CF16: =IF($B16="","",BH16+BI16+BJ16+BK16+BL16) | CG16: =IF($B16="","",BM16+BN16+BO16+BP16+BQ16) | CH16: =IF($B16="","",BS16+BT16) | CI16: =IF($B16="","",BU16+BV16) | CJ16: =IF($B16="","",BX16+BY16+BZ16) | CK16: =IF($B16="","",IF(ABS(CE16+CF16+CG16+CH16+CI16+CJ16-CA16)<1,"OK","MISMATCH")) | CL16: =IF($B16="","",IF(N16="","",N16/C16)) | CM16: =IF($B16="","",IF(N16="","",CA16-N16)) | CN16: =IF($B16="","",IF(N16="","",CA16/N16-1)) | CO16: =IF($B16="","",IF(O16="","",CC16/O16-1)) | CP16: =IF($B16="","",IF(C16>INDEX(tt_maxTR,Q16),"TR above type max; ","")&IF(AI16>r_Lmax,"Evap tube too long; ","")&IF(AR16>r_Lmax,"Cond tube too long; ","")&IF(AA16>r_carnotCap,"COP high vs lift; ","")&IF(AND(R16=1,G16+H16+INDEX(tt_condApp,Q16)>=X16+60),"Check temps; ",""))
Q17: =IF($B17="","",MATCH(B17,tt_name,0)) | R17: =IF($B17="","",INDEX(tt_wc,Q17)) | S17: =IF($B17="","",IF(INDEX(tt_volt,Q17)="HT",1,0)) | T17: =IF($B17="","",IF(INDEX(tt_evtype,Q17)="BPHE",1,0)) | U17: =IF($B17="","",C17*3.517) | V17: =IF($B17="","",U17/I17) | W17: =IF($B17="","",U17+V17) | X17: =IF($B17="","",F17-INDEX(tt_evapApp,Q17)) | Y17: =IF($B17="","",IF(R17=1,G17+H17+INDEX(tt_condApp,Q17),G17+INDEX(tt_condApp,Q17))) | Z17: =IF($B17="","",(X17+273.15)/(Y17-X17)) | AA17: =IF($B17="","",I17/Z17) | AB17: =IF($B17="","",(E17-F17)/LN((E17-X17)/(F17-X17))) | AC17: =IF($B17="","",IF(R17=1,H17/LN((Y17-G17)/(Y17-G17-H17)),0)) | AD17: =IF($B17="","",1/(1/INDEX(tt_Ue,Q17)+L17)) | AE17: =IF($B17="","",U17/(AD17*AB17)) | AF17: =IF($B17="","",U17/(r_cpw*(E17-F17))*3.6) | AG17: =IF($B17="","",IF(T17=1,0,ROUNDUP(AF17/3600/(INDEX(tt_vel,Q17)*r_tubeAi),0))) | AH17: =IF($B17="","",AG17*INDEX(tt_evPass,Q17)) | AI17: =IF($B17="","",IF(AH17=0,0,ROUNDUP(AE17/(AH17*PI()*r_tubeOD/1000)*10,0)/10)) | AJ17: =IF($B17="","",IF(AH17=0,0,(SQRT(4*AH17*0.866*(r_pitch*r_tubeOD/1000)^2/r_fill/PI())+r_shellClr)*r_floodFac)) | AK17: =IF($B17="","",IF(AH17=0,0,MAX(r_tmin,ROUNDUP((r_pDesE/10)*AJ17*1000/(2*r_stress-1.2*r_pDesE/10)+r_ca,0)))) | AL17: =IF($B17="","",IF(AH17=0,0,(PI()*AJ17*(AI17+0.3)*AK17/1000+(1+r_wbFac)*2*PI()/4*AJ17^2*r_tsheet/1000)*r_rhoSt*(1+r_supFac))) | AM17: =IF($B17="","",IF(R17=1,1/(1/INDEX(tt_Uc,Q17)+M17),0)) | AN17: =IF($B17="","",IF(R17=1,W17/(AM17*AC17),0)) | AO17: =IF($B17="","",IF(R17=1,W17/(r_cpw*H17)*3.6,0)) | AP17: =IF($B17="","",IF(R17=1,ROUNDUP(AO17/3600/(INDEX(tt_vel,Q17)*r_tubeAi),0),0)) | AQ17: =IF($B17="","",AP17*INDEX(tt_cdPass,Q17)) | AR17: =IF($B17="","",IF(AQ17=0,0,ROUNDUP(AN17/(AQ17*PI()*r_tubeOD/1000)*10,0)/10)) | AS17: =IF($B17="","",IF(AQ17=0,0,SQRT(4*AQ17*0.866*(r_pitch*r_tubeOD/1000)^2/r_fill/PI())+r_shellClr)) | AT17: =IF($B17="","",IF(AQ17=0,0,MAX(r_tmin,ROUNDUP((r_pDesC/10)*AS17*1000/(2*r_stress-1.2*r_pDesC/10)+r_ca,0)))) | AU17: =IF($B17="","",IF(AQ17=0,0,(PI()*AS17*(AR17+0.3)*AT17/1000+(1+r_wbFac)*2*PI()/4*AS17^2*r_tsheet/1000)*r_rhoSt*(1+r_supFac))) | AV17: =IF($B17="","",IF(R17=0,W17/(r_airCp*r_airRise*r_airRho),0)) | AW17: =IF($B17="","",AV17/r_faceV) | AX17: =IF($B17="","",IF(R17=0,ROUNDUP(AV17/r_fanFlow,0),0)) | AY17: =IF($B17="","",IF(INDEX(tt_motSep,Q17)=1,ROUNDUP(V17/r_motEff*r_motMargin/10,0)*10,0)) | AZ17: =IF($B17="","",IF(AY17>0,AY17,ROUNDUP(V17/r_motEff*r_motMargin/5,0)*5)) | BA17: =IF($B17="","",AH17*AI17*r_tubeKgM*r_cuTube) | BB17: =IF($B17="","",AL17*r_steelFab) | BC17: =IF($B17="","",IF(AH17=0,0,PI()*AJ17*AI17*1.15*r_insul)) | BD17: =IF($B17="","",IF(T17=1,AE17*r_bphe,0)) | BE17: =IF($B17="","",AQ17*AR17*r_tubeKgM*r_cuTube) | BF17: =IF($B17="","",AU17*r_steelFab) | BG17: =IF($B17="","",AW17*r_coilFace+AX17*r_fanAC+AW17*r_frameKg*r_steelFab) | BH17: =IF($B17="","",INDEX(tt_compRate,Q17)*INDEX(tt_compPref,Q17)*(V17/INDEX(tt_compPref,Q17))^INDEX(tt_compN,Q17)) | BI17: =IF($B17="","",AY17*IF(S17=1,r_motHT,r_motLT)) | BJ17: =IF($B17="","",IF(J17="Yes",AZ17*IF(S17=1,r_vfdHT,r_vfdLT),0)) | BK17: =IF($B17="","",IF(S17=1,r_swgrHT,r_swgrLTbase+r_swgrLTkw*AZ17)) | BL17: =IF($B17="","",INDEX(tt_lube,Q17)) | BM17: =IF($B17="","",C17*INDEX(tt_refKg,Q17)*r_refrig) | BN17: =IF($B17="","",INDEX(tt_ctl,Q17)) | BO17: =IF($B17="","",IF(AND(K17="Yes",R17=1),AQ17*r_atcTube+r_atcFixed,0)) | BP17: =IF($B17="","",r_pipePct*(BA17+BB17+BC17+BD17+BE17+BF17+BG17+BH17)) | BQ17: =IF($B17="","",r_avm) | BR17: =IF($B17="","",SUM(BA17:BQ17)) | BS17: =IF($B17="","",BR17*r_assyPct) | BT17: =IF($B17="","",BR17*r_testPct) | BU17: =IF($B17="","",(BR17+BS17+BT17)*r_logPct) | BV17: =IF($B17="","",BR17*r_dutyPct) | BW17: =IF($B17="","",BR17+BS17+BT17+BU17+BV17) | BX17: =IF($B17="","",BW17*r_ohPct) | BY17: =IF($B17="","",BW17*r_warrPct) | BZ17: =IF($B17="","",(BW17+BX17+BY17)*r_marginPct) | CA17: =IF($B17="","",BW17+BX17+BY17+BZ17) | CB17: =IF($B17="","",CA17/C17) | CC17: =IF($B17="","",CA17*r_ecPct) | CD17: =IF($B17="","",(CA17+CC17)*D17) | CE17: =IF($B17="","",BA17+BB17+BC17+BD17+BE17+BF17+BG17) | CF17: =IF($B17="","",BH17+BI17+BJ17+BK17+BL17) | CG17: =IF($B17="","",BM17+BN17+BO17+BP17+BQ17) | CH17: =IF($B17="","",BS17+BT17) | CI17: =IF($B17="","",BU17+BV17) | CJ17: =IF($B17="","",BX17+BY17+BZ17) | CK17: =IF($B17="","",IF(ABS(CE17+CF17+CG17+CH17+CI17+CJ17-CA17)<1,"OK","MISMATCH")) | CL17: =IF($B17="","",IF(N17="","",N17/C17)) | CM17: =IF($B17="","",IF(N17="","",CA17-N17)) | CN17: =IF($B17="","",IF(N17="","",CA17/N17-1)) | CO17: =IF($B17="","",IF(O17="","",CC17/O17-1)) | CP17: =IF($B17="","",IF(C17>INDEX(tt_maxTR,Q17),"TR above type max; ","")&IF(AI17>r_Lmax,"Evap tube too long; ","")&IF(AR17>r_Lmax,"Cond tube too long; ","")&IF(AA17>r_carnotCap,"COP high vs lift; ","")&IF(AND(R17=1,G17+H17+INDEX(tt_condApp,Q17)>=X17+60),"Check temps; ",""))
