Workbook

Sheet LT Batch Calculator
B1: LT POWER CABLE — BATCH SHOULD-COST CALCULATOR
B3: Refresh prices: | C3: https://liveindex.org/mcx-copper/ | D3: https://economictimes.indiatimes.com/commoditysummary/symbol-ALUMINIUM.cms | E3: https://www.plastemart.com/polymer-pricelist/hdpe-reliance-deem-export/2/41 | F3: https://plastemart.com/polymer-pricelist/pvc-reliance/7/9 | G3: https://steel.gov.in/monthly-summery
B4: MATERIAL MASTER | C4: Copper | D4: Aluminium | E4: XLPE | F4: PVC | G4: Steel Wire
B5: Density (g/cm³) | C5: 8.94 | D5: 2.63 | E5: 0.93 | F5: 1.35 | G5: 7.76 | I5: Edit density and price directly in these yellow cells; every row on this sheet updates instantly.
B6: Price (Rs/kg) | C6: 1430 | D6: 349 | E6: 135 | F6: 100 | G6: 68
K7: SPECIAL CONSTRUCTION (Y / N)
B8: Configuration label | C8: No. of cores | D8: Shape | E8: Size (sqmm) | F8: Conductor | G8: Insulation | H8: Inner sheath | I8: Armour | J8: Outer sheath | K8: FRLS inner | L8: FRLS outer | M8: LSZH inner | N8: LSZH outer | O8: Oxygen Index | P8: HRPVC inner | Q8: HRPVC outer | R8: Extr PVC inner ≤50 | S8: Extr PVC inner 70 | T8: Stranding of cond. | U8: SELLING LOW Rs/m | V8: SELLING HIGH Rs/m | W8: Material cost Rs/m | X8: Approx OD mm | Y8: Conductor weight g/m | AA8: cond angle | AB8: cond dia | AC8: cond dens | AD8: ins thk | AE8: dia/ins | AF8: ins dens | AG8: neut area | AH8: neut dia | AI8: neut ins thk | AJ8: neut core dia | AK8: laid-up dia | AL8: inner thk | AM8: dia/inner | AN8: inner dens | AO8: armour thk | AP8: dia/armour | AQ8: armour dens | AR8: outer thk | AS8: dia/outer | AT8: outer dens | AU8: approx OD | AV8: wt cond | AW8: wt ins | AX8: wt inner | AY8: wt outer | AZ8: wt armour | BA8: mat cost | BB8: special % | BC8: load S1 | BD8: load S2 | BE8: total S1 | BF8: total S2 | BG8: selling S1 | BH8: selling S2
B9: 4C x 25 Cu XLPE | C9: 4 | D9: Circular | E9: 6 | F9: Copper | G9: XLPE | H9: PVC | I9: Galvanised steel round wire | J9: XLPE | K9: N | L9: N | M9: N | N9: N | O9: N | P9: N | Q9: N | R9: N | S9: N | T9: N | U9: =IF($C9="","",MIN(BG9,BH9))/1000 -> 410.73303 | V9: =IF($C9="","",MAX(BG9,BH9))/1000 -> 434.8938 | W9: =IF($C9="","",BA9)/1000 -> 355.44205 | X9: =IF($C9="","",AU9) -> 17 | Y9: =IF($C9="","",AV9) -> 216.7056 | AA9: =IF($C9="","",IF(D9="Sector shaped",360/C9,360)) -> 360 | AB9: =IF($C9="","",SQRT(E9*(360/AA9)/PI())*2) -> 2.7639532 | AC9: =IF($C9="","",INDEX($C$5:$G$5,MATCH(F9,$C$4:$G$4,0))) -> 8.94 | AD9: =IF($C9="","",IF(AND(C9=1,I9="Unarmored"),INDEX('Assumptions & Ref'!$C$70:$C$90,MATCH(E9,'Assumptions & Ref'!$B$70:$B$90,0)),INDEX('Assumptions & Ref'!$D$70:$D$90,MATCH(E9,'Assumptions & Ref'!$B$70:$B$90,0)))) -> 0.7 | AE9: =IF($C9="","",IF(D9="Circular",AB9+2*AD9,AB9+4*AD9)) -> 4.1639532 | AF9: =IF($C9="","",INDEX($C$5:$G$5,MATCH(G9,$C$4:$G$4,0))) -> 0.93 | AG9: =IF($C9="","",IF(C9=3.5,IFERROR(INDEX('Assumptions & Ref'!$G$93:$G$105,MATCH(E9,'Assumptions & Ref'!$F$93:$F$105,0)),0),0)) -> 0 | AH9: =IF($C9="","",IF(C9=3.5,SQRT(AG9/PI())*2,0)) -> 0 | AI9: =IF($C9="","",IF(C9=3.5,IFERROR(INDEX('Assumptions & Ref'!$D$70:$D$90,MATCH(AG9,'Assumptions & Ref'!$B$70:$B$90,0)),0),0)) -> 0 | AJ9: =IF($C9="","",AH9+2*AI9) -> 0 | AK9: =IF($C9="","",ROUND(IF(C9=1,AE9,IF(C9=2,2*AE9,IF(C9=3,2.16*AE9,IF(C9=3.5,2.42*(3*AE9+AJ9)/4,IF(C9=4,2.42*AE9,0))))),1)) -> 10.1 | AL9: =IF($C9="","",IFERROR(INDEX('Assumptions & Ref'!$G$70:$G$74,IF(INDEX('Assumptions & Ref'!$F$70:$F$74,MATCH(AK9,'Assumptions & Ref'!$F$70:$F$74,1))=AK9,MATCH(AK9,'Assumptions & Ref'!$F$70:$F$74,1),MIN(MATCH(AK9,'Assumptions & Ref'!$F$70:$F$74,1)+1,5))),INDEX('Assumptions & Ref'!$G$70:$G$74,1))) -> 0.4 | AM9: =IF($C9="","",AK9+2*AL9) -> 10.9 | AN9: =IF($C9="","",INDEX($C$5:$G$5,MATCH(H9,$C$4:$G$4,0))) -> 1.35 | AO9: =IF($C9="","",IF(I9="Unarmored",0,IF(OR(I9="Galvanised steel flat strip",I9="Aluminium Flat Strip"),IFERROR(INDEX('Assumptions & Ref'!$C$93:$C$98,IF(INDEX('Assumptions & Ref'!$B$93:$B$98,MATCH(AM9,'Assumptions & Ref'!$B$93:$B$98,1))=AM9,MATCH(AM9,'Assumptions & Ref'!$B$93:$B$98,1),MIN(MATCH(AM9,'Assumptions & Ref'!$B$93:$B$98,1)+1,6))),INDEX('Assumptions & Ref'!$C$93:$C$98,1)),IFERROR(INDEX('Assumptions & Ref'!$D$93:$D$98,IF(INDEX('Assumptions & Ref'!$B$93:$B$98,MATCH(AM9,'Assumptions & Ref'!$B$93:$B$98,1))=AM9,MATCH(AM9,'Assumptions & Ref'!$B$93:$B$98,1),MIN(MATCH(AM9,'Assumptions & Ref'!$B$93:$B$98,1)+1,6))),INDEX('Assumptions & Ref'!$D$93:$D$98,1))))) -> 1.6 | AP9: =IF($C9="","",AM9+2*AO9) -> 14.1 | AQ9: =IF($C9="","",IF(I9="Unarmored",0,IF(OR(I9="Aluminium Flat Strip",I9="Aluminium Round Wired"),INDEX($C$5:$G$5,MATCH("Aluminium",$C$4:$G$4,0)),INDEX($C$5:$G$5,MATCH("Steel Wire",$C$4:$G$4,0))))) -> 7.76 | AR9: =IF($C9="","",IF(I9="Unarmored",IFERROR(INDEX('Assumptions & Ref'!$J$70:$J$81,IF(INDEX('Assumptions & Ref'!$I$70:$I$81,MATCH(AP9,'Assumptions & Ref'!$I$70:$I$81,1))=AP9,MATCH(AP9,'Assumptions & Ref'!$I$70:$I$81,1),MIN(MATCH(AP9,'Assumptions & Ref'!$I$70:$I$81,1)+1,12))),INDEX('Assumptions & Ref'!$J$70:$J$81,1)),IFERROR(INDEX('Assumptions & Ref'!$K$70:$K$81,IF(INDEX('Assumptions & Ref'!$I$70:$I$81,MATCH(AP9,'Assumptions & Ref'!$I$70:$I$81,1))=AP9,MATCH(AP9,'Assumptions & Ref'!$I$70:$I$81,1),MIN(MATCH(AP9,'Assumptions & Ref'!$I$70:$I$81,1)+1,12))),INDEX('Assumptions & Ref'!$K$70:$K$81,1)))) -> 1.4 | AS9: =IF($C9="","",AP9+2*AR9) -> 16.9 | AT9: =IF($C9="","",INDEX($C$5:$G$5,MATCH(J9,$C$4:$G$4,0))) -> 0.93 | AU9: =IF($C9="","",TRUNC(AS9+1)) -> 17 | AV9: =IF($C9="","",((E9*AC9*IF(C9=3.5,3,C9))+(AG9*AC9*IF(C9=3.5,1,0)))*(1+'Assumptions & Ref'!$C$22)) -> 216.7056 | AW9: =IF($C9="","",IF(C9=3.5,(PI()*(AE9^2-AB9^2)/4*AF9*3)+(PI()*(AJ9^2-AH9^2)/4*AF9),PI()*(AE9^2-AB9^2)/4*AF9*C9)*(1+'Assumptions & Ref'!$C$22)) -> 28.620963 | AX9: =IF($C9="","",PI()*(AM9^2-AK9^2)/4*AN9*(1+'Assumptions & Ref'!$C$22)) -> 17.990959 | AY9: =IF($C9="","",PI()*(AS9^2-AP9^2)/4*AT9*(1+'Assumptions & Ref'!$C$22)) -> 64.034486 | AZ9: =IF($C9="","",PI()*(AP9^2-AM9^2)/4*AQ9*(1+'Assumptions & Ref'!$C$22)) -> 492.45093 | BA9: =IF($C9="","",AV9*INDEX($C$6:$G$6,MATCH(F9,$C$4:$G$4,0))+IF(G9="XLPE",AW9*INDEX($C$6:$G$6,MATCH("XLPE",$C$4:$G$4,0)),0)+IF(G9="PVC",(AW9+AX9+AY9)*INDEX($C$6:$G$6,MATCH("PVC",$C$4:$G$4,0)),(AX9+AY9)*INDEX($C$6:$G$6,MATCH("PVC",$C$4:$G$4,0)))+IF(I9="Unarmored",0,IF(OR(I9="Aluminium Flat Strip",I9="Aluminium Round Wired"),AZ9*INDEX($C$6:$G$6,MATCH("Aluminium",$C$4:$G$4,0)),AZ9*INDEX($C$6:$G$6,MATCH("Steel Wire",$C$4:$G$4,0))))) -> 355442.05 | BB9: =IF($C9="","",IF(K9="Y",'Assumptions & Ref'!$C$40,0)+IF(L9="Y",'Assumptions & Ref'!$C$41,0)+IF(M9="Y",'Assumptions & Ref'!$C$42,0)+IF(N9="Y",'Assumptions & Ref'!$C$43,0)+IF(O9="Y",'Assumptions & Ref'!$C$44,0)+IF(P9="Y",'Assumptions & Ref'!$C$45,0)+IF(Q9="Y",'Assumptions & Ref'!$C$46,0)+IF(R9="Y",'Assumptions & Ref'!$C$47,0)+IF(S9="Y",'Assumptions & Ref'!$C$48,0)+IF(T9="Y",'Assumptions & Ref'!$C$49,0)) -> 0 | BC9: =IF($C9="","",(IF($F9="Aluminium",'Assumptions & Ref'!$D$17,'Assumptions & Ref'!$C$17)+IF($F9="Aluminium",'Assumptions & Ref'!$D$18,'Assumptions & Ref'!$C$18)+IF($F9="Aluminium",'Assumptions & Ref'!$D$19,'Assumptions & Ref'!$C$19)+IF($F9="Aluminium",'Assumptions & Ref'!$D$20,'Assumptions & Ref'!$C$20))/IF($F9="Aluminium",'Assumptions & Ref'!$D$16,'Assumptions & Ref'!$C$16)) -> 0.17647059 | BD9: =IF($C9="","",(IF($F9="Aluminium",'Assumptions & Ref'!$F$17,'Assumptions & Ref'!$E$17)+IF($F9="Aluminium",'Assumptions & Ref'!$F$18,'Assumptions & Ref'!$E$18)+IF($F9="Aluminium",'Assumptions & Ref'!$F$19,'Assumptions & Ref'!$E$19)+IF($F9="Aluminium",'Assumptions & Ref'!$F$20,'Assumptions & Ref'!$E$20))/IF($F9="Aluminium",'Assumptions & Ref'!$F$16,'Assumptions & Ref'!$E$16)) -> 0.11111111 | BE9: =IF($C9="","",BA9*(1+BC9)) -> 418167.11 | BF9: =IF($C9="","",BA9*(1+BD9)) -> 394935.61 | BG9: =IF($C9="","",BE9*(1+BB9)*(1+IF($F9="Aluminium",'Assumptions & Ref'!$D$21,'Assumptions & Ref'!$C$21))) -> 434893.8 | BH9: =IF($C9="","",BF9*(1+BB9)*(1+IF($F9="Aluminium",'Assumptions & Ref'!$F$21,'Assumptions & Ref'!$E$21))) -> 410733.03
B10: 3.5C x 300 sq.mm CU, XLPE | C10: 3.5 | D10: Circular | E10: 300 | F10: Copper | G10: XLPE | H10: PVC | I10: Unarmored | J10: XLPE | K10: N | L10: N | M10: N | N10: N | O10: N | P10: N | Q10: N | R10: N | S10: N | T10: N | U10: =IF($C10="","",MIN(BG10,BH10))/1000 -> 15809.642 | V10: =IF($C10="","",MAX(BG10,BH10))/1000 -> 16739.621 | W10: =IF($C10="","",BA10)/1000 -> 13681.421 | X10: =IF($C10="","",AU10) -> 60 | Y10: =IF($C10="","",AV10) -> 9480.87 | AA10: =IF($C10="","",IF(D10="Sector shaped",360/C10,360)) -> 360 | AB10: =IF($C10="","",SQRT(E10*(360/AA10)/PI())*2) -> 19.5441 | AC10: =IF($C10="","",INDEX($C$5:$G$5,MATCH(F10,$C$4:$G$4,0))) -> 8.94 | AD10: =IF($C10="","",IF(AND(C10=1,I10="Unarmored"),INDEX('Assumptions & Ref'!$C$70:$C$90,MATCH(E10,'Assumptions & Ref'!$B$70:$B$90,0)),INDEX('Assumptions & Ref'!$D$70:$D$90,MATCH(E10,'Assumptions & Ref'!$B$70:$B$90,0)))) -> 1.8 | AE10: =IF($C10="","",IF(D10="Circular",AB10+2*AD10,AB10+4*AD10)) -> 23.1441 | AF10: =IF($C10="","",INDEX($C$5:$G$5,MATCH(G10,$C$4:$G$4,0))) -> 0.93 | AG10: =IF($C10="","",IF(C10=3.5,IFERROR(INDEX('Assumptions & Ref'!$G$93:$G$105,MATCH(E10,'Assumptions & Ref'!$F$93:$F$105,0)),0),0)) -> 150 | AH10: =IF($C10="","",IF(C10=3.5,SQRT(AG10/PI())*2,0)) -> 13.819766 | AI10: =IF($C10="","",IF(C10=3.5,IFERROR(INDEX('Assumptions & Ref'!$D$70:$D$90,MATCH(AG10,'Assumptions & Ref'!$B$70:$B$90,0)),0),0)) -> 1.4 | AJ10: =IF($C10="","",AH10+2*AI10) -> 16.619766 | AK10: =IF($C10="","",ROUND(IF(C10=1,AE10,IF(C10=2,2*AE10,IF(C10=3,2.16*AE10,IF(C10=3.5,2.42*(3*AE10+AJ10)/4,IF(C10=4,2.42*AE10,0))))),1)) -> 52.1 | AL10: =IF($C10="","",IFERROR(INDEX('Assumptions & Ref'!$G$70:$G$74,IF(INDEX('Assumptions & Ref'!$F$70:$F$74,MATCH(AK10,'Assumptions & Ref'!$F$70:$F$74,1))=AK10,MATCH(AK10,'Assumptions & Ref'!$F$70:$F$74,1),MIN(MATCH(AK10,'Assumptions & Ref'!$F$70:$F$74,1)+1,5))),INDEX('Assumptions & Ref'!$G$70:$G$74,1))) -> 0.7 | AM10: =IF($C10="","",AK10+2*AL10) -> 53.5 | AN10: =IF($C10="","",INDEX($C$5:$G$5,MATCH(H10,$C$4:$G$4,0))) -> 1.35 | AO10: =IF($C10="","",IF(I10="Unarmored",0,IF(OR(I10="Galvanised steel flat strip",I10="Aluminium Flat Strip"),IFERROR(INDEX('Assumptions & Ref'!$C$93:$C$98,IF(INDEX('Assumptions & Ref'!$B$93:$B$98,MATCH(AM10,'Assumptions & Ref'!$B$93:$B$98,1))=AM10,MATCH(AM10,'Assumptions & Ref'!$B$93:$B$98,1),MIN(MATCH(AM10,'Assumptions & Ref'!$B$93:$B$98,1)+1,6))),INDEX('Assumptions & Ref'!$C$93:$C$98,1)),IFERROR(INDEX('Assumptions & Ref'!$D$93:$D$98,IF(INDEX('Assumptions & Ref'!$B$93:$B$98,MATCH(AM10,'Assumptions & Ref'!$B$93:$B$98,1))=AM10,MATCH(AM10,'Assumptions & Ref'!$B$93:$B$98,1),MIN(MATCH(AM10,'Assumptions & Ref'!$B$93:$B$98,1)+1,6))),INDEX('Assumptions & Ref'!$D$93:$D$98,1))))) -> 0 | AP10: =IF($C10="","",AM10+2*AO10) -> 53.5 | AQ10: =IF($C10="","",IF(I10="Unarmored",0,IF(OR(I10="Aluminium Flat Strip",I10="Aluminium Round Wired"),INDEX($C$5:$G$5,MATCH("Aluminium",$C$4:$G$4,0)),INDEX($C$5:$G$5,MATCH("Steel Wire",$C$4:$G$4,0))))) -> 0 | AR10: =IF($C10="","",IF(I10="Unarmored",IFERROR(INDEX('Assumptions & Ref'!$J$70:$J$81,IF(INDEX('Assumptions & Ref'!$I$70:$I$81,MATCH(AP10,'Assumptions & Ref'!$I$70:$I$81,1))=AP10,MATCH(AP10,'Assumptions & Ref'!$I$70:$I$81,1),MIN(MATCH(AP10,'Assumptions & Ref'!$I$70:$I$81,1)+1,12))),INDEX('Assumptions & Ref'!$J$70:$J$81,1)),IFERROR(INDEX('Assumptions & Ref'!$K$70:$K$81,IF(INDEX('Assumptions & Ref'!$I$70:$I$81,MATCH(AP10,'Assumptions & Ref'!$I$70:$I$81,1))=AP10,MATCH(AP10,'Assumptions & Ref'!$I$70:$I$81,1),MIN(MATCH(AP10,'Assumptions & Ref'!$I$70:$I$81,1)+1,12))),INDEX('Assumptions & Ref'!$K$70:$K$81,1)))) -> 3.2 | AS10: =IF($C10="","",AP10+2*AR10) -> 59.9 | AT10: =IF($C10="","",INDEX($C$5:$G$5,MATCH(J10,$C$4:$G$4,0))) -> 0.93 | AU10: =IF($C10="","",TRUNC(AS10+1)) -> 60 | AV10: =IF($C10="","",((E10*AC10*IF(C10=3.5,3,C10))+(AG10*AC10*IF(C10=3.5,1,0)))*(1+'Assumptions & Ref'!$C$22)) -> 9480.87 | AW10: =IF($C10="","",IF(C10=3.5,(PI()*(AE10^2-AB10^2)/4*AF10*3)+(PI()*(AJ10^2-AH10^2)/4*AF10),PI()*(AE10^2-AB10^2)/4*AF10*C10)*(1+'Assumptions & Ref'!$C$22)) -> 402.99179 | AX10: =IF($C10="","",PI()*(AM10^2-AK10^2)/4*AN10*(1+'Assumptions & Ref'!$C$22)) -> 158.32044 | AY10: =IF($C10="","",PI()*(AS10^2-AP10^2)/4*AT10*(1+'Assumptions & Ref'!$C$22)) -> 535.41093 | AZ10: =IF($C10="","",PI()*(AP10^2-AM10^2)/4*AQ10*(1+'Assumptions & Ref'!$C$22)) -> 0 | BA10: =IF($C10="","",AV10*INDEX($C$6:$G$6,MATCH(F10,$C$4:$G$4,0))+IF(G10="XLPE",AW10*INDEX($C$6:$G$6,MATCH("XLPE",$C$4:$G$4,0)),0)+IF(G10="PVC",(AW10+AX10+AY10)*INDEX($C$6:$G$6,MATCH("PVC",$C$4:$G$4,0)),(AX10+AY10)*INDEX($C$6:$G$6,MATCH("PVC",$C$4:$G$4,0)))+IF(I10="Unarmored",0,IF(OR(I10="Aluminium Flat Strip",I10="Aluminium Round Wired"),AZ10*INDEX($C$6:$G$6,MATCH("Aluminium",$C$4:$G$4,0)),AZ10*INDEX($C$6:$G$6,MATCH("Steel Wire",$C$4:$G$4,0))))) -> 13681421 | BB10: =IF($C10="","",IF(K10="Y",'Assumptions & Ref'!$C$40,0)+IF(L10="Y",'Assumptions & Ref'!$C$41,0)+IF(M10="Y",'Assumptions & Ref'!$C$42,0)+IF(N10="Y",'Assumptions & Ref'!$C$43,0)+IF(O10="Y",'Assumptions & Ref'!$C$44,0)+IF(P10="Y",'Assumptions & Ref'!$C$45,0)+IF(Q10="Y",'Assumptions & Ref'!$C$46,0)+IF(R10="Y",'Assumptions & Ref'!$C$47,0)+IF(S10="Y",'Assumptions & Ref'!$C$48,0)+IF(T10="Y",'Assumptions & Ref'!$C$49,0)) -> 0 | BC10: =IF($C10="","",(IF($F10="Aluminium",'Assumptions & Ref'!$D$17,'Assumptions & Ref'!$C$17)+IF($F10="Aluminium",'Assumptions & Ref'!$D$18,'Assumptions & Ref'!$C$18)+IF($F10="Aluminium",'Assumptions & Ref'!$D$19,'Assumptions & Ref'!$C$19)+IF($F10="Aluminium",'Assumptions & Ref'!$D$20,'Assumptions & Ref'!$C$20))/IF($F10="Aluminium",'Assumptions & Ref'!$D$16,'Assumptions & Ref'!$C$16)) -> 0.17647059 | BD10: =IF($C10="","",(IF($F10="Aluminium",'Assumptions & Ref'!$F$17,'Assumptions & Ref'!$E$17)+IF($F10="Aluminium",'Assumptions & Ref'!$F$18,'Assumptions & Ref'!$E$18)+IF($F10="Aluminium",'Assumptions & Ref'!$F$19,'Assumptions & Ref'!$E$19)+IF($F10="Aluminium",'Assumptions & Ref'!$F$20,'Assumptions & Ref'!$E$20))/IF($F10="Aluminium",'Assumptions & Ref'!$F$16,'Assumptions & Ref'!$E$16)) -> 0.11111111 | BE10: =IF($C10="","",BA10*(1+BC10)) -> 16095790 | BF10: =IF($C10="","",BA10*(1+BD10)) -> 15201579 | BG10: =IF($C10="","",BE10*(1+BB10)*(1+IF($F10="Aluminium",'Assumptions & Ref'!$D$21,'Assumptions & Ref'!$C$21))) -> 16739621 | BH10: =IF($C10="","",BF10*(1+BB10)*(1+IF($F10="Aluminium",'Assumptions & Ref'!$F$21,'Assumptions & Ref'!$E$21))) -> 15809642
B11: 3.5C x 240 sq.mm CU, XLPE | C11: 3.5 | D11: Circular | E11: 240 | F11: Copper | G11: XLPE | H11: PVC | I11: Unarmored | J11: XLPE | K11: N | L11: N | M11: N | N11: N | O11: N | P11: N | Q11: N | R11: N | S11: N | T11: N | U11: =IF($C11="","",MIN(BG11,BH11))/1000 -> 12654.646 | V11: =IF($C11="","",MAX(BG11,BH11))/1000 -> 13399.037 | W11: =IF($C11="","",BA11)/1000 -> 10951.136 | X11: =IF($C11="","",AU11) -> 55 | Y11: =IF($C11="","",AV11) -> 7584.696 | AA11: =IF($C11="","",IF(D11="Sector shaped",360/C11,360)) -> 360 | AB11: =IF($C11="","",SQRT(E11*(360/AA11)/PI())*2) -> 17.480775 | AC11: =IF($C11="","",INDEX($C$5:$G$5,MATCH(F11,$C$4:$G$4,0))) -> 8.94 | AD11: =IF($C11="","",IF(AND(C11=1,I11="Unarmored"),INDEX('Assumptions & Ref'!$C$70:$C$90,MATCH(E11,'Assumptions & Ref'!$B$70:$B$90,0)),INDEX('Assumptions & Ref'!$D$70:$D$90,MATCH(E11,'Assumptions & Ref'!$B$70:$B$90,0)))) -> 1.7 | AE11: =IF($C11="","",IF(D11="Circular",AB11+2*AD11,AB11+4*AD11)) -> 20.880775 | AF11: =IF($C11="","",INDEX($C$5:$G$5,MATCH(G11,$C$4:$G$4,0))) -> 0.93 | AG11: =IF($C11="","",IF(C11=3.5,IFERROR(INDEX('Assumptions & Ref'!$G$93:$G$105,MATCH(E11,'Assumptions & Ref'!$F$93:$F$105,0)),0),0)) -> 120 | AH11: =IF($C11="","",IF(C11=3.5,SQRT(AG11/PI())*2,0)) -> 12.360774 | AI11: =IF($C11="","",IF(C11=3.5,IFERROR(INDEX('Assumptions & Ref'!$D$70:$D$90,MATCH(AG11,'Assumptions & Ref'!$B$70:$B$90,0)),0),0)) -> 1.2 | AJ11: =IF($C11="","",AH11+2*AI11) -> 14.760774 | AK11: =IF($C11="","",ROUND(IF(C11=1,AE11,IF(C11=2,2*AE11,IF(C11=3,2.16*AE11,IF(C11=3.5,2.42*(3*AE11+AJ11)/4,IF(C11=4,2.42*AE11,0))))),1)) -> 46.8 | AL11: =IF($C11="","",IFERROR(INDEX('Assumptions & Ref'!$G$70:$G$74,IF(INDEX('Assumptions & Ref'!$F$70:$F$74,MATCH(AK11,'Assumptions & Ref'!$F$70:$F$74,1))=AK11,MATCH(AK11,'Assumptions & Ref'!$F$70:$F$74,1),MIN(MATCH(AK11,'Assumptions & Ref'!$F$70:$F$74,1)+1,5))),INDEX('Assumptions & Ref'!$G$70:$G$74,1))) -> 0.7 | AM11: =IF($C11="","",AK11+2*AL11) -> 48.2 | AN11: =IF($C11="","",INDEX($C$5:$G$5,MATCH(H11,$C$4:$G$4,0))) -> 1.35 | AO11: =IF($C11="","",IF(I11="Unarmored",0,IF(OR(I11="Galvanised steel flat strip",I11="Aluminium Flat Strip"),IFERROR(INDEX('Assumptions & Ref'!$C$93:$C$98,IF(INDEX('Assumptions & Ref'!$B$93:$B$98,MATCH(AM11,'Assumptions & Ref'!$B$93:$B$98,1))=AM11,MATCH(AM11,'Assumptions & Ref'!$B$93:$B$98,1),MIN(MATCH(AM11,'Assumptions & Ref'!$B$93:$B$98,1)+1,6))),INDEX('Assumptions & Ref'!$C$93:$C$98,1)),IFERROR(INDEX('Assumptions & Ref'!$D$93:$D$98,IF(INDEX('Assumptions & Ref'!$B$93:$B$98,MATCH(AM11,'Assumptions & Ref'!$B$93:$B$98,1))=AM11,MATCH(AM11,'Assumptions & Ref'!$B$93:$B$98,1),MIN(MATCH(AM11,'Assumptions & Ref'!$B$93:$B$98,1)+1,6))),INDEX('Assumptions & Ref'!$D$93:$D$98,1))))) -> 0 | AP11: =IF($C11="","",AM11+2*AO11) -> 48.2 | AQ11: =IF($C11="","",IF(I11="Unarmored",0,IF(OR(I11="Aluminium Flat Strip",I11="Aluminium Round Wired"),INDEX($C$5:$G$5,MATCH("Aluminium",$C$4:$G$4,0)),INDEX($C$5:$G$5,MATCH("Steel Wire",$C$4:$G$4,0))))) -> 0 | AR11: =IF($C11="","",IF(I11="Unarmored",IFERROR(INDEX('Assumptions & Ref'!$J$70:$J$81,IF(INDEX('Assumptions & Ref'!$I$70:$I$81,MATCH(AP11,'Assumptions & Ref'!$I$70:$I$81,1))=AP11,MATCH(AP11,'Assumptions & Ref'!$I$70:$I$81,1),MIN(MATCH(AP11,'Assumptions & Ref'!$I$70:$I$81,1)+1,12))),INDEX('Assumptions & Ref'!$J$70:$J$81,1)),IFERROR(INDEX('Assumptions & Ref'!$K$70:$K$81,IF(INDEX('Assumptions & Ref'!$I$70:$I$81,MATCH(AP11,'Assumptions & Ref'!$I$70:$I$81,1))=AP11,MATCH(AP11,'Assumptions & Ref'!$I$70:$I$81,1),MIN(MATCH(AP11,'Assumptions & Ref'!$I$70:$I$81,1)+1,12))),INDEX('Assumptions & Ref'!$K$70:$K$81,1)))) -> 3 | AS11: =IF($C11="","",AP11+2*AR11) -> 54.2 | AT11: =IF($C11="","",INDEX($C$5:$G$5,MATCH(J11,$C$4:$G$4,0))) -> 0.93 | AU11: =IF($C11="","",TRUNC(AS11+1)) -> 55 | AV11: =IF($C11="","",((E11*AC11*IF(C11=3.5,3,C11))+(AG11*AC11*IF(C11=3.5,1,0)))*(1+'Assumptions & Ref'!$C$22)) -> 7584.696 | AW11: =IF($C11="","",IF(C11=3.5,(PI()*(AE11^2-AB11^2)/4*AF11*3)+(PI()*(AJ11^2-AH11^2)/4*AF11),PI()*(AE11^2-AB11^2)/4*AF11*C11)*(1+'Assumptions & Ref'!$C$22)) -> 336.68235 | AX11: =IF($C11="","",PI()*(AM11^2-AK11^2)/4*AN11*(1+'Assumptions & Ref'!$C$22)) -> 142.42842 | AY11: =IF($C11="","",PI()*(AS11^2-AP11^2)/4*AT11*(1+'Assumptions & Ref'!$C$22)) -> 453.25793 | AZ11: =IF($C11="","",PI()*(AP11^2-AM11^2)/4*AQ11*(1+'Assumptions & Ref'!$C$22)) -> 0 | BA11: =IF($C11="","",AV11*INDEX($C$6:$G$6,MATCH(F11,$C$4:$G$4,0))+IF(G11="XLPE",AW11*INDEX($C$6:$G$6,MATCH("XLPE",$C$4:$G$4,0)),0)+IF(G11="PVC",(AW11+AX11+AY11)*INDEX($C$6:$G$6,MATCH("PVC",$C$4:$G$4,0)),(AX11+AY11)*INDEX($C$6:$G$6,MATCH("PVC",$C$4:$G$4,0)))+IF(I11="Unarmored",0,IF(OR(I11="Aluminium Flat Strip",I11="Aluminium Round Wired"),AZ11*INDEX($C$6:$G$6,MATCH("Aluminium",$C$4:$G$4,0)),AZ11*INDEX($C$6:$G$6,MATCH("Steel Wire",$C$4:$G$4,0))))) -> 10951136 | BB11: =IF($C11="","",IF(K11="Y",'Assumptions & Ref'!$C$40,0)+IF(L11="Y",'Assumptions & Ref'!$C$41,0)+IF(M11="Y",'Assumptions & Ref'!$C$42,0)+IF(N11="Y",'Assumptions & Ref'!$C$43,0)+IF(O11="Y",'Assumptions & Ref'!$C$44,0)+IF(P11="Y",'Assumptions & Ref'!$C$45,0)+IF(Q11="Y",'Assumptions & Ref'!$C$46,0)+IF(R11="Y",'Assumptions & Ref'!$C$47,0)+IF(S11="Y",'Assumptions & Ref'!$C$48,0)+IF(T11="Y",'Assumptions & Ref'!$C$49,0)) -> 0 | BC11: =IF($C11="","",(IF($F11="Aluminium",'Assumptions & Ref'!$D$17,'Assumptions & Ref'!$C$17)+IF($F11="Aluminium",'Assumptions & Ref'!$D$18,'Assumptions & Ref'!$C$18)+IF($F11="Aluminium",'Assumptions & Ref'!$D$19,'Assumptions & Ref'!$C$19)+IF($F11="Aluminium",'Assumptions & Ref'!$D$20,'Assumptions & Ref'!$C$20))/IF($F11="Aluminium",'Assumptions & Ref'!$D$16,'Assumptions & Ref'!$C$16)) -> 0.17647059 | BD11: =IF($C11="","",(IF($F11="Aluminium",'Assumptions & Ref'!$F$17,'Assumptions & Ref'!$E$17)+IF($F11="Aluminium",'Assumptions & Ref'!$F$18,'Assumptions & Ref'!$E$18)+IF($F11="Aluminium",'Assumptions & Ref'!$F$19,'Assumptions & Ref'!$E$19)+IF($F11="Aluminium",'Assumptions & Ref'!$F$20,'Assumptions & Ref'!$E$20))/IF($F11="Aluminium",'Assumptions & Ref'!$F$16,'Assumptions & Ref'!$E$16)) -> 0.11111111 | BE11: =IF($C11="","",BA11*(1+BC11)) -> 12883689 | BF11: =IF($C11="","",BA11*(1+BD11)) -> 12167929 | BG11: =IF($C11="","",BE11*(1+BB11)*(1+IF($F11="Aluminium",'Assumptions & Ref'!$D$21,'Assumptions & Ref'!$C$21))) -> 13399037 | BH11: =IF($C11="","",BF11*(1+BB11)*(1+IF($F11="Aluminium",'Assumptions & Ref'!$F$21,'Assumptions & Ref'!$E$21))) -> 12654646
B12: 3.5C x 185 sq.mm CU, XLPE | C12: 3.5 | D12: Circular | E12: 185 | F12: Copper | G12: XLPE | H12: PVC | I12: Unarmored | J12: XLPE | K12: N | L12: N | M12: N | N12: N | O12: N | P12: N | Q12: N | R12: N | S12: N | T12: N | U12: =IF($C12="","",MIN(BG12,BH12))/1000 -> 9798.0234 | V12: =IF($C12="","",MAX(BG12,BH12))/1000 -> 10374.378 | W12: =IF($C12="","",BA12)/1000 -> 8479.0587 | X12: =IF($C12="","",AU12) -> 49 | Y12: =IF($C12="","",AV12) -> 5869.11 | AA12: =IF($C12="","",IF(D12="Sector shaped",360/C12,360)) -> 360 | AB12: =IF($C12="","",SQRT(E12*(360/AA12)/PI())*2) -> 15.347616 | AC12: =IF($C12="","",INDEX($C$5:$G$5,MATCH(F12,$C$4:$G$4,0))) -> 8.94 | AD12: =IF($C12="","",IF(AND(C12=1,I12="Unarmored"),INDEX('Assumptions & Ref'!$C$70:$C$90,MATCH(E12,'Assumptions & Ref'!$B$70:$B$90,0)),INDEX('Assumptions & Ref'!$D$70:$D$90,MATCH(E12,'Assumptions & Ref'!$B$70:$B$90,0)))) -> 1.6 | AE12: =IF($C12="","",IF(D12="Circular",AB12+2*AD12,AB12+4*AD12)) -> 18.547616 | AF12: =IF($C12="","",INDEX($C$5:$G$5,MATCH(G12,$C$4:$G$4,0))) -> 0.93 | AG12: =IF($C12="","",IF(C12=3.5,IFERROR(INDEX('Assumptions & Ref'!$G$93:$G$105,MATCH(E12,'Assumptions & Ref'!$F$93:$F$105,0)),0),0)) -> 95 | AH12: =IF($C12="","",IF(C12=3.5,SQRT(AG12/PI())*2,0)) -> 10.99808 | AI12: =IF($C12="","",IF(C12=3.5,IFERROR(INDEX('Assumptions & Ref'!$D$70:$D$90,MATCH(AG12,'Assumptions & Ref'!$B$70:$B$90,0)),0),0)) -> 1.1 | AJ12: =IF($C12="","",AH12+2*AI12) -> 13.19808 | AK12: =IF($C12="","",ROUND(IF(C12=1,AE12,IF(C12=2,2*AE12,IF(C12=3,2.16*AE12,IF(C12=3.5,2.42*(3*AE12+AJ12)/4,IF(C12=4,2.42*AE12,0))))),1)) -> 41.6 | AL12: =IF($C12="","",IFERROR(INDEX('Assumptions & Ref'!$G$70:$G$74,IF(INDEX('Assumptions & Ref'!$F$70:$F$74,MATCH(AK12,'Assumptions & Ref'!$F$70:$F$74,1))=AK12,MATCH(AK12,'Assumptions & Ref'!$F$70:$F$74,1),MIN(MATCH(AK12,'Assumptions & Ref'!$F$70:$F$74,1)+1,5))),INDEX('Assumptions & Ref'!$G$70:$G$74,1))) -> 0.6 | AM12: =IF($C12="","",AK12+2*AL12) -> 42.8 | AN12: =IF($C12="","",INDEX($C$5:$G$5,MATCH(H12,$C$4:$G$4,0))) -> 1.35 | AO12: =IF($C12="","",IF(I12="Unarmored",0,IF(OR(I12="Galvanised steel flat strip",I12="Aluminium Flat Strip"),IFERROR(INDEX('Assumptions & Ref'!$C$93:$C$98,IF(INDEX('Assumptions & Ref'!$B$93:$B$98,MATCH(AM12,'Assumptions & Ref'!$B$93:$B$98,1))=AM12,MATCH(AM12,'Assumptions & Ref'!$B$93:$B$98,1),MIN(MATCH(AM12,'Assumptions & Ref'!$B$93:$B$98,1)+1,6))),INDEX('Assumptions & Ref'!$C$93:$C$98,1)),IFERROR(INDEX('Assumptions & Ref'!$D$93:$D$98,IF(INDEX('Assumptions & Ref'!$B$93:$B$98,MATCH(AM12,'Assumptions & Ref'!$B$93:$B$98,1))=AM12,MATCH(AM12,'Assumptions & Ref'!$B$93:$B$98,1),MIN(MATCH(AM12,'Assumptions & Ref'!$B$93:$B$98,1)+1,6))),INDEX('Assumptions & Ref'!$D$93:$D$98,1))))) -> 0 | AP12: =IF($C12="","",AM12+2*AO12) -> 42.8 | AQ12: =IF($C12="","",IF(I12="Unarmored",0,IF(OR(I12="Aluminium Flat Strip",I12="Aluminium Round Wired"),INDEX($C$5:$G$5,MATCH("Aluminium",$C$4:$G$4,0)),INDEX($C$5:$G$5,MATCH("Steel Wire",$C$4:$G$4,0))))) -> 0 | AR12: =IF($C12="","",IF(I12="Unarmored",IFERROR(INDEX('Assumptions & Ref'!$J$70:$J$81,IF(INDEX('Assumptions & Ref'!$I$70:$I$81,MATCH(AP12,'Assumptions & Ref'!$I$70:$I$81,1))=AP12,MATCH(AP12,'Assumptions & Ref'!$I$70:$I$81,1),MIN(MATCH(AP12,'Assumptions & Ref'!$I$70:$I$81,1)+1,12))),INDEX('Assumptions & Ref'!$J$70:$J$81,1)),IFERROR(INDEX('Assumptions & Ref'!$K$70:$K$81,IF(INDEX('Assumptions & Ref'!$I$70:$I$81,MATCH(AP12,'Assumptions & Ref'!$I$70:$I$81,1))=AP12,MATCH(AP12,'Assumptions & Ref'!$I$70:$I$81,1),MIN(MATCH(AP12,'Assumptions & Ref'!$I$70:$I$81,1)+1,12))),INDEX('Assumptions & Ref'!$K$70:$K$81,1)))) -> 2.8 | AS12: =IF($C12="","",AP12+2*AR12) -> 48.4 | AT12: =IF($C12="","",INDEX($C$5:$G$5,MATCH(J12,$C$4:$G$4,0))) -> 0.93 | AU12: =IF($C12="","",TRUNC(AS12+1)) -> 49 | AV12: =IF($C12="","",((E12*AC12*IF(C12=3.5,3,C12))+(AG12*AC12*IF(C12=3.5,1,0)))*(1+'Assumptions & Ref'!$C$22)) -> 5869.11 | AW12: =IF($C12="","",IF(C12=3.5,(PI()*(AE12^2-AB12^2)/4*AF12*3)+(PI()*(AJ12^2-AH12^2)/4*AF12),PI()*(AE12^2-AB12^2)/4*AF12*C12)*(1+'Assumptions & Ref'!$C$22)) -> 279.32151 | AX12: =IF($C12="","",PI()*(AM12^2-AK12^2)/4*AN12*(1+'Assumptions & Ref'!$C$22)) -> 108.45978 | AY12: =IF($C12="","",PI()*(AS12^2-AP12^2)/4*AT12*(1+'Assumptions & Ref'!$C$22)) -> 376.77065 | AZ12: =IF($C12="","",PI()*(AP12^2-AM12^2)/4*AQ12*(1+'Assumptions & Ref'!$C$22)) -> 0 | BA12: =IF($C12="","",AV12*INDEX($C$6:$G$6,MATCH(F12,$C$4:$G$4,0))+IF(G12="XLPE",AW12*INDEX($C$6:$G$6,MATCH("XLPE",$C$4:$G$4,0)),0)+IF(G12="PVC",(AW12+AX12+AY12)*INDEX($C$6:$G$6,MATCH("PVC",$C$4:$G$4,0)),(AX12+AY12)*INDEX($C$6:$G$6,MATCH("PVC",$C$4:$G$4,0)))+IF(I12="Unarmored",0,IF(OR(I12="Aluminium Flat Strip",I12="Aluminium Round Wired"),AZ12*INDEX($C$6:$G$6,MATCH("Aluminium",$C$4:$G$4,0)),AZ12*INDEX($C$6:$G$6,MATCH("Steel Wire",$C$4:$G$4,0))))) -> 8479058.7 | BB12: =IF($C12="","",IF(K12="Y",'Assumptions & Ref'!$C$40,0)+IF(L12="Y",'Assumptions & Ref'!$C$41,0)+IF(M12="Y",'Assumptions & Ref'!$C$42,0)+IF(N12="Y",'Assumptions & Ref'!$C$43,0)+IF(O12="Y",'Assumptions & Ref'!$C$44,0)+IF(P12="Y",'Assumptions & Ref'!$C$45,0)+IF(Q12="Y",'Assumptions & Ref'!$C$46,0)+IF(R12="Y",'Assumptions & Ref'!$C$47,0)+IF(S12="Y",'Assumptions & Ref'!$C$48,0)+IF(T12="Y",'Assumptions & Ref'!$C$49,0)) -> 0 | BC12: =IF($C12="","",(IF($F12="Aluminium",'Assumptions & Ref'!$D$17,'Assumptions & Ref'!$C$17)+IF($F12="Aluminium",'Assumptions & Ref'!$D$18,'Assumptions & Ref'!$C$18)+IF($F12="Aluminium",'Assumptions & Ref'!$D$19,'Assumptions & Ref'!$C$19)+IF($F12="Aluminium",'Assumptions & Ref'!$D$20,'Assumptions & Ref'!$C$20))/IF($F12="Aluminium",'Assumptions & Ref'!$D$16,'Assumptions & Ref'!$C$16)) -> 0.17647059 | BD12: =IF($C12="","",(IF($F12="Aluminium",'Assumptions & Ref'!$F$17,'Assumptions & Ref'!$E$17)+IF($F12="Aluminium",'Assumptions & Ref'!$F$18,'Assumptions & Ref'!$E$18)+IF($F12="Aluminium",'Assumptions & Ref'!$F$19,'Assumptions & Ref'!$E$19)+IF($F12="Aluminium",'Assumptions & Ref'!$F$20,'Assumptions & Ref'!$E$20))/IF($F12="Aluminium",'Assumptions & Ref'!$F$16,'Assumptions & Ref'!$E$16)) -> 0.11111111 | BE12: =IF($C12="","",BA12*(1+BC12)) -> 9975363.2 | BF12: =IF($C12="","",BA12*(1+BD12)) -> 9421176.4 | BG12: =IF($C12="","",BE12*(1+BB12)*(1+IF($F12="Aluminium",'Assumptions & Ref'!$D$21,'Assumptions & Ref'!$C$21))) -> 10374378 | BH12: =IF($C12="","",BF12*(1+BB12)*(1+IF($F12="Aluminium",'Assumptions & Ref'!$F$21,'Assumptions & Ref'!$E$21))) -> 9798023.4
B13: 3.5C x 150 sq.mm CU, XLPE | C13: 3.5 | D13: Circular | E13: 150 | F13: Copper | G13: XLPE | H13: PVC | I13: Unarmored | J13: XLPE | K13: N | L13: N | M13: N | N13: N | O13: N | P13: N | Q13: N | R13: N | S13: N | T13: N | U13: =IF($C13="","",MIN(BG13,BH13))/1000 -> 7841.0426 | V13: =IF($C13="","",MAX(BG13,BH13))/1000 -> 8302.2804 | W13: =IF($C13="","",BA13)/1000 -> 6785.5176 | X13: =IF($C13="","",AU13) -> 44 | Y13: =IF($C13="","",AV13) -> 4695.288 | AA13: =IF($C13="","",IF(D13="Sector shaped",360/C13,360)) -> 360 | AB13: =IF($C13="","",SQRT(E13*(360/AA13)/PI())*2) -> 13.819766 | AC13: =IF($C13="","",INDEX($C$5:$G$5,MATCH(F13,$C$4:$G$4,0))) -> 8.94 | AD13: =IF($C13="","",IF(AND(C13=1,I13="Unarmored"),INDEX('Assumptions & Ref'!$C$70:$C$90,MATCH(E13,'Assumptions & Ref'!$B$70:$B$90,0)),INDEX('Assumptions & Ref'!$D$70:$D$90,MATCH(E13,'Assumptions & Ref'!$B$70:$B$90,0)))) -> 1.4 | AE13: =IF($C13="","",IF(D13="Circular",AB13+2*AD13,AB13+4*AD13)) -> 16.619766 | AF13: =IF($C13="","",INDEX($C$5:$G$5,MATCH(G13,$C$4:$G$4,0))) -> 0.93 | AG13: =IF($C13="","",IF(C13=3.5,IFERROR(INDEX('Assumptions & Ref'!$G$93:$G$105,MATCH(E13,'Assumptions & Ref'!$F$93:$F$105,0)),0),0)) -> 70 | AH13: =IF($C13="","",IF(C13=3.5,SQRT(AG13/PI())*2,0)) -> 9.4406974 | AI13: =IF($C13="","",IF(C13=3.5,IFERROR(INDEX('Assumptions & Ref'!$D$70:$D$90,MATCH(AG13,'Assumptions & Ref'!$B$70:$B$90,0)),0),0)) -> 1.1 | AJ13: =IF($C13="","",AH13+2*AI13) -> 11.640697 | AK13: =IF($C13="","",ROUND(IF(C13=1,AE13,IF(C13=2,2*AE13,IF(C13=3,2.16*AE13,IF(C13=3.5,2.42*(3*AE13+AJ13)/4,IF(C13=4,2.42*AE13,0))))),1)) -> 37.2 | AL13: =IF($C13="","",IFERROR(INDEX('Assumptions & Ref'!$G$70:$G$74,IF(INDEX('Assumptions & Ref'!$F$70:$F$74,MATCH(AK13,'Assumptions & Ref'!$F$70:$F$74,1))=AK13,MATCH(AK13,'Assumptions & Ref'!$F$70:$F$74,1),MIN(MATCH(AK13,'Assumptions & Ref'!$F$70:$F$74,1)+1,5))),INDEX('Assumptions & Ref'!$G$70:$G$74,1))) -> 0.6 | AM13: =IF($C13="","",AK13+2*AL13) -> 38.4 | AN13: =IF($C13="","",INDEX($C$5:$G$5,MATCH(H13,$C$4:$G$4,0))) -> 1.35 | AO13: =IF($C13="","",IF(I13="Unarmored",0,IF(OR(I13="Galvanised steel flat strip",I13="Aluminium Flat Strip"),IFERROR(INDEX('Assumptions & Ref'!$C$93:$C$98,IF(INDEX('Assumptions & Ref'!$B$93:$B$98,MATCH(AM13,'Assumptions & Ref'!$B$93:$B$98,1))=AM13,MATCH(AM13,'Assumptions & Ref'!$B$93:$B$98,1),MIN(MATCH(AM13,'Assumptions & Ref'!$B$93:$B$98,1)+1,6))),INDEX('Assumptions & Ref'!$C$93:$C$98,1)),IFERROR(INDEX('Assumptions & Ref'!$D$93:$D$98,IF(INDEX('Assumptions & Ref'!$B$93:$B$98,MATCH(AM13,'Assumptions & Ref'!$B$93:$B$98,1))=AM13,MATCH(AM13,'Assumptions & Ref'!$B$93:$B$98,1),MIN(MATCH(AM13,'Assumptions & Ref'!$B$93:$B$98,1)+1,6))),INDEX('Assumptions & Ref'!$D$93:$D$98,1))))) -> 0 | AP13: =IF($C13="","",AM13+2*AO13) -> 38.4 | AQ13: =IF($C13="","",IF(I13="Unarmored",0,IF(OR(I13="Aluminium Flat Strip",I13="Aluminium Round Wired"),INDEX($C$5:$G$5,MATCH("Aluminium",$C$4:$G$4,0)),INDEX($C$5:$G$5,MATCH("Steel Wire",$C$4:$G$4,0))))) -> 0 | AR13: =IF($C13="","",IF(I13="Unarmored",IFERROR(INDEX('Assumptions & Ref'!$J$70:$J$81,IF(INDEX('Assumptions & Ref'!$I$70:$I$81,MATCH(AP13,'Assumptions & Ref'!$I$70:$I$81,1))=AP13,MATCH(AP13,'Assumptions & Ref'!$I$70:$I$81,1),MIN(MATCH(AP13,'Assumptions & Ref'!$I$70:$I$81,1)+1,12))),INDEX('Assumptions & Ref'!$J$70:$J$81,1)),IFERROR(INDEX('Assumptions & Ref'!$K$70:$K$81,IF(INDEX('Assumptions & Ref'!$I$70:$I$81,MATCH(AP13,'Assumptions & Ref'!$I$70:$I$81,1))=AP13,MATCH(AP13,'Assumptions & Ref'!$I$70:$I$81,1),MIN(MATCH(AP13,'Assumptions & Ref'!$I$70:$I$81,1)+1,12))),INDEX('Assumptions & Ref'!$K$70:$K$81,1)))) -> 2.6 | AS13: =IF($C13="","",AP13+2*AR13) -> 43.6 | AT13: =IF($C13="","",INDEX($C$5:$G$5,MATCH(J13,$C$4:$G$4,0))) -> 0.93 | AU13: =IF($C13="","",TRUNC(AS13+1)) -> 44 | AV13: =IF($C13="","",((E13*AC13*IF(C13=3.5,3,C13))+(AG13*AC13*IF(C13=3.5,1,0)))*(1+'Assumptions & Ref'!$C$22)) -> 4695.288 | AW13: =IF($C13="","",IF(C13=3.5,(PI()*(AE13^2-AB13^2)/4*AF13*3)+(PI()*(AJ13^2-AH13^2)/4*AF13),PI()*(AE13^2-AB13^2)/4*AF13*C13)*(1+'Assumptions & Ref'!$C$22)) -> 222.84528 | AX13: =IF($C13="","",PI()*(AM13^2-AK13^2)/4*AN13*(1+'Assumptions & Ref'!$C$22)) -> 97.151177 | AY13: =IF($C13="","",PI()*(AS13^2-AP13^2)/4*AT13*(1+'Assumptions & Ref'!$C$22)) -> 314.56572 | AZ13: =IF($C13="","",PI()*(AP13^2-AM13^2)/4*AQ13*(1+'Assumptions & Ref'!$C$22)) -> 0 | BA13: =IF($C13="","",AV13*INDEX($C$6:$G$6,MATCH(F13,$C$4:$G$4,0))+IF(G13="XLPE",AW13*INDEX($C$6:$G$6,MATCH("XLPE",$C$4:$G$4,0)),0)+IF(G13="PVC",(AW13+AX13+AY13)*INDEX($C$6:$G$6,MATCH("PVC",$C$4:$G$4,0)),(AX13+AY13)*INDEX($C$6:$G$6,MATCH("PVC",$C$4:$G$4,0)))+IF(I13="Unarmored",0,IF(OR(I13="Aluminium Flat Strip",I13="Aluminium Round Wired"),AZ13*INDEX($C$6:$G$6,MATCH("Aluminium",$C$4:$G$4,0)),AZ13*INDEX($C$6:$G$6,MATCH("Steel Wire",$C$4:$G$4,0))))) -> 6785517.6 | BB13: =IF($C13="","",IF(K13="Y",'Assumptions & Ref'!$C$40,0)+IF(L13="Y",'Assumptions & Ref'!$C$41,0)+IF(M13="Y",'Assumptions & Ref'!$C$42,0)+IF(N13="Y",'Assumptions & Ref'!$C$43,0)+IF(O13="Y",'Assumptions & Ref'!$C$44,0)+IF(P13="Y",'Assumptions & Ref'!$C$45,0)+IF(Q13="Y",'Assumptions & Ref'!$C$46,0)+IF(R13="Y",'Assumptions & Ref'!$C$47,0)+IF(S13="Y",'Assumptions & Ref'!$C$48,0)+IF(T13="Y",'Assumptions & Ref'!$C$49,0)) -> 0 | BC13: =IF($C13="","",(IF($F13="Aluminium",'Assumptions & Ref'!$D$17,'Assumptions & Ref'!$C$17)+IF($F13="Aluminium",'Assumptions & Ref'!$D$18,'Assumptions & Ref'!$C$18)+IF($F13="Aluminium",'Assumptions & Ref'!$D$19,'Assumptions & Ref'!$C$19)+IF($F13="Aluminium",'Assumptions & Ref'!$D$20,'Assumptions & Ref'!$C$20))/IF($F13="Aluminium",'Assumptions & Ref'!$D$16,'Assumptions & Ref'!$C$16)) -> 0.17647059 | BD13: =IF($C13="","",(IF($F13="Aluminium",'Assumptions & Ref'!$F$17,'Assumptions & Ref'!$E$17)+IF($F13="Aluminium",'Assumptions & Ref'!$F$18,'Assumptions & Ref'!$E$18)+IF($F13="Aluminium",'Assumptions & Ref'!$F$19,'Assumptions & Ref'!$E$19)+IF($F13="Aluminium",'Assumptions & Ref'!$F$20,'Assumptions & Ref'!$E$20))/IF($F13="Aluminium",'Assumptions & Ref'!$F$16,'Assumptions & Ref'!$E$16)) -> 0.11111111 | BE13: =IF($C13="","",BA13*(1+BC13)) -> 7982961.9 | BF13: =IF($C13="","",BA13*(1+BD13)) -> 7539464 | BG13: =IF($C13="","",BE13*(1+BB13)*(1+IF($F13="Aluminium",'Assumptions & Ref'!$D$21,'Assumptions & Ref'!$C$21))) -> 8302280.4 | BH13: =IF($C13="","",BF13*(1+BB13)*(1+IF($F13="Aluminium",'Assumptions & Ref'!$F$21,'Assumptions & Ref'!$E$21))) -> 7841042.6
B14: 3.5C x 50 sq.mm CU, XLPE | C14: 3.5 | D14: Circular | E14: 50 | F14: Copper | G14: XLPE | H14: PVC | I14: Unarmored | J14: XLPE | K14: N | L14: N | M14: N | N14: N | O14: N | P14: N | Q14: N | R14: N | S14: N | T14: N | U14: =IF($C14="","",MIN(BG14,BH14))/1000 -> 2649.9707 | V14: =IF($C14="","",MAX(BG14,BH14))/1000 -> 2805.8514 | W14: =IF($C14="","",BA14)/1000 -> 2293.2439 | X14: =IF($C14="","",AU14) -> 28 | Y14: =IF($C14="","",AV14) -> 1580.145 | AA14: =IF($C14="","",IF(D14="Sector shaped",360/C14,360)) -> 360 | AB14: =IF($C14="","",SQRT(E14*(360/AA14)/PI())*2) -> 7.9788456 | AC14: =IF($C14="","",INDEX($C$5:$G$5,MATCH(F14,$C$4:$G$4,0))) -> 8.94 | AD14: =IF($C14="","",IF(AND(C14=1,I14="Unarmored"),INDEX('Assumptions & Ref'!$C$70:$C$90,MATCH(E14,'Assumptions & Ref'!$B$70:$B$90,0)),INDEX('Assumptions & Ref'!$D$70:$D$90,MATCH(E14,'Assumptions & Ref'!$B$70:$B$90,0)))) -> 1 | AE14: =IF($C14="","",IF(D14="Circular",AB14+2*AD14,AB14+4*AD14)) -> 9.9788456 | AF14: =IF($C14="","",INDEX($C$5:$G$5,MATCH(G14,$C$4:$G$4,0))) -> 0.93 | AG14: =IF($C14="","",IF(C14=3.5,IFERROR(INDEX('Assumptions & Ref'!$G$93:$G$105,MATCH(E14,'Assumptions & Ref'!$F$93:$F$105,0)),0),0)) -> 25 | AH14: =IF($C14="","",IF(C14=3.5,SQRT(AG14/PI())*2,0)) -> 5.6418958 | AI14: =IF($C14="","",IF(C14=3.5,IFERROR(INDEX('Assumptions & Ref'!$D$70:$D$90,MATCH(AG14,'Assumptions & Ref'!$B$70:$B$90,0)),0),0)) -> 0.9 | AJ14: =IF($C14="","",AH14+2*AI14) -> 7.4418958 | AK14: =IF($C14="","",ROUND(IF(C14=1,AE14,IF(C14=2,2*AE14,IF(C14=3,2.16*AE14,IF(C14=3.5,2.42*(3*AE14+AJ14)/4,IF(C14=4,2.42*AE14,0))))),1)) -> 22.6 | AL14: =IF($C14="","",IFERROR(INDEX('Assumptions & Ref'!$G$70:$G$74,IF(INDEX('Assumptions & Ref'!$F$70:$F$74,MATCH(AK14,'Assumptions & Ref'!$F$70:$F$74,1))=AK14,MATCH(AK14,'Assumptions & Ref'!$F$70:$F$74,1),MIN(MATCH(AK14,'Assumptions & Ref'!$F$70:$F$74,1)+1,5))),INDEX('Assumptions & Ref'!$G$70:$G$74,1))) -> 0.4 | AM14: =IF($C14="","",AK14+2*AL14) -> 23.4 | AN14: =IF($C14="","",INDEX($C$5:$G$5,MATCH(H14,$C$4:$G$4,0))) -> 1.35 | AO14: =IF($C14="","",IF(I14="Unarmored",0,IF(OR(I14="Galvanised steel flat strip",I14="Aluminium Flat Strip"),IFERROR(INDEX('Assumptions & Ref'!$C$93:$C$98,IF(INDEX('Assumptions & Ref'!$B$93:$B$98,MATCH(AM14,'Assumptions & Ref'!$B$93:$B$98,1))=AM14,MATCH(AM14,'Assumptions & Ref'!$B$93:$B$98,1),MIN(MATCH(AM14,'Assumptions & Ref'!$B$93:$B$98,1)+1,6))),INDEX('Assumptions & Ref'!$C$93:$C$98,1)),IFERROR(INDEX('Assumptions & Ref'!$D$93:$D$98,IF(INDEX('Assumptions & Ref'!$B$93:$B$98,MATCH(AM14,'Assumptions & Ref'!$B$93:$B$98,1))=AM14,MATCH(AM14,'Assumptions & Ref'!$B$93:$B$98,1),MIN(MATCH(AM14,'Assumptions & Ref'!$B$93:$B$98,1)+1,6))),INDEX('Assumptions & Ref'!$D$93:$D$98,1))))) -> 0 | AP14: =IF($C14="","",AM14+2*AO14) -> 23.4 | AQ14: =IF($C14="","",IF(I14="Unarmored",0,IF(OR(I14="Aluminium Flat Strip",I14="Aluminium Round Wired"),INDEX($C$5:$G$5,MATCH("Aluminium",$C$4:$G$4,0)),INDEX($C$5:$G$5,MATCH("Steel Wire",$C$4:$G$4,0))))) -> 0 | AR14: =IF($C14="","",IF(I14="Unarmored",IFERROR(INDEX('Assumptions & Ref'!$J$70:$J$81,IF(INDEX('Assumptions & Ref'!$I$70:$I$81,MATCH(AP14,'Assumptions & Ref'!$I$70:$I$81,1))=AP14,MATCH(AP14,'Assumptions & Ref'!$I$70:$I$81,1),MIN(MATCH(AP14,'Assumptions & Ref'!$I$70:$I$81,1)+1,12))),INDEX('Assumptions & Ref'!$J$70:$J$81,1)),IFERROR(INDEX('Assumptions & Ref'!$K$70:$K$81,IF(INDEX('Assumptions & Ref'!$I$70:$I$81,MATCH(AP14,'Assumptions & Ref'!$I$70:$I$81,1))=AP14,MATCH(AP14,'Assumptions & Ref'!$I$70:$I$81,1),MIN(MATCH(AP14,'Assumptions & Ref'!$I$70:$I$81,1)+1,12))),INDEX('Assumptions & Ref'!$K$70:$K$81,1)))) -> 2.2 | AS14: =IF($C14="","",AP14+2*AR14) -> 27.8 | AT14: =IF($C14="","",INDEX($C$5:$G$5,MATCH(J14,$C$4:$G$4,0))) -> 0.93 | AU14: =IF($C14="","",TRUNC(AS14+1)) -> 28 | AV14: =IF($C14="","",((E14*AC14*IF(C14=3.5,3,C14))+(AG14*AC14*IF(C14=3.5,1,0)))*(1+'Assumptions & Ref'!$C$22)) -> 1580.145 | AW14: =IF($C14="","",IF(C14=3.5,(PI()*(AE14^2-AB14^2)/4*AF14*3)+(PI()*(AJ14^2-AH14^2)/4*AF14),PI()*(AE14^2-AB14^2)/4*AF14*C14)*(1+'Assumptions & Ref'!$C$22)) -> 96.860993 | AX14: =IF($C14="","",PI()*(AM14^2-AK14^2)/4*AN14*(1+'Assumptions & Ref'!$C$22)) -> 39.408767 | AY14: =IF($C14="","",PI()*(AS14^2-AP14^2)/4*AT14*(1+'Assumptions & Ref'!$C$22)) -> 166.19457 | AZ14: =IF($C14="","",PI()*(AP14^2-AM14^2)/4*AQ14*(1+'Assumptions & Ref'!$C$22)) -> 0 | BA14: =IF($C14="","",AV14*INDEX($C$6:$G$6,MATCH(F14,$C$4:$G$4,0))+IF(G14="XLPE",AW14*INDEX($C$6:$G$6,MATCH("XLPE",$C$4:$G$4,0)),0)+IF(G14="PVC",(AW14+AX14+AY14)*INDEX($C$6:$G$6,MATCH("PVC",$C$4:$G$4,0)),(AX14+AY14)*INDEX($C$6:$G$6,MATCH("PVC",$C$4:$G$4,0)))+IF(I14="Unarmored",0,IF(OR(I14="Aluminium Flat Strip",I14="Aluminium Round Wired"),AZ14*INDEX($C$6:$G$6,MATCH("Aluminium",$C$4:$G$4,0)),AZ14*INDEX($C$6:$G$6,MATCH("Steel Wire",$C$4:$G$4,0))))) -> 2293243.9 | BB14: =IF($C14="","",IF(K14="Y",'Assumptions & Ref'!$C$40,0)+IF(L14="Y",'Assumptions & Ref'!$C$41,0)+IF(M14="Y",'Assumptions & Ref'!$C$42,0)+IF(N14="Y",'Assumptions & Ref'!$C$43,0)+IF(O14="Y",'Assumptions & Ref'!$C$44,0)+IF(P14="Y",'Assumptions & Ref'!$C$45,0)+IF(Q14="Y",'Assumptions & Ref'!$C$46,0)+IF(R14="Y",'Assumptions & Ref'!$C$47,0)+IF(S14="Y",'Assumptions & Ref'!$C$48,0)+IF(T14="Y",'Assumptions & Ref'!$C$49,0)) -> 0 | BC14: =IF($C14="","",(IF($F14="Aluminium",'Assumptions & Ref'!$D$17,'Assumptions & Ref'!$C$17)+IF($F14="Aluminium",'Assumptions & Ref'!$D$18,'Assumptions & Ref'!$C$18)+IF($F14="Aluminium",'Assumptions & Ref'!$D$19,'Assumptions & Ref'!$C$19)+IF($F14="Aluminium",'Assumptions & Ref'!$D$20,'Assumptions & Ref'!$C$20))/IF($F14="Aluminium",'Assumptions & Ref'!$D$16,'Assumptions & Ref'!$C$16)) -> 0.17647059 | BD14: =IF($C14="","",(IF($F14="Aluminium",'Assumptions & Ref'!$F$17,'Assumptions & Ref'!$E$17)+IF($F14="Aluminium",'Assumptions & Ref'!$F$18,'Assumptions & Ref'!$E$18)+IF($F14="Aluminium",'Assumptions & Ref'!$F$19,'Assumptions & Ref'!$E$19)+IF($F14="Aluminium",'Assumptions & Ref'!$F$20,'Assumptions & Ref'!$E$20))/IF($F14="Aluminium",'Assumptions & Ref'!$F$16,'Assumptions & Ref'!$E$16)) -> 0.11111111 | BE14: =IF($C14="","",BA14*(1+BC14)) -> 2697934 | BF14: =IF($C14="","",BA14*(1+BD14)) -> 2548048.8 | BG14: =IF($C14="","",BE14*(1+BB14)*(1+IF($F14="Aluminium",'Assumptions & Ref'!$D$21,'Assumptions & Ref'!$C$21))) -> 2805851.4 | BH14: =IF($C14="","",BF14*(1+BB14)*(1+IF($F14="Aluminium",'Assumptions & Ref'!$F$21,'Assumptions & Ref'!$E$21))) -> 2649970.7
B15: 3C x 50 sq.mm CU, XLPE | C15: 3 | D15: Circular | E15: 2.5 | F15: Copper | G15: XLPE | H15: PVC | I15: Galvanised steel round wire | J15: XLPE | K15: N | L15: N | M15: N | N15: N | O15: N | P15: N | Q15: N | R15: N | S15: N | T15: N | U15: =IF($C15="","",MIN(BG15,BH15))/1000 -> 150.41267 | V15: =IF($C15="","",MAX(BG15,BH15))/1000 -> 159.26047 | W15: =IF($C15="","",BA15)/1000 -> 130.16481 | X15: =IF($C15="","",AU15) -> 14 | Y15: =IF($C15="","",AV15) -> 67.7205 | AA15: =IF($C15="","",IF(D15="Sector shaped",360/C15,360)) -> 360 | AB15: =IF($C15="","",SQRT(E15*(360/AA15)/PI())*2) -> 1.7841241 | AC15: =IF($C15="","",INDEX($C$5:$G$5,MATCH(F15,$C$4:$G$4,0))) -> 8.94 | AD15: =IF($C15="","",IF(AND(C15=1,I15="Unarmored"),INDEX('Assumptions & Ref'!$C$70:$C$90,MATCH(E15,'Assumptions & Ref'!$B$70:$B$90,0)),INDEX('Assumptions & Ref'!$D$70:$D$90,MATCH(E15,'Assumptions & Ref'!$B$70:$B$90,0)))) -> 0.7 | AE15: =IF($C15="","",IF(D15="Circular",AB15+2*AD15,AB15+4*AD15)) -> 3.1841241 | AF15: =IF($C15="","",INDEX($C$5:$G$5,MATCH(G15,$C$4:$G$4,0))) -> 0.93 | AG15: =IF($C15="","",IF(C15=3.5,IFERROR(INDEX('Assumptions & Ref'!$G$93:$G$105,MATCH(E15,'Assumptions & Ref'!$F$93:$F$105,0)),0),0)) -> 0 | AH15: =IF($C15="","",IF(C15=3.5,SQRT(AG15/PI())*2,0)) -> 0 | AI15: =IF($C15="","",IF(C15=3.5,IFERROR(INDEX('Assumptions & Ref'!$D$70:$D$90,MATCH(AG15,'Assumptions & Ref'!$B$70:$B$90,0)),0),0)) -> 0 | AJ15: =IF($C15="","",AH15+2*AI15) -> 0 | AK15: =IF($C15="","",ROUND(IF(C15=1,AE15,IF(C15=2,2*AE15,IF(C15=3,2.16*AE15,IF(C15=3.5,2.42*(3*AE15+AJ15)/4,IF(C15=4,2.42*AE15,0))))),1)) -> 6.9 | AL15: =IF($C15="","",IFERROR(INDEX('Assumptions & Ref'!$G$70:$G$74,IF(INDEX('Assumptions & Ref'!$F$70:$F$74,MATCH(AK15,'Assumptions & Ref'!$F$70:$F$74,1))=AK15,MATCH(AK15,'Assumptions & Ref'!$F$70:$F$74,1),MIN(MATCH(AK15,'Assumptions & Ref'!$F$70:$F$74,1)+1,5))),INDEX('Assumptions & Ref'!$G$70:$G$74,1))) -> 0.4 | AM15: =IF($C15="","",AK15+2*AL15) -> 7.7 | AN15: =IF($C15="","",INDEX($C$5:$G$5,MATCH(H15,$C$4:$G$4,0))) -> 1.35 | AO15: =IF($C15="","",IF(I15="Unarmored",0,IF(OR(I15="Galvanised steel flat strip",I15="Aluminium Flat Strip"),IFERROR(INDEX('Assumptions & Ref'!$C$93:$C$98,IF(INDEX('Assumptions & Ref'!$B$93:$B$98,MATCH(AM15,'Assumptions & Ref'!$B$93:$B$98,1))=AM15,MATCH(AM15,'Assumptions & Ref'!$B$93:$B$98,1),MIN(MATCH(AM15,'Assumptions & Ref'!$B$93:$B$98,1)+1,6))),INDEX('Assumptions & Ref'!$C$93:$C$98,1)),IFERROR(INDEX('Assumptions & Ref'!$D$93:$D$98,IF(INDEX('Assumptions & Ref'!$B$93:$B$98,MATCH(AM15,'Assumptions & Ref'!$B$93:$B$98,1))=AM15,MATCH(AM15,'Assumptions & Ref'!$B$93:$B$98,1),MIN(MATCH(AM15,'Assumptions & Ref'!$B$93:$B$98,1)+1,6))),INDEX('Assumptions & Ref'!$D$93:$D$98,1))))) -> 1.6 | AP15: =IF($C15="","",AM15+2*AO15) -> 10.9 | AQ15: =IF($C15="","",IF(I15="Unarmored",0,IF(OR(I15="Aluminium Flat Strip",I15="Aluminium Round Wired"),INDEX($C$5:$G$5,MATCH("Aluminium",$C$4:$G$4,0)),INDEX($C$5:$G$5,MATCH("Steel Wire",$C$4:$G$4,0))))) -> 7.76 | AR15: =IF($C15="","",IF(I15="Unarmored",IFERROR(INDEX('Assumptions & Ref'!$J$70:$J$81,IF(INDEX('Assumptions & Ref'!$I$70:$I$81,MATCH(AP15,'Assumptions & Ref'!$I$70:$I$81,1))=AP15,MATCH(AP15,'Assumptions & Ref'!$I$70:$I$81,1),MIN(MATCH(AP15,'Assumptions & Ref'!$I$70:$I$81,1)+1,12))),INDEX('Assumptions & Ref'!$J$70:$J$81,1)),IFERROR(INDEX('Assumptions & Ref'!$K$70:$K$81,IF(INDEX('Assumptions & Ref'!$I$70:$I$81,MATCH(AP15,'Assumptions & Ref'!$I$70:$I$81,1))=AP15,MATCH(AP15,'Assumptions & Ref'!$I$70:$I$81,1),MIN(MATCH(AP15,'Assumptions & Ref'!$I$70:$I$81,1)+1,12))),INDEX('Assumptions & Ref'!$K$70:$K$81,1)))) -> 1.4 | AS15: =IF($C15="","",AP15+2*AR15) -> 13.7 | AT15: =IF($C15="","",INDEX($C$5:$G$5,MATCH(J15,$C$4:$G$4,0))) -> 0.93 | AU15: =IF($C15="","",TRUNC(AS15+1)) -> 14 | AV15: =IF($C15="","",((E15*AC15*IF(C15=3.5,3,C15))+(AG15*AC15*IF(C15=3.5,1,0)))*(1+'Assumptions & Ref'!$C$22)) -> 67.7205 | AW15: =IF($C15="","",IF(C15=3.5,(PI()*(AE15^2-AB15^2)/4*AF15*3)+(PI()*(AJ15^2-AH15^2)/4*AF15),PI()*(AE15^2-AB15^2)/4*AF15*C15)*(1+'Assumptions & Ref'!$C$22)) -> 15.393833 | AX15: =IF($C15="","",PI()*(AM15^2-AK15^2)/4*AN15*(1+'Assumptions & Ref'!$C$22)) -> 12.508 | AY15: =IF($C15="","",PI()*(AS15^2-AP15^2)/4*AT15*(1+'Assumptions & Ref'!$C$22)) -> 50.814463 | AZ15: =IF($C15="","",PI()*(AP15^2-AM15^2)/4*AQ15*(1+'Assumptions & Ref'!$C$22)) -> 366.38349 | BA15: =IF($C15="","",AV15*INDEX($C$6:$G$6,MATCH(F15,$C$4:$G$4,0))+IF(G15="XLPE",AW15*INDEX($C$6:$G$6,MATCH("XLPE",$C$4:$G$4,0)),0)+IF(G15="PVC",(AW15+AX15+AY15)*INDEX($C$6:$G$6,MATCH("PVC",$C$4:$G$4,0)),(AX15+AY15)*INDEX($C$6:$G$6,MATCH("PVC",$C$4:$G$4,0)))+IF(I15="Unarmored",0,IF(OR(I15="Aluminium Flat Strip",I15="Aluminium Round Wired"),AZ15*INDEX($C$6:$G$6,MATCH("Aluminium",$C$4:$G$4,0)),AZ15*INDEX($C$6:$G$6,MATCH("Steel Wire",$C$4:$G$4,0))))) -> 130164.81 | BB15: =IF($C15="","",IF(K15="Y",'Assumptions & Ref'!$C$40,0)+IF(L15="Y",'Assumptions & Ref'!$C$41,0)+IF(M15="Y",'Assumptions & Ref'!$C$42,0)+IF(N15="Y",'Assumptions & Ref'!$C$43,0)+IF(O15="Y",'Assumptions & Ref'!$C$44,0)+IF(P15="Y",'Assumptions & Ref'!$C$45,0)+IF(Q15="Y",'Assumptions & Ref'!$C$46,0)+IF(R15="Y",'Assumptions & Ref'!$C$47,0)+IF(S15="Y",'Assumptions & Ref'!$C$48,0)+IF(T15="Y",'Assumptions & Ref'!$C$49,0)) -> 0 | BC15: =IF($C15="","",(IF($F15="Aluminium",'Assumptions & Ref'!$D$17,'Assumptions & Ref'!$C$17)+IF($F15="Aluminium",'Assumptions & Ref'!$D$18,'Assumptions & Ref'!$C$18)+IF($F15="Aluminium",'Assumptions & Ref'!$D$19,'Assumptions & Ref'!$C$19)+IF($F15="Aluminium",'Assumptions & Ref'!$D$20,'Assumptions & Ref'!$C$20))/IF($F15="Aluminium",'Assumptions & Ref'!$D$16,'Assumptions & Ref'!$C$16)) -> 0.17647059 | BD15: =IF($C15="","",(IF($F15="Aluminium",'Assumptions & Ref'!$F$17,'Assumptions & Ref'!$E$17)+IF($F15="Aluminium",'Assumptions & Ref'!$F$18,'Assumptions & Ref'!$E$18)+IF($F15="Aluminium",'Assumptions & Ref'!$F$19,'Assumptions & Ref'!$E$19)+IF($F15="Aluminium",'Assumptions & Ref'!$F$20,'Assumptions & Ref'!$E$20))/IF($F15="Aluminium",'Assumptions & Ref'!$F$16,'Assumptions & Ref'!$E$16)) -> 0.11111111 | BE15: =IF($C15="","",BA15*(1+BC15)) -> 153135.07 | BF15: =IF($C15="","",BA15*(1+BD15)) -> 144627.56 | BG15: =IF($C15="","",BE15*(1+BB15)*(1+IF($F15="Aluminium",'Assumptions & Ref'!$D$21,'Assumptions & Ref'!$C$21))) -> 159260.47 | BH15: =IF($C15="","",BF15*(1+BB15)*(1+IF($F15="Aluminium",'Assumptions & Ref'!$F$21,'Assumptions & Ref'!$E$21))) -> 150412.67
U16: =IF($C16="","",MIN(BG16,BH16)) | V16: =IF($C16="","",MAX(BG16,BH16)) | W16: =IF($C16="","",BA16) | X16: =IF($C16="","",AU16) | Y16: =IF($C16="","",IF(F16="Copper",AV16,0)) | AA16: =IF($C16="","",IF(D16="Sector shaped",360/C16,360)) | AB16: =IF($C16="","",SQRT(E16*(360/AA16)/PI())*2) | AC16: =IF($C16="","",INDEX($C$5:$G$5,MATCH(F16,$C$4:$G$4,0))) | AD16: =IF($C16="","",IF(AND(C16=1,I16="Unarmored"),INDEX('Assumptions & Ref'!$C$70:$C$90,MATCH(E16,'Assumptions & Ref'!$B$70:$B$90,0)),INDEX('Assumptions & Ref'!$D$70:$D$90,MATCH(E16,'Assumptions & Ref'!$B$70:$B$90,0)))) | AE16: =IF($C16="","",IF(D16="Circular",AB16+2*AD16,AB16+4*AD16)) | AF16: =IF($C16="","",INDEX($C$5:$G$5,MATCH(G16,$C$4:$G$4,0))) | AG16: =IF($C16="","",IF(C16=3.5,IFERROR(INDEX('Assumptions & Ref'!$G$93:$G$105,MATCH(E16,'Assumptions & Ref'!$F$93:$F$105,0)),0),0)) | AH16: =IF($C16="","",IF(C16=3.5,SQRT(AG16/PI())*2,0)) | AI16: =IF($C16="","",IF(C16=3.5,IFERROR(INDEX('Assumptions & Ref'!$D$70:$D$90,MATCH(AG16,'Assumptions & Ref'!$B$70:$B$90,0)),0),0)) | AJ16: =IF($C16="","",AH16+2*AI16) | AK16: =IF($C16="","",ROUND(IF(C16=1,AE16,IF(C16=2,2*AE16,IF(C16=3,2.16*AE16,IF(C16=3.5,2.42*(3*AE16+AJ16)/4,IF(C16=4,2.42*AE16,0))))),1)) | AL16: =IF($C16="","",IFERROR(INDEX('Assumptions & Ref'!$G$70:$G$74,IF(INDEX('Assumptions & Ref'!$F$70:$F$74,MATCH(AK16,'Assumptions & Ref'!$F$70:$F$74,1))=AK16,MATCH(AK16,'Assumptions & Ref'!$F$70:$F$74,1),MIN(MATCH(AK16,'Assumptions & Ref'!$F$70:$F$74,1)+1,5))),INDEX('Assumptions & Ref'!$G$70:$G$74,1))) | AM16: =IF($C16="","",AK16+2*AL16) | AN16: =IF($C16="","",INDEX($C$5:$G$5,MATCH(H16,$C$4:$G$4,0))) | AO16: =IF($C16="","",IF(I16="Unarmored",0,IF(OR(I16="Galvanised steel flat strip",I16="Aluminium Flat Strip"),IFERROR(INDEX('Assumptions & Ref'!$C$93:$C$98,IF(INDEX('Assumptions & Ref'!$B$93:$B$98,MATCH(AM16,'Assumptions & Ref'!$B$93:$B$98,1))=AM16,MATCH(AM16,'Assumptions & Ref'!$B$93:$B$98,1),MIN(MATCH(AM16,'Assumptions & Ref'!$B$93:$B$98,1)+1,6))),INDEX('Assumptions & Ref'!$C$93:$C$98,1)),IFERROR(INDEX('Assumptions & Ref'!$D$93:$D$98,IF(INDEX('Assumptions & Ref'!$B$93:$B$98,MATCH(AM16,'Assumptions & Ref'!$B$93:$B$98,1))=AM16,MATCH(AM16,'Assumptions & Ref'!$B$93:$B$98,1),MIN(MATCH(AM16,'Assumptions & Ref'!$B$93:$B$98,1)+1,6))),INDEX('Assumptions & Ref'!$D$93:$D$98,1))))) | AP16: =IF($C16="","",AM16+2*AO16) | AQ16: =IF($C16="","",IF(I16="Unarmored",0,IF(OR(I16="Aluminium Flat Strip",I16="Aluminium Round Wired"),INDEX($C$5:$G$5,MATCH("Aluminium",$C$4:$G$4,0)),INDEX($C$5:$G$5,MATCH("Steel Wire",$C$4:$G$4,0))))) | AR16: =IF($C16="","",IF(I16="Unarmored",IFERROR(INDEX('Assumptions & Ref'!$J$70:$J$81,IF(INDEX('Assumptions & Ref'!$I$70:$I$81,MATCH(AP16,'Assumptions & Ref'!$I$70:$I$81,1))=AP16,MATCH(AP16,'Assumptions & Ref'!$I$70:$I$81,1),MIN(MATCH(AP16,'Assumptions & Ref'!$I$70:$I$81,1)+1,12))),INDEX('Assumptions & Ref'!$J$70:$J$81,1)),IFERROR(INDEX('Assumptions & Ref'!$K$70:$K$81,IF(INDEX('Assumptions & Ref'!$I$70:$I$81,MATCH(AP16,'Assumptions & Ref'!$I$70:$I$81,1))=AP16,MATCH(AP16,'Assumptions & Ref'!$I$70:$I$81,1),MIN(MATCH(AP16,'Assumptions & Ref'!$I$70:$I$81,1)+1,12))),INDEX('Assumptions & Ref'!$K$70:$K$81,1)))) | AS16: =IF($C16="","",AP16+2*AR16) | AT16: =IF($C16="","",INDEX($C$5:$G$5,MATCH(J16,$C$4:$G$4,0))) | AU16: =IF($C16="","",TRUNC(AS16+1)) | AV16: =IF($C16="","",((E16*AC16*IF(C16=3.5,3,C16))+(AG16*AC16*IF(C16=3.5,1,0)))*(1+'Assumptions & Ref'!$C$22)) | AW16: =IF($C16="","",IF(C16=3.5,(PI()*(AE16^2-AB16^2)/4*AF16*3)+(PI()*(AJ16^2-AH16^2)/4*AF16),PI()*(AE16^2-AB16^2)/4*AF16*C16)*(1+'Assumptions & Ref'!$C$22)) | AX16: =IF($C16="","",PI()*(AM16^2-AK16^2)/4*AN16*(1+'Assumptions & Ref'!$C$22)) | AY16: =IF($C16="","",PI()*(AS16^2-AP16^2)/4*AT16*(1+'Assumptions & Ref'!$C$22)) | AZ16: =IF($C16="","",PI()*(AP16^2-AM16^2)/4*AQ16*(1+'Assumptions & Ref'!$C$22)) | BA16: =IF($C16="","",AV16*INDEX($C$6:$G$6,MATCH(F16,$C$4:$G$4,0))+IF(G16="XLPE",AW16*INDEX($C$6:$G$6,MATCH("XLPE",$C$4:$G$4,0)),0)+IF(G16="PVC",(AW16+AX16+AY16)*INDEX($C$6:$G$6,MATCH("PVC",$C$4:$G$4,0)),(AX16+AY16)*INDEX($C$6:$G$6,MATCH("PVC",$C$4:$G$4,0)))+IF(I16="Unarmored",0,IF(OR(I16="Aluminium Flat Strip",I16="Aluminium Round Wired"),AZ16*INDEX($C$6:$G$6,MATCH("Aluminium",$C$4:$G$4,0)),AZ16*INDEX($C$6:$G$6,MATCH("Steel Wire",$C$4:$G$4,0))))) | BB16: =IF($C16="","",IF(K16="Y",'Assumptions & Ref'!$C$40,0)+IF(L16="Y",'Assumptions & Ref'!$C$41,0)+IF(M16="Y",'Assumptions & Ref'!$C$42,0)+IF(N16="Y",'Assumptions & Ref'!$C$43,0)+IF(O16="Y",'Assumptions & Ref'!$C$44,0)+IF(P16="Y",'Assumptions & Ref'!$C$45,0)+IF(Q16="Y",'Assumptions & Ref'!$C$46,0)+IF(R16="Y",'Assumptions & Ref'!$C$47,0)+IF(S16="Y",'Assumptions & Ref'!$C$48,0)+IF(T16="Y",'Assumptions & Ref'!$C$49,0)) | BC16: =IF($C16="","",(IF($F16="Aluminium",'Assumptions & Ref'!$D$17,'Assumptions & Ref'!$C$17)+IF($F16="Aluminium",'Assumptions & Ref'!$D$18,'Assumptions & Ref'!$C$18)+IF($F16="Aluminium",'Assumptions & Ref'!$D$19,'Assumptions & Ref'!$C$19)+IF($F16="Aluminium",'Assumptions & Ref'!$D$20,'Assumptions & Ref'!$C$20))/IF($F16="Aluminium",'Assumptions & Ref'!$D$16,'Assumptions & Ref'!$C$16)) | BD16: =IF($C16="","",(IF($F16="Aluminium",'Assumptions & Ref'!$F$17,'Assumptions & Ref'!$E$17)+IF($F16="Aluminium",'Assumptions & Ref'!$F$18,'Assumptions & Ref'!$E$18)+IF($F16="Aluminium",'Assumptions & Ref'!$F$19,'Assumptions & Ref'!$E$19)+IF($F16="Aluminium",'Assumptions & Ref'!$F$20,'Assumptions & Ref'!$E$20))/IF($F16="Aluminium",'Assumptions & Ref'!$F$16,'Assumptions & Ref'!$E$16)) | BE16: =IF($C16="","",BA16*(1+BC16)) | BF16: =IF($C16="","",BA16*(1+BD16)) | BG16: =IF($C16="","",BE16*(1+BB16)*(1+IF($F16="Aluminium",'Assumptions & Ref'!$D$21,'Assumptions & Ref'!$C$21))) | BH16: =IF($C16="","",BF16*(1+BB16)*(1+IF($F16="Aluminium",'Assumptions & Ref'!$F$21,'Assumptions & Ref'!$E$21)))
U17: =IF($C17="","",MIN(BG17,BH17)) | V17: =IF($C17="","",MAX(BG17,BH17)) | W17: =IF($C17="","",BA17) | X17: =IF($C17="","",AU17) | Y17: =IF($C17="","",IF(F17="Copper",AV17,0)) | AA17: =IF($C17="","",IF(D17="Sector shaped",360/C17,360)) | AB17: =IF($C17="","",SQRT(E17*(360/AA17)/PI())*2) | AC17: =IF($C17="","",INDEX($C$5:$G$5,MATCH(F17,$C$4:$G$4,0))) | AD17: =IF($C17="","",IF(AND(C17=1,I17="Unarmored"),INDEX('Assumptions & Ref'!$C$70:$C$90,MATCH(E17,'Assumptions & Ref'!$B$70:$B$90,0)),INDEX('Assumptions & Ref'!$D$70:$D$90,MATCH(E17,'Assumptions & Ref'!$B$70:$B$90,0)))) | AE17: =IF($C17="","",IF(D17="Circular",AB17+2*AD17,AB17+4*AD17)) | AF17: =IF($C17="","",INDEX($C$5:$G$5,MATCH(G17,$C$4:$G$4,0))) | AG17: =IF($C17="","",IF(C17=3.5,IFERROR(INDEX('Assumptions & Ref'!$G$93:$G$105,MATCH(E17,'Assumptions & Ref'!$F$93:$F$105,0)),0),0)) | AH17: =IF($C17="","",IF(C17=3.5,SQRT(AG17/PI())*2,0)) | AI17: =IF($C17="","",IF(C17=3.5,IFERROR(INDEX('Assumptions & Ref'!$D$70:$D$90,MATCH(AG17,'Assumptions & Ref'!$B$70:$B$90,0)),0),0)) | AJ17: =IF($C17="","",AH17+2*AI17) | AK17: =IF($C17="","",ROUND(IF(C17=1,AE17,IF(C17=2,2*AE17,IF(C17=3,2.16*AE17,IF(C17=3.5,2.42*(3*AE17+AJ17)/4,IF(C17=4,2.42*AE17,0))))),1)) | AL17: =IF($C17="","",IFERROR(INDEX('Assumptions & Ref'!$G$70:$G$74,IF(INDEX('Assumptions & Ref'!$F$70:$F$74,MATCH(AK17,'Assumptions & Ref'!$F$70:$F$74,1))=AK17,MATCH(AK17,'Assumptions & Ref'!$F$70:$F$74,1),MIN(MATCH(AK17,'Assumptions & Ref'!$F$70:$F$74,1)+1,5))),INDEX('Assumptions & Ref'!$G$70:$G$74,1))) | AM17: =IF($C17="","",AK17+2*AL17) | AN17: =IF($C17="","",INDEX($C$5:$G$5,MATCH(H17,$C$4:$G$4,0))) | AO17: =IF($C17="","",IF(I17="Unarmored",0,IF(OR(I17="Galvanised steel flat strip",I17="Aluminium Flat Strip"),IFERROR(INDEX('Assumptions & Ref'!$C$93:$C$98,IF(INDEX('Assumptions & Ref'!$B$93:$B$98,MATCH(AM17,'Assumptions & Ref'!$B$93:$B$98,1))=AM17,MATCH(AM17,'Assumptions & Ref'!$B$93:$B$98,1),MIN(MATCH(AM17,'Assumptions & Ref'!$B$93:$B$98,1)+1,6))),INDEX('Assumptions & Ref'!$C$93:$C$98,1)),IFERROR(INDEX('Assumptions & Ref'!$D$93:$D$98,IF(INDEX('Assumptions & Ref'!$B$93:$B$98,MATCH(AM17,'Assumptions & Ref'!$B$93:$B$98,1))=AM17,MATCH(AM17,'Assumptions & Ref'!$B$93:$B$98,1),MIN(MATCH(AM17,'Assumptions & Ref'!$B$93:$B$98,1)+1,6))),INDEX('Assumptions & Ref'!$D$93:$D$98,1))))) | AP17: =IF($C17="","",AM17+2*AO17) | AQ17: =IF($C17="","",IF(I17="Unarmored",0,IF(OR(I17="Aluminium Flat Strip",I17="Aluminium Round Wired"),INDEX($C$5:$G$5,MATCH("Aluminium",$C$4:$G$4,0)),INDEX($C$5:$G$5,MATCH("Steel Wire",$C$4:$G$4,0))))) | AR17: =IF($C17="","",IF(I17="Unarmored",IFERROR(INDEX('Assumptions & Ref'!$J$70:$J$81,IF(INDEX('Assumptions & Ref'!$I$70:$I$81,MATCH(AP17,'Assumptions & Ref'!$I$70:$I$81,1))=AP17,MATCH(AP17,'Assumptions & Ref'!$I$70:$I$81,1),MIN(MATCH(AP17,'Assumptions & Ref'!$I$70:$I$81,1)+1,12))),INDEX('Assumptions & Ref'!$J$70:$J$81,1)),IFERROR(INDEX('Assumptions & Ref'!$K$70:$K$81,IF(INDEX('Assumptions & Ref'!$I$70:$I$81,MATCH(AP17,'Assumptions & Ref'!$I$70:$I$81,1))=AP17,MATCH(AP17,'Assumptions & Ref'!$I$70:$I$81,1),MIN(MATCH(AP17,'Assumptions & Ref'!$I$70:$I$81,1)+1,12))),INDEX('Assumptions & Ref'!$K$70:$K$81,1)))) | AS17: =IF($C17="","",AP17+2*AR17) | AT17: =IF($C17="","",INDEX($C$5:$G$5,MATCH(J17,$C$4:$G$4,0))) | AU17: =IF($C17="","",TRUNC(AS17+1)) | AV17: =IF($C17="","",((E17*AC17*IF(C17=3.5,3,C17))+(AG17*AC17*IF(C17=3.5,1,0)))*(1+'Assumptions & Ref'!$C$22)) | AW17: =IF($C17="","",IF(C17=3.5,(PI()*(AE17^2-AB17^2)/4*AF17*3)+(PI()*(AJ17^2-AH17^2)/4*AF17),PI()*(AE17^2-AB17^2)/4*AF17*C17)*(1+'Assumptions & Ref'!$C$22)) | AX17: =IF($C17="","",PI()*(AM17^2-AK17^2)/4*AN17*(1+'Assumptions & Ref'!$C$22)) | AY17: =IF($C17="","",PI()*(AS17^2-AP17^2)/4*AT17*(1+'Assumptions & Ref'!$C$22)) | AZ17: =IF($C17="","",PI()*(AP17^2-AM17^2)/4*AQ17*(1+'Assumptions & Ref'!$C$22)) | BA17: =IF($C17="","",AV17*INDEX($C$6:$G$6,MATCH(F17,$C$4:$G$4,0))+IF(G17="XLPE",AW17*INDEX($C$6:$G$6,MATCH("XLPE",$C$4:$G$4,0)),0)+IF(G17="PVC",(AW17+AX17+AY17)*INDEX($C$6:$G$6,MATCH("PVC",$C$4:$G$4,0)),(AX17+AY17)*INDEX($C$6:$G$6,MATCH("PVC",$C$4:$G$4,0)))+IF(I17="Unarmored",0,IF(OR(I17="Aluminium Flat Strip",I17="Aluminium Round Wired"),AZ17*INDEX($C$6:$G$6,MATCH("Aluminium",$C$4:$G$4,0)),AZ17*INDEX($C$6:$G$6,MATCH("Steel Wire",$C$4:$G$4,0))))) | BB17: =IF($C17="","",IF(K17="Y",'Assumptions & Ref'!$C$40,0)+IF(L17="Y",'Assumptions & Ref'!$C$41,0)+IF(M17="Y",'Assumptions & Ref'!$C$42,0)+IF(N17="Y",'Assumptions & Ref'!$C$43,0)+IF(O17="Y",'Assumptions & Ref'!$C$44,0)+IF(P17="Y",'Assumptions & Ref'!$C$45,0)+IF(Q17="Y",'Assumptions & Ref'!$C$46,0)+IF(R17="Y",'Assumptions & Ref'!$C$47,0)+IF(S17="Y",'Assumptions & Ref'!$C$48,0)+IF(T17="Y",'Assumptions & Ref'!$C$49,0)) | BC17: =IF($C17="","",(IF($F17="Aluminium",'Assumptions & Ref'!$D$17,'Assumptions & Ref'!$C$17)+IF($F17="Aluminium",'Assumptions & Ref'!$D$18,'Assumptions & Ref'!$C$18)+IF($F17="Aluminium",'Assumptions & Ref'!$D$19,'Assumptions & Ref'!$C$19)+IF($F17="Aluminium",'Assumptions & Ref'!$D$20,'Assumptions & Ref'!$C$20))/IF($F17="Aluminium",'Assumptions & Ref'!$D$16,'Assumptions & Ref'!$C$16)) | BD17: =IF($C17="","",(IF($F17="Aluminium",'Assumptions & Ref'!$F$17,'Assumptions & Ref'!$E$17)+IF($F17="Aluminium",'Assumptions & Ref'!$F$18,'Assumptions & Ref'!$E$18)+IF($F17="Aluminium",'Assumptions & Ref'!$F$19,'Assumptions & Ref'!$E$19)+IF($F17="Aluminium",'Assumptions & Ref'!$F$20,'Assumptions & Ref'!$E$20))/IF($F17="Aluminium",'Assumptions & Ref'!$F$16,'Assumptions & Ref'!$E$16)) | BE17: =IF($C17="","",BA17*(1+BC17)) | BF17: =IF($C17="","",BA17*(1+BD17)) | BG17: =IF($C17="","",BE17*(1+BB17)*(1+IF($F17="Aluminium",'Assumptions & Ref'!$D$21,'Assumptions & Ref'!$C$21))) | BH17: =IF($C17="","",BF17*(1+BB17)*(1+IF($F17="Aluminium",'Assumptions & Ref'!$F$21,'Assumptions & Ref'!$E$21)))
