Workbook
Name \a: #N/A
Name \b: #N/A
Name _TB2: '[1]SPT vs PHI'!$B$2:$C$65
Name A: '[2]PRECAST lightconc-II'!$J$19
Name B: '[2]PRECAST lightconc-II'!$K$19
Name bol: #REF!
Name boml: #REF!
Name botl: #REF!
Name botn: #REF!
Name bp_capacity: '[3]Concreting Input'!$E$7
Name Breaks: #REF!
Name bua: #REF!
Name checked: #REF!
Name Columns: #REF!
Name D: '[2]PRECAST lightconc-II'!$J$20
Name dc: #REF!
Name designed: #REF!
Name df: #REF!
Name dg: #REF!
Name docu: #REF!
Name dq: #REF!
Name E: '[2]PRECAST lightconc-II'!$K$20
Name g: #REF!
Name gs: #REF!
Name hf: #REF!
Name JobID: #REF!
Name lef: #REF!
Name lel: #REF!
Name p: #REF!
Name project: #REF!
Name rel: #REF!
Name Rev: #REF!
Name rig: #REF!
Name robot: #REF!
Name rosid: #REF!
Name schools: #REF!
Name Sdate: #REF!
Name StrID: #REF!
Name structure: #REF!
Name Subject: #REF!
Name table1: '[1]SPT vs PHI'!$E$2:$F$47
Name TABLE2: #REF!
Name TableRange: #REF!
Name Title: '[4]Civil Boq'!$D$3
Name Title1: #REF!
Name Title2: #REF!
Name tol: #REF!
Name topl: #REF!
Name topn: #REF!
Name work: #REF!

Sheet Input
G1: Input
B2: Cost Model - Input Sheet - To be filled by buyer
B5: Current Requirement
B6: Payable quantity | C6: MT | D6: 37000
B7: Wastage | C7: % | D7: 0.03 | E7: >>Typically (2-5%) for rolled sections, (5-8%) for built up sections & (8-10%) for bridge & girder fabrication
B8: Total structural steel requirement | C8: MT | D8: =D6*(1+D7) -> 38110
B10: Wastage recoveries | C10: % | D10: 0.025
A12: 1 | B12: Raw Materials
D14: Requirement (MT) | E14: Cost (INR/MT)
B15: Grade 1 (E.g., E250) | C15: - | D15: =D8*20% -> 7622 | E15: =61700*(1.05) -> 64785
B16: Grade 2 (E.g., E350) | C16: - | D16: =D8*80% -> 30488 | E16: =61700*(1.05) -> 64785
B17: Grade 3 | C17: - | D17: 0 | E17: 0
D18: =SUM(D15:D17) -> 38110 | E18: =SUMPRODUCT(D15:D17,E15:E17)/SUM(D15:D17) -> 64785
A20: 2 | B20: Plant & Machinery
B23: Fabrication Type | C23: Yes/No | E23: Requirement (MT)
A24: i | B24: Built-Up fabrication & Bits Shop | C24: Yes | D24: q | E24: =D18*80% -> 30488
A25: ii | B25: Bridge & Girder fabrication | C25: No | D25: q | E25: =D18*0% -> 0
A26: iii | B26: Hot roll fabrication | C26: Yes | D26: q | E26: =D18*20% -> 7622 | G26: 0.14
A27: iv | B27: Blasting & Painting | C27: Yes | D27: q | E27: =D18 -> 38110
F28: Hollow section | G28: 0.06
A30: 3 | B30: Manpower
B32: No inputs required
B34: Fabrication Type | C34: Yes/No
A35: i | B35: Built-Up fabrication & Bits Shop | C35: =C24 -> Yes
A36: ii | B36: Bridge & Girder fabrication | C36: =C25 -> No
A37: iii | B37: Hot roll fabrication | C37: =C26 -> Yes
A38: iv | B38: Blasting & Painting | C38: =C27 -> Yes
F39: Hollow section | G39: Low productivity | H39: 1.5x of hot roll fabrication
A40: 4 | B40: Utility and consumables
A42: =MAX($A$1:A41)+0.1 -> 4.1 | B42: Power Cost | C42: Yes | D42: q
A45: =MAX($A$1:A42)+0.1 -> 4.2 | B45: Water Cost (e.g. Surface Cleaning & Preparation, Equipment Cooling) | C45: Yes | D45: q
A47: =MAX($A$1:A46)+0.1 -> 4.3 | B47: Spares & consumables
A48: a) | B48: Consumables - Welding
A50: > | B50: Welding material requirement
B51: Low complexity | C51: % of total requirement | D51: 0.6
B52: Moderate complexity | C52: % of total requirement | D52: 0.25
B53: Heavy complexity | C53: % of total requirement | D53: 0.15
D54: =SUM(D51:D53) -> 1
A56: b) | B56: Blasting & Painting
A58: > | B58: Blasting Requirement | C58: Yes | D58: q
...

Sheet Output
B2: Cost Model - Output Sheet
B5: Structural Steel Fabrication Requirement | C5: =Input!D6 -> 37000 | D5: MT
C7: INR | D7: INR/MT
A8: 1 | B8: Output: Total Costs (exlcuding profit) | C8: =SUM(C13,C28,C32,C33) -> 4.560231e+09 | D8: =SUM(D13,D28,D32,D33) -> 123200
A11: i) | B11: Stage 1: Fabrication at vendor unit
B13: Stage 1: Total Costs | C13: =SUM(C14,C15:C19,C23,C26) -> 3.394731e+09 | D13: =SUM(D14,D15:D19,D23,D26) -> 91700
A14: > | B14: Raw Material (incl. wastage) | C14: ='Calculation Sheet'!F20-'Calculation Sheet'!F23 -> 2.4380944e+09 | D14: =IFERROR(ROUND(C14/C5,-2),"") -> 65900
A15: > | B15: Machinery | C15: ='Calculation Sheet'!I34 -> 89664361 | D15: =ROUND(C15/$C$5,-2) -> 2400
A16: > | B16: Salaries | C16: ='Calculation Sheet'!J149 -> 2.7557504e+08 | D16: =ROUND(C16/$C$5,-2) -> 7400
A17: > | B17: Overheads | C17: =SUM(C14,C15:C16,C18:C19,C26)*'Calculation Sheet'!$D$291 -> 1.2888774e+08 | D17: =ROUND(C17/$C$5,-2) -> 3500
A18: > | B18: Utilities (Power, Water) | C18: =IFERROR(SUMPRODUCT('Calculation Sheet'!$E$29:$E$33,'Calculation Sheet'!$F$225:$F$229),0)+IFERROR(('Calculation Sheet'!E232*'Calculation Sheet'!E233)*C5,0) -> 48859721 | D18: =ROUND(C18/$C$5,-2) -> 1300
A19: > | B19: Consumables | C19: =SUM(C20:C22) -> 170200000 | D19: =ROUND(C19/$C$5,-2) -> 4600
B20: - Welding | C20: =D20*$C$5 -> 81400000 | D20: =ROUND('Calculation Sheet'!D251,-2) -> 2200
B21: - Blasting & Painting | C21: =D21*$C$5 -> 77700000 | D21: =ROUND('Calculation Sheet'!D282,-2) -> 2100
B22: - Others (e., tools, heating gases) | C22: =D22*$C$5 -> 11100000 | D22: =ROUND('Calculation Sheet'!D284,-2) -> 300
A23: > | B23: Civil, Infra & Mobilization Costs | C23: =SUM(C24:C25) -> 43649704 | D23: =ROUND(SUM(D24:D25),-2) -> 1200
B24: - Civil & PEB/electricity infra (amortized, facility-level) | C24: =SUMPRODUCT('Calculation Sheet'!$E$29:$E$32,'Calculation Sheet'!$D$325:$D$328) -> 3199358 | D24: =C24/$C$5 -> 86.469136
B25: - Site utility, mobilization & setup (fixed, recovered over this order) | C25: =SUMPRODUCT('Calculation Sheet'!$E29:$E32,'Calculation Sheet'!$D$355:$D$358)+SUM('Calculation Sheet'!F342:F349) -> 40450346 | D25: =C25/$C$5 -> 1093.2526
A26: > | B26: Bolting Charges (Nuts, Bolts, Washers) | C26: =D26*$C$5 -> 199800000 | D26: =ROUND('Calculation Sheet'!D381,-2) -> 5400
A28: ii) | B28: Stage 2: Transportation from Vendor to Erection Site | C28: =C29 -> 166500000 | D28: =D29 -> 4500
B29: Transportation costs | C29: =C5*'Calculation Sheet'!D310 -> 166500000 | D29: =ROUND('Calculation Sheet'!D310,-2) -> 4500
A31: ii) | B31: Stage 3: Erection charges | C31: =C32 -> 962000000 | D31: =D32 -> 26000
A32: iii) | B32: Erection Charges | C32: =D32*$C$5 -> 962000000 | D32: =Input!D104 -> 26000
A33: iv) | B33: Contingency | C33: =D33*$C$5 -> 37000000 | D33: 1000
B35: Total Cost | C35: =SUM(C13,C28,C32,C33) -> 4.560231e+09 | D35: =SUM(D13,D28,D32,D33) -> 123200
B36: Raw Material Cost | C36: =C14 -> 2.4380944e+09 | D36: =D14 -> 65900
B37: Fabrication Cost | C37: =C35-C36 -> 2.1221366e+09 | D37: =SUM(D15:D19,D23,D26,D29,D32,D33) -> 57300
B39: Profit Margin | C39: =Input!$D$94 -> 0.05 | E39: >> As per maximum allowable vendor margin provided in input sheet
B40: Selling Price | C40: =C36+C37*(1+$C$39) -> 4.6663378e+09 | D40: =D36+D37*(1+$C$39) -> 126065
B41: Fabrication Selling Price | C41: =C40-C36 -> 2.2282434e+09 | D41: =D40-D36 -> 60165
B43: Fabrication Profit | C43: =C40-SUM(C36:C37) -> 1.0610683e+08 | D43: =D40-SUM(D36:D37) -> 2865
B46: Cost categorisation
A47: > | B47: Blasting & Painting Cost | C47: =SUM(C48:C50) -> 1.256692e+08 | D47: =IFERROR(SUM(D48:D50),0) -> 3396.4648
B48: Consumables | C48: =C21 -> 77700000 | D48: =D21 -> 2100
B49: Manpower | C49: ='Calculation Sheet'!J146 -> 38618133 | D49: =C49/C5 -> 1043.7333
B50: Machinery | C50: ='Calculation Sheet'!I32 -> 9351064.8 | D50: =IFERROR(C50/C5,0) -> 252.73148

Sheet Calculation Sheet
G1: Input
B2: Cost Model - Calculation Sheet
B5: Current Requirement
B6: Payable quantity | C6: MT | D6: =Input!D6 -> 37000
B7: Wastage | C7: % | D7: =Input!D7 -> 0.03
B8: Total structural steel requirement | C8: MT | D8: =D6*(1+D7) -> 38110
B11: Work-days per month | C11: Days | D11: 25
B12: Work-hours per day | C12: Hours | D12: 20
A14: 1 | B14: Raw Materials
D16: Requirement (MT) | E16: Cost (INR/MT) | F16: Total Cost for Requirement
B17: Grade 1 (E.g., E250) | C17: - | D17: =Input!D15 -> 7622 | E17: =Input!E15 -> 64785 | F17: =D17*E17 -> 493791270
B18: Grade 2 (E.g., E350) | C18: - | D18: =Input!D16 -> 30488 | E18: =Input!E16 -> 64785 | F18: =D18*E18 -> 1975165080
B19: Grade 3 | C19: - | D19: =Input!D17 -> 0 | E19: =Input!E17 -> 0 | F19: =D19*E19 -> 0
D20: =SUM(D17:D19) -> 38110 | E20: =SUMPRODUCT(D17:D19,E17:E19)/SUM(D17:D19) -> 64785 | F20: =SUM(F17:F19) -> 2468956350
D22: Requirement (MT) | E22: Cost (INR/MT) | F22: Total Cost for Requirement
B23: Wastage Recoveries | C23: MT | D23: =Input!D10*D20 -> 952.75 | E23: =E20*50% -> 32392.5 | F23: =D23*E23 -> 30861954
A25: 2 | B25: Plant & Machinery
G26: Capacity Utilisation
G27: 0.75
B28: Fabrication Type | C28: Yes/No | E28: Requirement (MT) | F28: Capacity (MT)/month | G28: Actual Production (MT)/month | H28: Requirement (Months) | I28: Total Equipment Cost for current requirement (INR)
A29: i | B29: Built-Up fabrication & Bits Shop | C29: =Input!C24 -> Yes | D29: q | E29: =Input!E24 -> 30488 | F29: 1500 | G29: =F29*$G$27 -> 1125 | H29: =IFERROR(IF(C29="Yes",E29/G29,""),"") -> 27.100444 | I29: =IFERROR(H29*H69*D38,"") -> 49966444
A30: ii | B30: Bridge & Girder fabrication | C30: =Input!C25 -> No | D30: q | E30: =Input!E25 -> 0 | F30: 1000 | G30: =F30*$G$27 -> 750 | H30: =IFERROR(IF(C30="Yes",E30/G30,""),"") | I30: =IFERROR(H30*H90*D38,"")
A31: iii | B31: Hot roll fabrication | C31: =Input!C26 -> Yes | D31: q | E31: =Input!E26 -> 7622 | F31: 750 | G31: =F31*$G$27 -> 562.5 | H31: =IFERROR(IF(C31="Yes",E31/G31,""),"") -> 13.550222 | I31: =IFERROR(H31*H112*D38,"") -> 15526296 | K31: Vendor Capacity/Plant Capacity | L31: Machinery Cost
A32: iv | B32: Blasting & Painting | C32: =Input!C27 -> Yes | D32: q | E32: =IFERROR(Input!E27*SUM(Input!E69:E71)/3,"") -> 38110 | F32: 1500 | G32: =F32*$G$27 -> 1125 | H32: =IFERROR(IF(C32="Yes",E32/G32,""),"") -> 33.875556 | I32: =IFERROR(H32*H125*D38,"") -> 9351064.8 | K32: 0.25 | L32: 1.1
A33: v | B33: Other Equipment | C33: Yes | D33: q | E33: =D8 -> 38110 | F33: =SUM(F29:F31) -> 3250 | G33: =F33*$G$27 -> 2437.5 | H33: =IFERROR(IF(C33="Yes",E33/G33,""),"") -> 15.634872 | I33: =IFERROR(H33*H134*D38,"") -> 14820556 | K33: 0.5 | L33: 1.066
H34: Total | I34: =SUM(I29:I33) -> 89664361 | K34: 0.75 | L34: 1.033
B35: Model - Plant Capacity | C35: MT/month | D35: =SUM(F29:F31) -> 3250 | K35: 0.9 | L35: 1
B36: Vendor - Plant Capacity | C36: MT/month | D36: 3250 | K36: 1 | L36: 1
B37: Vendor Capacity/Model Capacity | C37: % | D37: =D36/D35 -> 1 | K37: 1.1 | L37: 1
B38: Machinery cost impact due to vendor capacity | C38: % | D38: =IF($D$37<=K32,L32,IF($D$37<=K33,L33,IF($D$37<=K34,L34,IF($D$37<=K35,L35,IF($D$37<=K36,L36,IF($D$37<=K37,L37,IF($D$37<=K38,L38,IF($D$37<=K39,L39,L40)))))))) -> 1 | K38: 1.25 | L38: 0.9666
K39: 1.5 | L39: 0.93333
B40: Monthly Depreciation | C40: INR | D40: =H136 -> 4213541.7 | G40: Monthly Depreciation | H40: =100%/8/12 -> 0.010416667 | I40: of Purchase cost (Assuming 100% depreciation over 8 years) | K40: 1.75 | L40: 0.9
A42: 2.1 | B42: Fabrication Requirement: Built-Up fabrication & Bits Shop | D42: =$C$29 -> Yes
A44: =MAX($A$1:A41)+0.1 -> 2.1 | B44: Built-Up fabrication & Bits Shop , Bay No-1 | D44: Original No.s | E44: Updated No.s | F44: Rate | G44: Puchase Cost | H44: Monthly Rental | I44: Equipment Description | K44: Power Consumption
A45: i | B45: Material Handling | K45: Power rating | L45: PF | M45: Demand load | N45: Working hours (monthly) | O45: Usage hours | P45: Electricity Cost/month | Q45: Electricity Cost/MT | S45: Electricity Tariff | T45: HSD
B46: EOT Crane 10T | D46: 1 | E46: =D46 -> 1 | F46: 4000000 | G46: =IF($C$29="Yes",E46*F46,"") -> 4000000 | H46: =IFERROR(G46*$H$40,"") -> 41666.667 | I46: Electric Overhead Traveling Crane with a lifting capacity of 10 tons | K46: 3.6 | L46: 0.8 | M46: =E46*K46*L46 -> 2.88 | N46: =$D$11*$D$12 -> 500 | O46: 0.6 | P46: =M46*N46*O46*$S$46 -> 12096 | Q46: =P46/$G$29 -> 10.752 | S46: 14 | T46: 90
B47: EOT Crane 5T | D47: 4 | E47: =D47 -> 4 | F47: 2000000 | G47: =IF($C$29="Yes",E47*F47,"") -> 8000000 | H47: =IFERROR(G47*$H$40,"") -> 83333.333 | I47: Electric Overhead Traveling Crane with a lifting capacity of 5 tons | K47: 2.4 | L47: 0.8 | M47: =E47*K47*L47 -> 7.68 | N47: =$D$11*$D$12 -> 500 | O47: 0.6 | P47: =M47*N47*O47*$S$46 -> 32256 | Q47: =P47/$G$29 -> 28.672
A48: ii | B48: Cutting Equipment
B49: CNC Plasma Cutting Machine (Multi-Torch) | D49: 2 | E49: =D49 -> 2 | F49: 4000000 | G49: =IF($C$29="Yes",E49*F49,"") -> 8000000 | H49: =IFERROR(G49*$H$40,"") -> 83333.333 | I49: A CNC (Computer Numerical Control) machine that automates the cutting process. Equipped with multiple torches (Plasma or Oxy-Fuel) to cut several steel plates or sections at the same time. | K49: 12 | L49: 0.8 | M49: =E49*K49*L49 -> 19.2 | N49: =$D$11*$D$12 -> 500 | O49: 0.6 | P49: =M49*N49*O49*$S$46 -> 80640 | Q49: =P49/$G$29 -> 71.68
B50: Shearing Machine 6000 X 20 | D50: 1 | E50: =D50 -> 1 | F50: 20000000 | G50: =IF($C$29="Yes",E50*F50,"") -> 20000000 | H50: =IFERROR(G50*$H$40,"") -> 208333.33 | I50: A Shearing Machine 6000 X 20 is a metal cutting machine used to cut steel plates up to 6 meters (6000 mm) in length and 20 mm in thickness. | K50: 12 | L50: 0.8 | M50: =E50*K50*L50 -> 9.6 | N50: =$D$11*$D$12 -> 500 | O50: 0.6 | P50: =M50*N50*O50*$S$46 -> 40320 | Q50: =P50/$G$29 -> 35.84
...

Sheet >> Backups

Sheet Painting Inputs
C5: 24 Rs conversion - including wastage
C6: painting - 7.8 rs
C7: Transportation ODC 50% - | D7: 5.5
C13: Coating Name | D13: Layer | E13: Price per Litre (INR) | F13: Source URL
C14: Red Oxide Metal Primer | D14: 1 — Primer | E14: 135 | F14: https://m.indiamart.com/plasmacoating-products/metal-primer.html
C15: Red Oxide Zinc Chromate Primer | D15: 1 — Primer | E15: 175 | F15: https://m.indiamart.com/plasmacoating-products/metal-primer.html
C16: Epoxy Zinc Phosphate Primer (Jagdamba) | D16: 1 — Primer | E16: 180 | F16: https://m.indiamart.com/impcat/epoxy-primer-paint.html
C17: Apcodur HB ZP Primer (Asian Paints) | D17: 1 — Primer | E17: 220 | F17: https://m.indiamart.com/impcat/phosphate-primer.html
C18: Epoxy ZP Grey Primer (Plasma Paints) | D18: 1 — Primer | E18: 265 | F18: https://m.indiamart.com/plasmacoating-products/metal-primer.html
C19: Neropoxy HB MIO Primer Grey (Berger) | D19: 2 — Intermediate | E19: 215 | F19: https://m.indiamart.com/aimpolymers/epoxy-primer.html
C20: Epoxy Grey Primer HB (Plasma Paints) | D20: 2 — Intermediate | E20: 295 | F20: https://m.indiamart.com/plasmacoating-products/metal-primer.html
C21: PU Finish Paint (Alfa Paints) | D21: 3 — Final Coat | E21: 279 | F21: https://m.indiamart.com/impcat/phosphate-primer.html
C22: Nerothane PU Enamel (Berger) | D22: 3 — Final Coat | E22: 330 | F22: https://m.indiamart.com/aimpolymers/epoxy-primer.html
