Workbook
Name Armor: '[1]Ref - Data, Assumptions'!#REF!
Name Armor: 'Data Input'!#REF!
Name Armordensity: 'Data Input'!$J$2:$K$7
Name Armour: '[1]Ref - Data, Assumptions'!$H$12:$H$16
Name Armour: 'Data Input'!$J$3:$J$7
Name Conductor: 'Data Input'!$D$3:$D$4
Name Density: '[1]Ref - Data, Assumptions'!$H$3:$I$5
Name Density: 'Data Input'!$G$2:$H$4
Name Density1: '[1]Ref - Data, Assumptions'!$H$7:$I$9
Name Density1: 'Data Input'!$D$2:$E$4
Name Insulation: '[1]Ref - Data, Assumptions'!$H$4:$H$5
Name Insulation: 'Data Input'!$G$3:$G$4
Name Shape: '[1]Ref - Data, Assumptions'!$H$19:$H$20
Name Shape: 'Data Input'!$B$3:$B$4

Sheet Summary
J1: * Incl. wastage
A2: # | B2: Cable Type | C2: Wire Size | D2: Shape of the core | E2: Insulation Details | F2: Armoured / Unarmoured | G2: Conductor | H2: Spl. Construction | I2: Approx Net wt. (as per ppt) | J2: Approx Net wt. (as per cost sheet) | K2: Price as per cost sheet | L2: Baseline Price in INR/ KM | M2: Qty Required | N2: Total Spend in INR | O2: Cost Optimization Potential in INR | P2: % Benefit
A3: 1 | B3: LT Cable | C3: 1 x 300 mm2 | D3: Circular | E3: XLPE insl. | F3: Unarmoured | G3: Aluminium | H3: FRLS - inner, outer | I3: 1180 | J3: 1184.8826 | K3: ='Al LT Cables (1 x 300)'!M78 -> 165988.52 | L3: 242630 | M3: 4.32 | N3: =M3*L3 -> 1048161.6 | O3: =IF((L3-K3)*M3<0,0,(L3-K3)*M3) -> 331091.2 | P3: =(L3-K3)/L3 -> 0.31587801
A4: =A3+1 -> 2 | B4: LT Cable | C4: 1 x 630 mm2 | D4: Circular | E4: XLPE insl. | F4: Unarmoured | G4: Aluminium | H4: FRLS - inner, outer | I4: 2305 | J4: 2343.0609 | K4: ='Al LT Cables (1 x 630)'!M78 -> 334919.08 | L4: 434000 | M4: 79.906 | N4: =M4*L4 -> 34679204 | O4: =IF((L4-K4)*M4<0,0,(L4-K4)*M4) -> 7917160.3 | P4: =(L4-K4)/L4 -> 0.22829706
A5: =A4+1 -> 3 | B5: LT Cable | C5: 1 x 630 mm2 | D5: Circular | E5: XLPE insl. | F5: Unarmoured | G5: Copper | H5: FRLS - inner, outer | I5: 6195 | J5: 6392.1969 | K5: ='Cu LT Cables (1 x 630)'!M78 -> 2804390.3 | L5: 2521000 | M5: 2.56 | N5: =M5*L5 -> 6453760 | O5: =IF((L5-K5)*M5<0,0,(L5-K5)*M5) -> 0 | P5: =(L5-K5)/L5 -> -0.11241188
A6: =A5+1 -> 4 | B6: LT Cable | C6: 2 x 2.5 mm2 | D6: Sectoral - 180 Deg. | E6: XLPE insl. | F6: Unarmoured | G6: Copper | H6: FRLS - inner, outer | I6: 155 | J6: 154.46617 | K6: ='Cu LT Cables (2 x 2.5)'!M78 -> 32011.19 | L6: 35800 | M6: 189.315 | N6: =M6*L6 -> 6777477 | O6: =IF((L6-K6)*M6<0,0,(L6-K6)*M6) -> 717278.64 | P6: =(L6-K6)/L6 -> 0.10583269
A7: =A6+1 -> 5 | B7: LT Cable | C7: 2 x 6 mm2 | D7: Sectoral - 180 Deg. | E7: XLPE insl. | F7: Unarmoured | G7: Aluminium | H7: FRLS - inner, outer | I7: 175 | J7: 166.23762 | K7: ='Al LT Cables (2 x 6)'!M78 -> 17829.455 | L7: 28000 | M7: 102.994 | N7: =M7*L7 -> 2883832 | O7: =IF((L7-K7)*M7<0,0,(L7-K7)*M7) -> 1047505.1 | P7: =(L7-K7)/L7 -> 0.36323376
A8: =A7+1 -> 6 | B8: LT Cable | C8: 2 x 10mm2 | D8: Sectoral - 180 Deg. | E8: XLPE insl. | F8: Unarmoured | G8: Aluminium | H8: FRLS - inner, outer | I8: 215 | J8: 211.87899 | K8: ='Al LT Cables (2 x 10)'!M78 -> 23571.058 | L8: 34400 | M8: 13.164 | N8: =M8*L8 -> 452841.6 | O8: =IF((L8-K8)*M8<0,0,(L8-K8)*M8) -> 142552.19 | P8: =(L8-K8)/L8 -> 0.31479483
A9: =A8+1 -> 7 | B9: LT Cable | C9: 2 x 16 mm2 | D9: Sectoral - 180 Deg. | E9: XLPE insl. | F9: Unarmoured | G9: Aluminium | H9: FRLS - inner, outer | I9: 250 | J9: 241.62505 | K9: ='Al LT Cables (2 x 16)'!M78 -> 28616.015 | L9: 33400 | M9: 22.169 | N9: =M9*L9 -> 740444.6 | O9: =IF((L9-K9)*M9<0,0,(L9-K9)*M9) -> 106056.16 | P9: =(L9-K9)/L9 -> 0.14323309
A10: =A9+1 -> 8 | B10: LT Cable | C10: 2 x 25mm2 | D10: Sectoral - 180 Deg. | E10: XLPE insl. | F10: Unarmoured | G10: Aluminium | H10: FRLS - inner, outer | I10: 355 | J10: 351.8583 | K10: ='Al LT Cables (2 x 25)'!M78 -> 42397.259 | L10: 48800 | M10: 14.298 | N10: =M10*L10 -> 697742.4 | O10: =IF((L10-K10)*M10<0,0,(L10-K10)*M10) -> 91546.39 | P10: =(L10-K10)/L10 -> 0.13120371
A11: =A10+1 -> 9 | B11: LT Cable | C11: 2 x 35mm2 | D11: Sectoral - 180 Deg. | E11: XLPE insl. | F11: Unarmoured | G11: Aluminium | H11: FRLS - inner, outer | I11: 440 | J11: 430.6981 | K11: ='Al LT Cables (2 x 35)'!M78 -> 53453.124 | L11: 59800 | M11: 7.53 | N11: =M11*L11 -> 450294 | O11: =IF((L11-K11)*M11<0,0,(L11-K11)*M11) -> 47791.975 | P11: =(L11-K11)/L11 -> 0.10613505
A12: =A11+1 -> 10 | B12: LT Cable | C12: 2 x 50mm2 | D12: Sectoral - 180 Deg. | E12: XLPE insl. | F12: Unarmoured | G12: Aluminium | H12: FRLS - inner, outer | I12: 545 | J12: 553.665 | K12: ='Al LT Cables (2 x 50)'!M78 -> 70599.775 | L12: 74500 | M12: 11.288 | N12: =M12*L12 -> 840956 | O12: =IF((L12-K12)*M12<0,0,(L12-K12)*M12) -> 44025.737 | P12: =(L12-K12)/L12 -> 0.05235201
A13: =A12+1 -> 11 | B13: LT Cable | C13: 2 x 70mm2 | D13: Sectoral - 180 Deg. | E13: XLPE insl. | F13: Unarmoured | G13: Aluminium | H13: FRLS - inner, outer | I13: 710 | J13: 718.60097 | K13: ='Al LT Cables (2 x 70)'!M78 -> 93507.08 | L13: 97800 | M13: 7.623 | N13: =M13*L13 -> 745529.4 | O13: =IF((L13-K13)*M13<0,0,(L13-K13)*M13) -> 32724.928 | P13: =(L13-K13)/L13 -> 0.043894886
A14: =A13+1 -> 12 | B14: LT Cable | C14: 2 x 95mm2 | D14: Sectoral - 180 Deg. | E14: XLPE insl. | F14: Unarmoured | G14: Aluminium | H14: FRLS - inner, outer | I14: 930 | J14: 932.73387 | K14: ='Al LT Cables (2 x 95)'!M78 -> 122607.37 | L14: 130000 | M14: 23.557 | N14: =M14*L14 -> 3062410 | O14: =IF((L14-K14)*M14<0,0,(L14-K14)*M14) -> 174148.08 | P14: =(L14-K14)/L14 -> 0.056866349
A15: =A14+1 -> 13 | B15: LT Cable | C15: 2 x 120mm2 | D15: Sectoral - 180 Deg. | E15: XLPE insl. | F15: Unarmoured | G15: Aluminium | H15: FRLS - inner, outer | I15: 1110 | J15: 1126.7768 | K15: ='Al LT Cables (2 x 120)'!M78 -> 150083.06 | L15: 156600 | M15: 9.153 | N15: =M15*L15 -> 1433359.8 | O15: =IF((L15-K15)*M15<0,0,(L15-K15)*M15) -> 59649.59 | P15: =(L15-K15)/L15 -> 0.041615225
A16: =A15+1 -> 14 | B16: LT Cable | C16: 2 x 150mm2 | D16: Sectoral - 180 Deg. | E16: XLPE insl. | F16: Unarmoured | G16: Aluminium | H16: FRLS - inner, outer | I16: 1320 | J16: 1361.6583 | K16: ='Al LT Cables (2 x 150)'!M78 -> 183487.3 | L16: 186200 | M16: 10.702 | N16: =M16*L16 -> 1992712.4 | O16: =IF((L16-K16)*M16<0,0,(L16-K16)*M16) -> 29031.332 | P16: =(L16-K16)/L16 -> 0.014568752
A17: =A16+1 -> 15 | B17: LT Cable | C17: 2 x 240mm2 | D17: Sectoral - 180 Deg. | E17: XLPE insl. | F17: Unarmoured | G17: Aluminium | H17: FRLS - inner, outer | I17: 2085 | J17: 2130.1206 | K17: ='Al LT Cables (2 x 240)'!M78 -> 288894.39 | L17: 299200 | M17: 108 | N17: =M17*L17 -> 32313600 | O17: =IF((L17-K17)*M17<0,0,(L17-K17)*M17) -> 1113006.2 | P17: =(L17-K17)/L17 -> 0.034443892
A18: =A17+1 -> 16 | B18: LT Cable | C18: 3 x 6 mm2 | D18: Sectoral - 120 Deg. | E18: XLPE insl. | F18: Unarmoured | G18: Aluminium | H18: FRLS - inner, outer | I18: 210 | J18: 191.28924 | K18: ='Al LT Cables (3 x 6)'!M78 -> 21298.615 | L18: 32400 | M18: 256.995 | N18: =M18*L18 -> 8326638 | O18: =IF((L18-K18)*M18<0,0,(L18-K18)*M18) -> 2853000.4 | P18: =(L18-K18)/L18 -> 0.34263533
A19: =A18+1 -> 17 | B19: LT Cable | C19: 3 x 10mm2 | D19: Sectoral - 120 Deg. | E19: XLPE insl. | F19: Unarmoured | G19: Aluminium | H19: FRLS - inner, outer | I19: 260 | J19: 249.13709 | K19: ='Al LT Cables (3 x 10)'!M78 -> 28916.511 | L19: 40300 | M19: 65.575 | N19: =M19*L19 -> 2642672.5 | O19: =IF((L19-K19)*M19<0,0,(L19-K19)*M19) -> 746472.26 | P19: =(L19-K19)/L19 -> 0.2824687
A20: =A19+1 -> 18 | B20: LT Cable | C20: 3 x 16 mm2 | D20: Sectoral - 120 Deg. | E20: XLPE insl. | F20: Unarmoured | G20: Aluminium | H20: FRLS - inner, outer | I20: 335 | J20: 310.76971 | K20: ='Al LT Cables (3 x 16)'!M78 -> 38010.405 | L20: 45500 | M20: 131.51 | N20: =M20*L20 -> 5983705 | O20: =IF((L20-K20)*M20<0,0,(L20-K20)*M20) -> 984956.65 | P20: =(L20-K20)/L20 -> 0.16460649
A21: =A20+1 -> 19 | B21: LT Cable | C21: 3 x 25mm2 | D21: Sectoral - 120 Deg. | E21: XLPE insl. | F21: Unarmoured | G21: Aluminium | H21: FRLS - inner, outer | I21: 480 | J21: 451.49487 | K21: ='Al LT Cables (3 x 25)'!M78 -> 56313.017 | L21: 64800 | M21: 68.205 | N21: =M21*L21 -> 4419684 | O21: =IF((L21-K21)*M21<0,0,(L21-K21)*M21) -> 578854.66 | P21: =(L21-K21)/L21 -> 0.13097196
A22: =A21+1 -> 20 | B22: LT Cable | C22: 3 x 35mm2 | D22: Sectoral - 120 Deg. | E22: XLPE insl. | F22: Unarmoured | G22: Aluminium | H22: FRLS - inner, outer | I22: 600 | J22: 565.0229 | K22: ='Al LT Cables (3 x 35)'!M78 -> 72424.098 | L22: 80300 | M22: 68.78 | N22: =M22*L22 -> 5523034 | O22: =IF((L22-K22)*M22<0,0,(L22-K22)*M22) -> 541704.51 | P22: =(L22-K22)/L22 -> 0.098080965
A23: =A22+1 -> 21 | B23: LT Cable | C23: 3 x 50mm2 | D23: Sectoral - 120 Deg. | E23: XLPE insl. | F23: Unarmoured | G23: Aluminium | H23: FRLS - inner, outer | I23: 750 | J23: 738.59002 | K23: ='Al LT Cables (3 x 50)'!M78 -> 97042.99 | L23: 101400 | M23: 22.275 | N23: =M23*L23 -> 2258685 | O23: =IF((L23-K23)*M23<0,0,(L23-K23)*M23) -> 97052.389 | P23: =(L23-K23)/L23 -> 0.042968537
A24: =A23+1 -> 22 | B24: LT Cable | C24: 3 x 70mm2 | D24: Sectoral - 120 Deg. | E24: XLPE insl. | F24: Unarmoured | G24: Aluminium | H24: FRLS - inner, outer | I24: 1030 | J24: 1005.1718 | K24: ='Al LT Cables (3 x 70)'!M78 -> 133029.47 | L24: 141400 | M24: 62.73 | N24: =M24*L24 -> 8870022 | O24: =IF((L24-K24)*M24<0,0,(L24-K24)*M24) -> 525083.65 | P24: =(L24-K24)/L24 -> 0.059197559
A25: =A24+1 -> 23 | B25: LT Cable | C25: 3 x 95mm2 | D25: Sectoral - 120 Deg. | E25: XLPE insl. | F25: Unarmoured | G25: Aluminium | H25: FRLS - inner, outer | I25: 1290 | J25: 1260.4529 | K25: ='Al LT Cables (3 x 95)'!M78 -> 170580.76 | L25: 179000 | M25: 28.65 | N25: =M25*L25 -> 5128350 | O25: =IF((L25-K25)*M25<0,0,(L25-K25)*M25) -> 241211.34 | P25: =(L25-K25)/L25 -> 0.047034883
A26: =A25+1 -> 24 | B26: LT Cable | C26: 3 x 120mm2 | D26: Sectoral - 120 Deg. | E26: XLPE insl. | F26: Unarmoured | G26: Aluminium | H26: FRLS - inner, outer | I26: 1560 | J26: 1535.0456 | K26: ='Al LT Cables (3 x 120)'!M78 -> 210144.91 | L26: 218700 | M26: 37.8 | N26: =M26*L26 -> 8266860 | O26: =IF((L26-K26)*M26<0,0,(L26-K26)*M26) -> 323382.34 | P26: =(L26-K26)/L26 -> 0.039117916
A27: =A26+1 -> 25 | B27: LT Cable | C27: 3 x 150mm2 | D27: Sectoral - 120 Deg. | E27: XLPE insl. | F27: Unarmoured | G27: Aluminium | H27: FRLS - inner, outer | I27: 1920 | J27: 1928.079 | K27: ='Al LT Cables (3 x 150)'!M78 -> 263719.35 | L27: 271300 | M27: 35.86 | N27: =M27*L27 -> 9728818 | O27: =IF((L27-K27)*M27<0,0,(L27-K27)*M27) -> 271842.02 | P27: =(L27-K27)/L27 -> 0.027941937
A28: =A27+1 -> 26 | B28: LT Cable | C28: 3 x 240mm2 | D28: Sectoral - 120 Deg. | E28: XLPE insl. | F28: Unarmoured | G28: Aluminium | H28: FRLS - inner, outer | I28: 3025 | J28: 3011.9108 | K28: ='Al LT Cables (3 x 240)'!M78 -> 414984.13 | L28: 437000 | M28: 223.285 | N28: =M28*L28 -> 97575545 | O28: =IF((L28-K28)*M28<0,0,(L28-K28)*M28) -> 4915813 | P28: =(L28-K28)/L28 -> 0.05037956
A29: =A28+1 -> 27 | B29: LT Cable | C29: 4 x 6 mm2 | D29: Sectoral - 90 Deg. | E29: XLPE insl. | F29: Unarmoured | G29: Aluminium | H29: FRLS - inner, outer | I29: 250 | J29: 225.04329 | K29: ='Al LT Cables (4 x 6)'!M78 -> 25552.473 | L29: 37600 | M29: 171.55 | N29: =M29*L29 -> 6450280 | O29: =IF((L29-K29)*M29<0,0,(L29-K29)*M29) -> 2066753.2 | P29: =(L29-K29)/L29 -> 0.32041295
A30: =A29+1 -> 28 | B30: LT Cable | C30: 4 x 10mm2 | D30: Sectoral - 90 Deg. | E30: XLPE insl. | F30: Unarmoured | G30: Aluminium | H30: FRLS - inner, outer | I30: 315 | J30: 294.93159 | K30: ='Al LT Cables (4 x 10)'!M78 -> 35028.366 | L30: 48600 | M30: 1.87 | N30: =M30*L30 -> 90882 | O30: =IF((L30-K30)*M30<0,0,(L30-K30)*M30) -> 25378.955 | P30: =(L30-K30)/L30 -> 0.27925172
A31: =A30+1 -> 29 | B31: LT Cable | C31: 4 x 16 mm2 | D31: Sectoral - 90 Deg. | E31: XLPE insl. | F31: Unarmoured | G31: Aluminium | H31: FRLS - inner, outer | I31: 410 | J31: 378.96671 | K31: ='Al LT Cables (4 x 16)'!M78 -> 47300.667 | L31: 55700 | M31: 9.525 | N31: =M31*L31 -> 530542.5 | O31: =IF((L31-K31)*M31<0,0,(L31-K31)*M31) -> 80003.648 | P31: =(L31-K31)/L31 -> 0.15079593
N32: =SUM(N3:N31) -> 2.6036804e+08 | O32: =SUM(O3:O31) -> 26105077 | P32: =O32/N32 -> 0.10026222

Sheet Data Input
B2: Shape | D2: Conductor | E2: Density | G2: Insulation | H2: Density | J2: Armour | K2: Density | M2: Commodity | N2: Landed | O2: UoM | P2: Price as on | Q2: Remarks / Source
B3: Sector shaped | D3: Copper | E3: 8.94 | G3: XLPE | H3: 0.93 | J3: Galvanised steel round wire | K3: 7.86 | M3: Aluminium | N3: =123*1.05 -> 129.15 | O3: Rs/Kg. | P3: Jun'17 | Q3: MCX
B4: Circular | D4: Aluminium | E4: 2.7 | G4: PVC | H4: 1.35 | J4: Galvanised steel flat strip | K4: 7.86 | M4: Copper | N4: =368.558*1.05 -> 386.9859 | O4: Rs/Kg. | P4: Jun'17 | Q4: MCX
J5: Aluminium Flat Strip | K5: 2.7 | M5: PVC | N5: =71.5*1.05 -> 75.075 | O5: Rs/Kg. | P5: Jun'17 | Q5: Plasetmart
J6: Unarmored | K6: 0 | M6: Steel Wire | N6: =40*1.05 -> 42 | O6: Rs/Kg. | P6: Jun'17 | Q6: meps / other
J7: Aluminium Round Wired | K7: 2.7

Sheet Commodities
C3: Aluminum | D3: https://www.indexmundi.com/commodities/?commodity=aluminum&months=60&currency=inr
C44: Copper | D44: https://www.indexmundi.com/commodities/?commodity=copper&months=120&currency=inr

Sheet Al LT Cables (1 x 300)
B2: ="Cost Sheet for"&" "&C6&" Core"&" "&C9&" sq.mm"&" "&C10&" Cable" -> Cost Sheet for 1 Core 300 sq.mm Aluminium Cable
B4: Data Inputs
B6: No. of cores | C6: 1
B7: Shape of the core | C7: Circular
B8: Conductor
B9: Conductor Size (in sq. mm) | C9: 300 | D9: sq. mm
B10: Conductor Material | C10: Aluminium | L10: =2*L9 -> 0
B11: Angle - Main | C11: =IF(C7="Sector shaped", (360/C6),360) -> 360
B12: Angle - Main | C12: =IF(C7="Sector shaped",360-C11*3,0) -> 0
B13: Conductor Radius | C13: =SQRT((C9*(360/C11))/PI()) -> 9.7720502 | D13: mm
B14: Density of Conductor | C14: =VLOOKUP(C10,Density1,2,0) -> 2.7 | D14: g/cm3
B16: Insulation
B17: Material | C17: XLPE
B18: Nominal thickness of insulation | C18: 1.8
B19: Calculated radius over insulation | C19: =IF(C7="Circular", C13+C18,C13+2*C18) -> 11.57205 | D19: mm
B20: Density of Conductor | C20: =VLOOKUP(C17,Density,2,0) -> 0.93 | D20: g/cm3
B22: PVC Filler
B23: Filler Type | C23: PVC
B24: Area below inner sheath | C24: =PI()*((C31/2)^2) -> 471.43525 | D24: mm2
B25: Area till insulation | C25: =IF(C6=3.5,((C11/360)*PI()*(C19^2)*3)+((C12/360)*PI()*(C19^2)),(C11/360)*PI()*(C19^2)*C6) -> 420.69804 | D25: mm2
B26: Density | C26: =VLOOKUP(C23,Density,2,0) -> 1.35 | D26: g/cm3
B28: Inner Sheath
B29: Material | C29: PVC
B30: Minimum Thickness | C30: 0 | D30: mm
B31: Calculated diameter below innersheath | C31: =C37-2*C30 -> 24.5 | D31: mm
B32: Density of Conductor | C32: =VLOOKUP(C29,Density,2,0) -> 1.35 | D32: g/cm3
B34: Armour
B35: Material | C35: Unarmored
B36: Thickness of armour | C36: 0 | D36: mm
B37: Calculated diameter below armor | C37: =C43-2*C36 -> 24.5 | D37: mm
B38: Density of Conductor | C38: =VLOOKUP(C35,Armordensity,2,0) -> 0 | D38: g/cm3
B40: Outer Sheath
B41: Material | C41: PVC
B42: Minimum Thickness | C42: 2 | D42: mm
B43: Calculated diameter below outersheath | C43: =C46-(2*C42) -> 24.5 | D43: mm
B44: Density of Conductor | C44: =VLOOKUP(C41,Density,2,0) -> 1.35 | D44: g/cm3
B46: Overall OD of Cable | C46: 28.5
A48: ="COST SHEET FOR "&C6 & " CORE "&C9&" SQMM "&C10&" CABLE" -> COST SHEET FOR 1 CORE 300 SQMM Aluminium CABLE
A50: ASSUMPTIONS | G50: CALCULATION - SCENARIO 1
B52: Wastage Assumptions | H52: Material Cost Estimation | J52: Loading | K52: %
...

Sheet Al LT Cables (1 x 630)
B2: ="Cost Sheet for"&" "&C6&" Core"&" "&C9&" sq.mm"&" "&C10&" Cable" -> Cost Sheet for 1 Core 630 sq.mm Aluminium Cable
B4: Data Inputs
B6: No. of cores | C6: 1
B7: Shape of the core | C7: Circular
B8: Conductor
B9: Conductor Size (in sq. mm) | C9: 630 | D9: sq. mm
B10: Conductor Material | C10: Aluminium | L10: =2*L9 -> 0
B11: Angle - Main | C11: =IF(C7="Sector shaped", (360/C6),360) -> 360
B12: Angle - Main | C12: =IF(C7="Sector shaped",360-C11*3,0) -> 0
B13: Conductor Radius | C13: =SQRT((C9*(360/C11))/PI()) -> 14.161046 | D13: mm
B14: Density of Conductor | C14: =VLOOKUP(C10,Density1,2,0) -> 2.7 | D14: g/cm3
B16: Insulation
B17: Material | C17: XLPE
B18: Nominal thickness of insulation | C18: 2.4
B19: Calculated radius over insulation | C19: =IF(C7="Circular", C13+C18,C13+2*C18) -> 16.561046 | D19: mm
B20: Density of Conductor | C20: =VLOOKUP(C17,Density,2,0) -> 0.93 | D20: g/cm3
B22: PVC Filler
B23: Filler Type | C23: PVC
B24: Area below inner sheath | C24: =PI()*((C31/2)^2) -> 995.38222 | D24: mm2
B25: Area till insulation | C25: =IF(C6=3.5,((C11/360)*PI()*(C19^2)*3)+((C12/360)*PI()*(C19^2)),(C11/360)*PI()*(C19^2)*C6) -> 861.63912 | D25: mm2
B26: Density | C26: =VLOOKUP(C23,Density,2,0) -> 1.35 | D26: g/cm3
B28: Inner Sheath
B29: Material | C29: PVC
B30: Minimum Thickness | C30: 0 | D30: mm
B31: Calculated diameter below innersheath | C31: =C37-2*C30 -> 35.6 | D31: mm
B32: Density of Conductor | C32: =VLOOKUP(C29,Density,2,0) -> 1.35 | D32: g/cm3
B34: Armour
B35: Material | C35: Unarmored
B36: Thickness of armour | C36: 0 | D36: mm
B37: Calculated diameter below armor | C37: =C43-2*C36 -> 35.6 | D37: mm
B38: Density of Conductor | C38: =VLOOKUP(C35,Armordensity,2,0) -> 0 | D38: g/cm3
B40: Outer Sheath
B41: Material | C41: PVC
B42: Minimum Thickness | C42: 2.2 | D42: mm
B43: Calculated diameter below outersheath | C43: =C46-(2*C42) -> 35.6 | D43: mm
B44: Density of Conductor | C44: =VLOOKUP(C41,Density,2,0) -> 1.35 | D44: g/cm3
B46: Overall OD of Cable | C46: 40
A48: ="COST SHEET FOR "&C6 & " CORE "&C9&" SQMM "&C10&" CABLE" -> COST SHEET FOR 1 CORE 630 SQMM Aluminium CABLE
A50: ASSUMPTIONS | G50: CALCULATION - SCENARIO 1
B52: Wastage Assumptions | H52: Material Cost Estimation | J52: Loading | K52: %
...

Sheet Cu LT Cables (1 x 630)
B1: =#REF! -> #REF! | C1: =SUM(D67:D72) -> 6327.3504
B2: ="Cost Sheet for"&" "&C6&" Core"&" "&C9&" sq.mm"&" "&C10&" Cable" -> Cost Sheet for 1 Core 630 sq.mm Copper Cable
B4: Data Inputs
B6: No. of cores | C6: 1
B7: Shape of the core | C7: Circular
B8: Conductor
B9: Conductor Size (in sq. mm) | C9: 630 | D9: sq. mm
B10: Conductor Material | C10: Copper
B11: Angle - Main | C11: =IF(C7="Sector shaped", (360/C6),360) -> 360
B12: Angle - Main | C12: =IF(C7="Sector shaped",360-C11*3,0) -> 0
B13: Conductor Radius | C13: =SQRT((C9*(360/C11))/PI()) -> 14.161046 | D13: mm
B14: Density of Conductor | C14: =VLOOKUP(C10,Density1,2,0) -> 8.94 | D14: g/cm3
B16: Insulation
B17: Material | C17: XLPE
B18: Nominal thickness of insulation | C18: 2.4
B19: Calculated radius over insulation | C19: =IF(C7="Circular", C13+C18,C13+2*C18) -> 16.561046 | D19: mm
B20: Density of Conductor | C20: =VLOOKUP(C17,Density,2,0) -> 0.93 | D20: g/cm3
B22: PVC Filler
B23: Filler Type | C23: PVC
B24: Area below inner sheath | C24: =PI()*((C31/2)^2) -> 995.38222 | D24: mm2
B25: Area till insulation | C25: =IF(C6=3.5,((C11/360)*PI()*(C19^2)*3)+((C12/360)*PI()*(C19^2)),(C11/360)*PI()*(C19^2)*C6) -> 861.63912 | D25: mm2
B26: Density | C26: =VLOOKUP(C23,Density,2,0) -> 1.35 | D26: g/cm3
B28: Inner Sheath
B29: Material | C29: PVC
B30: Minimum Thickness | C30: 0 | D30: mm
B31: Calculated diameter below innersheath | C31: =C37-2*C30 -> 35.6 | D31: mm
B32: Density of Conductor | C32: =VLOOKUP(C29,Density,2,0) -> 1.35 | D32: g/cm3
B34: Armour
B35: Material | C35: Unarmored
B36: Thickness of armour | C36: 0 | D36: mm
B37: Calculated diameter below armor | C37: =C43-2*C36 -> 35.6 | D37: mm
B38: Density of Conductor | C38: =VLOOKUP(C35,Armordensity,2,0) -> 0 | D38: g/cm3
B40: Outer Sheath
B41: Material | C41: PVC
B42: Minimum Thickness | C42: 2.2 | D42: mm
B43: Calculated diameter below outersheath | C43: =C46-(2*C42) -> 35.6 | D43: mm
B44: Density of Conductor | C44: =VLOOKUP(C41,Density,2,0) -> 1.35 | D44: g/cm3
B46: Overall OD of Cable | C46: 40
A48: ="COST SHEET FOR "&C6 & " CORE "&C9&" SQMM "&C10&" CABLE" -> COST SHEET FOR 1 CORE 630 SQMM Copper CABLE
A50: ASSUMPTIONS | G50: CALCULATION - SCENARIO 1
...

Sheet Cu LT Cables (2 x 2.5)
B1: =#REF! -> #REF! | C1: =SUM(D67:D72) -> 152.45535
B2: ="Cost Sheet for"&" "&C6&" Core"&" "&C9&" sq.mm"&" "&C10&" Cable" -> Cost Sheet for 2 Core 2.5 sq.mm Copper Cable
B4: Data Inputs
B6: No. of cores | C6: 2
B7: Shape of the core | C7: Sector shaped
B8: Conductor
B9: Conductor Size (in sq. mm) | C9: 2.5 | D9: sq. mm
B10: Conductor Material | C10: Copper
B11: Angle - Main | C11: =IF(C7="Sector shaped", (360/C6),360) -> 180
B12: Angle - Main | C12: =IF(C7="Sector shaped",360-C11*3,0) -> -180
B13: Conductor Radius | C13: =SQRT((C9*(360/C11))/PI()) -> 1.2615663 | D13: mm
B14: Density of Conductor | C14: =VLOOKUP(C10,Density1,2,0) -> 8.94 | D14: g/cm3
B16: Insulation
B17: Material | C17: XLPE
B18: Nominal thickness of insulation | C18: 0.7
B19: Calculated radius over insulation | C19: =IF(C7="Circular", C13+C18,C13+2*C18) -> 2.6615663 | D19: mm
B20: Density of Conductor | C20: =VLOOKUP(C17,Density,2,0) -> 0.93 | D20: g/cm3
B22: PVC Filler
B23: Filler Type | C23: PVC
B24: Area below inner sheath | C24: =PI()*((C31/2)^2) -> 47.783624 | D24: mm2
B25: Area till insulation | C25: =IF(C6=3.5,((C11/360)*PI()*(C19^2)*3)+((C12/360)*PI()*(C19^2)),(C11/360)*PI()*(C19^2)*C6) -> 22.254838 | D25: mm2
B26: Density | C26: =VLOOKUP(C23,Density,2,0) -> 1.35 | D26: g/cm3
B28: Inner Sheath
B29: Material | C29: PVC
B30: Minimum Thickness | C30: 0.3 | D30: mm
B31: Calculated diameter below innersheath | C31: =C37-2*C30 -> 7.8 | D31: mm
B32: Density of Conductor | C32: =VLOOKUP(C29,Density,2,0) -> 1.35 | D32: g/cm3
B34: Armour
B35: Material | C35: Unarmored
B36: Thickness of armour | C36: 0 | D36: mm
B37: Calculated diameter below armor | C37: =C43-2*C36 -> 8.4 | D37: mm
B38: Density of Conductor | C38: =VLOOKUP(C35,Armordensity,2,0) -> 0 | D38: g/cm3
B40: Outer Sheath
B41: Material | C41: PVC
B42: Minimum Thickness | C42: 1.8 | D42: mm
B43: Calculated diameter below outersheath | C43: =C46-(2*C42) -> 8.4 | D43: mm
B44: Density of Conductor | C44: =VLOOKUP(C41,Density,2,0) -> 1.35 | D44: g/cm3
B46: Overall OD of Cable | C46: 12
A48: ="COST SHEET FOR "&C6 & " CORE "&C9&" SQMM "&C10&" CABLE" -> COST SHEET FOR 2 CORE 2.5 SQMM Copper CABLE
A50: ASSUMPTIONS | G50: CALCULATION - SCENARIO 1
...

Sheet Al LT Cables (2 x 6)
B1: =#REF! -> #REF! | C1: =SUM(D67:D72) -> 163.99729
B2: ="Cost Sheet for"&" "&C6&" Core"&" "&C9&" sq.mm"&" "&C10&" Cable" -> Cost Sheet for 2 Core 6 sq.mm Aluminium Cable
B4: Data Inputs
B6: No. of cores | C6: 2
B7: Shape of the core | C7: Sector shaped
B8: Conductor
B9: Conductor Size (in sq. mm) | C9: 6 | D9: sq. mm
B10: Conductor Material | C10: Aluminium | L10: =2*L9 -> 0
B11: Angle - Main | C11: =IF(C7="Sector shaped", (360/C6),360) -> 180
B12: Angle - Main | C12: =IF(C7="Sector shaped",360-C11*3,0) -> -180
B13: Conductor Radius | C13: =SQRT((C9*(360/C11))/PI()) -> 1.95441 | D13: mm
B14: Density of Conductor | C14: =VLOOKUP(C10,Density1,2,0) -> 2.7 | D14: g/cm3
B16: Insulation
B17: Material | C17: XLPE
B18: Nominal thickness of insulation | C18: 0.7
B19: Calculated radius over insulation | C19: =IF(C7="Circular", C13+C18,C13+2*C18) -> 3.35441 | D19: mm
B20: Density of Conductor | C20: =VLOOKUP(C17,Density,2,0) -> 0.93 | D20: g/cm3
B22: PVC Filler
B23: Filler Type | C23: PVC
B24: Area below inner sheath | C24: =PI()*((C31/2)^2) -> 75.42964 | D24: mm2
B25: Area till insulation | C25: =IF(C6=3.5,((C11/360)*PI()*(C19^2)*3)+((C12/360)*PI()*(C19^2)),(C11/360)*PI()*(C19^2)*C6) -> 35.34941 | D25: mm2
B26: Density | C26: =VLOOKUP(C23,Density,2,0) -> 1.35 | D26: g/cm3
B28: Inner Sheath
B29: Material | C29: PVC
B30: Minimum Thickness | C30: 0.3 | D30: mm
B31: Calculated diameter below innersheath | C31: =C37-2*C30 -> 9.8 | D31: mm
B32: Density of Conductor | C32: =VLOOKUP(C29,Density,2,0) -> 1.35 | D32: g/cm3
B34: Armour
B35: Material | C35: Unarmored
B36: Thickness of armour | C36: 0 | D36: mm
B37: Calculated diameter below armor | C37: =C43-2*C36 -> 10.4 | D37: mm
B38: Density of Conductor | C38: =VLOOKUP(C35,Armordensity,2,0) -> 0 | D38: g/cm3
B40: Outer Sheath
B41: Material | C41: PVC
B42: Minimum Thickness | C42: 1.8 | D42: mm
B43: Calculated diameter below outersheath | C43: =C46-(2*C42) -> 10.4 | D43: mm
B44: Density of Conductor | C44: =VLOOKUP(C41,Density,2,0) -> 1.35 | D44: g/cm3
B46: Overall OD of Cable | C46: 14
A48: ="COST SHEET FOR "&C6 & " CORE "&C9&" SQMM "&C10&" CABLE" -> COST SHEET FOR 2 CORE 6 SQMM Aluminium CABLE
A50: ASSUMPTIONS | G50: CALCULATION - SCENARIO 1
...

Sheet Al LT Cables (2 x 10)
B1: =#REF! -> #REF! | C1: =SUM(D67:D72) -> 209.08526
B2: ="Cost Sheet for"&" "&C6&" Core"&" "&C9&" sq.mm"&" "&C10&" Cable" -> Cost Sheet for 2 Core 10 sq.mm Aluminium Cable
B4: Data Inputs
B6: No. of cores | C6: 2
B7: Shape of the core | C7: Sector shaped
B8: Conductor
B9: Conductor Size (in sq. mm) | C9: 10 | D9: sq. mm
B10: Conductor Material | C10: Aluminium | L10: =2*L9 -> 0
B11: Angle - Main | C11: =IF(C7="Sector shaped", (360/C6),360) -> 180
B12: Angle - Main | C12: =IF(C7="Sector shaped",360-C11*3,0) -> -180
B13: Conductor Radius | C13: =SQRT((C9*(360/C11))/PI()) -> 2.5231325 | D13: mm
B14: Density of Conductor | C14: =VLOOKUP(C10,Density1,2,0) -> 2.7 | D14: g/cm3
B16: Insulation
B17: Material | C17: XLPE
B18: Nominal thickness of insulation | C18: 0.7
B19: Calculated radius over insulation | C19: =IF(C7="Circular", C13+C18,C13+2*C18) -> 3.9231325 | D19: mm
B20: Density of Conductor | C20: =VLOOKUP(C17,Density,2,0) -> 0.93 | D20: g/cm3
B22: PVC Filler
B23: Filler Type | C23: PVC
B24: Area below inner sheath | C24: =PI()*((C31/2)^2) -> 109.35884 | D24: mm2
B25: Area till insulation | C25: =IF(C6=3.5,((C11/360)*PI()*(C19^2)*3)+((C12/360)*PI()*(C19^2)),(C11/360)*PI()*(C19^2)*C6) -> 48.352154 | D25: mm2
B26: Density | C26: =VLOOKUP(C23,Density,2,0) -> 1.35 | D26: g/cm3
B28: Inner Sheath
B29: Material | C29: PVC
B30: Minimum Thickness | C30: 0.3 | D30: mm
B31: Calculated diameter below innersheath | C31: =C37-2*C30 -> 11.8 | D31: mm
B32: Density of Conductor | C32: =VLOOKUP(C29,Density,2,0) -> 1.35 | D32: g/cm3
B34: Armour
B35: Material | C35: Unarmored
B36: Thickness of armour | C36: 0 | D36: mm
B37: Calculated diameter below armor | C37: =C43-2*C36 -> 12.4 | D37: mm
B38: Density of Conductor | C38: =VLOOKUP(C35,Armordensity,2,0) -> 0 | D38: g/cm3
B40: Outer Sheath
B41: Material | C41: PVC
B42: Minimum Thickness | C42: 1.8 | D42: mm
B43: Calculated diameter below outersheath | C43: =C46-(2*C42) -> 12.4 | D43: mm
B44: Density of Conductor | C44: =VLOOKUP(C41,Density,2,0) -> 1.35 | D44: g/cm3
B46: Overall OD of Cable | C46: 16
A48: ="COST SHEET FOR "&C6 & " CORE "&C9&" SQMM "&C10&" CABLE" -> COST SHEET FOR 2 CORE 10 SQMM Aluminium CABLE
A50: ASSUMPTIONS | G50: CALCULATION - SCENARIO 1
...

Sheet Al LT Cables (2 x 16)
B1: =#REF! -> #REF! | C1: =SUM(D67:D72) -> 238.55961
B2: ="Cost Sheet for"&" "&C6&" Core"&" "&C9&" sq.mm"&" "&C10&" Cable" -> Cost Sheet for 2 Core 16 sq.mm Aluminium Cable
B4: Data Inputs
B6: No. of cores | C6: 2
B7: Shape of the core | C7: Sector shaped
B8: Conductor
B9: Conductor Size (in sq. mm) | C9: 16 | D9: sq. mm
B10: Conductor Material | C10: Aluminium | L10: =2*L9 -> 0
B11: Angle - Main | C11: =IF(C7="Sector shaped", (360/C6),360) -> 180
B12: Angle - Main | C12: =IF(C7="Sector shaped",360-C11*3,0) -> -180
B13: Conductor Radius | C13: =SQRT((C9*(360/C11))/PI()) -> 3.1915382 | D13: mm
B14: Density of Conductor | C14: =VLOOKUP(C10,Density1,2,0) -> 2.7 | D14: g/cm3
B16: Insulation
B17: Material | C17: XLPE
B18: Nominal thickness of insulation | C18: 0.7
B19: Calculated radius over insulation | C19: =IF(C7="Circular", C13+C18,C13+2*C18) -> 4.5915382 | D19: mm
B20: Density of Conductor | C20: =VLOOKUP(C17,Density,2,0) -> 0.93 | D20: g/cm3
B22: PVC Filler
B23: Filler Type | C23: PVC
B24: Area below inner sheath | C24: =PI()*((C31/2)^2) -> 91.608842 | D24: mm2
B25: Area till insulation | C25: =IF(C6=3.5,((C11/360)*PI()*(C19^2)*3)+((C12/360)*PI()*(C19^2)),(C11/360)*PI()*(C19^2)*C6) -> 66.231758 | D25: mm2
B26: Density | C26: =VLOOKUP(C23,Density,2,0) -> 1.35 | D26: g/cm3
B28: Inner Sheath
B29: Material | C29: PVC
B30: Minimum Thickness | C30: 0.3 | D30: mm
B31: Calculated diameter below innersheath | C31: =C37-2*C30 -> 10.8 | D31: mm
B32: Density of Conductor | C32: =VLOOKUP(C29,Density,2,0) -> 1.35 | D32: g/cm3
B34: Armour
B35: Material | C35: Unarmored
B36: Thickness of armour | C36: 0 | D36: mm
B37: Calculated diameter below armor | C37: =C43-2*C36 -> 11.4 | D37: mm
B38: Density of Conductor | C38: =VLOOKUP(C35,Armordensity,2,0) -> 0 | D38: g/cm3
B40: Outer Sheath
B41: Material | C41: PVC
B42: Minimum Thickness | C42: 1.8 | D42: mm
B43: Calculated diameter below outersheath | C43: =C46-(2*C42) -> 11.4 | D43: mm
B44: Density of Conductor | C44: =VLOOKUP(C41,Density,2,0) -> 1.35 | D44: g/cm3
B46: Overall OD of Cable | C46: 15
A48: ="COST SHEET FOR "&C6 & " CORE "&C9&" SQMM "&C10&" CABLE" -> COST SHEET FOR 2 CORE 16 SQMM Aluminium CABLE
A50: ASSUMPTIONS | G50: CALCULATION - SCENARIO 1
...

Sheet Al LT Cables (2 x 25)
B1: =#REF! -> #REF! | C1: =SUM(D67:D72) -> 347.43895
B2: ="Cost Sheet for"&" "&C6&" Core"&" "&C9&" sq.mm"&" "&C10&" Cable" -> Cost Sheet for 2 Core 25 sq.mm Aluminium Cable
B4: Data Inputs
B6: No. of cores | C6: 2
B7: Shape of the core | C7: Sector shaped
B8: Conductor
B9: Conductor Size (in sq. mm) | C9: 25 | D9: sq. mm
B10: Conductor Material | C10: Aluminium | L10: =2*L9 -> 0
B11: Angle - Main | C11: =IF(C7="Sector shaped", (360/C6),360) -> 180
B12: Angle - Main | C12: =IF(C7="Sector shaped",360-C11*3,0) -> -180
B13: Conductor Radius | C13: =SQRT((C9*(360/C11))/PI()) -> 3.9894228 | D13: mm
B14: Density of Conductor | C14: =VLOOKUP(C10,Density1,2,0) -> 2.7 | D14: g/cm3
B16: Insulation
B17: Material | C17: XLPE
B18: Nominal thickness of insulation | C18: 0.9
B19: Calculated radius over insulation | C19: =IF(C7="Circular", C13+C18,C13+2*C18) -> 5.7894228 | D19: mm
B20: Density of Conductor | C20: =VLOOKUP(C17,Density,2,0) -> 0.93 | D20: g/cm3
B22: PVC Filler
B23: Filler Type | C23: PVC
B24: Area below inner sheath | C24: =PI()*((C31/2)^2) -> 141.02609 | D24: mm2
B25: Area till insulation | C25: =IF(C6=3.5,((C11/360)*PI()*(C19^2)*3)+((C12/360)*PI()*(C19^2)),(C11/360)*PI()*(C19^2)*C6) -> 105.29807 | D25: mm2
B26: Density | C26: =VLOOKUP(C23,Density,2,0) -> 1.35 | D26: g/cm3
B28: Inner Sheath
B29: Material | C29: PVC
B30: Minimum Thickness | C30: 0.3 | D30: mm
B31: Calculated diameter below innersheath | C31: =C37-2*C30 -> 13.4 | D31: mm
B32: Density of Conductor | C32: =VLOOKUP(C29,Density,2,0) -> 1.35 | D32: g/cm3
B34: Armour
B35: Material | C35: Unarmored
B36: Thickness of armour | C36: 0 | D36: mm
B37: Calculated diameter below armor | C37: =C43-2*C36 -> 14 | D37: mm
B38: Density of Conductor | C38: =VLOOKUP(C35,Armordensity,2,0) -> 0 | D38: g/cm3
B40: Outer Sheath
B41: Material | C41: PVC
B42: Minimum Thickness | C42: 2 | D42: mm
B43: Calculated diameter below outersheath | C43: =C46-(2*C42) -> 14 | D43: mm
B44: Density of Conductor | C44: =VLOOKUP(C41,Density,2,0) -> 1.35 | D44: g/cm3
B46: Overall OD of Cable | C46: 18
A48: ="COST SHEET FOR "&C6 & " CORE "&C9&" SQMM "&C10&" CABLE" -> COST SHEET FOR 2 CORE 25 SQMM Aluminium CABLE
A50: ASSUMPTIONS | G50: CALCULATION - SCENARIO 1
...

Sheet Al LT Cables (2 x 35)
B1: =#REF! -> #REF! | C1: =SUM(D67:D72) -> 425.40385
B2: ="Cost Sheet for"&" "&C6&" Core"&" "&C9&" sq.mm"&" "&C10&" Cable" -> Cost Sheet for 2 Core 35 sq.mm Aluminium Cable
B4: Data Inputs
B6: No. of cores | C6: 2
B7: Shape of the core | C7: Sector shaped
B8: Conductor
B9: Conductor Size (in sq. mm) | C9: 35 | D9: sq. mm
B10: Conductor Material | C10: Aluminium | L10: =2*L9 -> 0
B11: Angle - Main | C11: =IF(C7="Sector shaped", (360/C6),360) -> 180
B12: Angle - Main | C12: =IF(C7="Sector shaped",360-C11*3,0) -> -180
B13: Conductor Radius | C13: =SQRT((C9*(360/C11))/PI()) -> 4.7203487 | D13: mm
B14: Density of Conductor | C14: =VLOOKUP(C10,Density1,2,0) -> 2.7 | D14: g/cm3
B16: Insulation
B17: Material | C17: XLPE
B18: Nominal thickness of insulation | C18: 0.9
B19: Calculated radius over insulation | C19: =IF(C7="Circular", C13+C18,C13+2*C18) -> 6.5203487 | D19: mm
B20: Density of Conductor | C20: =VLOOKUP(C17,Density,2,0) -> 0.93 | D20: g/cm3
B22: PVC Filler
B23: Filler Type | C23: PVC
B24: Area below inner sheath | C24: =PI()*((C31/2)^2) -> 174.36625 | D24: mm2
B25: Area till insulation | C25: =IF(C6=3.5,((C11/360)*PI()*(C19^2)*3)+((C12/360)*PI()*(C19^2)),(C11/360)*PI()*(C19^2)*C6) -> 133.56465 | D25: mm2
B26: Density | C26: =VLOOKUP(C23,Density,2,0) -> 1.35 | D26: g/cm3
B28: Inner Sheath
B29: Material | C29: PVC
B30: Minimum Thickness | C30: 0.3 | D30: mm
B31: Calculated diameter below innersheath | C31: =C37-2*C30 -> 14.9 | D31: mm
B32: Density of Conductor | C32: =VLOOKUP(C29,Density,2,0) -> 1.35 | D32: g/cm3
B34: Armour
B35: Material | C35: Unarmored
B36: Thickness of armour | C36: 0 | D36: mm
B37: Calculated diameter below armor | C37: =C43-2*C36 -> 15.5 | D37: mm
B38: Density of Conductor | C38: =VLOOKUP(C35,Armordensity,2,0) -> 0 | D38: g/cm3
B40: Outer Sheath
B41: Material | C41: PVC
B42: Minimum Thickness | C42: 2 | D42: mm
B43: Calculated diameter below outersheath | C43: =C46-(2*C42) -> 15.5 | D43: mm
B44: Density of Conductor | C44: =VLOOKUP(C41,Density,2,0) -> 1.35 | D44: g/cm3
B46: Overall OD of Cable | C46: 19.5
A48: ="COST SHEET FOR "&C6 & " CORE "&C9&" SQMM "&C10&" CABLE" -> COST SHEET FOR 2 CORE 35 SQMM Aluminium CABLE
A50: ASSUMPTIONS | G50: CALCULATION - SCENARIO 1
...

Sheet Al LT Cables (2 x 50)
B1: =#REF! -> #REF! | C1: =SUM(D67:D72) -> 546.99051
B2: ="Cost Sheet for"&" "&C6&" Core"&" "&C9&" sq.mm"&" "&C10&" Cable" -> Cost Sheet for 2 Core 50 sq.mm Aluminium Cable
B4: Data Inputs
B6: No. of cores | C6: 2
B7: Shape of the core | C7: Sector shaped
B8: Conductor
B9: Conductor Size (in sq. mm) | C9: 50 | D9: sq. mm
B10: Conductor Material | C10: Aluminium | L10: =2*L9 -> 0
B11: Angle - Main | C11: =IF(C7="Sector shaped", (360/C6),360) -> 180
B12: Angle - Main | C12: =IF(C7="Sector shaped",360-C11*3,0) -> -180
B13: Conductor Radius | C13: =SQRT((C9*(360/C11))/PI()) -> 5.6418958 | D13: mm
B14: Density of Conductor | C14: =VLOOKUP(C10,Density1,2,0) -> 2.7 | D14: g/cm3
B16: Insulation
B17: Material | C17: XLPE
B18: Nominal thickness of insulation | C18: 1
B19: Calculated radius over insulation | C19: =IF(C7="Circular", C13+C18,C13+2*C18) -> 7.6418958 | D19: mm
B20: Density of Conductor | C20: =VLOOKUP(C17,Density,2,0) -> 0.93 | D20: g/cm3
B22: PVC Filler
B23: Filler Type | C23: PVC
B24: Area below inner sheath | C24: =PI()*((C31/2)^2) -> 224.31757 | D24: mm2
B25: Area till insulation | C25: =IF(C6=3.5,((C11/360)*PI()*(C19^2)*3)+((C12/360)*PI()*(C19^2)),(C11/360)*PI()*(C19^2)*C6) -> 183.46452 | D25: mm2
B26: Density | C26: =VLOOKUP(C23,Density,2,0) -> 1.35 | D26: g/cm3
B28: Inner Sheath
B29: Material | C29: PVC
B30: Minimum Thickness | C30: 0.3 | D30: mm
B31: Calculated diameter below innersheath | C31: =C37-2*C30 -> 16.9 | D31: mm
B32: Density of Conductor | C32: =VLOOKUP(C29,Density,2,0) -> 1.35 | D32: g/cm3
B34: Armour
B35: Material | C35: Unarmored
B36: Thickness of armour | C36: 0 | D36: mm
B37: Calculated diameter below armor | C37: =C43-2*C36 -> 17.5 | D37: mm
B38: Density of Conductor | C38: =VLOOKUP(C35,Armordensity,2,0) -> 0 | D38: g/cm3
B40: Outer Sheath
B41: Material | C41: PVC
B42: Minimum Thickness | C42: 2 | D42: mm
B43: Calculated diameter below outersheath | C43: =C46-(2*C42) -> 17.5 | D43: mm
B44: Density of Conductor | C44: =VLOOKUP(C41,Density,2,0) -> 1.35 | D44: g/cm3
B46: Overall OD of Cable | C46: 21.5
A48: ="COST SHEET FOR "&C6 & " CORE "&C9&" SQMM "&C10&" CABLE" -> COST SHEET FOR 2 CORE 50 SQMM Aluminium CABLE
A50: ASSUMPTIONS | G50: CALCULATION - SCENARIO 1
...

Sheet Al LT Cables (2 x 70)
B1: =#REF! -> #REF! | C1: =SUM(D67:D72) -> 710.07202
B2: ="Cost Sheet for"&" "&C6&" Core"&" "&C9&" sq.mm"&" "&C10&" Cable" -> Cost Sheet for 2 Core 70 sq.mm Aluminium Cable
B4: Data Inputs
B6: No. of cores | C6: 2
B7: Shape of the core | C7: Sector shaped
B8: Conductor
B9: Conductor Size (in sq. mm) | C9: 70 | D9: sq. mm
B10: Conductor Material | C10: Aluminium | L10: =2*L9 -> 0
B11: Angle - Main | C11: =IF(C7="Sector shaped", (360/C6),360) -> 180
B12: Angle - Main | C12: =IF(C7="Sector shaped",360-C11*3,0) -> -180
B13: Conductor Radius | C13: =SQRT((C9*(360/C11))/PI()) -> 6.6755812 | D13: mm
B14: Density of Conductor | C14: =VLOOKUP(C10,Density1,2,0) -> 2.7 | D14: g/cm3
B16: Insulation
B17: Material | C17: XLPE
B18: Nominal thickness of insulation | C18: 1.1
B19: Calculated radius over insulation | C19: =IF(C7="Circular", C13+C18,C13+2*C18) -> 8.8755812 | D19: mm
B20: Density of Conductor | C20: =VLOOKUP(C17,Density,2,0) -> 0.93 | D20: g/cm3
B22: PVC Filler
B23: Filler Type | C23: PVC
B24: Area below inner sheath | C24: =PI()*((C31/2)^2) -> 311.02553 | D24: mm2
B25: Area till insulation | C25: =IF(C6=3.5,((C11/360)*PI()*(C19^2)*3)+((C12/360)*PI()*(C19^2)),(C11/360)*PI()*(C19^2)*C6) -> 247.48192 | D25: mm2
B26: Density | C26: =VLOOKUP(C23,Density,2,0) -> 1.35 | D26: g/cm3
B28: Inner Sheath
B29: Material | C29: PVC
B30: Minimum Thickness | C30: 0.3 | D30: mm
B31: Calculated diameter below innersheath | C31: =C37-2*C30 -> 19.9 | D31: mm
B32: Density of Conductor | C32: =VLOOKUP(C29,Density,2,0) -> 1.35 | D32: g/cm3
B34: Armour
B35: Material | C35: Unarmored
B36: Thickness of armour | C36: 0 | D36: mm
B37: Calculated diameter below armor | C37: =C43-2*C36 -> 20.5 | D37: mm
B38: Density of Conductor | C38: =VLOOKUP(C35,Armordensity,2,0) -> 0 | D38: g/cm3
B40: Outer Sheath
B41: Material | C41: PVC
B42: Minimum Thickness | C42: 2 | D42: mm
B43: Calculated diameter below outersheath | C43: =C46-(2*C42) -> 20.5 | D43: mm
B44: Density of Conductor | C44: =VLOOKUP(C41,Density,2,0) -> 1.35 | D44: g/cm3
B46: Overall OD of Cable | C46: 24.5
A48: ="COST SHEET FOR "&C6 & " CORE "&C9&" SQMM "&C10&" CABLE" -> COST SHEET FOR 2 CORE 70 SQMM Aluminium CABLE
A50: ASSUMPTIONS | G50: CALCULATION - SCENARIO 1
...

Sheet Al LT Cables (2 x 95)
B1: =#REF! -> #REF! | C1: =SUM(D67:D72) -> 921.77198
B2: ="Cost Sheet for"&" "&C6&" Core"&" "&C9&" sq.mm"&" "&C10&" Cable" -> Cost Sheet for 2 Core 95 sq.mm Aluminium Cable
B4: Data Inputs
B6: No. of cores | C6: 2
B7: Shape of the core | C7: Sector shaped
B8: Conductor
B9: Conductor Size (in sq. mm) | C9: 95 | D9: sq. mm
B10: Conductor Material | C10: Aluminium | L10: =2*L9 -> 0
B11: Angle - Main | C11: =IF(C7="Sector shaped", (360/C6),360) -> 180
B12: Angle - Main | C12: =IF(C7="Sector shaped",360-C11*3,0) -> -180
B13: Conductor Radius | C13: =SQRT((C9*(360/C11))/PI()) -> 7.7768167 | D13: mm
B14: Density of Conductor | C14: =VLOOKUP(C10,Density1,2,0) -> 2.7 | D14: g/cm3
B16: Insulation
B17: Material | C17: XLPE
B18: Nominal thickness of insulation | C18: 1.1
B19: Calculated radius over insulation | C19: =IF(C7="Circular", C13+C18,C13+2*C18) -> 9.9768167 | D19: mm
B20: Density of Conductor | C20: =VLOOKUP(C17,Density,2,0) -> 0.93 | D20: g/cm3
B22: PVC Filler
B23: Filler Type | C23: PVC
B24: Area below inner sheath | C24: =PI()*((C31/2)^2) -> 390.57065 | D24: mm2
B25: Area till insulation | C25: =IF(C6=3.5,((C11/360)*PI()*(C19^2)*3)+((C12/360)*PI()*(C19^2)),(C11/360)*PI()*(C19^2)*C6) -> 312.70431 | D25: mm2
B26: Density | C26: =VLOOKUP(C23,Density,2,0) -> 1.35 | D26: g/cm3
B28: Inner Sheath
B29: Material | C29: PVC
B30: Minimum Thickness | C30: 0.4 | D30: mm
B31: Calculated diameter below innersheath | C31: =C37-2*C30 -> 22.3 | D31: mm
B32: Density of Conductor | C32: =VLOOKUP(C29,Density,2,0) -> 1.35 | D32: g/cm3
B34: Armour
B35: Material | C35: Unarmored
B36: Thickness of armour | C36: 0 | D36: mm
B37: Calculated diameter below armor | C37: =C43-2*C36 -> 23.1 | D37: mm
B38: Density of Conductor | C38: =VLOOKUP(C35,Armordensity,2,0) -> 0 | D38: g/cm3
B40: Outer Sheath
B41: Material | C41: PVC
B42: Minimum Thickness | C42: 2.2 | D42: mm
B43: Calculated diameter below outersheath | C43: =C46-(2*C42) -> 23.1 | D43: mm
B44: Density of Conductor | C44: =VLOOKUP(C41,Density,2,0) -> 1.35 | D44: g/cm3
B46: Overall OD of Cable | C46: 27.5
A48: ="COST SHEET FOR "&C6 & " CORE "&C9&" SQMM "&C10&" CABLE" -> COST SHEET FOR 2 CORE 95 SQMM Aluminium CABLE
A50: ASSUMPTIONS | G50: CALCULATION - SCENARIO 1
...

Sheet Al LT Cables (2 x 120)
B1: =#REF! -> #REF! | C1: =SUM(D67:D72) -> 1113.6717
B2: ="Cost Sheet for"&" "&C6&" Core"&" "&C9&" sq.mm"&" "&C10&" Cable" -> Cost Sheet for 2 Core 120 sq.mm Aluminium Cable
B4: Data Inputs
B6: No. of cores | C6: 2
B7: Shape of the core | C7: Sector shaped
B8: Conductor
B9: Conductor Size (in sq. mm) | C9: 120 | D9: sq. mm
B10: Conductor Material | C10: Aluminium | L10: =2*L9 -> 0
B11: Angle - Main | C11: =IF(C7="Sector shaped", (360/C6),360) -> 180
B12: Angle - Main | C12: =IF(C7="Sector shaped",360-C11*3,0) -> -180
B13: Conductor Radius | C13: =SQRT((C9*(360/C11))/PI()) -> 8.7403874 | D13: mm
B14: Density of Conductor | C14: =VLOOKUP(C10,Density1,2,0) -> 2.7 | D14: g/cm3
B16: Insulation
B17: Material | C17: XLPE
B18: Nominal thickness of insulation | C18: 1.2
B19: Calculated radius over insulation | C19: =IF(C7="Circular", C13+C18,C13+2*C18) -> 11.140387 | D19: mm
B20: Density of Conductor | C20: =VLOOKUP(C17,Density,2,0) -> 0.93 | D20: g/cm3
B22: PVC Filler
B23: Filler Type | C23: PVC
B24: Area below inner sheath | C24: =PI()*((C31/2)^2) -> 483.05129 | D24: mm2
B25: Area till insulation | C25: =IF(C6=3.5,((C11/360)*PI()*(C19^2)*3)+((C12/360)*PI()*(C19^2)),(C11/360)*PI()*(C19^2)*C6) -> 389.89751 | D25: mm2
B26: Density | C26: =VLOOKUP(C23,Density,2,0) -> 1.35 | D26: g/cm3
B28: Inner Sheath
B29: Material | C29: PVC
B30: Minimum Thickness | C30: 0.4 | D30: mm
B31: Calculated diameter below innersheath | C31: =C37-2*C30 -> 24.8 | D31: mm
B32: Density of Conductor | C32: =VLOOKUP(C29,Density,2,0) -> 1.35 | D32: g/cm3
B34: Armour
B35: Material | C35: Unarmored
B36: Thickness of armour | C36: 0 | D36: mm
B37: Calculated diameter below armor | C37: =C43-2*C36 -> 25.6 | D37: mm
B38: Density of Conductor | C38: =VLOOKUP(C35,Armordensity,2,0) -> 0 | D38: g/cm3
B40: Outer Sheath
B41: Material | C41: PVC
B42: Minimum Thickness | C42: 2.2 | D42: mm
B43: Calculated diameter below outersheath | C43: =C46-(2*C42) -> 25.6 | D43: mm
B44: Density of Conductor | C44: =VLOOKUP(C41,Density,2,0) -> 1.35 | D44: g/cm3
B46: Overall OD of Cable | C46: 30
A48: ="COST SHEET FOR "&C6 & " CORE "&C9&" SQMM "&C10&" CABLE" -> COST SHEET FOR 2 CORE 120 SQMM Aluminium CABLE
A50: ASSUMPTIONS | G50: CALCULATION - SCENARIO 1
...

Sheet Al LT Cables (2 x 150)
B1: =#REF! -> #REF! | C1: =SUM(D67:D72) -> 1345.9521
B2: ="Cost Sheet for"&" "&C6&" Core"&" "&C9&" sq.mm"&" "&C10&" Cable" -> Cost Sheet for 2 Core 150 sq.mm Aluminium Cable
B4: Data Inputs
B6: No. of cores | C6: 2
B7: Shape of the core | C7: Sector shaped
B8: Conductor
B9: Conductor Size (in sq. mm) | C9: 150 | D9: sq. mm
B10: Conductor Material | C10: Aluminium | L10: =2*L9 -> 0
B11: Angle - Main | C11: =IF(C7="Sector shaped", (360/C6),360) -> 180
B12: Angle - Main | C12: =IF(C7="Sector shaped",360-C11*3,0) -> -180
B13: Conductor Radius | C13: =SQRT((C9*(360/C11))/PI()) -> 9.7720502 | D13: mm
B14: Density of Conductor | C14: =VLOOKUP(C10,Density1,2,0) -> 2.7 | D14: g/cm3
B16: Insulation
B17: Material | C17: XLPE
B18: Nominal thickness of insulation | C18: 1.4
B19: Calculated radius over insulation | C19: =IF(C7="Circular", C13+C18,C13+2*C18) -> 12.57205 | D19: mm
B20: Density of Conductor | C20: =VLOOKUP(C17,Density,2,0) -> 0.93 | D20: g/cm3
B22: PVC Filler
B23: Filler Type | C23: PVC
B24: Area below inner sheath | C24: =PI()*((C31/2)^2) -> 564.10438 | D24: mm2
B25: Area till insulation | C25: =IF(C6=3.5,((C11/360)*PI()*(C19^2)*3)+((C12/360)*PI()*(C19^2)),(C11/360)*PI()*(C19^2)*C6) -> 496.54897 | D25: mm2
B26: Density | C26: =VLOOKUP(C23,Density,2,0) -> 1.35 | D26: g/cm3
B28: Inner Sheath
B29: Material | C29: PVC
B30: Minimum Thickness | C30: 0.4 | D30: mm
B31: Calculated diameter below innersheath | C31: =C37-2*C30 -> 26.8 | D31: mm
B32: Density of Conductor | C32: =VLOOKUP(C29,Density,2,0) -> 1.35 | D32: g/cm3
B34: Armour
B35: Material | C35: Unarmored
B36: Thickness of armour | C36: 0 | D36: mm
B37: Calculated diameter below armor | C37: =C43-2*C36 -> 27.6 | D37: mm
B38: Density of Conductor | C38: =VLOOKUP(C35,Armordensity,2,0) -> 0 | D38: g/cm3
B40: Outer Sheath
B41: Material | C41: PVC
B42: Minimum Thickness | C42: 2.2 | D42: mm
B43: Calculated diameter below outersheath | C43: =C46-(2*C42) -> 27.6 | D43: mm
B44: Density of Conductor | C44: =VLOOKUP(C41,Density,2,0) -> 1.35 | D44: g/cm3
B46: Overall OD of Cable | C46: 32
A48: ="COST SHEET FOR "&C6 & " CORE "&C9&" SQMM "&C10&" CABLE" -> COST SHEET FOR 2 CORE 150 SQMM Aluminium CABLE
A50: ASSUMPTIONS | G50: CALCULATION - SCENARIO 1
...

Sheet Al LT Cables (2 x 185)
B1: =#REF! -> #REF! | C1: =SUM(D67:D72) -> 1668.7281
B2: ="Cost Sheet for"&" "&C6&" Core"&" "&C9&" sq.mm"&" "&C10&" Cable" -> Cost Sheet for 2 Core 185 sq.mm Aluminium Cable
B4: Data Inputs
B6: No. of cores | C6: 2
B7: Shape of the core | C7: Sector shaped
B8: Conductor
B9: Conductor Size (in sq. mm) | C9: 185 | D9: sq. mm
B10: Conductor Material | C10: Aluminium | L10: =2*L9 -> 0
B11: Angle - Main | C11: =IF(C7="Sector shaped", (360/C6),360) -> 180
B12: Angle - Main | C12: =IF(C7="Sector shaped",360-C11*3,0) -> -180
B13: Conductor Radius | C13: =SQRT((C9*(360/C11))/PI()) -> 10.852403 | D13: mm
B14: Density of Conductor | C14: =VLOOKUP(C10,Density1,2,0) -> 2.7 | D14: g/cm3
B16: Insulation
B17: Material | C17: XLPE
B18: Nominal thickness of insulation | C18: 1.6
B19: Calculated radius over insulation | C19: =IF(C7="Circular", C13+C18,C13+2*C18) -> 14.052403 | D19: mm
B20: Density of Conductor | C20: =VLOOKUP(C17,Density,2,0) -> 0.93 | D20: g/cm3
B22: PVC Filler
B23: Filler Type | C23: PVC
B24: Area below inner sheath | C24: =PI()*((C31/2)^2) -> 692.79187 | D24: mm2
B25: Area till insulation | C25: =IF(C6=3.5,((C11/360)*PI()*(C19^2)*3)+((C12/360)*PI()*(C19^2)),(C11/360)*PI()*(C19^2)*C6) -> 620.37042 | D25: mm2
B26: Density | C26: =VLOOKUP(C23,Density,2,0) -> 1.35 | D26: g/cm3
B28: Inner Sheath
B29: Material | C29: PVC
B30: Minimum Thickness | C30: 0.5 | D30: mm
B31: Calculated diameter below innersheath | C31: =C37-2*C30 -> 29.7 | D31: mm
B32: Density of Conductor | C32: =VLOOKUP(C29,Density,2,0) -> 1.35 | D32: g/cm3
B34: Armour
B35: Material | C35: Unarmored
B36: Thickness of armour | C36: 0 | D36: mm
B37: Calculated diameter below armor | C37: =C43-2*C36 -> 30.7 | D37: mm
B38: Density of Conductor | C38: =VLOOKUP(C35,Armordensity,2,0) -> 0 | D38: g/cm3
B40: Outer Sheath
B41: Material | C41: PVC
B42: Minimum Thickness | C42: 2.4 | D42: mm
B43: Calculated diameter below outersheath | C43: =C46-(2*C42) -> 30.7 | D43: mm
B44: Density of Conductor | C44: =VLOOKUP(C41,Density,2,0) -> 1.35 | D44: g/cm3
B46: Overall OD of Cable | C46: 35.5
A48: ="COST SHEET FOR "&C6 & " CORE "&C9&" SQMM "&C10&" CABLE" -> COST SHEET FOR 2 CORE 185 SQMM Aluminium CABLE
A50: ASSUMPTIONS | G50: CALCULATION - SCENARIO 1
...

Sheet Al LT Cables (2 x 240)
B1: =#REF! -> #REF! | C1: =SUM(D67:D72) -> 2105.6908
B2: ="Cost Sheet for"&" "&C6&" Core"&" "&C9&" sq.mm"&" "&C10&" Cable" -> Cost Sheet for 2 Core 240 sq.mm Aluminium Cable
B4: Data Inputs
B6: No. of cores | C6: 2
B7: Shape of the core | C7: Sector shaped
B8: Conductor
B9: Conductor Size (in sq. mm) | C9: 240 | D9: sq. mm
B10: Conductor Material | C10: Aluminium | L10: =2*L9 -> 0
B11: Angle - Main | C11: =IF(C7="Sector shaped", (360/C6),360) -> 180
B12: Angle - Main | C12: =IF(C7="Sector shaped",360-C11*3,0) -> -180
B13: Conductor Radius | C13: =SQRT((C9*(360/C11))/PI()) -> 12.360774 | D13: mm
B14: Density of Conductor | C14: =VLOOKUP(C10,Density1,2,0) -> 2.7 | D14: g/cm3
B16: Insulation
B17: Material | C17: XLPE
B18: Nominal thickness of insulation | C18: 1.7
B19: Calculated radius over insulation | C19: =IF(C7="Circular", C13+C18,C13+2*C18) -> 15.760774 | D19: mm
B20: Density of Conductor | C20: =VLOOKUP(C17,Density,2,0) -> 0.93 | D20: g/cm3
B22: PVC Filler
B23: Filler Type | C23: PVC
B24: Area below inner sheath | C24: =PI()*((C31/2)^2) -> 897.27028 | D24: mm2
B25: Area till insulation | C25: =IF(C6=3.5,((C11/360)*PI()*(C19^2)*3)+((C12/360)*PI()*(C19^2)),(C11/360)*PI()*(C19^2)*C6) -> 780.37794 | D25: mm2
B26: Density | C26: =VLOOKUP(C23,Density,2,0) -> 1.35 | D26: g/cm3
B28: Inner Sheath
B29: Material | C29: PVC
B30: Minimum Thickness | C30: 0.5 | D30: mm
B31: Calculated diameter below innersheath | C31: =C37-2*C30 -> 33.8 | D31: mm
B32: Density of Conductor | C32: =VLOOKUP(C29,Density,2,0) -> 1.35 | D32: g/cm3
B34: Armour
B35: Material | C35: Unarmored
B36: Thickness of armour | C36: 0 | D36: mm
B37: Calculated diameter below armor | C37: =C43-2*C36 -> 34.8 | D37: mm
B38: Density of Conductor | C38: =VLOOKUP(C35,Armordensity,2,0) -> 0 | D38: g/cm3
B40: Outer Sheath
B41: Material | C41: PVC
B42: Minimum Thickness | C42: 2.6 | D42: mm
B43: Calculated diameter below outersheath | C43: =C46-(2*C42) -> 34.8 | D43: mm
B44: Density of Conductor | C44: =VLOOKUP(C41,Density,2,0) -> 1.35 | D44: g/cm3
B46: Overall OD of Cable | C46: 40
A48: ="COST SHEET FOR "&C6 & " CORE "&C9&" SQMM "&C10&" CABLE" -> COST SHEET FOR 2 CORE 240 SQMM Aluminium CABLE
A50: ASSUMPTIONS | G50: CALCULATION - SCENARIO 1
...

Sheet Al LT Cables (3 x 6)
B1: =#REF! -> #REF! | C1: =SUM(D67:D72) -> 188.76625
B2: ="Cost Sheet for"&" "&C6&" Core"&" "&C9&" sq.mm"&" "&C10&" Cable" -> Cost Sheet for 3 Core 6 sq.mm Aluminium Cable
B4: Data Inputs
B6: No. of cores | C6: 3
B7: Shape of the core | C7: Sector shaped
B8: Conductor
B9: Conductor Size (in sq. mm) | C9: 6 | D9: sq. mm
B10: Conductor Material | C10: Aluminium | L10: =2*L9 -> 0
B11: Angle - Main | C11: =IF(C7="Sector shaped", (360/C6),360) -> 120
B12: Angle - Main | C12: =IF(C7="Sector shaped",360-C11*3,0) -> 0
B13: Conductor Radius | C13: =SQRT((C9*(360/C11))/PI()) -> 2.3936537 | D13: mm
B14: Density of Conductor | C14: =VLOOKUP(C10,Density1,2,0) -> 2.7 | D14: g/cm3
B16: Insulation
B17: Material | C17: XLPE
B18: Nominal thickness of insulation | C18: 0.7
B19: Calculated radius over insulation | C19: =IF(C7="Circular", C13+C18,C13+2*C18) -> 3.7936537 | D19: mm
B20: Density of Conductor | C20: =VLOOKUP(C17,Density,2,0) -> 0.93 | D20: g/cm3
B22: PVC Filler
B23: Filler Type | C23: PVC
B24: Area below inner sheath | C24: =PI()*((C31/2)^2) -> 83.322891 | D24: mm2
B25: Area till insulation | C25: =IF(C6=3.5,((C11/360)*PI()*(C19^2)*3)+((C12/360)*PI()*(C19^2)),(C11/360)*PI()*(C19^2)*C6) -> 45.213199 | D25: mm2
B26: Density | C26: =VLOOKUP(C23,Density,2,0) -> 1.35 | D26: g/cm3
B28: Inner Sheath
B29: Material | C29: PVC
B30: Minimum Thickness | C30: 0.3 | D30: mm
B31: Calculated diameter below innersheath | C31: =C37-2*C30 -> 10.3 | D31: mm
B32: Density of Conductor | C32: =VLOOKUP(C29,Density,2,0) -> 1.35 | D32: g/cm3
B34: Armour
B35: Material | C35: Unarmored
B36: Thickness of armour | C36: 0 | D36: mm
B37: Calculated diameter below armor | C37: =C43-2*C36 -> 10.9 | D37: mm
B38: Density of Conductor | C38: =VLOOKUP(C35,Armordensity,2,0) -> 0 | D38: g/cm3
B40: Outer Sheath
B41: Material | C41: PVC
B42: Minimum Thickness | C42: 1.8 | D42: mm
B43: Calculated diameter below outersheath | C43: =C46-(2*C42) -> 10.9 | D43: mm
B44: Density of Conductor | C44: =VLOOKUP(C41,Density,2,0) -> 1.35 | D44: g/cm3
B46: Overall OD of Cable | C46: 14.5
A48: ="COST SHEET FOR "&C6 & " CORE "&C9&" SQMM "&C10&" CABLE" -> COST SHEET FOR 3 CORE 6 SQMM Aluminium CABLE
A50: ASSUMPTIONS | G50: CALCULATION - SCENARIO 1
...

Sheet Al LT Cables (3 x 10)
B1: =#REF! -> #REF! | C1: =SUM(D67:D72) -> 245.93709
B2: ="Cost Sheet for"&" "&C6&" Core"&" "&C9&" sq.mm"&" "&C10&" Cable" -> Cost Sheet for 3 Core 10 sq.mm Aluminium Cable
B4: Data Inputs
B6: No. of cores | C6: 3
B7: Shape of the core | C7: Sector shaped
B8: Conductor
B9: Conductor Size (in sq. mm) | C9: 10 | D9: sq. mm
B10: Conductor Material | C10: Aluminium | L10: =2*L9 -> 0
B11: Angle - Main | C11: =IF(C7="Sector shaped", (360/C6),360) -> 120
B12: Angle - Main | C12: =IF(C7="Sector shaped",360-C11*3,0) -> 0
B13: Conductor Radius | C13: =SQRT((C9*(360/C11))/PI()) -> 3.0901936 | D13: mm
B14: Density of Conductor | C14: =VLOOKUP(C10,Density1,2,0) -> 2.7 | D14: g/cm3
B16: Insulation
B17: Material | C17: XLPE
B18: Nominal thickness of insulation | C18: 0.7
B19: Calculated radius over insulation | C19: =IF(C7="Circular", C13+C18,C13+2*C18) -> 4.4901936 | D19: mm
B20: Density of Conductor | C20: =VLOOKUP(C17,Density,2,0) -> 0.93 | D20: g/cm3
B22: PVC Filler
B23: Filler Type | C23: PVC
B24: Area below inner sheath | C24: =PI()*((C31/2)^2) -> 118.82289 | D24: mm2
B25: Area till insulation | C25: =IF(C6=3.5,((C11/360)*PI()*(C19^2)*3)+((C12/360)*PI()*(C19^2)),(C11/360)*PI()*(C19^2)*C6) -> 63.340284 | D25: mm2
B26: Density | C26: =VLOOKUP(C23,Density,2,0) -> 1.35 | D26: g/cm3
B28: Inner Sheath
B29: Material | C29: PVC
B30: Minimum Thickness | C30: 0.3 | D30: mm
B31: Calculated diameter below innersheath | C31: =C37-2*C30 -> 12.3 | D31: mm
B32: Density of Conductor | C32: =VLOOKUP(C29,Density,2,0) -> 1.35 | D32: g/cm3
B34: Armour
B35: Material | C35: Unarmored
B36: Thickness of armour | C36: 0 | D36: mm
B37: Calculated diameter below armor | C37: =C43-2*C36 -> 12.9 | D37: mm
B38: Density of Conductor | C38: =VLOOKUP(C35,Armordensity,2,0) -> 0 | D38: g/cm3
B40: Outer Sheath
B41: Material | C41: PVC
B42: Minimum Thickness | C42: 1.8 | D42: mm
B43: Calculated diameter below outersheath | C43: =C46-(2*C42) -> 12.9 | D43: mm
B44: Density of Conductor | C44: =VLOOKUP(C41,Density,2,0) -> 1.35 | D44: g/cm3
B46: Overall OD of Cable | C46: 16.5
A48: ="COST SHEET FOR "&C6 & " CORE "&C9&" SQMM "&C10&" CABLE" -> COST SHEET FOR 3 CORE 10 SQMM Aluminium CABLE
A50: ASSUMPTIONS | G50: CALCULATION - SCENARIO 1
...

Sheet Al LT Cables (3 x 16)
B1: =#REF! -> #REF! | C1: =SUM(D67:D72) -> 306.91676
B2: ="Cost Sheet for"&" "&C6&" Core"&" "&C9&" sq.mm"&" "&C10&" Cable" -> Cost Sheet for 3 Core 16 sq.mm Aluminium Cable
B4: Data Inputs
B6: No. of cores | C6: 3
B7: Shape of the core | C7: Sector shaped
B8: Conductor
B9: Conductor Size (in sq. mm) | C9: 16 | D9: sq. mm
B10: Conductor Material | C10: Aluminium | L10: =2*L9 -> 0
B11: Angle - Main | C11: =IF(C7="Sector shaped", (360/C6),360) -> 120
B12: Angle - Main | C12: =IF(C7="Sector shaped",360-C11*3,0) -> 0
B13: Conductor Radius | C13: =SQRT((C9*(360/C11))/PI()) -> 3.9088201 | D13: mm
B14: Density of Conductor | C14: =VLOOKUP(C10,Density1,2,0) -> 2.7 | D14: g/cm3
B16: Insulation
B17: Material | C17: XLPE
B18: Nominal thickness of insulation | C18: 0.7
B19: Calculated radius over insulation | C19: =IF(C7="Circular", C13+C18,C13+2*C18) -> 5.3088201 | D19: mm
B20: Density of Conductor | C20: =VLOOKUP(C17,Density,2,0) -> 0.93 | D20: g/cm3
B22: PVC Filler
B23: Filler Type | C23: PVC
B24: Area below inner sheath | C24: =PI()*((C31/2)^2) -> 128.67964 | D24: mm2
B25: Area till insulation | C25: =IF(C6=3.5,((C11/360)*PI()*(C19^2)*3)+((C12/360)*PI()*(C19^2)),(C11/360)*PI()*(C19^2)*C6) -> 88.541299 | D25: mm2
B26: Density | C26: =VLOOKUP(C23,Density,2,0) -> 1.35 | D26: g/cm3
B28: Inner Sheath
B29: Material | C29: PVC
B30: Minimum Thickness | C30: 0.3 | D30: mm
B31: Calculated diameter below innersheath | C31: =C37-2*C30 -> 12.8 | D31: mm
B32: Density of Conductor | C32: =VLOOKUP(C29,Density,2,0) -> 1.35 | D32: g/cm3
B34: Armour
B35: Material | C35: Unarmored
B36: Thickness of armour | C36: 0 | D36: mm
B37: Calculated diameter below armor | C37: =C43-2*C36 -> 13.4 | D37: mm
B38: Density of Conductor | C38: =VLOOKUP(C35,Armordensity,2,0) -> 0 | D38: g/cm3
B40: Outer Sheath
B41: Material | C41: PVC
B42: Minimum Thickness | C42: 1.8 | D42: mm
B43: Calculated diameter below outersheath | C43: =C46-(2*C42) -> 13.4 | D43: mm
B44: Density of Conductor | C44: =VLOOKUP(C41,Density,2,0) -> 1.35 | D44: g/cm3
B46: Overall OD of Cable | C46: 17
A48: ="COST SHEET FOR "&C6 & " CORE "&C9&" SQMM "&C10&" CABLE" -> COST SHEET FOR 3 CORE 16 SQMM Aluminium CABLE
A50: ASSUMPTIONS | G50: CALCULATION - SCENARIO 1
...

Sheet Al LT Cables (3 x 25)
B1: =#REF! -> #REF! | C1: =SUM(D67:D72) -> 445.96622
B2: ="Cost Sheet for"&" "&C6&" Core"&" "&C9&" sq.mm"&" "&C10&" Cable" -> Cost Sheet for 3 Core 25 sq.mm Aluminium Cable
B4: Data Inputs
B6: No. of cores | C6: 3
B7: Shape of the core | C7: Sector shaped
B8: Conductor
B9: Conductor Size (in sq. mm) | C9: 25 | D9: sq. mm
B10: Conductor Material | C10: Aluminium | L10: =2*L9 -> 0
B11: Angle - Main | C11: =IF(C7="Sector shaped", (360/C6),360) -> 120
B12: Angle - Main | C12: =IF(C7="Sector shaped",360-C11*3,0) -> 0
B13: Conductor Radius | C13: =SQRT((C9*(360/C11))/PI()) -> 4.8860251 | D13: mm
B14: Density of Conductor | C14: =VLOOKUP(C10,Density1,2,0) -> 2.7 | D14: g/cm3
B16: Insulation
B17: Material | C17: XLPE
B18: Nominal thickness of insulation | C18: 0.9
B19: Calculated radius over insulation | C19: =IF(C7="Circular", C13+C18,C13+2*C18) -> 6.6860251 | D19: mm
B20: Density of Conductor | C20: =VLOOKUP(C17,Density,2,0) -> 0.93 | D20: g/cm3
B22: PVC Filler
B23: Filler Type | C23: PVC
B24: Area below inner sheath | C24: =PI()*((C31/2)^2) -> 186.26503 | D24: mm2
B25: Area till insulation | C25: =IF(C6=3.5,((C11/360)*PI()*(C19^2)*3)+((C12/360)*PI()*(C19^2)),(C11/360)*PI()*(C19^2)*C6) -> 140.4384 | D25: mm2
B26: Density | C26: =VLOOKUP(C23,Density,2,0) -> 1.35 | D26: g/cm3
B28: Inner Sheath
B29: Material | C29: PVC
B30: Minimum Thickness | C30: 0.3 | D30: mm
B31: Calculated diameter below innersheath | C31: =C37-2*C30 -> 15.4 | D31: mm
B32: Density of Conductor | C32: =VLOOKUP(C29,Density,2,0) -> 1.35 | D32: g/cm3
B34: Armour
B35: Material | C35: Unarmored
B36: Thickness of armour | C36: 0 | D36: mm
B37: Calculated diameter below armor | C37: =C43-2*C36 -> 16 | D37: mm
B38: Density of Conductor | C38: =VLOOKUP(C35,Armordensity,2,0) -> 0 | D38: g/cm3
B40: Outer Sheath
B41: Material | C41: PVC
B42: Minimum Thickness | C42: 2 | D42: mm
B43: Calculated diameter below outersheath | C43: =C46-(2*C42) -> 16 | D43: mm
B44: Density of Conductor | C44: =VLOOKUP(C41,Density,2,0) -> 1.35 | D44: g/cm3
B46: Overall OD of Cable | C46: 20
A48: ="COST SHEET FOR "&C6 & " CORE "&C9&" SQMM "&C10&" CABLE" -> COST SHEET FOR 3 CORE 25 SQMM Aluminium CABLE
A50: ASSUMPTIONS | G50: CALCULATION - SCENARIO 1
...

Sheet Al LT Cables (3 x 35)
B1: =#REF! -> #REF! | C1: =SUM(D67:D72) -> 558.25014
B2: ="Cost Sheet for"&" "&C6&" Core"&" "&C9&" sq.mm"&" "&C10&" Cable" -> Cost Sheet for 3 Core 35 sq.mm Aluminium Cable
B4: Data Inputs
B6: No. of cores | C6: 3
B7: Shape of the core | C7: Sector shaped
B8: Conductor
B9: Conductor Size (in sq. mm) | C9: 35 | D9: sq. mm
B10: Conductor Material | C10: Aluminium | L10: =2*L9 -> 0
B11: Angle - Main | C11: =IF(C7="Sector shaped", (360/C6),360) -> 120
B12: Angle - Main | C12: =IF(C7="Sector shaped",360-C11*3,0) -> 0
B13: Conductor Radius | C13: =SQRT((C9*(360/C11))/PI()) -> 5.7812229 | D13: mm
B14: Density of Conductor | C14: =VLOOKUP(C10,Density1,2,0) -> 2.7 | D14: g/cm3
B16: Insulation
B17: Material | C17: XLPE
B18: Nominal thickness of insulation | C18: 0.9
B19: Calculated radius over insulation | C19: =IF(C7="Circular", C13+C18,C13+2*C18) -> 7.5812229 | D19: mm
B20: Density of Conductor | C20: =VLOOKUP(C17,Density,2,0) -> 0.93 | D20: g/cm3
B22: PVC Filler
B23: Filler Type | C23: PVC
B24: Area below inner sheath | C24: =PI()*((C31/2)^2) -> 237.78715 | D24: mm2
B25: Area till insulation | C25: =IF(C6=3.5,((C11/360)*PI()*(C19^2)*3)+((C12/360)*PI()*(C19^2)),(C11/360)*PI()*(C19^2)*C6) -> 180.56285 | D25: mm2
B26: Density | C26: =VLOOKUP(C23,Density,2,0) -> 1.35 | D26: g/cm3
B28: Inner Sheath
B29: Material | C29: PVC
B30: Minimum Thickness | C30: 0.3 | D30: mm
B31: Calculated diameter below innersheath | C31: =C37-2*C30 -> 17.4 | D31: mm
B32: Density of Conductor | C32: =VLOOKUP(C29,Density,2,0) -> 1.35 | D32: g/cm3
B34: Armour
B35: Material | C35: Unarmored
B36: Thickness of armour | C36: 0 | D36: mm
B37: Calculated diameter below armor | C37: =C43-2*C36 -> 18 | D37: mm
B38: Density of Conductor | C38: =VLOOKUP(C35,Armordensity,2,0) -> 0 | D38: g/cm3
B40: Outer Sheath
